Workbook

Sheet PO
Z1: CONFIDENTIAL
A10: TO | B10: ` | D10: : | E10: PT. JATIM AUTOCOMP | R10: REF | U10: : | X10: : | AA10: - | AD10: /
E11: INDONESIA | R11: DATE | U11: : | V11: =+'List Order'!C1 -> 46091
A12: ATTN | D12: : | E12: MR. AVIF | R12: PAGE | U12: : | V12: 1 | Z12: attached sheet : | AE12: 1 | AG12: / | AH12: 1
A13: CC | D13: : | E13: MR. WAHYUDI
A14: FROM | D14: : | E14: MRS. RARAS | R14: CC | U14: : | V14: MRS. DIANA , MR. NOBUHISA DAKIIWA
L16: PURCHASE ORDER
H18: Please find attached
H19: Order Number | M19: Requested ETA | T19: Shipment
M20: Surabaya on or about | T20: will be through
H21: JL60421 | M21: 46119 | T21: TRUCKING
H22: JL60422 | M22: 46120 | T22: TRUCKING
H23: JL60431 | M23: 46126 | T23: TRUCKING
H24: JL60432 | M24: 46127 | T24: TRUCKING
H25: JL60441 | M25: 46133 | T25: TRUCKING
H26: JL60442 | M26: 46134 | T26: TRUCKING
H27: JL60451 | M27: 46140 | T27: TRUCKING
H28: JL60452 | M28: 46141 | T28: TRUCKING
H34: We request that all products delivery to SAI is SoC free in accordance with
H35: EU End of Life Vehicle Directive for Substance of Concern materials as follows :
H43: Please sign below and send back this page to us by fax transmission
H44: on the following day after acceptance of this order
H45: With kind regards, | X45: Confirmation of Acceptance
H49: RARAS AYUSWANTI | X49: AVIF PRIMA
H50: Inventory Control Supervisor
Q53: NOBUHISA DAKIIWA
Q54: Senior Manager Logistic

Sheet List Order
A1: SEND DATE: | C1: 46091 | AD1: 27 | AE1: =+AD1+2 -> 29 | AF1: =+AE1+2 -> 31 | AG1: =+AF1+2 -> 33 | AH1: =+AG1+2 -> 35 | AI1: =+AH1+2 -> 37 | AJ1: =+AI1+2 -> 39 | AK1: =+AJ1+2 -> 41 | AL1: =+AK1+2 -> 43 | ... AY1: =+AX1+2 -> 69 | BF1: 69 | BG1: =+BF1+11 -> 80 | BH1: Remarks
B2: 1 | C2: =+B2+1 -> 2 | D2: =+C2+1 -> 3 | E2: =+D2+1 -> 4 | F2: =+E2+1 -> 5 | G2: =+F2+1 -> 6 | H2: =+G2+1 -> 7 | I2: =+H2+1 -> 8 | J2: =+I2+1 -> 9 | ... BG2: =+BF2+1 -> 58
A3: < ORDER SHEET >
E4: FIRM JAN W1 | G4: FIRM JAN W2 | I4: FIRM JAN W3 | K4: FIRM JAN W4 | M4: FIRM FEB W1 | O4: FIRM FEB W2 | Q4: FIRM FEB W3 | S4: FIRM FEB W4 | U4: FIRM MAR W1 | W4: FIRM MAR W2 | Y4: FIRM MAR W3 | AA4: FIRM APRIL W1 | AB4: FIRM APRIL W2 | AD4: FORECAST APRIL W3 | AF4: FORECAST APRIL W4 | AH4: FORECAST APRIL W5 | AJ4: FORECAST MAY W1 | AL4: FORECAST MAY W2 | AN4: FORECAST MAY W3 | AP4: FORECAST JUNE W1 | AR4: FORECAST JUNE W2 | AT4: FORECAST JUNE W3 | AV4: FORECAST JUNE W4 | AX4: FORECAST JUNE W5 | AZ4: TOTAL FORECAST JAN 2026 | BA4: TOTAL FORECAST FEB 2026 | BB4: TOTAL FORECAST MAR 2026 | BC4: TOTAL FORECAST APR 2026 | BD4: TOTAL FORECAST MAY 2026 | BE4: TOTAL FORECAST JUN 2026 | BF4: TOTAL FORECAST JUL 2026 | BG4: TOTAL FORECAST AUG 2026
A5: SHIP BY : | E5: TRUCK | F5: TRUCK | G5: TRUCK | H5: TRUCK | I5: TRUCK | J5: TRUCK | K5: TRUCK | L5: TRUCK | M5: TRUCK | N5: TRUCK | O5: TRUCK | P5: TRUCK | Q5: TRUCK | R5: TRUCK | S5: TRUCK | T5: TRUCK | U5: TRUCK | V5: TRUCK | W5: TRUCK | X5: TRUCK | Y5: TRUCK | Z5: TRUCK | AA5: TRUCK | AB5: TRUCK | AC5: TRUCK | AD5: TRUCK | AE5: TRUCK | AF5: TRUCK | AG5: TRUCK | AH5: TRUCK | AI5: TRUCK | AJ5: TRUCK | AK5: TRUCK | AL5: TRUCK | AM5: TRUCK | AN5: TRUCK | AO5: TRUCK | AP5: TRUCK | AQ5: TRUCK | AR5: TRUCK | AS5: TRUCK | AT5: TRUCK | AU5: TRUCK | AV5: TRUCK | AW5: TRUCK | AX5: TRUCK | AY5: TRUCK
A6: P/O #: | E6: JL60111 | F6: JL60112 | G6: JL60121 | H6: JL60122 | I6: JL60131 | J6: JL60132 | K6: JL60141 | L6: JL60142 | M6: JL60211 | N6: JL60212 | O6: JL60221 | P6: JL60222 | Q6: JL60231 | R6: JL60232 | S6: JL60241 | T6: JL60242 | U6: JL60311 | V6: JL60312 | W6: JL60321 | X6: JL60322 | Y6: JL60331 | Z6: JL60332 | AA6: JL60411 | AB6: JL60421 | AC6: JL60422 | AD6: JL60431 | AE6: JL60432 | AF6: JL60441 | AG6: JL60442 | AH6: JL60451 | AI6: JL60452 | AJ6: JL60511 | AK6: JL60512 | AL6: JL60521 | AM6: JL60522 | AN6: JL60531 | AO6: JL60532 | AP6: JL60611 | AQ6: JL60612 | AR6: JL60621 | AS6: JL60622 | AT6: JL60631 | AU6: JL60632 | AV6: JL60641 | AW6: JL60642 | AX6: JL60651 | AY6: JL60652
E7: JL60111A | H7: JL60122A | P7: JL60222A | T7: JL60242A | U7: JL60311A | X7: JL60322A | Y7: JL60331A
Y8: JL60331B
A9: ETD : JAI | E9: 46028 | F9: 46029 | G9: 46035 | H9: 46036 | I9: 46042 | J9: 46043 | K9: 46049 | L9: 46050 | M9: 46056 | N9: 46057 | O9: 46063 | P9: 46064 | Q9: 46071 | R9: 46072 | S9: 46077 | T9: 46078 | U9: 46084 | V9: 46085 | W9: 46091 | X9: 46092 | Y9: 46098 | Z9: 46099 | AA9: 46113 | AB9: 46119 | AC9: 46120 | AD9: 46126 | AE9: 46127 | AF9: 46133 | AG9: 46134 | AH9: 46140 | AI9: 46141 | AJ9: 46147 | AK9: 46148 | AL9: 46154 | AM9: 46155 | AN9: 46161 | AO9: 46162 | AP9: 46175 | AQ9: =+AP9+1 -> 46176 | AR9: =+AP9+7 -> 46182 | AS9: =+AR9+1 -> 46183 | AT9: =+AR9+8 -> 46190 | AU9: =+AS9+8 -> 46191 | AV9: =+AT9+6 -> 46196 | AW9: =+AU9+6 -> 46197 | AX9: =+AV9+6 -> 46202 | AY9: =+AW9+6 -> 46203
A10: ETA : SAI | E10: 46028 | F10: 46029 | G10: 46035 | H10: 46036 | I10: 46042 | J10: 46043 | K10: 46049 | L10: 46050 | M10: 46056 | N10: 46057 | O10: 46063 | P10: 46064 | Q10: 46071 | R10: 46072 | S10: 46077 | T10: 46078 | U10: 46084 | V10: 46085 | W10: 46091 | X10: 46092 | Y10: 46098 | Z10: 46099 | AA10: 46113 | AB10: 46119 | AC10: 46120 | AD10: 46126 | AE10: 46127 | AF10: 46133 | AG10: 46134 | AH10: 46140 | AI10: 46141 | AJ10: 46147 | AK10: 46148 | AL10: 46154 | AM10: 46155 | AN10: 46161 | AO10: 46162 | AP10: 46175 | AQ10: =+AP10+1 -> 46176 | AR10: =+AP10+7 -> 46182 | AS10: =+AR10+1 -> 46183 | AT10: =+AR10+8 -> 46190 | AU10: =+AS10+8 -> 46191 | AV10: =+AT10+6 -> 46196 | AW10: =+AU10+6 -> 46197 | AX10: =+AV10+6 -> 46202 | AY10: =+AW10+6 -> 46203 | AZ10: QTY | BA10: QTY | BB10: QTY | BC10: QTY | BD10: QTY | BE10: QTY | BF10: QTY | BG10: QTY
A11: No. | B11: PART NUMBER | C11: BUPPIN | D11: Last Cum | E11: QTY | F11: QTY | G11: QTY | H11: QTY | I11: QTY | J11: QTY | K11: QTY | L11: QTY | M11: QTY | N11: QTY | O11: QTY | P11: QTY | Q11: QTY | R11: QTY | S11: QTY | T11: QTY | U11: QTY | V11: QTY | W11: QTY | X11: QTY | Y11: QTY | Z11: QTY | AA11: QTY | AB11: QTY | AC11: QTY | AD11: QTY | AE11: QTY | AF11: QTY | AG11: QTY | AH11: QTY | AI11: QTY | AJ11: QTY | AK11: QTY | AL11: QTY | AM11: QTY | AN11: QTY | AO11: QTY | AP11: QTY | AQ11: QTY | AR11: QTY | AS11: QTY | AT11: QTY | AU11: QTY | AV11: QTY | AW11: QTY | AX11: QTY | AY11: QTY
A13: 1 | B13: JN111-62063-3 0002 | C13: JN111-62063-3 0002 | E13: 0 | F13: 0 | G13: 0 | H13: 0 | I13: 0 | J13: 0 | K13: 0 | L13: 0 | M13: 0 | N13: 0 | O13: 0 | P13: 0 | Q13: 0 | R13: 0 | S13: 0 | T13: 0 | U13: 0 | V13: 0 | W13: 0 | X13: 0 | Y13: 0 | Z13: 0 | AA13: 0 | AB13: 0 | AC13: 0 | AD13: 0 | AE13: 0 | AF13: 0 | AG13: 0 | AH13: 0 | AI13: 0 | AJ13: 0 | AK13: 0 | AL13: 0 | AM13: 0 | AN13: 0 | AO13: 0 | AP13: 0 | AQ13: 0 | AR13: 0 | AS13: 0 | AT13: 0 | AU13: 0 | AV13: 0 | AW13: 0 | AX13: 0 | AY13: 0 | AZ13: 0 | BA13: =+SUM(M13:T13) -> 0 | BB13: 0 | BC13: =SUM(AA13:AI13) -> 0 | BD13: =SUM(AJ13:AO13) -> 0 | BE13: =SUM(AP13:AY13) -> 0 | BF13: 0 | BG13: 0 | BH13: 766W(245D)
C14: CUM | D14: =E14 -> 610 | E14: 610 | F14: =+E14+F13 -> 610 | G14: =+F14+G13 -> 610 | H14: =+G14+H13 -> 610 | I14: =+H14+I13 -> 610 | J14: =+I14+J13 -> 610 | K14: =+J14+K13 -> 610 | L14: =+K14+L13 -> 610 | M14: =+L14+M13 -> 610 | ... AO14: =+AN14+AO13 -> 610 | AP14: =+AG14+AP13 -> 610 | AQ14: =+AP14+AQ13 -> 610 | AR14: =+AI14+AR13 -> 610 | AS14: =+AR14+AS13 -> 610 | AT14: =+AK14+AT13 -> 610 | AU14: =+AT14+AU13 -> 610 | AV14: =+AM14+AV13 -> 610 | AW14: =+AV14+AW13 -> 610 | AX14: =+AO14+AX13 -> 610 | AY14: =+AX14+AY13 -> 610 | AZ14: 610 | BA14: =+AZ14+BA13 -> 610 | BB14: =+BA14+BB13 -> 610 | BC14: =+BB14+BC13 -> 610 | BD14: =+BC14+BD13 -> 610 | BE14: =+BD14+BE13 -> 610 | BF14: =+BE14+BF13 -> 610 | BG14: =+BF14+BG13 -> 610
A15: =+A13+1 -> 2 | B15: JN111-62063-4 0002 | C15: JN111-62063-4 0002 | E15: 0 | F15: 0 | G15: 0 | H15: 0 | I15: 0 | J15: 0 | K15: 0 | L15: 0 | M15: 0 | N15: 0 | O15: 0 | P15: 0 | Q15: 0 | R15: 0 | S15: 0 | T15: 0 | U15: 0 | V15: 0 | W15: 0 | X15: 0 | Y15: 0 | Z15: 0 | AA15: 0 | AB15: 0 | AC15: 0 | AD15: 0 | AE15: 0 | AF15: 0 | AG15: 0 | AH15: 0 | AI15: 0 | AJ15: 0 | AK15: 0 | AL15: 0 | AM15: 0 | AN15: 0 | AO15: 0 | AP15: 0 | AQ15: 0 | AR15: 0 | AS15: 0 | AT15: 0 | AU15: 0 | AV15: 0 | AW15: 0 | AX15: 0 | AY15: 0 | AZ15: 0 | BA15: =+SUM(M15:T15) -> 0 | BB15: =SUM(U15:Z15) -> 0 | BC15: =SUM(AA15:AI15) -> 0 | BD15: =SUM(AJ15:AO15) -> 0 | BE15: =SUM(AP15:AY15) -> 0 | BF15: 0 | BG15: 0 | BH15: 766W(245D)
C16: CUM | D16: =E16 -> 510 | E16: 510 | F16: =+E16+F15 -> 510 | G16: =+F16+G15 -> 510 | H16: =+G16+H15 -> 510 | I16: =+H16+I15 -> 510 | J16: =+I16+J15 -> 510 | K16: =+J16+K15 -> 510 | L16: =+K16+L15 -> 510 | M16: =+L16+M15 -> 510 | ... AO16: =+AN16+AO15 -> 510 | AP16: =+AG16+AP15 -> 510 | AQ16: =+AP16+AQ15 -> 510 | AR16: =+AI16+AR15 -> 510 | AS16: =+AR16+AS15 -> 510 | AT16: =+AK16+AT15 -> 510 | AU16: =+AT16+AU15 -> 510 | AV16: =+AM16+AV15 -> 510 | AW16: =+AV16+AW15 -> 510 | AX16: =+AO16+AX15 -> 510 | AY16: =+AX16+AY15 -> 510 | AZ16: 510 | BA16: =+AZ16+BA15 -> 510 | BB16: =+BA16+BB15 -> 510 | BC16: =+BB16+BC15 -> 510 | BD16: =+BC16+BD15 -> 510 | BE16: =+BD16+BE15 -> 510 | BF16: =+BE16+BF15 -> 510 | BG16: =+BF16+BG15 -> 510
A17: =+A15+1 -> 3 | B17: JN111-62093-3 0002 | C17: JN111-62093-3 0002 | E17: 0 | F17: 0 | G17: 0 | H17: 0 | I17: 0 | J17: 0 | K17: 0 | L17: 0 | M17: 0 | N17: 0 | O17: 0 | P17: 0 | Q17: 0 | R17: 0 | S17: 0 | T17: 0 | U17: 0 | V17: 0 | W17: 0 | X17: 0 | Y17: 0 | Z17: 0 | AA17: 0 | AB17: 0 | AC17: 0 | AD17: 0 | AE17: 0 | AF17: 0 | AG17: 0 | AH17: 0 | AI17: 0 | AJ17: 0 | AK17: 0 | AL17: 0 | AM17: 0 | AN17: 0 | AO17: 0 | AP17: 0 | AQ17: 0 | AR17: 0 | AS17: 0 | AT17: 0 | AU17: 0 | AV17: 0 | AW17: 0 | AX17: 0 | AY17: 0 | AZ17: 0 | BA17: =+SUM(M17:T17) -> 0 | BB17: =SUM(U17:Z17) -> 0 | BC17: =SUM(AA17:AI17) -> 0 | BD17: =SUM(AJ17:AO17) -> 0 | BE17: =SUM(AP17:AY17) -> 0 | BF17: 0 | BG17: 0 | BH17: 766W(245D)
C18: CUM | D18: =E18 -> 830 | E18: 830 | F18: =+E18+F17 -> 830 | G18: =+F18+G17 -> 830 | H18: =+G18+H17 -> 830 | I18: =+H18+I17 -> 830 | J18: =+I18+J17 -> 830 | K18: =+J18+K17 -> 830 | L18: =+K18+L17 -> 830 | M18: =+L18+M17 -> 830 | ... AO18: =+AN18+AO17 -> 830 | AP18: =+AG18+AP17 -> 830 | AQ18: =+AP18+AQ17 -> 830 | AR18: =+AI18+AR17 -> 830 | AS18: =+AR18+AS17 -> 830 | AT18: =+AK18+AT17 -> 830 | AU18: =+AT18+AU17 -> 830 | AV18: =+AM18+AV17 -> 830 | AW18: =+AV18+AW17 -> 830 | AX18: =+AO18+AX17 -> 830 | AY18: =+AX18+AY17 -> 830 | AZ18: 830 | BA18: =+AZ18+BA17 -> 830 | BB18: =+BA18+BB17 -> 830 | BC18: =+BB18+BC17 -> 830 | BD18: =+BC18+BD17 -> 830 | BE18: =+BD18+BE17 -> 830 | BF18: =+BE18+BF17 -> 830 | BG18: =+BF18+BG17 -> 830
A19: =+A17+1 -> 4 | B19: JN111-62093-4 0002 | C19: JN111-62093-4 0002 | E19: 0 | F19: 0 | G19: 0 | H19: 0 | I19: 0 | J19: 0 | K19: 0 | L19: 0 | M19: 0 | N19: 0 | O19: 0 | P19: 0 | Q19: 0 | R19: 0 | S19: 0 | T19: 0 | U19: 0 | V19: 0 | W19: 0 | X19: 0 | Y19: 0 | Z19: 0 | AA19: 0 | AB19: 0 | AC19: 0 | AD19: 0 | AE19: 0 | AF19: 0 | AG19: 0 | AH19: 0 | AI19: 0 | AJ19: 0 | AK19: 0 | AL19: 0 | AM19: 0 | AN19: 0 | AO19: 0 | AP19: 0 | AQ19: 0 | AR19: 0 | AS19: 0 | AT19: 0 | AU19: 0 | AV19: 0 | AW19: 0 | AX19: 0 | AY19: 0 | AZ19: 0 | BA19: =+SUM(M19:T19) -> 0 | BB19: 0 | BC19: =SUM(AA19:AI19) -> 0 | BD19: =SUM(AJ19:AO19) -> 0 | BE19: =SUM(AP19:AY19) -> 0 | BF19: 0 | BG19: 0 | BH19: 766W(245D)
C20: CUM | D20: =E20 -> 880 | E20: 880 | F20: =+E20+F19 -> 880 | G20: =+F20+G19 -> 880 | H20: =+G20+H19 -> 880 | I20: =+H20+I19 -> 880 | J20: =+I20+J19 -> 880 | K20: =+J20+K19 -> 880 | L20: =+K20+L19 -> 880 | M20: =+L20+M19 -> 880 | ... AO20: =+AN20+AO19 -> 880 | AP20: =+AG20+AP19 -> 880 | AQ20: =+AP20+AQ19 -> 880 | AR20: =+AI20+AR19 -> 880 | AS20: =+AR20+AS19 -> 880 | AT20: =+AK20+AT19 -> 880 | AU20: =+AT20+AU19 -> 880 | AV20: =+AM20+AV19 -> 880 | AW20: =+AV20+AW19 -> 880 | AX20: =+AO20+AX19 -> 880 | AY20: =+AX20+AY19 -> 880 | AZ20: 880 | BA20: =+AZ20+BA19 -> 880 | BB20: =+BA20+BB19 -> 880 | BC20: =+BB20+BC19 -> 880 | BD20: =+BC20+BD19 -> 880 | BE20: =+BD20+BE19 -> 880 | BF20: =+BE20+BF19 -> 880 | BG20: =+BF20+BG19 -> 880
A21: =+A19+1 -> 5 | B21: BC121-6B220-1 B 0001 | C21: BC121-6B220-1 B 0001 | E21: 80 | F21: 80 | G21: 240 | H21: 240 | I21: 320 | J21: 240 | K21: 160 | L21: 160 | M21: 240 | N21: 240 | O21: 320 | P21: =160+560 -> 720 | Q21: 320 | R21: 160 | S21: 720 | T21: 800 | U21: 0 | V21: 160 | W21: 160 | X21: 320 | Y21: =240+80 -> 320 | Z21: 400 | AA21: 800 | AB21: 240 | AC21: 320 | AD21: 320 | AE21: 240 | AF21: 400 | AG21: 240 | AH21: 400 | AI21: 320 | AJ21: 400 | AK21: 320 | AL21: 400 | AM21: 400 | AN21: 320 | AO21: 320 | AP21: 560 | AQ21: 320 | AR21: 480 | AS21: 320 | AT21: 240 | AU21: 320 | AV21: 480 | AW21: 320 | AX21: 320 | AY21: 480 | AZ21: 1520 | BA21: =+SUM(M21:T21) -> 3520 | BB21: =SUM(U21:Z21) -> 1360 | BC21: =SUM(AA21:AI21) -> 3280 | BD21: =SUM(AJ21:AO21) -> 2160 | BE21: =SUM(AP21:AY21) -> 3840 | BF21: 3920 | BG21: 3440 | BH21: 940W(120D)
C22: CUM | D22: =E22 -> 128280 | E22: 128280 | F22: =+E22+F21 -> 128360 | G22: =+F22+G21 -> 128600 | H22: =+G22+H21 -> 128840 | I22: =+H22+I21 -> 129160 | J22: =+I22+J21 -> 129400 | K22: =+J22+K21 -> 129560 | L22: =+K22+L21 -> 129720 | M22: =+L22+M21 -> 129960 | ... AO22: =+AN22+AO21 -> 140040 | AP22: =+AG22+AP21 -> 137720 | AQ22: =+AP22+AQ21 -> 138040 | AR22: =+AI22+AR21 -> 138360 | AS22: =+AR22+AS21 -> 138680 | AT22: =+AK22+AT21 -> 138840 | AU22: =+AT22+AU21 -> 139160 | AV22: =+AM22+AV21 -> 139880 | AW22: =+AV22+AW21 -> 140200 | AX22: =+AO22+AX21 -> 140360 | AY22: =+AX22+AY21 -> 140840 | AZ22: 146760 | BA22: =+AZ22+BA21 -> 150280 | BB22: =+BA22+BB21 -> 151640 | BC22: =+BB22+BC21 -> 154920 | BD22: =+BC22+BD21 -> 157080 | BE22: =+BD22+BE21 -> 160920 | BF22: =+BE22+BF21 -> 164840 | BG22: =+BF22+BG21 -> 168280
A23: =+A21+1 -> 6 | B23: BC121-6B230-1 C 0001 | C23: BC121-6B230-1 B 0001 | E23: 0 | F23: 0 | G23: 0 | H23: 0 | I23: 0 | J23: 0 | K23: 0 | L23: 0 | M23: 0 | N23: 0 | O23: 0 | P23: 0 | Q23: 0 | R23: 0 | S23: 0 | T23: 0 | U23: 0 | V23: 0 | W23: 0 | X23: 0 | Y23: 0 | Z23: 0 | AA23: 0 | AB23: 0 | AC23: 0 | AD23: 0 | AE23: 0 | AF23: 0 | AG23: 0 | AH23: 0 | AI23: 0 | AJ23: 0 | AK23: 0 | AL23: 0 | AM23: 0 | AN23: 0 | AO23: 0 | AP23: 0 | AQ23: 0 | AR23: 0 | AS23: 0 | AT23: 0 | AU23: 0 | AV23: 0 | AW23: 0 | AX23: 0 | AY23: 0 | AZ23: 0 | BA23: =+SUM(M23:T23) -> 0 | BB23: =SUM(U23:Z23) -> 0 | BC23: =SUM(AA23:AI23) -> 0 | BD23: =SUM(AJ23:AO23) -> 0 | BE23: =SUM(AP23:AY23) -> 0 | BF23: 0 | BG23: 0 | BH23: 940W(120D)
C24: CUM | D24: =E24 -> 510 | E24: 510 | F24: =+E24+F23 -> 510 | G24: =+F24+G23 -> 510 | H24: =+G24+H23 -> 510 | I24: =+H24+I23 -> 510 | J24: =+I24+J23 -> 510 | K24: =+J24+K23 -> 510 | L24: =+K24+L23 -> 510 | M24: =+L24+M23 -> 510 | ... AO24: =+AN24+AO23 -> 510 | AP24: =+AG24+AP23 -> 510 | AQ24: =+AP24+AQ23 -> 510 | AR24: =+AI24+AR23 -> 510 | AS24: =+AR24+AS23 -> 510 | AT24: =+AK24+AT23 -> 510 | AU24: =+AT24+AU23 -> 510 | AV24: =+AM24+AV23 -> 510 | AW24: =+AV24+AW23 -> 510 | AX24: =+AO24+AX23 -> 510 | AY24: =+AX24+AY23 -> 510 | AZ24: 510 | BA24: =+AZ24+BA23 -> 510 | BB24: =+BA24+BB23 -> 510 | BC24: =+BB24+BC23 -> 510 | BD24: =+BC24+BD23 -> 510 | BE24: =+BD24+BE23 -> 510 | BF24: =+BE24+BF23 -> 510 | BG24: =+BF24+BG23 -> 510
A25: =+A23+1 -> 7 | B25: BC121-6B250-1 B 0001 | C25: BC121-6B250-1 B 0001 | E25: 0 | F25: 0 | G25: 0 | H25: 0 | I25: 0 | J25: 0 | K25: 0 | L25: 0 | M25: 0 | N25: 0 | O25: 0 | P25: 0 | Q25: 0 | R25: 0 | S25: 0 | T25: 0 | U25: 0 | V25: 0 | W25: 0 | X25: 0 | Y25: 0 | Z25: 0 | AA25: 60 | AB25: 0 | AC25: 30 | AD25: 0 | AE25: 30 | AF25: 0 | AG25: 0 | AH25: 30 | AI25: 0 | AJ25: 0 | AK25: 30 | AL25: 0 | AM25: 30 | AN25: 0 | AO25: 0 | AP25: 30 | AQ25: 0 | AR25: 30 | AS25: 0 | AT25: 0 | AU25: 30 | AV25: 0 | AW25: 30 | AX25: 0 | AY25: 30 | AZ25: 0 | BA25: =+SUM(M25:T25) -> 0 | BB25: =SUM(U25:Z25) -> 0 | BC25: =SUM(AA25:AI25) -> 150 | BD25: =SUM(AJ25:AO25) -> 60 | BE25: =SUM(AP25:AY25) -> 150 | BF25: 150 | BG25: 120 | BH25: 940W(120D)
C26: CUM | D26: =E26 -> 960 | E26: 960 | F26: =+E26+F25 -> 960 | G26: =+F26+G25 -> 960 | H26: =+G26+H25 -> 960 | I26: =+H26+I25 -> 960 | J26: =+I26+J25 -> 960 | K26: =+J26+K25 -> 960 | L26: =+K26+L25 -> 960 | M26: =+L26+M25 -> 960 | ... AO26: =+AN26+AO25 -> 1170 | AP26: =+AG26+AP25 -> 1110 | AQ26: =+AP26+AQ25 -> 1110 | AR26: =+AI26+AR25 -> 1140 | AS26: =+AR26+AS25 -> 1140 | AT26: =+AK26+AT25 -> 1140 | AU26: =+AT26+AU25 -> 1170 | AV26: =+AM26+AV25 -> 1170 | AW26: =+AV26+AW25 -> 1200 | AX26: =+AO26+AX25 -> 1170 | AY26: =+AX26+AY25 -> 1200 | AZ26: 960 | BA26: =+AZ26+BA25 -> 960 | BB26: =+BA26+BB25 -> 960 | BC26: =+BB26+BC25 -> 1110 | BD26: =+BC26+BD25 -> 1170 | BE26: =+BD26+BE25 -> 1320 | BF26: =+BE26+BF25 -> 1470 | BG26: =+BF26+BG25 -> 1590
A27: =+A25+1 -> 8 | B27: BC121-6B260-1 B 0001 | C27: BC121-6B260-1 B 0001 | E27: 180 | F27: 260 | G27: 580 | H27: =640+160 -> 800 | I27: 1060 | J27: 540 | K27: 660 | L27: 480 | M27: 480 | N27: 520 | O27: 560 | P27: 480 | Q27: 580 | R27: 400 | S27: 0 | T27: 340 | U27: 320 | V27: 380 | W27: 440 | X27: 400 | Y27: 560 | Z27: 560 | AA27: 0 | AB27: 0 | AC27: 0 | AD27: 80 | AE27: 180 | AF27: 260 | AG27: 180 | AH27: 280 | AI27: 160 | AJ27: 280 | AK27: 160 | AL27: 260 | AM27: 260 | AN27: 160 | AO27: 200 | AP27: 400 | AQ27: 200 | AR27: 300 | AS27: 180 | AT27: 200 | AU27: 200 | AV27: 280 | AW27: 220 | AX27: 240 | AY27: 360 | AZ27: 4560 | BA27: =+SUM(M27:T27) -> 3360 | BB27: =SUM(U27:Z27) -> 2660 | BC27: =SUM(AA27:AI27) -> 1140 | BD27: =SUM(AJ27:AO27) -> 1320 | BE27: =SUM(AP27:AY27) -> 2580 | BF27: 3120 | BG27: 2540 | BH27: 940W(120D)
C28: CUM | D28: =E28 -> 304840 | E28: 304840 | F28: =+E28+F27 -> 305100 | G28: =+F28+G27 -> 305680 | H28: =+G28+H27 -> 306480 | I28: =+H28+I27 -> 307540 | J28: =+I28+J27 -> 308080 | K28: =+J28+K27 -> 308740 | L28: =+K28+L27 -> 309220 | M28: =+L28+M27 -> 309700 | ... AO28: =+AN28+AO27 -> 317700 | AP28: =+AG28+AP27 -> 316340 | AQ28: =+AP28+AQ27 -> 316540 | AR28: =+AI28+AR27 -> 316680 | AS28: =+AR28+AS27 -> 316860 | AT28: =+AK28+AT27 -> 317020 | AU28: =+AT28+AU27 -> 317220 | AV28: =+AM28+AV27 -> 317620 | AW28: =+AV28+AW27 -> 317840 | AX28: =+AO28+AX27 -> 317940 | AY28: =+AX28+AY27 -> 318300 | AZ28: 352540 | BA28: =+AZ28+BA27 -> 355900 | BB28: =+BA28+BB27 -> 358560 | BC28: =+BB28+BC27 -> 359700 | BD28: =+BC28+BD27 -> 361020 | BE28: =+BD28+BE27 -> 363600 | BF28: =+BE28+BF27 -> 366720 | BG28: =+BF28+BG27 -> 369260
A29: =+A27+1 -> 9 | B29: BC121-6B370-1 B 0001 | C29: BC121-6B370-1 B 0001 | E29: 330 | F29: 60 | G29: 420 | H29: =120+210 -> 330 | I29: 570 | J29: 420 | K29: 210 | L29: 270 | M29: 390 | N29: 330 | O29: 300 | P29: =300+210 -> 510 | Q29: 420 | R29: 270 | S29: 630 | T29: 510 | U29: 510 | V29: 150 | W29: 390 | X29: =390+90 -> 480 | Y29: =360+150 -> 510 | Z29: 420 | AA29: 840 | AB29: 390 | AC29: 330 | AD29: 390 | AE29: 270 | AF29: 420 | AG29: 270 | AH29: 360 | AI29: 240 | AJ29: 330 | AK29: 240 | AL29: 360 | AM29: 330 | AN29: 240 | AO29: 240 | AP29: 540 | AQ29: 240 | AR29: 390 | AS29: 270 | AT29: 240 | AU29: 270 | AV29: 360 | AW29: 300 | AX29: 270 | AY29: 450 | AZ29: 2610 | BA29: =+SUM(M29:T29) -> 3360 | BB29: =SUM(U29:Z29) -> 2460 | BC29: =SUM(AA29:AI29) -> 3510 | BD29: =SUM(AJ29:AO29) -> 1740 | BE29: =SUM(AP29:AY29) -> 3330 | BF29: 2940 | BG29: 2400 | BH29: 940W(120D)
C30: CUM | D30: =E30 -> 113250 | E30: 113250 | F30: =+E30+F29 -> 113310 | G30: =+F30+G29 -> 113730 | H30: =+G30+H29 -> 114060 | I30: =+H30+I29 -> 114630 | J30: =+I30+J29 -> 115050 | K30: =+J30+K29 -> 115260 | L30: =+K30+L29 -> 115530 | M30: =+L30+M29 -> 115920 | ... AO30: =+AN30+AO29 -> 126600 | AP30: =+AG30+AP29 -> 124800 | AQ30: =+AP30+AQ29 -> 125040 | AR30: =+AI30+AR29 -> 125250 | AS30: =+AR30+AS29 -> 125520 | AT30: =+AK30+AT29 -> 125670 | AU30: =+AT30+AU29 -> 125940 | AV30: =+AM30+AV29 -> 126480 | AW30: =+AV30+AW29 -> 126780 | AX30: =+AO30+AX29 -> 126870 | AY30: =+AX30+AY29 -> 127320 | AZ30: 140220 | BA30: =+AZ30+BA29 -> 143580 | BB30: =+BA30+BB29 -> 146040 | BC30: =+BB30+BC29 -> 149550 | BD30: =+BC30+BD29 -> 151290 | BE30: =+BD30+BE29 -> 154620 | BF30: =+BE30+BF29 -> 157560 | BG30: =+BF30+BG29 -> 159960
A31: =+A29+1 -> 10 | B31: BC121-6B370-2 B 0001 | C31: BC121-6B370-2 B 0001 | E31: 330 | F31: 60 | G31: 420 | H31: =120+210 -> 330 | I31: 570 | J31: 420 | K31: 240 | L31: 270 | M31: 390 | N31: 330 | O31: 300 | P31: =300+210 -> 510 | Q31: 390 | R31: 270 | S31: 630 | T31: 510 | U31: 510 | V31: 150 | W31: 390 | X31: =390+90 -> 480 | Y31: =360+150 -> 510 | Z31: 420 | AA31: 840 | AB31: 390 | AC31: 330 | AD31: 390 | AE31: 270 | AF31: 420 | AG31: 270 | AH31: 360 | AI31: 240 | AJ31: 330 | AK31: 240 | AL31: 360 | AM31: 330 | AN31: 240 | AO31: 240 | AP31: 540 | AQ31: 240 | AR31: 390 | AS31: 270 | AT31: 240 | AU31: 270 | AV31: 360 | AW31: 300 | AX31: 270 | AY31: 450 | AZ31: 2640 | BA31: =+SUM(M31:T31) -> 3330 | BB31: =SUM(U31:Z31) -> 2460 | BC31: =SUM(AA31:AI31) -> 3510 | BD31: =SUM(AJ31:AO31) -> 1740 | BE31: =SUM(AP31:AY31) -> 3330 | BF31: 2940 | BG31: 2400 | BH31: 940W(120D)
C32: CUM | D32: =E32 -> 113040 | E32: 113040 | F32: =+E32+F31 -> 113100 | G32: =+F32+G31 -> 113520 | H32: =+G32+H31 -> 113850 | I32: =+H32+I31 -> 114420 | J32: =+I32+J31 -> 114840 | K32: =+J32+K31 -> 115080 | L32: =+K32+L31 -> 115350 | M32: =+L32+M31 -> 115740 | ... AO32: =+AN32+AO31 -> 126390 | AP32: =+AG32+AP31 -> 124590 | AQ32: =+AP32+AQ31 -> 124830 | AR32: =+AI32+AR31 -> 125040 | AS32: =+AR32+AS31 -> 125310 | AT32: =+AK32+AT31 -> 125460 | AU32: =+AT32+AU31 -> 125730 | AV32: =+AM32+AV31 -> 126270 | AW32: =+AV32+AW31 -> 126570 | AX32: =+AO32+AX31 -> 126660 | AY32: =+AX32+AY31 -> 127110 | AZ32: 140040 | BA32: =+AZ32+BA31 -> 143370 | BB32: =+BA32+BB31 -> 145830 | BC32: =+BB32+BC31 -> 149340 | BD32: =+BC32+BD31 -> 151080 | BE32: =+BD32+BE31 -> 154410 | BF32: =+BE32+BF31 -> 157350 | BG32: =+BF32+BG31 -> 159750
A33: =+A31+1 -> 11 | B33: BC121-6AM60-1 C 0001 | C33: BC121-6AM60-1 C 0001 | E33: 0 | F33: 0 | G33: 0 | H33: 0 | I33: 0 | J33: 0 | K33: 0 | L33: 0 | M33: 0 | N33: 0 | O33: 0 | P33: 0 | Q33: 0 | R33: 0 | S33: 0 | T33: 0 | U33: 0 | V33: 0 | W33: 0 | X33: 0 | Y33: 0 | Z33: 0 | AA33: 0 | AB33: 0 | AC33: 0 | AD33: 0 | AE33: 0 | AF33: 0 | AG33: 0 | AH33: 0 | AI33: 0 | AJ33: 0 | AK33: 0 | AL33: 0 | AM33: 0 | AN33: 0 | AO33: 0 | AP33: 0 | AQ33: 0 | AR33: 0 | AS33: 0 | AT33: 0 | AU33: 0 | AV33: 0 | AW33: 0 | AX33: 0 | AY33: 0 | AZ33: 0 | BA33: =+SUM(M33:T33) -> 0 | BB33: =SUM(U33:Z33) -> 0 | BC33: =SUM(AA33:AI33) -> 0 | BD33: =SUM(AJ33:AO33) -> 0 | BE33: =SUM(AP33:AY33) -> 0 | BF33: 2440 | BG33: 2020 | BH33: 940W(120D)
C34: CUM | D34: =E34 -> 43430 | E34: 43430 | F34: =+E34+F33 -> 43430 | G34: =+F34+G33 -> 43430 | H34: =+G34+H33 -> 43430 | I34: =+H34+I33 -> 43430 | J34: =+I34+J33 -> 43430 | K34: =+J34+K33 -> 43430 | L34: =+K34+L33 -> 43430 | M34: =+L34+M33 -> 43430 | ... AO34: =+AN34+AO33 -> 43430 | AP34: =+AG34+AP33 -> 43430 | AQ34: =+AP34+AQ33 -> 43430 | AR34: =+AI34+AR33 -> 43430 | AS34: =+AR34+AS33 -> 43430 | AT34: =+AK34+AT33 -> 43430 | AU34: =+AT34+AU33 -> 43430 | AV34: =+AM34+AV33 -> 43430 | AW34: =+AV34+AW33 -> 43430 | AX34: =+AO34+AX33 -> 43430 | AY34: =+AX34+AY33 -> 43430 | AZ34: 45590 | BA34: =+AZ34+BA33 -> 45590 | BB34: =+BA34+BB33 -> 45590 | BC34: =+BB34+BC33 -> 45590 | BD34: =+BC34+BD33 -> 45590 | BE34: =+BD34+BE33 -> 45590 | BF34: =+BE34+BF33 -> 48030 | BG34: =+BF34+BG33 -> 50050
A35: =+A33+1 -> 12 | B35: BC121-35G70-1 D 0001 | C35: BC121-35G70-1 D 0001 | E35: 450 | F35: 240 | G35: 600 | H35: 240 | I35: 240 | J35: 660 | K35: 270 | L35: 450 | M35: 840 | N35: 510 | O35: 30 | P35: =420+750 -> 1170 | Q35: 390 | R35: 420 | S35: 1320 | T35: 1170 | U35: 0 | V35: 360 | W35: 540 | X35: 540 | Y35: 780 | Z35: 600 | AA35: 810 | AB35: 420 | AC35: 450 | AD35: 510 | AE35: 330 | AF35: 540 | AG35: 360 | AH35: 570 | AI35: 390 | AJ35: 600 | AK35: 390 | AL35: 570 | AM35: 570 | AN35: 390 | AO35: 420 | AP35: 840 | AQ35: 390 | AR35: 630 | AS35: 420 | AT35: 390 | AU35: 420 | AV35: 600 | AW35: 360 | AX35: 360 | AY35: 510 | AZ35: 3150 | BA35: =+SUM(M35:T35) -> 5850 | BB35: =SUM(U35:Z35) -> 2820 | BC35: =SUM(AA35:AI35) -> 4380 | BD35: =SUM(AJ35:AO35) -> 2940 | BE35: =SUM(AP35:AY35) -> 4920 | BF35: 4290 | BG35: 3570 | BH35: 969W(930B)
C36: CUM | D36: =E36 -> 137940 | E36: 137940 | F36: =+E36+F35 -> 138180 | G36: =+F36+G35 -> 138780 | H36: =+G36+H35 -> 139020 | I36: =+H36+I35 -> 139260 | J36: =+I36+J35 -> 139920 | K36: =+J36+K35 -> 140190 | L36: =+K36+L35 -> 140640 | M36: =+L36+M35 -> 141480 | ... AO36: =+AN36+AO35 -> 156630 | AP36: =+AG36+AP35 -> 153570 | AQ36: =+AP36+AQ35 -> 153960 | AR36: =+AI36+AR35 -> 154320 | AS36: =+AR36+AS35 -> 154740 | AT36: =+AK36+AT35 -> 155070 | AU36: =+AT36+AU35 -> 155490 | AV36: =+AM36+AV35 -> 156420 | AW36: =+AV36+AW35 -> 156780 | AX36: =+AO36+AX35 -> 156990 | AY36: =+AX36+AY35 -> 157500 | AZ36: 177300 | BA36: =+AZ36+BA35 -> 183150 | BB36: =+BA36+BB35 -> 185970 | BC36: =+BB36+BC35 -> 190350 | BD36: =+BC36+BD35 -> 193290 | BE36: =+BD36+BE35 -> 198210 | BF36: =+BE36+BF35 -> 202500 | BG36: =+BF36+BG35 -> 206070
A37: =+A35+1 -> 13 | B37: BC121-35G90-1 D 0001 | C37: BC121-35G90-1 D 0001 | E37: 220 | F37: 100 | G37: 40 | H37: 220 | I37: 180 | J37: 120 | K37: 160 | L37: 140 | M37: 200 | N37: 140 | O37: 0 | P37: =120+140 -> 260 | Q37: 100 | R37: 120 | S37: 360 | T37: 200 | U37: 60 | V37: 140 | W37: 160 | X37: =160+300 -> 460 | Y37: 120 | Z37: 200 | AA37: 280 | AB37: 120 | AC37: 180 | AD37: 160 | AE37: 120 | AF37: 180 | AG37: 120 | AH37: 240 | AI37: 140 | AJ37: 220 | AK37: 160 | AL37: 220 | AM37: 220 | AN37: 140 | AO37: 140 | AP37: 320 | AQ37: 140 | AR37: 220 | AS37: 140 | AT37: 160 | AU37: 140 | AV37: 220 | AW37: 140 | AX37: 160 | AY37: 220 | AZ37: 1180 | BA37: =+SUM(M37:T37) -> 1380 | BB37: =SUM(U37:Z37) -> 1140 | BC37: =SUM(AA37:AI37) -> 1540 | BD37: =SUM(AJ37:AO37) -> 1100 | BE37: =SUM(AP37:AY37) -> 1860 | BF37: 1620 | BG37: 1320 | BH37: 969W(930B)
C38: CUM | D38: =E38 -> 48970 | E38: 48970 | F38: =+E38+F37 -> 49070 | G38: =+F38+G37 -> 49110 | H38: =+G38+H37 -> 49330 | I38: =+H38+I37 -> 49510 | J38: =+I38+J37 -> 49630 | K38: =+J38+K37 -> 49790 | L38: =+K38+L37 -> 49930 | M38: =+L38+M37 -> 50130 | ... AO38: =+AN38+AO37 -> 55090 | AP38: =+AG38+AP37 -> 53930 | AQ38: =+AP38+AQ37 -> 54070 | AR38: =+AI38+AR37 -> 54210 | AS38: =+AR38+AS37 -> 54350 | AT38: =+AK38+AT37 -> 54530 | AU38: =+AT38+AU37 -> 54670 | AV38: =+AM38+AV37 -> 55030 | AW38: =+AV38+AW37 -> 55170 | AX38: =+AO38+AX37 -> 55250 | AY38: =+AX38+AY37 -> 55470 | AZ38: 67550 | BA38: =+AZ38+BA37 -> 68930 | BB38: =+BA38+BB37 -> 70070 | BC38: =+BB38+BC37 -> 71610 | BD38: =+BC38+BD37 -> 72710 | BE38: =+BD38+BE37 -> 74570 | BF38: =+BE38+BF37 -> 76190 | BG38: =+BF38+BG37 -> 77510
A39: =+A37+1 -> 14 | B39: BC121-35K80-1 C 0001 | C39: BC121-35K80-1 C 0001 | E39: 180 | F39: 150 | G39: 240 | H39: 300 | I39: 240 | J39: 360 | K39: 180 | L39: 210 | M39: 330 | N39: 240 | O39: 120 | P39: =240+60 -> 300 | Q39: 90 | R39: 210 | S39: 330 | T39: 240 | U39: 240 | V39: 210 | W39: 0 | X39: 0 | Y39: 0 | Z39: 120 | AA39: 0 | AB39: 0 | AC39: 0 | AD39: 0 | AE39: 0 | AF39: 0 | AG39: 0 | AH39: 60 | AI39: 180 | AJ39: 300 | AK39: 210 | AL39: 300 | AM39: 270 | AN39: 210 | AO39: 240 | AP39: 450 | AQ39: 210 | AR39: 360 | AS39: 210 | AT39: 240 | AU39: 210 | AV39: 360 | AW39: 210 | AX39: 210 | AY39: 300 | AZ39: 1860 | BA39: =+SUM(M39:T39) -> 1860 | BB39: =SUM(U39:Z39) -> 570 | BC39: =SUM(AA39:AI39) -> 240 | BD39: =SUM(AJ39:AO39) -> 1530 | BE39: =SUM(AP39:AY39) -> 2760 | BF39: 2070 | BG39: 1710 | BH39: 969W(930B)
C40: CUM | D40: =E40 -> 43286 | E40: 43286 | F40: =+E40+F39 -> 43436 | G40: =+F40+G39 -> 43676 | H40: =+G40+H39 -> 43976 | I40: =+H40+I39 -> 44216 | J40: =+I40+J39 -> 44576 | K40: =+J40+K39 -> 44756 | L40: =+K40+L39 -> 44966 | M40: =+L40+M39 -> 45296 | ... AO40: =+AN40+AO39 -> 49166 | AP40: =+AG40+AP39 -> 47846 | AQ40: =+AP40+AQ39 -> 48056 | AR40: =+AI40+AR39 -> 47996 | AS40: =+AR40+AS39 -> 48206 | AT40: =+AK40+AT39 -> 48386 | AU40: =+AT40+AU39 -> 48596 | AV40: =+AM40+AV39 -> 49076 | AW40: =+AV40+AW39 -> 49286 | AX40: =+AO40+AX39 -> 49376 | AY40: =+AX40+AY39 -> 49676 | AZ40: 65816 | BA40: =+AZ40+BA39 -> 67676 | BB40: =+BA40+BB39 -> 68246 | BC40: =+BB40+BC39 -> 68486 | BD40: =+BC40+BD39 -> 70016 | BE40: =+BD40+BE39 -> 72776 | BF40: =+BE40+BF39 -> 74846 | BG40: =+BF40+BG39 -> 76556
A41: =+A39+1 -> 15 | B41: BC111-V1020-1 D 0101 | C41: BC111-V1020-1 D 0101 | E41: 240 | F41: 300 | G41: 480 | H41: 420 | I41: 480 | J41: 600 | K41: 840 | L41: 660 | M41: 540 | N41: 780 | O41: 1080 | P41: 720 | Q41: 840 | R41: 660 | S41: 0 | T41: 240 | U41: 420 | V41: 480 | W41: 660 | X41: =480+360 -> 840 | Y41: 540 | Z41: 120 | AA41: 0 | AB41: 0 | AC41: 0 | AD41: 0 | AE41: 0 | AF41: 0 | AG41: 0 | AH41: 0 | AI41: 0 | AJ41: 0 | AK41: 0 | AL41: 60 | AM41: 60 | AN41: 60 | AO41: 60 | AP41: 60 | AQ41: 60 | AR41: 60 | AS41: 60 | AT41: 60 | AU41: 0 | AV41: 60 | AW41: 60 | AX41: 0 | AY41: 60 | AZ41: 4020 | BA41: =+SUM(M41:T41) -> 4860 | BB41: =SUM(U41:Z41) -> 3060 | BC41: =SUM(AA41:AI41) -> 0 | BD41: =SUM(AJ41:AO41) -> 240 | BE41: =SUM(AP41:AY41) -> 480 | BF41: 360 | BG41: 300 | BH41: 841W
...

Sheet Sheet2
C4: PART NUMBER | D4: JL51121 | E4: JL51122
D5: 45972 | E5: 45973
D6: Req Advance 07-11-25
D7: QTY | E7: QTY
C8: BC121-35G90-1 D 0001 | D8: 200 | E8: 120
C9: BC111-1HR01-1 0002 | D9: 1360 | E9: 0

Sheet QTY PACKING
A1: No. | B1: PART NUMBER | C1: MOQ | D1: JL60321 | E1: JL60322
A3: 1 | B3: JN111-62063-3 0002 | C3: 40 | D3: =+VLOOKUP($B3,'List Order'!$B$13:$X$124,22,0)/$C3 -> 0 | E3: =+VLOOKUP($B3,'List Order'!$B$13:$X$124,23,0)/$C3 -> 0
A4: 2 | B4: JN111-62063-4 0002 | C4: 50 | D4: =+VLOOKUP($B4,'List Order'!$B$13:$X$124,22,0)/$C4 -> 0 | E4: =+VLOOKUP($B4,'List Order'!$B$13:$X$124,23,0)/$C4 -> 0
A5: 3 | B5: JN111-62093-3 0002 | C5: 50 | D5: =+VLOOKUP($B5,'List Order'!$B$13:$X$124,22,0)/$C5 -> 0 | E5: =+VLOOKUP($B5,'List Order'!$B$13:$X$124,23,0)/$C5 -> 0
A6: 4 | B6: JN111-62093-4 0002 | C6: 50 | D6: =+VLOOKUP($B6,'List Order'!$B$13:$X$124,22,0)/$C6 -> 0 | E6: =+VLOOKUP($B6,'List Order'!$B$13:$X$124,23,0)/$C6 -> 0
A7: 5 | B7: BC121-6B220-1 B 0001 | C7: 80 | D7: =+VLOOKUP($B7,'List Order'!$B$13:$X$124,22,0)/$C7 -> 2 | E7: =+VLOOKUP($B7,'List Order'!$B$13:$X$124,23,0)/$C7 -> 4
A8: 6 | B8: BC121-6B230-1 C 0001 | C8: 30 | D8: =+VLOOKUP($B8,'List Order'!$B$13:$X$124,22,0)/$C8 -> 0 | E8: =+VLOOKUP($B8,'List Order'!$B$13:$X$124,23,0)/$C8 -> 0
A9: 7 | B9: BC121-6B250-1 B 0001 | C9: 30 | D9: =+VLOOKUP($B9,'List Order'!$B$13:$X$124,22,0)/$C9 -> 0 | E9: =+VLOOKUP($B9,'List Order'!$B$13:$X$124,23,0)/$C9 -> 0
A10: 8 | B10: BC121-6B260-1 B 0001 | C10: 20 | D10: =+VLOOKUP($B10,'List Order'!$B$13:$X$124,22,0)/$C10 -> 22 | E10: =+VLOOKUP($B10,'List Order'!$B$13:$X$124,23,0)/$C10 -> 20
A11: 9 | B11: BC121-6B370-1 B 0001 | C11: 30 | D11: =+VLOOKUP($B11,'List Order'!$B$13:$X$124,22,0)/$C11 -> 13 | E11: =+VLOOKUP($B11,'List Order'!$B$13:$X$124,23,0)/$C11 -> 16
A12: 10 | B12: BC121-6B370-2 B 0001 | C12: 30 | D12: =+VLOOKUP($B12,'List Order'!$B$13:$X$124,22,0)/$C12 -> 13 | E12: =+VLOOKUP($B12,'List Order'!$B$13:$X$124,23,0)/$C12 -> 16
A13: 11 | B13: BC121-6AM60-1 C 0001 | C13: 20 | D13: =+VLOOKUP($B13,'List Order'!$B$13:$X$124,22,0)/$C13 -> 0 | E13: =+VLOOKUP($B13,'List Order'!$B$13:$X$124,23,0)/$C13 -> 0
A14: 12 | B14: BC121-35G70-1 D 0001 | C14: 30 | D14: =+VLOOKUP($B14,'List Order'!$B$13:$X$124,22,0)/$C14 -> 18 | E14: =+VLOOKUP($B14,'List Order'!$B$13:$X$124,23,0)/$C14 -> 18
... A58: 56 | B58: BC111-1KU50-2 0001 | C58: 60 | D58: =+VLOOKUP($B58,'List Order'!$B$13:$X$124,22,0)/$C58 -> 0 | E58: =+VLOOKUP($B58,'List Order'!$B$13:$X$124,23,0)/$C58 -> 0
B59: Total Box | D59: =+SUM(D3:D58) -> #N/A | E59: =+SUM(E3:E58) -> #N/A
B60: Total Pallet | D60: =+D59/20 -> #N/A | E60: =+E59/20 -> #N/A

Sheet Sheet1
C4: PART NUMBER | D4: QTY
C5: BC121-6B260-1 B 0001 | D5: 120
C6: BC111-2FE72-2 F 0201 | D6: 100
C7: DC111-2FK53 F 0201 | D7: 80
C8: BC111-V3891-6 B 0201 | D8: 20
C12: JN111-62063-3 0002 | D12: 14PL | F12: BC111-5DR50-1 B 0001
C13: JN111-62063-4 0002 | D13: 14PL | F13: BC111-5DR50-2 B 0001
C14: JN111-62093-3 0002 | D14: 14PL | F14: BC111-1HY10-2 A 1001
C15: JN111-62093-4 0002 | D15: 14PL
C16: BC111-62092-2 B 1001 | D16: 14PL
C17: BC111-62062-2 B 1001 | D17: 14PL
C18: BC111-11730-3 B 0001 | D18: 14PL
C19: BC111-11810-3 2001 | D19: 14PL
C20: BC111-5A843-2 0001 | D20: 14PL
C21: BC111-5A883-2 0001 | D21: 14PL
C22: BC111-5AC33-2 0001 | D22: 14PL
C23: BC111-5AA03-2 0001 | D23: 14PL
C24: JN111-62064-1 0001 | D24: 14PL
C25: JN111-62064-3 0001 | D25: 14PL
C26: JN111-62215-1 0001 | D26: 14PL
... C29: BC111-62215-2 0001 | D29: 14PL
