Workbook

Sheet Sheet1

Sheet XXXXXX

Sheet XXXXXXXX

Sheet XXXXXXXXXX

Sheet XXXXXXXXX0

Sheet QTY 
I1: SIX MONTH PRODUCTION PLAN ( QTY ) | AB1: CHECKED
A2: S/R NO : | I2: BC120D
A3: FAX NO : EMAIL | I3: 46082 | AG3: AS400
A4: DATE : | B4: =+NOW() -> 46094.693 | J4: ACT
D5: 1 | E5: 1 | F5: =+E5+1 -> 2 | G5: =+F5+1 -> 3 | H5: =+G5+1 -> 4 | I5: =+H5+1 -> 5 | J5: =+I5+1 -> 6 | K5: =+J5+1 -> 7 | L5: =+K5+1 -> 8 | M5: =+L5+1 -> 9 | ... Y5: =+X5+1 -> 21
A6: TYPE | D6: HARNESS No. | E6: HARNESS No. | G6: UMH | H6: UMH (Jan-Jun)2012 | I6: FEB | L6: MAR | O6: APR | R6: MAY | U6: JUN | X6: JUL | AA6: AUG | AD6: BAL
I7: =VLOOKUP(I6,[1]Calender!$A$386:$I$455,9,0) -> 01/FEB ~ 28/FEB | L7: =VLOOKUP(L6,[1]Calender!$A$386:$I$455,9,0) -> 01/MAR ~ 31/MAR | O7: =VLOOKUP(O6,[1]Calender!$A$386:$I$455,9,0) -> 01/APR ~ 29/APR | R7: =VLOOKUP(R6,[1]Calender!$A$386:$I$455,9,0) -> 02/MAY ~ 31/MAY | U7: =VLOOKUP(U6,[1]Calender!$A$386:$I$455,9,0) -> 01/JUN ~ 30/JUN | X7: =VLOOKUP(X6,[1]Calender!$A$386:$I$455,9,0) -> 01/JUL ~ 29/JUL | AA7: =VLOOKUP(AA6,[1]Calender!$A$386:$I$455,9,0) -> 01/AUG ~ 26/AUG | AG7: 5 | AH7: 4 | AI7: 4 | AJ7: 5 | AK7: 4
I8: BAL | J8: DEL | K8: PROD | L8: BAL | M8: DEL | N8: PROD | O8: BAL | P8: DEL | Q8: PROD | R8: BAL | S8: DEL | T8: PROD | U8: BAL | V8: DEL | W8: PROD | X8: BAL | Y8: DEL | Z8: PROD | AA8: BAL | AB8: DEL | AC8: PROD | AG8: =O6 -> APR | AH8: =R6 -> MAY | AI8: =U6:U6 -> JUN | AJ8: =X6 -> JUL | AK8: =AA6 -> AUG
B9: BC121-6B370-1 | C9: 1 | D9: GBEG67030 | E9: BC121-6B370-1 B 0001 | F9: 120D | G9: =VLOOKUP($E9,'[2]UMH Monthly'!$D$4:$V$510,19,0) -> 0.015695 | I9: 0 | J9: 3300 | K9: 3300 | L9: =I9+K9-J9 -> 0 | M9: =VLOOKUP($E9,[3]Sheet1!$B$8:$AF$147,13,0) -> 3360 | N9: =IF(L9>M9,0,M9-L9) -> 3360 | O9: =L9+N9-M9 -> 0 | P9: =VLOOKUP($E9,[3]Sheet1!$B$8:$AF$461,19,0) -> 2520 | Q9: =IF(O9>P9,0,P9-O9) -> 2520 | R9: =O9+Q9-P9 -> 0 | S9: =VLOOKUP($E9,[3]Sheet1!$B$8:$AF$461,25,0) -> 1950 | T9: =IF(R9>S9,0,S9-R9) -> 1950 | U9: =R9+T9-S9 -> 0 | V9: =VLOOKUP($E9,[3]Sheet1!$B$8:$BF$461,31,0) -> 2550 | W9: =IF(U9>V9,0,V9-U9) -> 2550 | X9: =U9+W9-V9 -> 0 | Y9: =VLOOKUP($E9,[3]Sheet1!$B$8:$BF$461,37,0) -> 2940 | Z9: =IF(X9>Y9,0,Y9-X9) -> 2940 | AA9: =X9+Z9-Y9 -> 0 | AB9: =+Y9 -> 2940 | AC9: =IF(AA9>AB9,0,AB9-AA9) -> 2940 | AD9: =+AA9+AC9-AB9 -> 0 | AE9: GBEG-67030A | AF9: =+AB9+Y9+V9+S9+P9+M9+J9 -> 19560 | AG9: =ROUNDUP((Q9/$AG$7),0) -> 504 | AH9: =ROUNDUP((T9/$AH$7),0) -> 488 | AI9: =ROUNDUP((W9/$AI$7),0) -> 638 | AJ9: =ROUNDUP((Z9/$AJ$7),0) -> 588 | AK9: =ROUNDUP((AC9/$AK$7),0) -> 735 | AL9: =+#REF!+1 -> #REF! | AM9: =AG9*AG$7 -> 2520 | AN9: =AH9*AH$7 -> 1952 | AO9: =AI9*AI$7 -> 2552 | AP9: =AJ9*AJ$7 -> 2940 | AQ9: =AK9*AK$7 -> 2940 | AR9: =VLOOKUP(E9,'[4]DATA SR'!$D$79:$D$238,1,2) -> #N/A | AS9: BC121-6B370-1 B 0001
B10: BC121-6B370-2 | C10: =C9+1 -> 2 | D10: GBEG67030 | E10: BC121-6B370-2 B 0001 | F10: 120D | G10: =VLOOKUP($E10,'[2]UMH Monthly'!$D$4:$V$510,19,0) -> 0.015746667 | I10: 0 | J10: 3270 | K10: 3270 | L10: =I10+K10-J10 -> 0 | M10: =VLOOKUP($E10,[3]Sheet1!$B$8:$AF$147,13,0) -> 3360 | N10: =IF(L10>M10,0,M10-L10) -> 3360 | O10: =L10+N10-M10 -> 0 | P10: =VLOOKUP($E10,[3]Sheet1!$B$8:$AF$461,19,0) -> 2520 | Q10: =IF(O10>P10,0,P10-O10) -> 2520 | R10: =O10+Q10-P10 -> 0 | S10: =VLOOKUP($E10,[3]Sheet1!$B$8:$AF$461,25,0) -> 1950 | T10: =IF(R10>S10,0,S10-R10) -> 1950 | U10: =R10+T10-S10 -> 0 | V10: =VLOOKUP($E10,[3]Sheet1!$B$8:$BF$461,31,0) -> 2550 | W10: =IF(U10>V10,0,V10-U10) -> 2550 | X10: =U10+W10-V10 -> 0 | Y10: =VLOOKUP($E10,[3]Sheet1!$B$8:$BF$461,37,0) -> 2940 | Z10: =IF(X10>Y10,0,Y10-X10) -> 2940 | AA10: =X10+Z10-Y10 -> 0 | AB10: =+Y10 -> 2940 | AC10: =IF(AA10>AB10,0,AB10-AA10) -> 2940 | AD10: =+AA10+AC10-AB10 -> 0 | AE10: GBEG-67030A | AF10: =+AB10+Y10+V10+S10+P10+M10+J10 -> 19530 | AG10: =ROUNDUP((Q10/$AG$7),0) -> 504 | AH10: =ROUNDUP((T10/$AH$7),0) -> 488 | AI10: =ROUNDUP((W10/$AI$7),0) -> 638 | AJ10: =ROUNDUP((Z10/$AJ$7),0) -> 588 | AK10: =ROUNDUP((AC10/$AK$7),0) -> 735 | AL10: =+#REF!+1 -> #REF! | AM10: =AG10*AG$7 -> 2520 | AN10: =AH10*AH$7 -> 1952 | AO10: =AI10*AI$7 -> 2552 | AP10: =AJ10*AJ$7 -> 2940 | AQ10: =AK10*AK$7 -> 2940 | AR10: =VLOOKUP(E10,'[4]DATA SR'!$D$79:$D$238,1,2) -> #N/A | AS10: BC121-6B370-2 B 0001
B11: BC121-6B220-1 | C11: =C10+1 -> 3 | D11: GBER67030 | E11: BC121-6B220-1 B 0001 | F11: 120D | G11: =VLOOKUP($E11,'[2]UMH Monthly'!$D$4:$V$510,19,0) -> 0.012176667 | I11: 0 | J11: 3200 | K11: 3200 | L11: =I11+K11-J11 -> 0 | M11: =VLOOKUP($E11,[3]Sheet1!$B$8:$AF$147,13,0) -> 2560 | N11: =IF(L11>M11,0,M11-L11) -> 2560 | O11: =L11+N11-M11 -> 0 | P11: =VLOOKUP($E11,[3]Sheet1!$B$8:$AF$461,19,0) -> 2640 | Q11: =IF(O11>P11,0,P11-O11) -> 2640 | R11: =O11+Q11-P11 -> 0 | S11: =VLOOKUP($E11,[3]Sheet1!$B$8:$AF$461,25,0) -> 2320 | T11: =IF(R11>S11,0,S11-R11) -> 2320 | U11: =R11+T11-S11 -> 0 | V11: =VLOOKUP($E11,[3]Sheet1!$B$8:$BF$461,31,0) -> 2960 | W11: =IF(U11>V11,0,V11-U11) -> 2960 | X11: =U11+W11-V11 -> 0 | Y11: =VLOOKUP($E11,[3]Sheet1!$B$8:$BF$461,37,0) -> 3920 | Z11: =IF(X11>Y11,0,Y11-X11) -> 3920 | AA11: =X11+Z11-Y11 -> 0 | AB11: =+Y11 -> 3920 | AC11: =IF(AA11>AB11,0,AB11-AA11) -> 3920 | AD11: =+AA11+AC11-AB11 -> 0 | AE11: GBER-67030A | AF11: =+AB11+Y11+V11+S11+P11+M11+J11 -> 21520 | AG11: =ROUNDUP((Q11/$AG$7),0) -> 528 | AH11: =ROUNDUP((T11/$AH$7),0) -> 580 | AI11: =ROUNDUP((W11/$AI$7),0) -> 740 | AJ11: =ROUNDUP((Z11/$AJ$7),0) -> 784 | AK11: =ROUNDUP((AC11/$AK$7),0) -> 980 | AL11: =+AL9+1 -> #REF! | AM11: =AG11*AG$7 -> 2640 | AN11: =AH11*AH$7 -> 2320 | AO11: =AI11*AI$7 -> 2960 | AP11: =AJ11*AJ$7 -> 3920 | AQ11: =AK11*AK$7 -> 3920 | AR11: =VLOOKUP(E11,'[4]DATA SR'!$D$79:$D$238,1,2) -> #N/A | AS11: BC121-6B220-1 B 0001
B12: BC121-6B250-1 | C12: =C11+1 -> 4 | D12: GBER67030 | E12: BC121-6B250-1 B 0001 | F12: 120D | G12: =VLOOKUP($E12,[5]Sheet1!$D$5:$W$460,20,0) -> 0.013471667 | I12: 0 | J12: 0 | K12: 0 | L12: =I12+K12-J12 -> 0 | M12: =VLOOKUP($E12,[3]Sheet1!$B$8:$AF$147,13,0) -> 90 | N12: =IF(L12>M12,0,M12-L12) -> 90 | O12: =L12+N12-M12 -> 0 | P12: =VLOOKUP($E12,[3]Sheet1!$B$8:$AF$461,19,0) -> 90 | Q12: =IF(O12>P12,0,P12-O12) -> 90 | R12: =O12+Q12-P12 -> 0 | S12: =VLOOKUP($E12,[3]Sheet1!$B$8:$AF$461,25,0) -> 60 | T12: =IF(R12>S12,0,S12-R12) -> 60 | U12: =R12+T12-S12 -> 0 | V12: =VLOOKUP($E12,[3]Sheet1!$B$8:$BF$461,31,0) -> 120 | W12: =IF(U12>V12,0,V12-U12) -> 120 | X12: =U12+W12-V12 -> 0 | Y12: =VLOOKUP($E12,[3]Sheet1!$B$8:$BF$461,37,0) -> 150 | Z12: =IF(X12>Y12,0,Y12-X12) -> 150 | AA12: =X12+Z12-Y12 -> 0 | AB12: =+Y12 -> 150 | AC12: =IF(AA12>AB12,0,AB12-AA12) -> 150 | AD12: =+AA12+AC12-AB12 -> 0 | AE12: GBER-67030A | AF12: =+AB12+Y12+V12+S12+P12+M12+J12 -> 660 | AG12: =ROUNDUP((Q12/$AG$7),0) -> 18 | AH12: =ROUNDUP((T12/$AH$7),0) -> 15 | AI12: =ROUNDUP((W12/$AI$7),0) -> 30 | AJ12: =ROUNDUP((Z12/$AJ$7),0) -> 30 | AK12: =ROUNDUP((AC12/$AK$7),0) -> 38 | AL12: =+AL10+1 -> #REF! | AM12: =AG12*AG$7 -> 90 | AN12: =AH12*AH$7 -> 60 | AO12: =AI12*AI$7 -> 120 | AP12: =AJ12*AJ$7 -> 150 | AQ12: =AK12*AK$7 -> 152 | AR12: =VLOOKUP(E12,'[4]DATA SR'!$D$79:$D$238,1,2) -> #N/A | AS12: BC121-6B250-1 B 0001
B13: BC121-6B260-1 | C13: =C12+1 -> 5 | D13: GNC967030 | E13: BC121-6B260-1 B 0001 | F13: 120D | G13: =VLOOKUP($E13,'[2]UMH Monthly'!$D$4:$V$510,19,0) -> 0.015718333 | H13: 0 | I13: 0 | J13: 3060 | K13: 3060 | L13: =I13+K13-J13 -> 0 | M13: =VLOOKUP($E13,[3]Sheet1!$B$8:$AF$147,13,0) -> 1960 | N13: =IF(L13>M13,0,M13-L13) -> 1960 | O13: =L13+N13-M13 -> 0 | P13: =VLOOKUP($E13,[3]Sheet1!$B$8:$AF$461,19,0) -> 1580 | Q13: =IF(O13>P13,0,P13-O13) -> 1580 | R13: =O13+Q13-P13 -> 0 | S13: =VLOOKUP($E13,[3]Sheet1!$B$8:$AF$461,25,0) -> 1480 | T13: =IF(R13>S13,0,S13-R13) -> 1480 | U13: =R13+T13-S13 -> 0 | V13: =VLOOKUP($E13,[3]Sheet1!$B$8:$BF$461,31,0) -> 1980 | W13: =IF(U13>V13,0,V13-U13) -> 1980 | X13: =U13+W13-V13 -> 0 | Y13: =VLOOKUP($E13,[3]Sheet1!$B$8:$BF$461,37,0) -> 3120 | Z13: =IF(X13>Y13,0,Y13-X13) -> 3120 | AA13: =X13+Z13-Y13 -> 0 | AB13: =+Y13 -> 3120 | AC13: =IF(AA13>AB13,0,AB13-AA13) -> 3120 | AD13: =+AA13+AC13-AB13 -> 0 | AE13: GNC9-67030A | AF13: =+AB13+Y13+V13+S13+P13+M13+J13 -> 16300 | AG13: =ROUNDUP((Q13/$AG$7),0) -> 316 | AH13: =ROUNDUP((T13/$AH$7),0) -> 370 | AI13: =ROUNDUP((W13/$AI$7),0) -> 495 | AJ13: =ROUNDUP((Z13/$AJ$7),0) -> 624 | AK13: =ROUNDUP((AC13/$AK$7),0) -> 780 | AL13: =+#REF!+1 -> #REF! | AM13: =AG13*AG$7 -> 1580 | AN13: =AH13*AH$7 -> 1480 | AO13: =AI13*AI$7 -> 1980 | AP13: =AJ13*AJ$7 -> 3120 | AQ13: =AK13*AK$7 -> 3120 | AR13: =VLOOKUP(E13,'[4]DATA SR'!$D$79:$D$238,1,2) -> #N/A | AS13: BC121-6B260-1 B 0001
B14: BC121-6B230-1 | C14: =C13+1 -> 6 | D14: GNC967030 | E14: BC121-6B230-1 B 0001 | F14: 120D | G14: 0.016306667 | H14: 0 | I14: 0 | J14: 0 | K14: 0 | L14: =I14+K14-J14 -> 0 | M14: =VLOOKUP($E14,[3]Sheet1!$B$8:$AF$147,13,0) -> 0 | N14: =IF(L14>M14,0,M14-L14) -> 0 | O14: =L14+N14-M14 -> 0 | P14: =VLOOKUP($E14,[3]Sheet1!$B$8:$AF$461,19,0) -> 0 | Q14: =IF(O14>P14,0,P14-O14) -> 0 | R14: =O14+Q14-P14 -> 0 | S14: =VLOOKUP($E14,[3]Sheet1!$B$8:$AF$461,25,0) -> 0 | T14: =IF(R14>S14,0,S14-R14) -> 0 | U14: =R14+T14-S14 -> 0 | V14: =VLOOKUP($E14,[3]Sheet1!$B$8:$BF$461,31,0) -> 0 | W14: =IF(U14>V14,0,V14-U14) -> 0 | X14: =U14+W14-V14 -> 0 | Y14: =VLOOKUP($E14,[3]Sheet1!$B$8:$BF$461,37,0) -> 0 | Z14: =IF(X14>Y14,0,Y14-X14) -> 0 | AA14: =X14+Z14-Y14 -> 0 | AB14: =+Y14 -> 0 | AC14: =IF(AA14>AB14,0,AB14-AA14) -> 0 | AD14: =+AA14+AC14-AB14 -> 0 | AE14: GNC9-67030A | AF14: =+AB14+Y14+V14+S14+P14+M14+J14 -> 0 | AG14: =ROUNDUP((Q14/$AG$7),0) -> 0 | AH14: =ROUNDUP((T14/$AH$7),0) -> 0 | AI14: =ROUNDUP((W14/$AI$7),0) -> 0 | AJ14: =ROUNDUP((Z14/$AJ$7),0) -> 0 | AK14: =ROUNDUP((AC14/$AK$7),0) -> 0 | AL14: =+#REF!+1 -> #REF! | AM14: =AG14*AG$7 -> 0 | AN14: =AH14*AH$7 -> 0 | AO14: =AI14*AI$7 -> 0 | AP14: =AJ14*AJ$7 -> 0 | AQ14: =AK14*AK$7 -> 0 | AR14: =VLOOKUP(E14,'[4]DATA SR'!$D$79:$D$238,1,2) -> #N/A | AS14: BC121-6B230-1 B 0001
B15: BC121-6AM60-1 | C15: =C14+1 -> 7 | D15: GND267030 | E15: BC121-6AM60-1 C 0001 | F15: 120D | G15: =VLOOKUP($E15,'[2]UMH Monthly'!$D$4:$V$510,19,0) -> 0.015331667 | H15: =VLOOKUP($E15,[6]MARET!$C$676:$E$776,3,0) -> #N/A | I15: 0 | J15: 0 | K15: 0 | L15: =I15+K15-J15 -> 0 | M15: =VLOOKUP($E15,[3]Sheet1!$B$8:$AF$147,13,0) -> 0 | N15: =IF(L15>M15,0,M15-L15) -> 0 | O15: =L15+N15-M15 -> 0 | P15: =VLOOKUP($E15,[3]Sheet1!$B$8:$AF$461,19,0) -> 0 | Q15: =IF(O15>P15,0,P15-O15) -> 0 | R15: =O15+Q15-P15 -> 0 | S15: =VLOOKUP($E15,[3]Sheet1!$B$8:$AF$461,25,0) -> 0 | T15: =IF(R15>S15,0,S15-R15) -> 0 | U15: =R15+T15-S15 -> 0 | V15: =VLOOKUP($E15,[3]Sheet1!$B$8:$BF$461,31,0) -> 0 | W15: =IF(U15>V15,0,V15-U15) -> 0 | X15: =U15+W15-V15 -> 0 | Y15: =VLOOKUP($E15,[3]Sheet1!$B$8:$BF$461,37,0) -> 2440 | Z15: =IF(X15>Y15,0,Y15-X15) -> 2440 | AA15: =X15+Z15-Y15 -> 0 | AB15: =+Y15 -> 2440 | AC15: =IF(AA15>AB15,0,AB15-AA15) -> 2440 | AD15: =+AA15+AC15-AB15 -> 0 | AE15: GND2-67030A | AF15: =+AB15+Y15+V15+S15+P15+M15+J15 -> 4880 | AG15: =ROUNDUP((Q15/$AG$7),0) -> 0 | AH15: =ROUNDUP((T15/$AH$7),0) -> 0 | AI15: =ROUNDUP((W15/$AI$7),0) -> 0 | AJ15: =ROUNDUP((Z15/$AJ$7),0) -> 488 | AK15: =ROUNDUP((AC15/$AK$7),0) -> 610 | AL15: =+#REF!+1 -> #REF! | AM15: =AG15*AG$7 -> 0 | AN15: =AH15*AH$7 -> 0 | AO15: =AI15*AI$7 -> 0 | AP15: =AJ15*AJ$7 -> 2440 | AQ15: =AK15*AK$7 -> 2440 | AR15: =VLOOKUP(E15,'[4]DATA SR'!$D$79:$D$238,1,2) -> #N/A | AS15: BC121-6AM60-1 C 0001
B16: BC121-35G90-1 | E16: BC121-35G70-1 D 0001 | F16: 930B | G16: =VLOOKUP($E16,'[2]UMH Monthly'!$D$4:$V$510,19,0) -> 0.015318333 | I16: 0 | J16: 4860 | K16: 4860 | L16: =I16+K16-J16 -> 0 | M16: =VLOOKUP($E16,[3]Sheet1!$B$8:$AF$147,13,0) -> 4140 | N16: =IF(L16>M16,0,M16-L16) -> 4140 | O16: =L16+N16-M16 -> 0 | P16: =VLOOKUP($E16,[3]Sheet1!$B$8:$AF$461,19,0) -> 3690 | Q16: =IF(O16>P16,0,P16-O16) -> 3690 | R16: =O16+Q16-P16 -> 0 | S16: =VLOOKUP($E16,[3]Sheet1!$B$8:$AF$461,25,0) -> 3180 | T16: =IF(R16>S16,0,S16-R16) -> 3180 | U16: =R16+T16-S16 -> 0 | V16: =VLOOKUP($E16,[3]Sheet1!$B$8:$BF$461,31,0) -> 3690 | W16: =IF(U16>V16,0,V16-U16) -> 3690 | X16: =U16+W16-V16 -> 0 | Y16: =VLOOKUP($E16,[3]Sheet1!$B$8:$BF$461,37,0) -> 4290 | Z16: =IF(X16>Y16,0,Y16-X16) -> 4290 | AA16: =X16+Z16-Y16 -> 0 | AB16: =+Y16 -> 4290 | AC16: =IF(AA16>AB16,0,AB16-AA16) -> 4290 | AD16: =+AA16+AC16-AB16 -> 0 | AE16: GND2-67030A | AF16: =+AB16+Y16+V16+S16+P16+M16+J16 -> 28140 | AG16: =ROUNDUP((Q16/$AG$7),0) -> 738 | AH16: =ROUNDUP((T16/$AH$7),0) -> 795 | AI16: =ROUNDUP((W16/$AI$7),0) -> 923 | AJ16: =ROUNDUP((Z16/$AJ$7),0) -> 858 | AK16: =ROUNDUP((AC16/$AK$7),0) -> 1073 | AL16: =+#REF!+1 -> #REF! | AM16: =AG16*AG$7 -> 3690 | AN16: =AH16*AH$7 -> 3180 | AO16: =AI16*AI$7 -> 3692 | AP16: =AJ16*AJ$7 -> 4290 | AQ16: =AK16*AK$7 -> 4292 | AR16: =VLOOKUP(E16,'[4]DATA SR'!$D$79:$D$238,1,2) -> #N/A | AS16: BC121-35G70-1 D 0001
B17: BC121-35J20-1 | E17: BC121-35G90-1 D 0001 | F17: 930B | G17: =VLOOKUP($E17,'[2]UMH Monthly'!$D$4:$V$510,19,0) -> 0.015331667 | I17: 0 | J17: 1240 | K17: 1240 | L17: =I17+K17-J17 -> 0 | M17: =VLOOKUP($E17,[3]Sheet1!$B$8:$AF$147,13,0) -> 1520 | N17: =IF(L17>M17,0,M17-L17) -> 1520 | O17: =L17+N17-M17 -> 0 | P17: =VLOOKUP($E17,[3]Sheet1!$B$8:$AF$461,19,0) -> 1340 | Q17: =IF(O17>P17,0,P17-O17) -> 1340 | R17: =O17+Q17-P17 -> 0 | S17: =VLOOKUP($E17,[3]Sheet1!$B$8:$AF$461,25,0) -> 1180 | T17: =IF(R17>S17,0,S17-R17) -> 1180 | U17: =R17+T17-S17 -> 0 | V17: =VLOOKUP($E17,[3]Sheet1!$B$8:$BF$461,31,0) -> 1400 | W17: =IF(U17>V17,0,V17-U17) -> 1400 | X17: =U17+W17-V17 -> 0 | Y17: =VLOOKUP($E17,[3]Sheet1!$B$8:$BF$461,37,0) -> 1620 | Z17: =IF(X17>Y17,0,Y17-X17) -> 1620 | AA17: =X17+Z17-Y17 -> 0 | AB17: =+Y17 -> 1620 | AC17: =IF(AA17>AB17,0,AB17-AA17) -> 1620 | AD17: =+AA17+AC17-AB17 -> 0 | AS17: BC121-35G90-1 D 0001
B18: BC139-930B2-1 | E18: BC121-35K80-1 C 0001 | F18: 930B | G18: =VLOOKUP($E18,'[2]UMH Monthly'!$D$4:$V$510,19,0) -> 0.015296667 | I18: 0 | J18: 1740 | K18: 1740 | L18: =I18+K18-J18 -> 0 | M18: =VLOOKUP($E18,[3]Sheet1!$B$8:$AF$147,13,0) -> 120 | N18: =IF(L18>M18,0,M18-L18) -> 120 | O18: =L18+N18-M18 -> 0 | P18: =VLOOKUP($E18,[3]Sheet1!$B$8:$AF$461,19,0) -> 750 | Q18: =IF(O18>P18,0,P18-O18) -> 750 | R18: =O18+Q18-P18 -> 0 | S18: =VLOOKUP($E18,[3]Sheet1!$B$8:$AF$461,25,0) -> 1680 | T18: =IF(R18>S18,0,S18-R18) -> 1680 | U18: =R18+T18-S18 -> 0 | V18: =VLOOKUP($E18,[3]Sheet1!$B$8:$BF$461,31,0) -> 2100 | W18: =IF(U18>V18,0,V18-U18) -> 2100 | X18: =U18+W18-V18 -> 0 | Y18: =VLOOKUP($E18,[3]Sheet1!$B$8:$BF$461,37,0) -> 2070 | Z18: =IF(X18>Y18,0,Y18-X18) -> 2070 | AA18: =X18+Z18-Y18 -> 0 | AB18: =+Y18 -> 2070 | AC18: =IF(AA18>AB18,0,AB18-AA18) -> 2070 | AD18: =+AA18+AC18-AB18 -> 0 | AS18: BC121-35K80-1 C 0001
B19: BC111-2FE72-1 | E19: BC111-2FE72-1 F 0201 | F19: BC 602W | G19: =VLOOKUP($E19,'[2]UMH Monthly'!$D$4:$V$510,19,0) -> 0.011176667 | I19: 0 | J19: 1260 | K19: 1260 | L19: =I19+K19-J19 -> 0 | M19: =VLOOKUP($E19,[3]Sheet1!$B$8:$AF$147,13,0) -> 1620 | N19: =IF(L19>M19,0,M19-L19) -> 1620 | O19: =L19+N19-M19 -> 0 | P19: =VLOOKUP($E19,[3]Sheet1!$B$8:$AF$461,19,0) -> 1560 | Q19: =IF(O19>P19,0,P19-O19) -> 1560 | R19: =O19+Q19-P19 -> 0 | S19: =VLOOKUP($E19,[3]Sheet1!$B$8:$AF$461,25,0) -> 1320 | T19: =IF(R19>S19,0,S19-R19) -> 1320 | U19: =R19+T19-S19 -> 0 | V19: =VLOOKUP($E19,[3]Sheet1!$B$8:$BF$461,31,0) -> 1440 | W19: =IF(U19>V19,0,V19-U19) -> 1440 | X19: =U19+W19-V19 -> 0 | Y19: =VLOOKUP($E19,[3]Sheet1!$B$8:$BF$461,37,0) -> 1680 | Z19: =IF(X19>Y19,0,Y19-X19) -> 1680 | AA19: =X19+Z19-Y19 -> 0 | AB19: =+Y19 -> 1680 | AC19: =IF(AA19>AB19,0,AB19-AA19) -> 1680 | AD19: =+AA19+AC19-AB19 -> 0 | AS19: BC111-2FE72-1 F 0201
B20: BC111-2FE72-2 | E20: BC111-2FE72-2 F 0201 | F20: BC 602W | G20: =VLOOKUP($E20,'[2]UMH Monthly'!$D$4:$V$510,19,0) -> 0.011361667 | I20: 0 | J20: 1560 | K20: 1560 | L20: =I20+K20-J20 -> 0 | M20: =VLOOKUP($E20,[3]Sheet1!$B$8:$AF$147,13,0) -> 1840 | N20: =IF(L20>M20,0,M20-L20) -> 1840 | O20: =L20+N20-M20 -> 0 | P20: =VLOOKUP($E20,[3]Sheet1!$B$8:$AF$461,19,0) -> 1360 | Q20: =IF(O20>P20,0,P20-O20) -> 1360 | R20: =O20+Q20-P20 -> 0 | S20: =VLOOKUP($E20,[3]Sheet1!$B$8:$AF$461,25,0) -> 1080 | T20: =IF(R20>S20,0,S20-R20) -> 1080 | U20: =R20+T20-S20 -> 0 | V20: =VLOOKUP($E20,[3]Sheet1!$B$8:$BF$461,31,0) -> 1180 | W20: =IF(U20>V20,0,V20-U20) -> 1180 | X20: =U20+W20-V20 -> 0 | Y20: =VLOOKUP($E20,[3]Sheet1!$B$8:$BF$461,37,0) -> 1340 | Z20: =IF(X20>Y20,0,Y20-X20) -> 1340 | AA20: =X20+Z20-Y20 -> 0 | AB20: =+Y20 -> 1340 | AC20: =IF(AA20>AB20,0,AB20-AA20) -> 1340 | AD20: =+AA20+AC20-AB20 -> 0 | AS20: BC111-2FE72-2 F 0201
B21: BC111-V3881-1 | E21: BC111-V3881-1 B 0201 | F21: BC 602W | G21: =VLOOKUP($E21,'[2]UMH Monthly'!$D$4:$V$510,19,0) -> 0.0081883333 | I21: 0 | J21: 6800 | K21: 6800 | L21: =I21+K21-J21 -> 0 | M21: =VLOOKUP($E21,[3]Sheet1!$B$8:$AF$147,13,0) -> 5360 | N21: =IF(L21>M21,0,M21-L21) -> 5360 | O21: =L21+N21-M21 -> 0 | P21: =VLOOKUP($E21,[3]Sheet1!$B$8:$AF$461,19,0) -> 4480 | Q21: =IF(O21>P21,0,P21-O21) -> 4480 | R21: =O21+Q21-P21 -> 0 | S21: =VLOOKUP($E21,[3]Sheet1!$B$8:$AF$461,25,0) -> 3920 | T21: =IF(R21>S21,0,S21-R21) -> 3920 | U21: =R21+T21-S21 -> 0 | V21: =VLOOKUP($E21,[3]Sheet1!$B$8:$BF$461,31,0) -> 4240 | W21: =IF(U21>V21,0,V21-U21) -> 4240 | X21: =U21+W21-V21 -> 0 | Y21: =VLOOKUP($E21,[3]Sheet1!$B$8:$BF$461,37,0) -> 4960 | Z21: =IF(X21>Y21,0,Y21-X21) -> 4960 | AA21: =X21+Z21-Y21 -> 0 | AB21: =+Y21 -> 4960 | AC21: =IF(AA21>AB21,0,AB21-AA21) -> 4960 | AD21: =+AA21+AC21-AB21 -> 0 | AS21: BC111-V3881-1 B 0201
B22: BC111-V3650-2 | E22: BC111-V3650-2 C 0201 | F22: BC 602W | G22: =VLOOKUP($E22,'[2]UMH Monthly'!$D$4:$V$510,19,0) -> 0.011546667 | I22: 0 | J22: 540 | K22: 540 | L22: =I22+K22-J22 -> 0 | M22: =VLOOKUP($E22,[3]Sheet1!$B$8:$AF$147,13,0) -> 0 | N22: =IF(L22>M22,0,M22-L22) -> 0 | O22: =L22+N22-M22 -> 0 | P22: =VLOOKUP($E22,[3]Sheet1!$B$8:$AF$461,19,0) -> 0 | Q22: =IF(O22>P22,0,P22-O22) -> 0 | R22: =O22+Q22-P22 -> 0 | S22: =VLOOKUP($E22,[3]Sheet1!$B$8:$AF$461,25,0) -> 0 | T22: =IF(R22>S22,0,S22-R22) -> 0 | U22: =R22+T22-S22 -> 0 | V22: =VLOOKUP($E22,[3]Sheet1!$B$8:$BF$461,31,0) -> 0 | W22: =IF(U22>V22,0,V22-U22) -> 0 | X22: =U22+W22-V22 -> 0 | Y22: =VLOOKUP($E22,[3]Sheet1!$B$8:$BF$461,37,0) -> 120 | Z22: =IF(X22>Y22,0,Y22-X22) -> 120 | AA22: =X22+Z22-Y22 -> 0 | AB22: =+Y22 -> 120 | AC22: =IF(AA22>AB22,0,AB22-AA22) -> 120 | AD22: =+AA22+AC22-AB22 -> 0 | AS22: BC111-V3650-2 C 0201
B23: BC111-V3891-6 | E23: BC111-V3891-6 B 0201 | F23: BC 602W | G23: =VLOOKUP($E23,'[2]UMH Monthly'!$D$4:$V$510,19,0) -> 0.014185 | I23: 0 | J23: 0 | K23: 0 | L23: =I23+K23-J23 -> 0 | M23: =VLOOKUP($E23,[3]Sheet1!$B$8:$AF$147,13,0) -> 0 | N23: =IF(L23>M23,0,M23-L23) -> 0 | O23: =L23+N23-M23 -> 0 | P23: =VLOOKUP($E23,[3]Sheet1!$B$8:$AF$461,19,0) -> 20 | Q23: =IF(O23>P23,0,P23-O23) -> 20 | R23: =O23+Q23-P23 -> 0 | S23: =VLOOKUP($E23,[3]Sheet1!$B$8:$AF$461,25,0) -> 0 | T23: =IF(R23>S23,0,S23-R23) -> 0 | U23: =R23+T23-S23 -> 0 | V23: =VLOOKUP($E23,[3]Sheet1!$B$8:$BF$461,31,0) -> 0 | W23: =IF(U23>V23,0,V23-U23) -> 0 | X23: =U23+W23-V23 -> 0 | Y23: =VLOOKUP($E23,[3]Sheet1!$B$8:$BF$461,37,0) -> 0 | Z23: =IF(X23>Y23,0,Y23-X23) -> 0 | AA23: =X23+Z23-Y23 -> 0 | AB23: =+Y23 -> 0 | AC23: =IF(AA23>AB23,0,AB23-AA23) -> 0 | AD23: =+AA23+AC23-AB23 -> 0 | AS23: BC111-V3891-6 B 0201
B24: BC111-V3891-1 | E24: BC111-V3891-1 F 0001 | F24: BC 602W | G24: =VLOOKUP($E24,'[2]UMH Monthly'!$D$4:$V$510,19,0) -> 0.013916667 | I24: 0 | J24: 0 | K24: 0 | L24: =I24+K24-J24 -> 0 | M24: =VLOOKUP($E24,[3]Sheet1!$B$8:$AF$147,13,0) -> 0 | N24: =IF(L24>M24,0,M24-L24) -> 0 | O24: =L24+N24-M24 -> 0 | P24: =VLOOKUP($E24,[3]Sheet1!$B$8:$AF$461,19,0) -> 0 | Q24: =IF(O24>P24,0,P24-O24) -> 0 | R24: =O24+Q24-P24 -> 0 | S24: =VLOOKUP($E24,[3]Sheet1!$B$8:$AF$461,25,0) -> 0 | T24: =IF(R24>S24,0,S24-R24) -> 0 | U24: =R24+T24-S24 -> 0 | V24: =VLOOKUP($E24,[3]Sheet1!$B$8:$BF$461,31,0) -> 0 | W24: =IF(U24>V24,0,V24-U24) -> 0 | X24: =U24+W24-V24 -> 0 | Y24: =VLOOKUP($E24,[3]Sheet1!$B$8:$BF$461,37,0) -> 0 | Z24: =IF(X24>Y24,0,Y24-X24) -> 0 | AA24: =X24+Z24-Y24 -> 0 | AB24: =+Y24 -> 0 | AC24: =IF(AA24>AB24,0,AB24-AA24) -> 0 | AD24: =+AA24+AC24-AB24 -> 0 | AS24: BC111-V3891-1 F 0001
B25: BC111-V3891-2 | E25: BC111-V3891-2 F 0001 | F25: BC 602W | G25: =VLOOKUP($E25,'[2]UMH Monthly'!$D$4:$V$510,19,0) -> 0.011736667 | I25: 0 | J25: 0 | K25: 0 | L25: =I25+K25-J25 -> 0 | M25: =VLOOKUP($E25,[3]Sheet1!$B$8:$AF$147,13,0) -> 0 | N25: =IF(L25>M25,0,M25-L25) -> 0 | O25: =L25+N25-M25 -> 0 | P25: =VLOOKUP($E25,[3]Sheet1!$B$8:$AF$461,19,0) -> 0 | Q25: =IF(O25>P25,0,P25-O25) -> 0 | R25: =O25+Q25-P25 -> 0 | S25: =VLOOKUP($E25,[3]Sheet1!$B$8:$AF$461,25,0) -> 0 | T25: =IF(R25>S25,0,S25-R25) -> 0 | U25: =R25+T25-S25 -> 0 | V25: =VLOOKUP($E25,[3]Sheet1!$B$8:$BF$461,31,0) -> 0 | W25: =IF(U25>V25,0,V25-U25) -> 0 | X25: =U25+W25-V25 -> 0 | Y25: =VLOOKUP($E25,[3]Sheet1!$B$8:$BF$461,37,0) -> 0 | Z25: =IF(X25>Y25,0,Y25-X25) -> 0 | AA25: =X25+Z25-Y25 -> 0 | AB25: =+Y25 -> 0 | AC25: =IF(AA25>AB25,0,AB25-AA25) -> 0 | AD25: =+AA25+AC25-AB25 -> 0 | AS25: BC111-V3891-2 F 0001
B26: DC111-2FE72 | E26: DC111-2FE72 F 0201 | F26: BC 602W | G26: =VLOOKUP($E26,'[2]UMH Monthly'!$D$4:$V$510,19,0) -> 0.015235 | I26: 0 | J26: 160 | K26: 160 | L26: =I26+K26-J26 -> 0 | M26: =VLOOKUP($E26,[3]Sheet1!$B$8:$AF$147,13,0) -> 160 | N26: =IF(L26>M26,0,M26-L26) -> 160 | O26: =L26+N26-M26 -> 0 | P26: =VLOOKUP($E26,[3]Sheet1!$B$8:$AF$461,19,0) -> 80 | Q26: =IF(O26>P26,0,P26-O26) -> 80 | R26: =O26+Q26-P26 -> 0 | S26: =VLOOKUP($E26,[3]Sheet1!$B$8:$AF$461,25,0) -> 80 | T26: =IF(R26>S26,0,S26-R26) -> 80 | U26: =R26+T26-S26 -> 0 | V26: =VLOOKUP($E26,[3]Sheet1!$B$8:$BF$461,31,0) -> 80 | W26: =IF(U26>V26,0,V26-U26) -> 80 | X26: =U26+W26-V26 -> 0 | Y26: =VLOOKUP($E26,[3]Sheet1!$B$8:$BF$461,37,0) -> 120 | Z26: =IF(X26>Y26,0,Y26-X26) -> 120 | AA26: =X26+Z26-Y26 -> 0 | AB26: =+Y26 -> 120 | AC26: =IF(AA26>AB26,0,AB26-AA26) -> 120 | AD26: =+AA26+AC26-AB26 -> 0 | AS26: DC111-2FE72 F 0201
B27: DC111-2FK53 | E27: DC111-2FK53 F 0201 | F27: BC 602W | G27: =VLOOKUP($E27,'[2]UMH Monthly'!$D$4:$V$510,19,0) -> 0.015235 | I27: 0 | J27: 1440 | K27: 1440 | L27: =I27+K27-J27 -> 0 | M27: =VLOOKUP($E27,[3]Sheet1!$B$8:$AF$147,13,0) -> 1680 | N27: =IF(L27>M27,0,M27-L27) -> 1680 | O27: =L27+N27-M27 -> 0 | P27: =VLOOKUP($E27,[3]Sheet1!$B$8:$AF$461,19,0) -> 1240 | Q27: =IF(O27>P27,0,P27-O27) -> 1240 | R27: =O27+Q27-P27 -> 0 | S27: =VLOOKUP($E27,[3]Sheet1!$B$8:$AF$461,25,0) -> 1040 | T27: =IF(R27>S27,0,S27-R27) -> 1040 | U27: =R27+T27-S27 -> 0 | V27: =VLOOKUP($E27,[3]Sheet1!$B$8:$BF$461,31,0) -> 1080 | W27: =IF(U27>V27,0,V27-U27) -> 1080 | X27: =U27+W27-V27 -> 0 | Y27: =VLOOKUP($E27,[3]Sheet1!$B$8:$BF$461,37,0) -> 1240 | Z27: =IF(X27>Y27,0,Y27-X27) -> 1240 | AA27: =X27+Z27-Y27 -> 0 | AB27: =+Y27 -> 1240 | AC27: =IF(AA27>AB27,0,AB27-AA27) -> 1240 | AD27: =+AA27+AC27-AB27 -> 0 | AS27: DC111-2FK53 F 0201
B28: DC111-V3A41 | E28: DC111-V3A41 B 0201 | F28: BC 602W | G28: =VLOOKUP($E28,'[2]UMH Monthly'!$D$4:$V$510,19,0) -> 0.015096667 | I28: 0 | J28: 0 | K28: 0 | L28: =I28+K28-J28 -> 0 | M28: =VLOOKUP($E28,[3]Sheet1!$B$8:$AF$147,13,0) -> 0 | N28: =IF(L28>M28,0,M28-L28) -> 0 | O28: =L28+N28-M28 -> 0 | P28: =VLOOKUP($E28,[3]Sheet1!$B$8:$AF$461,19,0) -> 0 | Q28: =IF(O28>P28,0,P28-O28) -> 0 | R28: =O28+Q28-P28 -> 0 | S28: =VLOOKUP($E28,[3]Sheet1!$B$8:$AF$461,25,0) -> 0 | T28: =IF(R28>S28,0,S28-R28) -> 0 | U28: =R28+T28-S28 -> 0 | V28: =VLOOKUP($E28,[3]Sheet1!$B$8:$BF$461,31,0) -> 0 | W28: =IF(U28>V28,0,V28-U28) -> 0 | X28: =U28+W28-V28 -> 0 | Y28: =VLOOKUP($E28,[3]Sheet1!$B$8:$BF$461,37,0) -> 0 | Z28: =IF(X28>Y28,0,Y28-X28) -> 0 | AA28: =X28+Z28-Y28 -> 0 | AB28: =+Y28 -> 0 | AC28: =IF(AA28>AB28,0,AB28-AA28) -> 0 | AD28: =+AA28+AC28-AB28 -> 0 | AS28: DC111-V3A41 B 0201
... B31: DC111-V3891 | E31: DC111-V3891 B 0201 | F31: BC 602W | G31: =VLOOKUP($E31,'[2]UMH Monthly'!$D$4:$V$510,19,0) -> 0.015805 | I31: 0 | J31: 0 | K31: 0 | L31: =I31+K31-J31 -> 0 | M31: =VLOOKUP($E31,[3]Sheet1!$B$8:$AF$147,13,0) -> 0 | N31: =IF(L31>M31,0,M31-L31) -> 0 | O31: =L31+N31-M31 -> 0 | P31: =VLOOKUP($E31,[3]Sheet1!$B$8:$AF$461,19,0) -> 0 | Q31: =IF(O31>P31,0,P31-O31) -> 0 | R31: =O31+Q31-P31 -> 0 | S31: =VLOOKUP($E31,[3]Sheet1!$B$8:$AF$461,25,0) -> 0 | T31: =IF(R31>S31,0,S31-R31) -> 0 | U31: =R31+T31-S31 -> 0 | V31: =VLOOKUP($E31,[3]Sheet1!$B$8:$BF$461,31,0) -> 0 | W31: =IF(U31>V31,0,V31-U31) -> 0 | X31: =U31+W31-V31 -> 0 | Y31: =VLOOKUP($E31,[3]Sheet1!$B$8:$BF$461,37,0) -> 0 | Z31: =IF(X31>Y31,0,Y31-X31) -> 0 | AA31: =X31+Z31-Y31 -> 0 | AB31: =+Y31 -> 0 | AC31: =IF(AA31>AB31,0,AB31-AA31) -> 0 | AD31: =+AA31+AC31-AB31 -> 0 | AS31: DC111-V3891 B 0201
B32: BC111-11730-3 | E32: BC111-11730-3 B 0001 | F32: BC 819W | G32: =VLOOKUP($E32,'[2]UMH Monthly'!$D$4:$V$510,19,0) -> 0.014606667 | I32: 0 | J32: 0 | K32: 0 | L32: =I32+K32-J32 -> 0 | M32: =VLOOKUP($E32,[3]Sheet1!$B$8:$AF$147,13,0) -> 0 | N32: =IF(L32>M32,0,M32-L32) -> 0 | O32: =L32+N32-M32 -> 0 | P32: =VLOOKUP($E32,[3]Sheet1!$B$8:$AF$461,19,0) -> 0 | Q32: =IF(O32>P32,0,P32-O32) -> 0 | R32: =O32+Q32-P32 -> 0 | S32: =VLOOKUP($E32,[3]Sheet1!$B$8:$AF$461,25,0) -> 0 | T32: =IF(R32>S32,0,S32-R32) -> 0 | U32: =R32+T32-S32 -> 0 | V32: =VLOOKUP($E32,[3]Sheet1!$B$8:$BF$461,31,0) -> 0 | W32: =IF(U32>V32,0,V32-U32) -> 0 | X32: =U32+W32-V32 -> 0 | Y32: =VLOOKUP($E32,[3]Sheet1!$B$8:$BF$461,37,0) -> 0 | Z32: =IF(X32>Y32,0,Y32-X32) -> 0 | AA32: =X32+Z32-Y32 -> 0 | AB32: =+Y32 -> 0 | AC32: =IF(AA32>AB32,0,AB32-AA32) -> 0 | AD32: =+AA32+AC32-AB32 -> 0 | AE32: BC111-11730-3 B 0001 | AS32: BC111-11730-3 B 0001
B33: BC111-11810-3 | E33: BC111-11810-3 2001 | F33: BC 819W | G33: =VLOOKUP($E33,'[2]UMH Monthly'!$D$4:$V$510,19,0) -> 0.014675 | I33: 0 | J33: 0 | K33: 0 | L33: =I33+K33-J33 -> 0 | M33: =VLOOKUP($E33,[3]Sheet1!$B$8:$AF$147,13,0) -> 0 | N33: =IF(L33>M33,0,M33-L33) -> 0 | O33: =L33+N33-M33 -> 0 | P33: =VLOOKUP($E33,[3]Sheet1!$B$8:$AF$461,19,0) -> 20 | Q33: =IF(O33>P33,0,P33-O33) -> 20 | R33: =O33+Q33-P33 -> 0 | S33: =VLOOKUP($E33,[3]Sheet1!$B$8:$AF$461,25,0) -> 0 | T33: =IF(R33>S33,0,S33-R33) -> 0 | U33: =R33+T33-S33 -> 0 | V33: =VLOOKUP($E33,[3]Sheet1!$B$8:$BF$461,31,0) -> 0 | W33: =IF(U33>V33,0,V33-U33) -> 0 | X33: =U33+W33-V33 -> 0 | Y33: =VLOOKUP($E33,[3]Sheet1!$B$8:$BF$461,37,0) -> 0 | Z33: =IF(X33>Y33,0,Y33-X33) -> 0 | AA33: =X33+Z33-Y33 -> 0 | AB33: =+Y33 -> 0 | AC33: =IF(AA33>AB33,0,AB33-AA33) -> 0 | AD33: =+AA33+AC33-AB33 -> 0 | AE33: BC111-11810-3 2001 | AS33: BC111-11810-3 2001
B34: BC111-5A851-2 | E34: BC111-5A843-2 0001 | F34: BC 819W | G34: =VLOOKUP($E34,'[2]UMH Monthly'!$D$4:$V$510,19,0) -> 0.016293333 | I34: 0 | J34: 0 | K34: 0 | L34: =I34+K34-J34 -> 0 | M34: =VLOOKUP($E34,[3]Sheet1!$B$8:$AF$147,13,0) -> 0 | N34: =IF(L34>M34,0,M34-L34) -> 0 | O34: =L34+N34-M34 -> 0 | P34: =VLOOKUP($E34,[3]Sheet1!$B$8:$AF$461,19,0) -> 40 | Q34: =IF(O34>P34,0,P34-O34) -> 40 | R34: =O34+Q34-P34 -> 0 | S34: =VLOOKUP($E34,[3]Sheet1!$B$8:$AF$461,25,0) -> 0 | T34: =IF(R34>S34,0,S34-R34) -> 0 | U34: =R34+T34-S34 -> 0 | V34: =VLOOKUP($E34,[3]Sheet1!$B$8:$BF$461,31,0) -> 0 | W34: =IF(U34>V34,0,V34-U34) -> 0 | X34: =U34+W34-V34 -> 0 | Y34: =VLOOKUP($E34,[3]Sheet1!$B$8:$BF$461,37,0) -> 0 | Z34: =IF(X34>Y34,0,Y34-X34) -> 0 | AA34: =X34+Z34-Y34 -> 0 | AB34: =+Y34 -> 0 | AC34: =IF(AA34>AB34,0,AB34-AA34) -> 0 | AD34: =+AA34+AC34-AB34 -> 0 | AE34: BC111-5A843-2 0001 | AS34: BC111-5A843-2 0001
B35: BC111-5A852-2 | E35: BC111-5A852-2 A 0002 | F35: BC 819W | G35: =VLOOKUP($E35,'[2]UMH Monthly'!$D$4:$V$510,19,0) -> 0.014731667 | I35: 0 | J35: 0 | K35: 0 | L35: =I35+K35-J35 -> 0 | M35: =VLOOKUP($E35,[3]Sheet1!$B$8:$AF$147,13,0) -> 0 | N35: =IF(L35>M35,0,M35-L35) -> 0 | O35: =L35+N35-M35 -> 0 | P35: =VLOOKUP($E35,[3]Sheet1!$B$8:$AF$461,19,0) -> 0 | Q35: =IF(O35>P35,0,P35-O35) -> 0 | R35: =O35+Q35-P35 -> 0 | S35: =VLOOKUP($E35,[3]Sheet1!$B$8:$AF$461,25,0) -> 0 | T35: =IF(R35>S35,0,S35-R35) -> 0 | U35: =R35+T35-S35 -> 0 | V35: =VLOOKUP($E35,[3]Sheet1!$B$8:$BF$461,31,0) -> 0 | W35: =IF(U35>V35,0,V35-U35) -> 0 | X35: =U35+W35-V35 -> 0 | Y35: =VLOOKUP($E35,[3]Sheet1!$B$8:$BF$461,37,0) -> 0 | Z35: =IF(X35>Y35,0,Y35-X35) -> 0 | AA35: =X35+Z35-Y35 -> 0 | AB35: =+Y35 -> 0 | AC35: =IF(AA35>AB35,0,AB35-AA35) -> 0 | AD35: =+AA35+AC35-AB35 -> 0 | AE35: BC111-5A883-2 0001 | AS35: BC111-5A852-2 A 0002
B36: BC111-5AA01-2 | E36: BC111-5A883-2 0001 | F36: BC 819W | G36: =VLOOKUP($E36,'[2]UMH Monthly'!$D$4:$V$510,19,0) -> 0.016293333 | I36: 0 | J36: 20 | K36: 20 | L36: =I36+K36-J36 -> 0 | M36: =VLOOKUP($E36,[3]Sheet1!$B$8:$AF$147,13,0) -> 40 | N36: =IF(L36>M36,0,M36-L36) -> 40 | O36: =L36+N36-M36 -> 0 | P36: =VLOOKUP($E36,[3]Sheet1!$B$8:$AF$461,19,0) -> 40 | Q36: =IF(O36>P36,0,P36-O36) -> 40 | R36: =O36+Q36-P36 -> 0 | S36: =VLOOKUP($E36,[3]Sheet1!$B$8:$AF$461,25,0) -> 20 | T36: =IF(R36>S36,0,S36-R36) -> 20 | U36: =R36+T36-S36 -> 0 | V36: =VLOOKUP($E36,[3]Sheet1!$B$8:$BF$461,31,0) -> 0 | W36: =IF(U36>V36,0,V36-U36) -> 0 | X36: =U36+W36-V36 -> 0 | Y36: =VLOOKUP($E36,[3]Sheet1!$B$8:$BF$461,37,0) -> 0 | Z36: =IF(X36>Y36,0,Y36-X36) -> 0 | AA36: =X36+Z36-Y36 -> 0 | AB36: =+Y36 -> 0 | AC36: =IF(AA36>AB36,0,AB36-AA36) -> 0 | AD36: =+AA36+AC36-AB36 -> 0 | AE36: BC111-5AC33-2 0001 | AS36: BC111-5A883-2 0001
B37: BC111-5AE91-2 | E37: BC111-5AC33-2 0001 | F37: BC 819W | G37: =VLOOKUP($E37,'[2]UMH Monthly'!$D$4:$V$510,19,0) -> 0.01628 | I37: 0 | J37: 40 | K37: 40 | L37: =I37+K37-J37 -> 0 | M37: =VLOOKUP($E37,[3]Sheet1!$B$8:$AF$147,13,0) -> 20 | N37: =IF(L37>M37,0,M37-L37) -> 20 | O37: =L37+N37-M37 -> 0 | P37: =VLOOKUP($E37,[3]Sheet1!$B$8:$AF$461,19,0) -> 20 | Q37: =IF(O37>P37,0,P37-O37) -> 20 | R37: =O37+Q37-P37 -> 0 | S37: =VLOOKUP($E37,[3]Sheet1!$B$8:$AF$461,25,0) -> 20 | T37: =IF(R37>S37,0,S37-R37) -> 20 | U37: =R37+T37-S37 -> 0 | V37: =VLOOKUP($E37,[3]Sheet1!$B$8:$BF$461,31,0) -> 0 | W37: =IF(U37>V37,0,V37-U37) -> 0 | X37: =U37+W37-V37 -> 0 | Y37: =VLOOKUP($E37,[3]Sheet1!$B$8:$BF$461,37,0) -> 0 | Z37: =IF(X37>Y37,0,Y37-X37) -> 0 | AA37: =X37+Z37-Y37 -> 0 | AB37: =+Y37 -> 0 | AC37: =IF(AA37>AB37,0,AB37-AA37) -> 0 | AD37: =+AA37+AC37-AB37 -> 0 | AE37: BC111-5AA03-2 0001 | AF37: =+AB37+Y37+V37+S37+P37+M37+J37 -> 100 | AG37: =ROUNDUP((Q37/$AG$7),0) -> 4 | AH37: =ROUNDUP((T37/$AH$7),0) -> 5 | AI37: =ROUNDUP((W37/$AI$7),0) -> 0 | AJ37: =ROUNDUP((Z37/$AJ$7),0) -> 0 | AK37: =ROUNDUP((AC37/$AK$7),0) -> 0 | AL37: =+#REF!+1 -> #REF! | AM37: =AG37*AG$7 -> 20 | AN37: =AH37*AH$7 -> 20 | AO37: =AI37*AI$7 -> 0 | AP37: =AJ37*AJ$7 -> 0 | AQ37: =AK37*AK$7 -> 0 | AR37: =VLOOKUP(E37,'[4]DATA SR'!$D$79:$D$238,1,2) -> #N/A | AS37: BC111-5AC33-2 0001
B38: BC111-5AA03-2 | E38: BC111-5AA03-2 0001 | F38: BC 819W | G38: =VLOOKUP($E38,'[2]UMH Monthly'!$D$4:$V$510,19,0) -> 0.016305 | I38: 0 | J38: 40 | K38: 40 | L38: =I38+K38-J38 -> 0 | M38: =VLOOKUP($E38,[3]Sheet1!$B$8:$AF$147,13,0) -> 20 | N38: =IF(L38>M38,0,M38-L38) -> 20 | O38: =L38+N38-M38 -> 0 | P38: =VLOOKUP($E38,[3]Sheet1!$B$8:$AF$461,19,0) -> 40 | Q38: =IF(O38>P38,0,P38-O38) -> 40 | R38: =O38+Q38-P38 -> 0 | S38: =VLOOKUP($E38,[3]Sheet1!$B$8:$AF$461,25,0) -> 20 | T38: =IF(R38>S38,0,S38-R38) -> 20 | U38: =R38+T38-S38 -> 0 | V38: =VLOOKUP($E38,[3]Sheet1!$B$8:$BF$461,31,0) -> 0 | W38: =IF(U38>V38,0,V38-U38) -> 0 | X38: =U38+W38-V38 -> 0 | Y38: =VLOOKUP($E38,[3]Sheet1!$B$8:$BF$461,37,0) -> 0 | Z38: =IF(X38>Y38,0,Y38-X38) -> 0 | AA38: =X38+Z38-Y38 -> 0 | AB38: =+Y38 -> 0 | AC38: =IF(AA38>AB38,0,AB38-AA38) -> 0 | AD38: =+AA38+AC38-AB38 -> 0 | AE38: BC111-62092-2 B 1001 | AS38: BC111-5AA03-2 0001
B39: BC111-5AA02-2 | E39: BC111-5AA02-2 A 0002 | F39: BC 819W | G39: =VLOOKUP($E39,'[2]UMH Monthly'!$D$4:$V$510,19,0) -> 0.014756667 | I39: 0 | J39: 0 | K39: 0 | L39: =I39+K39-J39 -> 0 | M39: =VLOOKUP($E39,[3]Sheet1!$B$8:$AF$147,13,0) -> 0 | N39: =IF(L39>M39,0,M39-L39) -> 0 | O39: =L39+N39-M39 -> 0 | P39: =VLOOKUP($E39,[3]Sheet1!$B$8:$AF$461,19,0) -> 0 | Q39: =IF(O39>P39,0,P39-O39) -> 0 | R39: =O39+Q39-P39 -> 0 | S39: =VLOOKUP($E39,[3]Sheet1!$B$8:$AF$461,25,0) -> 0 | T39: =IF(R39>S39,0,S39-R39) -> 0 | U39: =R39+T39-S39 -> 0 | V39: =VLOOKUP($E39,[3]Sheet1!$B$8:$BF$461,31,0) -> 0 | W39: =IF(U39>V39,0,V39-U39) -> 0 | X39: =U39+W39-V39 -> 0 | Y39: =VLOOKUP($E39,[3]Sheet1!$B$8:$BF$461,37,0) -> 0 | Z39: =IF(X39>Y39,0,Y39-X39) -> 0 | AA39: =X39+Z39-Y39 -> 0 | AB39: =+Y39 -> 0 | AC39: =IF(AA39>AB39,0,AB39-AA39) -> 0 | AD39: =+AA39+AC39-AB39 -> 0 | AE39: BC111-62062-2 B 1001 | AF39: =+AB39+Y39+V39+S39+P39+M39+J39 -> 0 | AG39: =ROUNDUP((Q39/$AG$7),0) -> 0 | AH39: =ROUNDUP((T39/$AH$7),0) -> 0 | AI39: =ROUNDUP((W39/$AI$7),0) -> 0 | AJ39: =ROUNDUP((Z39/$AJ$7),0) -> 0 | AK39: =ROUNDUP((AC39/$AK$7),0) -> 0 | AL39: =+#REF!+1 -> #REF! | AM39: =AG39*AG$7 -> 0 | AN39: =AH39*AH$7 -> 0 | AO39: =AI39*AI$7 -> 0 | AP39: =AJ39*AJ$7 -> 0 | AQ39: =AK39*AK$7 -> 0 | AR39: =VLOOKUP(E39,'[4]DATA SR'!$D$79:$D$238,1,2) -> #N/A | AS39: BC111-5AA02-2 A 0002
B40: BC111-5A841-2 | E40: BC111-5A841-2 A 0002 | F40: BC 819W | G40: =VLOOKUP($E40,'[2]UMH Monthly'!$D$4:$V$510,19,0) -> 0.014745 | I40: 0 | J40: 0 | K40: 0 | L40: =I40+K40-J40 -> 0 | M40: =VLOOKUP($E40,[3]Sheet1!$B$8:$AF$147,13,0) -> 0 | N40: =IF(L40>M40,0,M40-L40) -> 0 | O40: =L40+N40-M40 -> 0 | P40: =VLOOKUP($E40,[3]Sheet1!$B$8:$AF$461,19,0) -> 0 | Q40: =IF(O40>P40,0,P40-O40) -> 0 | R40: =O40+Q40-P40 -> 0 | S40: =VLOOKUP($E40,[3]Sheet1!$B$8:$AF$461,25,0) -> 0 | T40: =IF(R40>S40,0,S40-R40) -> 0 | U40: =R40+T40-S40 -> 0 | V40: =VLOOKUP($E40,[3]Sheet1!$B$8:$BF$461,31,0) -> 0 | W40: =IF(U40>V40,0,V40-U40) -> 0 | X40: =U40+W40-V40 -> 0 | Y40: =VLOOKUP($E40,[3]Sheet1!$B$8:$BF$461,37,0) -> 0 | Z40: =IF(X40>Y40,0,Y40-X40) -> 0 | AA40: =X40+Z40-Y40 -> 0 | AB40: =+Y40 -> 0 | AC40: =IF(AA40>AB40,0,AB40-AA40) -> 0 | AD40: =+AA40+AC40-AB40 -> 0 | AE40: GBER-67030A | AF40: =+AB40+Y40+V40+S40+P40+M40+J40 -> 0 | AG40: =ROUNDUP((Q40/$AG$7),0) -> 0 | AH40: =ROUNDUP((T40/$AH$7),0) -> 0 | AI40: =ROUNDUP((W40/$AI$7),0) -> 0 | AJ40: =ROUNDUP((Z40/$AJ$7),0) -> 0 | AK40: =ROUNDUP((AC40/$AK$7),0) -> 0 | AL40: =+AL37+1 -> #REF! | AM40: =AG40*AG$7 -> 0 | AN40: =AH40*AH$7 -> 0 | AO40: =AI40*AI$7 -> 0 | AP40: =AJ40*AJ$7 -> 0 | AQ40: =AK40*AK$7 -> 0 | AR40: =VLOOKUP(E40,'[4]DATA SR'!$D$79:$D$238,1,2) -> #N/A | AS40: BC111-5A841-2 A 0002
B41: BC111-5A881-2 | E41: BC111-5A881-2 A 0002 | F41: BC 819W | G41: =VLOOKUP($E41,'[2]UMH Monthly'!$D$4:$V$510,19,0) -> 0.014745 | I41: 0 | J41: 0 | K41: 0 | L41: =I41+K41-J41 -> 0 | M41: =VLOOKUP($E41,[3]Sheet1!$B$8:$AF$147,13,0) -> 0 | N41: =IF(L41>M41,0,M41-L41) -> 0 | O41: =L41+N41-M41 -> 0 | P41: =VLOOKUP($E41,[3]Sheet1!$B$8:$AF$461,19,0) -> 0 | Q41: =IF(O41>P41,0,P41-O41) -> 0 | R41: =O41+Q41-P41 -> 0 | S41: =VLOOKUP($E41,[3]Sheet1!$B$8:$AF$461,25,0) -> 0 | T41: =IF(R41>S41,0,S41-R41) -> 0 | U41: =R41+T41-S41 -> 0 | V41: =VLOOKUP($E41,[3]Sheet1!$B$8:$BF$461,31,0) -> 0 | W41: =IF(U41>V41,0,V41-U41) -> 0 | X41: =U41+W41-V41 -> 0 | Y41: =VLOOKUP($E41,[3]Sheet1!$B$8:$BF$461,37,0) -> 0 | Z41: =IF(X41>Y41,0,Y41-X41) -> 0 | AA41: =X41+Z41-Y41 -> 0 | AB41: =+Y41 -> 0 | AC41: =IF(AA41>AB41,0,AB41-AA41) -> 0 | AD41: =+AA41+AC41-AB41 -> 0 | AE41: GBER-67030A | AF41: =+AB41+Y41+V41+S41+P41+M41+J41 -> 0 | AG41: =ROUNDUP((Q41/$AG$7),0) -> 0 | AH41: =ROUNDUP((T41/$AH$7),0) -> 0 | AI41: =ROUNDUP((W41/$AI$7),0) -> 0 | AJ41: =ROUNDUP((Z41/$AJ$7),0) -> 0 | AK41: =ROUNDUP((AC41/$AK$7),0) -> 0 | AL41: =+AL39+1 -> #REF! | AM41: =AG41*AG$7 -> 0 | AN41: =AH41*AH$7 -> 0 | AO41: =AI41*AI$7 -> 0 | AP41: =AJ41*AJ$7 -> 0 | AQ41: =AK41*AK$7 -> 0 | AR41: =VLOOKUP(E41,'[4]DATA SR'!$D$79:$D$238,1,2) -> #N/A | AS41: BC111-5A881-2 A 0002
B42: BC111-1HQ61-1 | E42: BC111-1HQ61-1 A 1001 | F42: BC 891W | G42: =VLOOKUP($E42,'[2]UMH Monthly'!$D$4:$V$510,19,0) -> 0.012791667 | I42: 0 | J42: 4520 | K42: 4520 | L42: =I42+K42-J42 -> 0 | M42: =VLOOKUP($E42,[3]Sheet1!$B$8:$AF$147,13,0) -> 5000 | N42: =IF(L42>M42,0,M42-L42) -> 5000 | O42: =L42+N42-M42 -> 0 | P42: =VLOOKUP($E42,[3]Sheet1!$B$8:$AF$461,19,0) -> 5320 | Q42: =IF(O42>P42,0,P42-O42) -> 5320 | R42: =O42+Q42-P42 -> 0 | S42: =VLOOKUP($E42,[3]Sheet1!$B$8:$AF$461,25,0) -> 4440 | T42: =IF(R42>S42,0,S42-R42) -> 4440 | U42: =R42+T42-S42 -> 0 | V42: =VLOOKUP($E42,[3]Sheet1!$B$8:$BF$461,31,0) -> 5280 | W42: =IF(U42>V42,0,V42-U42) -> 5280 | X42: =U42+W42-V42 -> 0 | Y42: =VLOOKUP($E42,[3]Sheet1!$B$8:$BF$461,37,0) -> 6280 | Z42: =IF(X42>Y42,0,Y42-X42) -> 6280 | AA42: =X42+Z42-Y42 -> 0 | AB42: =+Y42 -> 6280 | AC42: =IF(AA42>AB42,0,AB42-AA42) -> 6280 | AD42: =+AA42+AC42-AB42 -> 0 | AE42: GNC9-67030A | AF42: =+AB42+Y42+V42+S42+P42+M42+J42 -> 37120 | AG42: =ROUNDUP((Q42/$AG$7),0) -> 1064 | AH42: =ROUNDUP((T42/$AH$7),0) -> 1110 | AI42: =ROUNDUP((W42/$AI$7),0) -> 1320 | AJ42: =ROUNDUP((Z42/$AJ$7),0) -> 1256 | AK42: =ROUNDUP((AC42/$AK$7),0) -> 1570 | AL42: =+#REF!+1 -> #REF! | AM42: =AG42*AG$7 -> 5320 | AN42: =AH42*AH$7 -> 4440 | AO42: =AI42*AI$7 -> 5280 | AP42: =AJ42*AJ$7 -> 6280 | AQ42: =AK42*AK$7 -> 6280 | AR42: =VLOOKUP(E42,'[4]DATA SR'!$D$79:$D$238,1,2) -> #N/A | AS42: BC111-1HQ61-1 A 1001
...

Sheet GUM UMH
L1: SIX MONTH PRODUCTION PLAN ( UMH ) | AE1: CHECKED
A2: S/R NO : | B2: ='QTY '!B2:C2 -> 0 | L2: ='QTY '!I2 -> BC120D
A3: FAX NO : EMAIL | L3: ='QTY '!I3 -> 46082 | AJ3: AS400
A4: DATE | B4: ='QTY '!B4 -> 46094.693 | AE4: ASE
A6: TYPE | C6: HARNESS No. | D6: LEVEL | E6: ASSY CODE | F6: CCT | G6: STD PACK | H6: UMH (Jul-Des) 2011 | I6: UMH (Jan-Jun) 2010 | J6: UMH (Jul-Dec) 2010 | K6: ='QTY '!G6:G8 -> UMH | L6: ='QTY '!I6 -> FEB | O6: ='QTY '!L6 -> MAR | R6: ='QTY '!O6 -> APR | U6: ='QTY '!R6 -> MAY | X6: ='QTY '!U6 -> JUN | AA6: ='QTY '!X6 -> JUL | AD6: ='QTY '!AA6 -> AUG | AG6: BAL
L7: =VLOOKUP(L6,[1]Calender!$A$386:$I$455,9,0) -> 01/FEB ~ 28/FEB | O7: =VLOOKUP(O6,[1]Calender!$A$386:$I$455,9,0) -> 01/MAR ~ 31/MAR | R7: =VLOOKUP(R6,[1]Calender!$A$386:$I$455,9,0) -> 01/APR ~ 29/APR | U7: =VLOOKUP(U6,[1]Calender!$A$386:$I$455,9,0) -> 02/MAY ~ 31/MAY | X7: =VLOOKUP(X6,[1]Calender!$A$386:$I$455,9,0) -> 01/JUN ~ 30/JUN | AA7: =VLOOKUP(AA6,[1]Calender!$A$386:$I$455,9,0) -> 01/JUL ~ 29/JUL | AD7: =VLOOKUP(AD6,[1]Calender!$A$386:$I$455,9,0) -> 01/AUG ~ 26/AUG | AJ7: 4 | AK7: 4 | AL7: 4 | AM7: 4 | AN7: 4
L8: BAL | M8: DEL | N8: PROD | O8: BAL | P8: DEL | Q8: PROD | R8: BAL | S8: DEL | T8: PROD | U8: BAL | V8: DEL | W8: PROD | X8: BAL | Y8: DEL | Z8: PROD | AA8: BAL | AB8: DEL | AC8: PROD | AD8: BAL | AE8: DEL | AF8: PROD | AJ8: =R6 -> APR | AK8: =U6 -> MAY | AL8: =X6:X6 -> JUN | AM8: =AA6 -> JUL | AN8: =AD6 -> AUG
A9: ='QTY '!C9 -> 1 | B9: =+'QTY '!F9 -> 120D | C9: =+'QTY '!E9 -> BC121-6B370-1 B 0001 | D9: =VLOOKUP(C9,'[9]1'!$B$6:$C$112,2,0) -> #N/A | G9: 32 | H9: =+'[10]QTY '!#REF! -> #REF! | K9: =VLOOKUP($C9,'QTY '!E9:G47,3,0) -> 0.015695 | L9: =$K9*'QTY '!I9 -> 0 | M9: =$K9*'QTY '!J9 -> 51.7935 | N9: =$K9*'QTY '!K9 -> 51.7935 | O9: =$K9*'QTY '!L9 -> 0 | P9: =$K9*'QTY '!M9 -> 52.7352 | Q9: =$K9*'QTY '!N9 -> 52.7352 | R9: =$K9*'QTY '!O9 -> 0 | S9: =$K9*'QTY '!P9 -> 39.5514 | ... AF9: =$K9*'QTY '!AC9 -> 46.1433 | AG9: =+AD9+AF9-AE9 -> 0 | AJ9: =ROUNDUP((T9/$AJ$7),0) -> 10 | AK9: =ROUNDUP((W9/$AK$7),0) -> 8 | AL9: =ROUNDUP((Z9/$AL$7),0) -> 11 | AM9: =ROUNDUP((AC9/$AM$7),0) -> 12 | AN9: =ROUNDUP((AF9/$AN$7),0) -> 12 | AO9: =+#REF!+1 -> #REF! | AP9: =AJ9*AJ$7 -> 40 | AQ9: =AK9*AK$7 -> 32 | AR9: =AL9*AL$7 -> 44 | AS9: =AM9*AM$7 -> 48 | AT9: =AN9*AN$7 -> 48
A10: ='QTY '!C10 -> 2 | B10: =+'QTY '!F10 -> 120D | C10: =+'QTY '!E10 -> BC121-6B370-2 B 0001 | D10: =VLOOKUP(C10,'[9]1'!$B$6:$C$112,2,0) -> #N/A | G10: 32 | H10: =+'[10]QTY '!#REF! -> #REF! | K10: =VLOOKUP($C10,'QTY '!E10:G85,3,0) -> 0.015746667 | L10: =$K10*'QTY '!I10 -> 0 | M10: =$K10*'QTY '!J10 -> 51.4916 | N10: =$K10*'QTY '!K10 -> 51.4916 | O10: =$K10*'QTY '!L10 -> 0 | P10: =$K10*'QTY '!M10 -> 52.9088 | Q10: =$K10*'QTY '!N10 -> 52.9088 | R10: =$K10*'QTY '!O10 -> 0 | S10: =$K10*'QTY '!P10 -> 39.6816 | ... AF10: =$K10*'QTY '!AC10 -> 46.2952 | AG10: =+AD10+AF10-AE10 -> 0 | AJ10: =ROUNDUP((T10/$AJ$7),0) -> 10 | AK10: =ROUNDUP((W10/$AK$7),0) -> 8 | AL10: =ROUNDUP((Z10/$AL$7),0) -> 11 | AM10: =ROUNDUP((AC10/$AM$7),0) -> 12 | AN10: =ROUNDUP((AF10/$AN$7),0) -> 12 | AO10: =+#REF!+1 -> #REF! | AP10: =AJ10*AJ$7 -> 40 | AQ10: =AK10*AK$7 -> 32 | AR10: =AL10*AL$7 -> 44 | AS10: =AM10*AM$7 -> 48 | AT10: =AN10*AN$7 -> 48
A11: ='QTY '!C11 -> 3 | B11: =+'QTY '!F11 -> 120D | C11: =+'QTY '!E11 -> BC121-6B220-1 B 0001 | D11: =VLOOKUP(C11,'[9]1'!$B$6:$C$112,2,0) -> #N/A | G11: 32 | H11: =+'[10]QTY '!#REF! -> #REF! | K11: =VLOOKUP($C11,'QTY '!E11:G86,3,0) -> 0.012176667 | L11: =$K11*'QTY '!I11 -> 0 | M11: =$K11*'QTY '!J11 -> 38.965333 | N11: =$K11*'QTY '!K11 -> 38.965333 | O11: =$K11*'QTY '!L11 -> 0 | P11: =$K11*'QTY '!M11 -> 31.172267 | Q11: =$K11*'QTY '!N11 -> 31.172267 | R11: =$K11*'QTY '!O11 -> 0 | S11: =$K11*'QTY '!P11 -> 32.1464 | ... AF11: =$K11*'QTY '!AC11 -> 47.732533 | AG11: =+AD11+AF11-AE11 -> 0 | AJ11: =ROUNDUP((T11/$AJ$7),0) -> 9 | AK11: =ROUNDUP((W11/$AK$7),0) -> 8 | AL11: =ROUNDUP((Z11/$AL$7),0) -> 10 | AM11: =ROUNDUP((AC11/$AM$7),0) -> 12 | AN11: =ROUNDUP((AF11/$AN$7),0) -> 12 | AO11: =+#REF!+1 -> #REF! | AP11: =AJ11*AJ$7 -> 36 | AQ11: =AK11*AK$7 -> 32 | AR11: =AL11*AL$7 -> 40 | AS11: =AM11*AM$7 -> 48 | AT11: =AN11*AN$7 -> 48
A12: ='QTY '!C12 -> 4 | B12: =+'QTY '!F12 -> 120D | C12: =+'QTY '!E12 -> BC121-6B250-1 B 0001 | D12: =VLOOKUP(C12,'[9]1'!$B$6:$C$112,2,0) -> #N/A | G12: 32 | H12: =+'[10]QTY '!#REF! -> #REF! | K12: =VLOOKUP($C12,'QTY '!E12:G87,3,0) -> 0.013471667 | L12: =$K12*'QTY '!I12 -> 0 | M12: =$K12*'QTY '!J12 -> 0 | N12: =$K12*'QTY '!K12 -> 0 | O12: =$K12*'QTY '!L12 -> 0 | P12: =$K12*'QTY '!M12 -> 1.21245 | Q12: =$K12*'QTY '!N12 -> 1.21245 | R12: =$K12*'QTY '!O12 -> 0 | S12: =$K12*'QTY '!P12 -> 1.21245 | ... AF12: =$K12*'QTY '!AC12 -> 2.02075 | AG12: =+AD12+AF12-AE12 -> 0 | AJ12: =ROUNDUP((T12/$AJ$7),0) -> 1 | AK12: =ROUNDUP((W12/$AK$7),0) -> 1 | AL12: =ROUNDUP((Z12/$AL$7),0) -> 1 | AM12: =ROUNDUP((AC12/$AM$7),0) -> 1 | AN12: =ROUNDUP((AF12/$AN$7),0) -> 1 | AO12: =+#REF!+1 -> #REF! | AP12: =AJ12*AJ$7 -> 4 | AQ12: =AK12*AK$7 -> 4 | AR12: =AL12*AL$7 -> 4 | AS12: =AM12*AM$7 -> 4 | AT12: =AN12*AN$7 -> 4
A13: ='QTY '!C13 -> 5 | B13: =+'QTY '!F13 -> 120D | C13: =+'QTY '!E13 -> BC121-6B260-1 B 0001 | D13: =VLOOKUP(C13,'[9]1'!$B$6:$C$112,2,0) -> #N/A | G13: 32 | H13: =+'[10]QTY '!#REF! -> #REF! | K13: =VLOOKUP($C13,'QTY '!E13:G88,3,0) -> 0.015718333 | L13: =$K13*'QTY '!I13 -> 0 | M13: =$K13*'QTY '!J13 -> 48.0981 | N13: =$K13*'QTY '!K13 -> 48.0981 | O13: =$K13*'QTY '!L13 -> 0 | P13: =$K13*'QTY '!M13 -> 30.807933 | Q13: =$K13*'QTY '!N13 -> 30.807933 | R13: =$K13*'QTY '!O13 -> 0 | S13: =$K13*'QTY '!P13 -> 24.834967 | ... AF13: =$K13*'QTY '!AC13 -> 49.0412 | AG13: =+AD13+AF13-AE13 -> 0 | AJ13: =ROUNDUP((T13/$AJ$7),0) -> 7 | AK13: =ROUNDUP((W13/$AK$7),0) -> 6 | AL13: =ROUNDUP((Z13/$AL$7),0) -> 8 | AM13: =ROUNDUP((AC13/$AM$7),0) -> 13 | AN13: =ROUNDUP((AF13/$AN$7),0) -> 13 | AO13: =+#REF!+1 -> #REF! | AP13: =AJ13*AJ$7 -> 28 | AQ13: =AK13*AK$7 -> 24 | AR13: =AL13*AL$7 -> 32 | AS13: =AM13*AM$7 -> 52 | AT13: =AN13*AN$7 -> 52
A14: ='QTY '!C14 -> 6 | B14: =+'QTY '!F14 -> 120D | C14: =+'QTY '!E14 -> BC121-6B230-1 B 0001 | D14: =VLOOKUP(C14,'[9]1'!$B$6:$C$112,2,0) -> #N/A | G14: 32 | H14: =+'[10]QTY '!#REF! -> #REF! | K14: =VLOOKUP($C14,'QTY '!E14:G89,3,0) -> 0.016306667 | L14: =$K14*'QTY '!I14 -> 0 | M14: =$K14*'QTY '!J14 -> 0 | N14: =$K14*'QTY '!K14 -> 0 | O14: =$K14*'QTY '!L14 -> 0 | P14: =$K14*'QTY '!M14 -> 0 | Q14: =$K14*'QTY '!N14 -> 0 | R14: =$K14*'QTY '!O14 -> 0 | S14: =$K14*'QTY '!P14 -> 0 | ... AF14: =$K14*'QTY '!AC14 -> 0 | AG14: =+AD14+AF14-AE14 -> 0 | AJ14: =ROUNDUP((T14/$AJ$7),0) -> 0 | AK14: =ROUNDUP((W14/$AK$7),0) -> 0 | AL14: =ROUNDUP((Z14/$AL$7),0) -> 0 | AM14: =ROUNDUP((AC14/$AM$7),0) -> 0 | AN14: =ROUNDUP((AF14/$AN$7),0) -> 0 | AO14: =+#REF!+1 -> #REF! | AP14: =AJ14*AJ$7 -> 0 | AQ14: =AK14*AK$7 -> 0 | AR14: =AL14*AL$7 -> 0 | AS14: =AM14*AM$7 -> 0 | AT14: =AN14*AN$7 -> 0
A15: ='QTY '!C15 -> 7 | B15: =+'QTY '!F15 -> 120D | C15: =+'QTY '!E15 -> BC121-6AM60-1 C 0001 | D15: =VLOOKUP(C15,'[9]1'!$B$6:$C$112,2,0) -> #N/A | G15: 32 | H15: =+'[10]QTY '!#REF! -> #REF! | K15: =VLOOKUP($C15,'QTY '!E15:G90,3,0) -> 0.015331667 | L15: =$K15*'QTY '!I15 -> 0 | M15: =$K15*'QTY '!J15 -> 0 | N15: =$K15*'QTY '!K15 -> 0 | O15: =$K15*'QTY '!L15 -> 0 | P15: =$K15*'QTY '!M15 -> 0 | Q15: =$K15*'QTY '!N15 -> 0 | R15: =$K15*'QTY '!O15 -> 0 | S15: =$K15*'QTY '!P15 -> 0 | ... AF15: =$K15*'QTY '!AC15 -> 37.409267 | AG15: =+AD15+AF15-AE15 -> 0 | AJ15: =ROUNDUP((T15/$AJ$7),0) -> 0 | AK15: =ROUNDUP((W15/$AK$7),0) -> 0 | AL15: =ROUNDUP((Z15/$AL$7),0) -> 0 | AM15: =ROUNDUP((AC15/$AM$7),0) -> 10 | AN15: =ROUNDUP((AF15/$AN$7),0) -> 10 | AO15: =+#REF!+1 -> #REF! | AP15: =AJ15*AJ$7 -> 0 | AQ15: =AK15*AK$7 -> 0 | AR15: =AL15*AL$7 -> 0 | AS15: =AM15*AM$7 -> 40 | AT15: =AN15*AN$7 -> 40
B16: =+'QTY '!F16 -> 930B | C16: =+'QTY '!E16 -> BC121-35G70-1 D 0001 | K16: =VLOOKUP($C16,'QTY '!E16:G91,3,0) -> 0.015318333 | L16: =$K16*'QTY '!I16 -> 0 | M16: =$K16*'QTY '!J16 -> 74.4471 | N16: =$K16*'QTY '!K16 -> 74.4471 | O16: =$K16*'QTY '!L16 -> 0 | P16: =$K16*'QTY '!M16 -> 63.4179 | Q16: =$K16*'QTY '!N16 -> 63.4179 | R16: =$K16*'QTY '!O16 -> 0 | S16: =$K16*'QTY '!P16 -> 56.52465 | ... AF16: =$K16*'QTY '!AC16 -> 65.71565 | AG16: =+AD16+AF16-AE16 -> 0
B17: =+'QTY '!F17 -> 930B | C17: =+'QTY '!E17 -> BC121-35G90-1 D 0001 | K17: =VLOOKUP($C17,'QTY '!E17:G92,3,0) -> 0.015331667 | L17: =$K17*'QTY '!I17 -> 0 | M17: =$K17*'QTY '!J17 -> 19.011267 | N17: =$K17*'QTY '!K17 -> 19.011267 | O17: =$K17*'QTY '!L17 -> 0 | P17: =$K17*'QTY '!M17 -> 23.304133 | Q17: =$K17*'QTY '!N17 -> 23.304133 | R17: =$K17*'QTY '!O17 -> 0 | S17: =$K17*'QTY '!P17 -> 20.544433 | ... AF17: =$K17*'QTY '!AC17 -> 24.8373 | AG17: =+AD17+AF17-AE17 -> 0
B18: =+'QTY '!F18 -> 930B | C18: =+'QTY '!E18 -> BC121-35K80-1 C 0001 | K18: =VLOOKUP($C18,'QTY '!E18:G93,3,0) -> 0.015296667 | L18: =$K18*'QTY '!I18 -> 0 | M18: =$K18*'QTY '!J18 -> 26.6162 | N18: =$K18*'QTY '!K18 -> 26.6162 | O18: =$K18*'QTY '!L18 -> 0 | P18: =$K18*'QTY '!M18 -> 1.8356 | Q18: =$K18*'QTY '!N18 -> 1.8356 | R18: =$K18*'QTY '!O18 -> 0 | S18: =$K18*'QTY '!P18 -> 11.4725 | ... AF18: =$K18*'QTY '!AC18 -> 31.6641 | AG18: =+AD18+AF18-AE18 -> 0
B19: =+'QTY '!F19 -> BC 602W | C19: =+'QTY '!E19 -> BC111-2FE72-1 F 0201 | K19: =VLOOKUP($C19,'QTY '!E19:G94,3,0) -> 0.011176667 | L19: =$K19*'QTY '!I19 -> 0 | M19: =$K19*'QTY '!J19 -> 14.0826 | N19: =$K19*'QTY '!K19 -> 14.0826 | O19: =$K19*'QTY '!L19 -> 0 | P19: =$K19*'QTY '!M19 -> 18.1062 | Q19: =$K19*'QTY '!N19 -> 18.1062 | R19: =$K19*'QTY '!O19 -> 0 | S19: =$K19*'QTY '!P19 -> 17.4356 | ... AF19: =$K19*'QTY '!AC19 -> 18.7768 | AG19: =+AD19+AF19-AE19 -> 0
B20: =+'QTY '!F20 -> BC 602W | C20: =+'QTY '!E20 -> BC111-2FE72-2 F 0201 | K20: =VLOOKUP($C20,'QTY '!E20:G95,3,0) -> 0.011361667 | L20: =$K20*'QTY '!I20 -> 0 | M20: =$K20*'QTY '!J20 -> 17.7242 | N20: =$K20*'QTY '!K20 -> 17.7242 | O20: =$K20*'QTY '!L20 -> 0 | P20: =$K20*'QTY '!M20 -> 20.905467 | Q20: =$K20*'QTY '!N20 -> 20.905467 | R20: =$K20*'QTY '!O20 -> 0 | S20: =$K20*'QTY '!P20 -> 15.451867 | ... AF20: =$K20*'QTY '!AC20 -> 15.224633 | AG20: =+AD20+AF20-AE20 -> 0
B21: =+'QTY '!F21 -> BC 602W | C21: =+'QTY '!E21 -> BC111-V3881-1 B 0201 | K21: =VLOOKUP($C21,'QTY '!E21:G96,3,0) -> 0.0081883333 | L21: =$K21*'QTY '!I21 -> 0 | M21: =$K21*'QTY '!J21 -> 55.680667 | N21: =$K21*'QTY '!K21 -> 55.680667 | O21: =$K21*'QTY '!L21 -> 0 | P21: =$K21*'QTY '!M21 -> 43.889467 | Q21: =$K21*'QTY '!N21 -> 43.889467 | R21: =$K21*'QTY '!O21 -> 0 | S21: =$K21*'QTY '!P21 -> 36.683733 | ... AF21: =$K21*'QTY '!AC21 -> 40.614133 | AG21: =+AD21+AF21-AE21 -> 0
B22: =+'QTY '!F22 -> BC 602W | C22: =+'QTY '!E22 -> BC111-V3650-2 C 0201 | K22: =VLOOKUP($C22,'QTY '!E22:G97,3,0) -> 0.011546667 | L22: =$K22*'QTY '!I22 -> 0 | M22: =$K22*'QTY '!J22 -> 6.2352 | N22: =$K22*'QTY '!K22 -> 6.2352 | O22: =$K22*'QTY '!L22 -> 0 | P22: =$K22*'QTY '!M22 -> 0 | Q22: =$K22*'QTY '!N22 -> 0 | R22: =$K22*'QTY '!O22 -> 0 | S22: =$K22*'QTY '!P22 -> 0 | ... AF22: =$K22*'QTY '!AC22 -> 1.3856 | AG22: =+AD22+AF22-AE22 -> 0
B23: =+'QTY '!F23 -> BC 602W | C23: =+'QTY '!E23 -> BC111-V3891-6 B 0201 | K23: =VLOOKUP($C23,'QTY '!E23:G98,3,0) -> 0.014185 | L23: =$K23*'QTY '!I23 -> 0 | M23: =$K23*'QTY '!J23 -> 0 | N23: =$K23*'QTY '!K23 -> 0 | O23: =$K23*'QTY '!L23 -> 0 | P23: =$K23*'QTY '!M23 -> 0 | Q23: =$K23*'QTY '!N23 -> 0 | R23: =$K23*'QTY '!O23 -> 0 | S23: =$K23*'QTY '!P23 -> 0.2837 | ... AF23: =$K23*'QTY '!AC23 -> 0 | AG23: =+AD23+AF23-AE23 -> 0
B24: =+'QTY '!F24 -> BC 602W | C24: =+'QTY '!E24 -> BC111-V3891-1 F 0001 | K24: =VLOOKUP($C24,'QTY '!E24:G99,3,0) -> 0.013916667 | L24: =$K24*'QTY '!I24 -> 0 | M24: =$K24*'QTY '!J24 -> 0 | N24: =$K24*'QTY '!K24 -> 0 | O24: =$K24*'QTY '!L24 -> 0 | P24: =$K24*'QTY '!M24 -> 0 | Q24: =$K24*'QTY '!N24 -> 0 | R24: =$K24*'QTY '!O24 -> 0 | S24: =$K24*'QTY '!P24 -> 0 | ... AF24: =$K24*'QTY '!AC24 -> 0 | AG24: =+AD24+AF24-AE24 -> 0
B25: =+'QTY '!F25 -> BC 602W | C25: =+'QTY '!E25 -> BC111-V3891-2 F 0001 | K25: =VLOOKUP($C25,'QTY '!E25:G100,3,0) -> 0.011736667 | L25: =$K25*'QTY '!I25 -> 0 | M25: =$K25*'QTY '!J25 -> 0 | N25: =$K25*'QTY '!K25 -> 0 | O25: =$K25*'QTY '!L25 -> 0 | P25: =$K25*'QTY '!M25 -> 0 | Q25: =$K25*'QTY '!N25 -> 0 | R25: =$K25*'QTY '!O25 -> 0 | S25: =$K25*'QTY '!P25 -> 0 | ... AF25: =$K25*'QTY '!AC25 -> 0 | AG25: =+AD25+AF25-AE25 -> 0
B26: =+'QTY '!F26 -> BC 602W | C26: =+'QTY '!E26 -> DC111-2FE72 F 0201 | K26: =VLOOKUP($C26,'QTY '!E26:G101,3,0) -> 0.015235 | L26: =$K26*'QTY '!I26 -> 0 | M26: =$K26*'QTY '!J26 -> 2.4376 | N26: =$K26*'QTY '!K26 -> 2.4376 | O26: =$K26*'QTY '!L26 -> 0 | P26: =$K26*'QTY '!M26 -> 2.4376 | Q26: =$K26*'QTY '!N26 -> 2.4376 | R26: =$K26*'QTY '!O26 -> 0 | S26: =$K26*'QTY '!P26 -> 1.2188 | ... AF26: =$K26*'QTY '!AC26 -> 1.8282 | AG26: =+AD26+AF26-AE26 -> 0
B27: =+'QTY '!F27 -> BC 602W | C27: =+'QTY '!E27 -> DC111-2FK53 F 0201 | K27: =VLOOKUP($C27,'QTY '!E27:G102,3,0) -> 0.015235 | L27: =$K27*'QTY '!I27 -> 0 | M27: =$K27*'QTY '!J27 -> 21.9384 | N27: =$K27*'QTY '!K27 -> 21.9384 | O27: =$K27*'QTY '!L27 -> 0 | P27: =$K27*'QTY '!M27 -> 25.5948 | Q27: =$K27*'QTY '!N27 -> 25.5948 | R27: =$K27*'QTY '!O27 -> 0 | S27: =$K27*'QTY '!P27 -> 18.8914 | ... AF27: =$K27*'QTY '!AC27 -> 18.8914 | AG27: =+AD27+AF27-AE27 -> 0
... B37: =+'QTY '!F37 -> BC 819W | C37: =+'QTY '!E37 -> BC111-5AC33-2 0001 | K37: =VLOOKUP($C37,'QTY '!E37:G112,3,0) -> 0.01628 | L37: =$K37*'QTY '!I37 -> 0 | M37: =$K37*'QTY '!J37 -> 0.6512 | N37: =$K37*'QTY '!K37 -> 0.6512 | O37: =$K37*'QTY '!L37 -> 0 | P37: =$K37*'QTY '!M37 -> 0.3256 | Q37: =$K37*'QTY '!N37 -> 0.3256 | R37: =$K37*'QTY '!O37 -> 0 | S37: =$K37*'QTY '!P37 -> 0.3256 | ... AF37: =$K37*'QTY '!AC37 -> 0 | AG37: =+AD37+AF37-AE37 -> 0
B38: =+'QTY '!F39 -> BC 819W | C38: =+'QTY '!E38 -> BC111-5AA03-2 0001 | K38: =VLOOKUP($C38,'QTY '!E38:G113,3,0) -> 0.016305 | L38: =$K38*'QTY '!I38 -> 0 | M38: =$K38*'QTY '!J38 -> 0.6522 | N38: =$K38*'QTY '!K38 -> 0.6522 | O38: =$K38*'QTY '!L38 -> 0 | P38: =$K38*'QTY '!M38 -> 0.3261 | Q38: =$K38*'QTY '!N38 -> 0.3261 | R38: =$K38*'QTY '!O38 -> 0 | S38: =$K38*'QTY '!P38 -> 0.6522 | ... AF38: =$K38*'QTY '!AC38 -> 0 | AG38: =+AD38+AF38-AE38 -> 0
B39: =+'QTY '!F40 -> BC 819W | C39: =+'QTY '!E39 -> BC111-5AA02-2 A 0002 | K39: =VLOOKUP($C39,'QTY '!E39:G114,3,0) -> 0.014756667 | L39: =$K39*'QTY '!I39 -> 0 | M39: =$K39*'QTY '!J39 -> 0 | N39: =$K39*'QTY '!K39 -> 0 | O39: =$K39*'QTY '!L39 -> 0 | P39: =$K39*'QTY '!M39 -> 0 | Q39: =$K39*'QTY '!N39 -> 0 | R39: =$K39*'QTY '!O39 -> 0 | S39: =$K39*'QTY '!P39 -> 0 | ... AF39: =$K39*'QTY '!AC39 -> 0 | AG39: =+AD39+AF39-AE39 -> 0
B40: =+'QTY '!F41 -> BC 819W | C40: =+'QTY '!E40 -> BC111-5A841-2 A 0002 | K40: =VLOOKUP($C40,'QTY '!E40:G115,3,0) -> 0.014745 | L40: =$K40*'QTY '!I40 -> 0 | M40: =$K40*'QTY '!J40 -> 0 | N40: =$K40*'QTY '!K40 -> 0 | O40: =$K40*'QTY '!L40 -> 0 | P40: =$K40*'QTY '!M40 -> 0 | Q40: =$K40*'QTY '!N40 -> 0 | R40: =$K40*'QTY '!O40 -> 0 | S40: =$K40*'QTY '!P40 -> 0 | ... AF40: =$K40*'QTY '!AC40 -> 0 | AG40: =+AD40+AF40-AE40 -> 0
B41: =+'QTY '!F42 -> BC 891W | C41: =+'QTY '!E41 -> BC111-5A881-2 A 0002 | K41: =VLOOKUP($C41,'QTY '!E41:G116,3,0) -> 0.014745 | L41: =$K41*'QTY '!I41 -> 0 | M41: =$K41*'QTY '!J41 -> 0 | N41: =$K41*'QTY '!K41 -> 0 | O41: =$K41*'QTY '!L41 -> 0 | P41: =$K41*'QTY '!M41 -> 0 | Q41: =$K41*'QTY '!N41 -> 0 | R41: =$K41*'QTY '!O41 -> 0 | S41: =$K41*'QTY '!P41 -> 0 | ... AF41: =$K41*'QTY '!AC41 -> 0 | AG41: =+AD41+AF41-AE41 -> 0
B42: =+'QTY '!F43 -> BC 891W | C42: =+'QTY '!E42 -> BC111-1HQ61-1 A 1001 | K42: =VLOOKUP($C42,'QTY '!E42:G117,3,0) -> 0.012791667 | L42: =$K42*'QTY '!I42 -> 0 | M42: =$K42*'QTY '!J42 -> 57.818333 | N42: =$K42*'QTY '!K42 -> 57.818333 | O42: =$K42*'QTY '!L42 -> 0 | P42: =$K42*'QTY '!M42 -> 63.958333 | Q42: =$K42*'QTY '!N42 -> 63.958333 | R42: =$K42*'QTY '!O42 -> 0 | S42: =$K42*'QTY '!P42 -> 68.051667 | ... AF42: =$K42*'QTY '!AC42 -> 80.331667 | AG42: =+AD42+AF42-AE42 -> 0
B43: =+'QTY '!F44 -> BC 891W | C43: =+'QTY '!E43 -> BC111-1HY10-1 A 1001 | K43: =VLOOKUP($C43,'QTY '!E43:G118,3,0) -> 0.01391 | L43: =$K43*'QTY '!I43 -> 0 | M43: =$K43*'QTY '!J43 -> 0 | N43: =$K43*'QTY '!K43 -> 0 | O43: =$K43*'QTY '!L43 -> 0 | P43: =$K43*'QTY '!M43 -> 1.6692 | Q43: =$K43*'QTY '!N43 -> 1.6692 | R43: =$K43*'QTY '!O43 -> 0 | S43: =$K43*'QTY '!P43 -> 0.8346 | ... AF43: =$K43*'QTY '!AC43 -> 0.8346 | AG43: =+AD43+AF43-AE43 -> 0
B44: =+'QTY '!F45 -> BC 891W | C44: =+'QTY '!E44 -> BC111-1HY10-2 A 1001 | K44: =VLOOKUP($C44,'QTY '!E44:G119,3,0) -> 0.013613333 | L44: =$K44*'QTY '!I44 -> 0 | M44: =$K44*'QTY '!J44 -> 0 | N44: =$K44*'QTY '!K44 -> 0 | O44: =$K44*'QTY '!L44 -> 0 | P44: =$K44*'QTY '!M44 -> 0 | Q44: =$K44*'QTY '!N44 -> 0 | R44: =$K44*'QTY '!O44 -> 0 | S44: =$K44*'QTY '!P44 -> 0 | ... AF44: =$K44*'QTY '!AC44 -> 0 | AG44: =+AD44+AF44-AE44 -> 0
B45: =+'QTY '!F46 -> BC 766W | C45: =+'QTY '!E45 -> BC111-1HR01-1 0002 | K45: =VLOOKUP($C45,'QTY '!E45:G120,3,0) -> 0.012791667 | L45: =$K45*'QTY '!I45 -> 0 | M45: =$K45*'QTY '!J45 -> 88.518333 | N45: =$K45*'QTY '!K45 -> 88.518333 | O45: =$K45*'QTY '!L45 -> 0 | P45: =$K45*'QTY '!M45 -> 82.378333 | Q45: =$K45*'QTY '!N45 -> 82.378333 | R45: =$K45*'QTY '!O45 -> 0 | S45: =$K45*'QTY '!P45 -> 82.89 | ... AF45: =$K45*'QTY '!AC45 -> 107.96167 | AG45: =+AD45+AF45-AE45 -> 0
B46: =+'QTY '!F47 -> BC 766W | C46: =+'QTY '!E46 -> BC111-62092-2 B 1001 | K46: =VLOOKUP($C46,'QTY '!E46:G121,3,0) -> 0.014745 | L46: =$K46*'QTY '!I46 -> 0 | M46: =$K46*'QTY '!J46 -> 0 | N46: =$K46*'QTY '!K46 -> 0 | O46: =$K46*'QTY '!L46 -> 0 | P46: =$K46*'QTY '!M46 -> 0 | Q46: =$K46*'QTY '!N46 -> 0 | R46: =$K46*'QTY '!O46 -> 0 | S46: =$K46*'QTY '!P46 -> 0 | ... AF46: =$K46*'QTY '!AC46 -> 0 | AG46: =+AD46+AF46-AE46 -> 0
C47: =+'QTY '!E47 -> BC111-62062-2 B 1001 | K47: =VLOOKUP($C47,'QTY '!E47:G122,3,0) -> 0.014745 | L47: =$K47*'QTY '!I47 -> 0 | M47: =$K47*'QTY '!J47 -> 0 | N47: =$K47*'QTY '!K47 -> 0 | O47: =$K47*'QTY '!L47 -> 0 | P47: =$K47*'QTY '!M47 -> 0 | Q47: =$K47*'QTY '!N47 -> 0 | R47: =$K47*'QTY '!O47 -> 0 | S47: =$K47*'QTY '!P47 -> 0 | ... AF47: =$K47*'QTY '!AC47 -> 0 | AG47: =+AD47+AF47-AE47 -> 0
C48: =+'QTY '!E48 -> BC111-16P60-1 0001 | K48: =VLOOKUP($C48,'QTY '!E48:G123,3,0) -> 0.01233 | L48: =$K48*'QTY '!I48 -> 0 | M48: =$K48*'QTY '!J48 -> 18.2484 | N48: =$K48*'QTY '!K48 -> 18.2484 | O48: =$K48*'QTY '!L48 -> 0 | P48: =$K48*'QTY '!M48 -> 26.8794 | Q48: =$K48*'QTY '!N48 -> 26.8794 | R48: =$K48*'QTY '!O48 -> 0 | S48: =$K48*'QTY '!P48 -> 20.961 | ... AF48: =$K48*'QTY '!AC48 -> 19.2348 | AG48: =+AD48+AF48-AE48 -> 0
C49: =+'QTY '!E49 -> BC111-16J40-1 0001 | K49: =VLOOKUP($C49,'QTY '!E49:G124,3,0) -> 0.012791667 | L49: =$K49*'QTY '!I49 -> 0 | M49: =$K49*'QTY '!J49 -> 65.493333 | N49: =$K49*'QTY '!K49 -> 65.493333 | O49: =$K49*'QTY '!L49 -> 0 | P49: =$K49*'QTY '!M49 -> 54.236667 | Q49: =$K49*'QTY '!N49 -> 54.236667 | R49: =$K49*'QTY '!O49 -> 0 | S49: =$K49*'QTY '!P49 -> 57.818333 | ... AF49: =$K49*'QTY '!AC49 -> 50.655 | AG49: =+AD49+AF49-AE49 -> 0
C50: =+'QTY '!E50 -> BC111-16R30-1 0001 | K50: =VLOOKUP($C50,'QTY '!E50:G125,3,0) -> 0.012791667 | L50: =$K50*'QTY '!I50 -> 0 | M50: =$K50*'QTY '!J50 -> 35.816667 | N50: =$K50*'QTY '!K50 -> 35.816667 | O50: =$K50*'QTY '!L50 -> 0 | P50: =$K50*'QTY '!M50 -> 18.931667 | Q50: =$K50*'QTY '!N50 -> 18.931667 | R50: =$K50*'QTY '!O50 -> 0 | S50: =$K50*'QTY '!P50 -> 26.606667 | ... AF50: =$K50*'QTY '!AC50 -> 24.56 | AG50: =+AD50+AF50-AE50 -> 0
...

Sheet AS400 JEMBATAN
A2: ='[14]Qty & UMH GUM'!A2 -> S/R NO : | B2: ='QTY '!B2 -> 0
A3: ='[14]Qty & UMH GUM'!A4 -> DATE : | B3: ='QTY '!B4 -> 46094.693
D4: 4 | M4: 5 | V4: 4 | AE4: 4 | AN4: 5
A5: Printed : | B5: =NOW() -> 46094.693 | D5: Q | M5: T | V5: W | AE5: Z | AN5: AC
A6: TYPE | B6: HARNESS No. | C6: LEVEL | D6: =+'QTY '!O6 -> APR | M6: =+'QTY '!R6 -> MAY | V6: =+'QTY '!U6 -> JUN | AE6: =+'QTY '!X6 -> JUL | AN6: =+'QTY '!AA6 -> AUG
D8: 1 | E8: 2 | F8: 3 | G8: 4 | H8: 5 | I8: SR | J8: SPP | K8: BAL | L8: VALUE | M8: 1 | N8: 2 | O8: 3 | P8: 4 | Q8: 5 | R8: SR | S8: SPP | T8: BAL | U8: VALUE | V8: 1 | W8: 2 | X8: 3 | Y8: 4 | Z8: 5 | AA8: SR | AB8: SPP | AC8: BAL | AD8: VALUE | AE8: 1 | AF8: 2 | AG8: 3 | AH8: 4 | AI8: =+AH8+1 -> 5 | AJ8: SR | AK8: SPP | AL8: BAL | AM8: VALUE | AN8: 1 | AO8: 2 | AP8: 3 | AQ8: 4 | AR8: 5 | AS8: SR | AT8: SPP | AU8: BAL | AV8: VALUE | AW8: =+J6 -> 0 | AX8: =+S6 -> 0 | AY8: =+AB6 -> 0 | AZ8: =+AK6 -> 0 | BA8: =+AT6 -> 0
A9: =+'QTY '!B9 -> BC121-6B370-1 | B9: =+'QTY '!E9 -> BC121-6B370-1 B 0001 | C9: ='QTY '!F9 -> 120D | D9: =VLOOKUP($B9,[3]Sheet1!$B$8:$CF$451,14,0) -> 660 | E9: =VLOOKUP($B9,[3]Sheet1!$B$8:$CF$451,15,0) -> 690 | F9: =VLOOKUP($B9,[3]Sheet1!$B$8:$CF$451,16,0) -> 600 | G9: =VLOOKUP($B9,[3]Sheet1!$B$8:$CF$451,17,0) -> 570 | H9: =VLOOKUP($B9,[3]Sheet1!$B$8:$CF$451,18,0) -> 0 | I9: =SUM(D9:H9) -> 2520 | J9: ='QTY '!Q9 -> 2520 | K9: =ROUNDUP((J9-I9)/$D$4,0) -> 0 | M9: =VLOOKUP($B9,[3]Sheet1!$B$8:$CF$451,20,0) -> 690 | N9: =VLOOKUP($B9,[3]Sheet1!$B$8:$CF$451,21,0) -> 480 | O9: =VLOOKUP($B9,[3]Sheet1!$B$8:$CF$451,22,0) -> 0 | P9: =VLOOKUP($B9,[3]Sheet1!$B$8:$CF$451,23,0) -> 780 | Q9: =VLOOKUP($B9,[3]Sheet1!$B$8:$CF$451,24,0) -> 0 | R9: =SUM(M9:Q9) -> 1950 | S9: ='QTY '!T9 -> 1950 | T9: =ROUNDUP((S9-R9)/$M$4,0) -> 0 | V9: =+VLOOKUP($B9,[3]Sheet1!$B$8:$CF$406,26,0) -> 660 | W9: =+VLOOKUP($B9,[3]Sheet1!$B$8:$CF$406,27,0) -> 510 | X9: =+VLOOKUP($B9,[3]Sheet1!$B$8:$CF$406,28,0) -> 660 | Y9: =+VLOOKUP($B9,[3]Sheet1!$B$8:$CF$406,29,0) -> 720 | Z9: =+VLOOKUP($B9,[3]Sheet1!$B$8:$CF$406,30,0) -> 0 | AA9: =SUM(V9:Z9) -> 2550 | AB9: ='QTY '!W9 -> 2550 | AC9: =ROUNDUP((AB9-AA9)/$V$4,0) -> 0 | AE9: =+VLOOKUP($B9,[3]Sheet1!$B$8:$CF$406,32,0) -> 735 | AF9: =+VLOOKUP($B9,[3]Sheet1!$B$8:$CF$406,33,0) -> 735 | AG9: =+VLOOKUP($B9,[3]Sheet1!$B$8:$CF$406,34,0) -> 735 | AH9: =+VLOOKUP($B9,[3]Sheet1!$B$8:$CF$406,35,0) -> 735 | AI9: =+VLOOKUP($B9,[3]Sheet1!$B$8:$CF$406,36,0) -> 0 | AJ9: =SUM(AE9:AI9) -> 2940 | AK9: ='QTY '!Z9 -> 2940 | AL9: =ROUNDUP((AK9-AJ9)/$AE$4,0) -> 0 | AN9: =+AE9 -> 735 | AO9: =+AF9 -> 735 | AP9: =+AG9 -> 735 | AQ9: =+AH9 -> 735 | AS9: =SUM(AN9:AR9) -> 2940 | AT9: ='QTY '!AC9 -> 2940 | AU9: =ROUNDUP((AT9-AS9)/$AN$4,0) -> 0 | AW9: =+D9*D$8 -> 660 | AX9: =+M9*M$8 -> 690 | AY9: =+V9*V$8 -> 660 | AZ9: =+AE9*AE$8 -> 735 | BA9: =+AN9*AN$8 -> 735 | BB9: =#REF!+1 -> #REF!
