Workbook

Sheet GUM
A1: TOTAL 5 BULAN | B1: =+M54+P54+S54+V54+Y54 -> 13152 | K1: SIX MONTH PRODUCTION PLAN ( QTY )
K2: TOYOTA 359D | AA2: PREPARED
B3: S/R NO : JAI-2026-2.26 | K3: Periode : MAR 2026
B4: FAX NO : EMAIL
BD6: AS 400
Y7: NSO
W8: =192-96 -> 96
C9: 1 | D9: =+C9+1 -> 2 | E9: =+D9+1 -> 3 | F9: =+E9+1 -> 4 | G9: =+F9+1 -> 5 | H9: =+G9+1 -> 6 | I9: =+H9+1 -> 7 | J9: =+I9+1 -> 8 | K9: =+J9+1 -> 9 | ... AD9: =+AC9+1 -> 28 | AG9: Cutting Qty
B10: Print Date : | C10: =NOW() -> 46093.481
A11: TYPE | C11: HARNESS No. | D11: LEVEL | E11: ASSY CODE | F11: CCT. | G11: Std pack | H11: JAN - JUN | I11: FEB | L11: MAR | O11: APR | R11: MAY | U11: JUN | X11: JUL | AA11: AUG | AD11: BAL | AG11: =I11 -> FEB | AJ11: =L11 -> MAR | AM11: =O11 -> APR | AP11: =R11 -> MAY | AS11: =U11 -> JUN | AV11: =X11 -> JUL | AY11: =AA11 -> AUG
H12: UMH | I12: =VLOOKUP(I11,WEEK!A3:D14,2,0) -> 02/FEB ~ 27/FEB | L12: =VLOOKUP(L11,WEEK!A3:D14,2,0) -> 02/MAR ~ 31/MAR | O12: =VLOOKUP(O11,WEEK!A3:D14,2,0) -> 01/APR ~ 30/APR | R12: =VLOOKUP(R11,WEEK!A3:D14,2,0) -> 02/MAY ~ 30/MAY | U12: =VLOOKUP(U11,WEEK!A3:D14,2,0) -> 02/JUN ~ 30/JUN | X12: =VLOOKUP(X11,WEEK!A3:D14,2,0) -> 01/JUL ~ 31/JUL | AA12: =VLOOKUP(AA11,WEEK!A3:D14,2,0) -> 03/AUG ~ 31/AUG | AG12: =I12 -> 02/FEB ~ 27/FEB | AJ12: =L12 -> 02/MAR ~ 31/MAR | AM12: =O12 -> 01/APR ~ 30/APR | AP12: =R12 -> 02/MAY ~ 30/MAY | AS12: =U12 -> 02/JUN ~ 30/JUN | AV12: =X12 -> 01/JUL ~ 31/JUL | AY12: =AA12 -> 03/AUG ~ 31/AUG | BC12: =L11 -> MAR | BD12: =O11 -> APR | BE12: =R11 -> MAY | BF12: =U11 -> JUN | BG12: =X11 -> JUL | BH12: =AA11 -> AUG
I13: BAL | J13: DEL | K13: PROD | L13: BAL | M13: DEL | N13: PROD | O13: BAL | P13: DEL | Q13: PROD | R13: BAL | S13: DEL | T13: PROD | U13: BAL | V13: DEL | W13: PROD | X13: BAL | Y13: DEL | Z13: PROD | AA13: BAL | AB13: DEL | AC13: PROD | AG13: =I13 -> BAL | AH13: =J13 -> DEL | AI13: =K13 -> PROD | AJ13: =L13 -> BAL | AK13: =M13 -> DEL | AL13: =N13 -> PROD | AM13: =O13 -> BAL | AN13: =P13 -> DEL | ... BA13: =AC13 -> PROD | BC13: 4 | BD13: 5 | BE13: 4 | BF13: 5 | BG13: 4 | BH13: 4
A14: 359D | AG14: =I14*$F14 -> 0 | AH14: =J14*$F14 -> 0 | AI14: =K14*$F14 -> 0 | AJ14: =L14*$F14 -> 0 | AK14: =J14*$F14 -> 0 | AL14: =N14*$F14 -> 0 | AM14: =O14*$F14 -> 0 | AN14: =M14*$F14 -> 0 | AO14: =Q14*$F14 -> 0 | AP14: =R14*$F14 -> 0 | AQ14: =P14*$F14 -> 0 | AR14: =T14*$F14 -> 0 | AS14: =U14*$F14 -> 0 | AT14: =S14*$F14 -> 0 | AU14: =W14*$F14 -> 0 | AV14: =X14*$F14 -> 0 | AW14: =V14*$F14 -> 0 | AX14: =Z14*$F14 -> 0 | AY14: =AA14*$F14 -> 0 | AZ14: =Y14*$F14 -> 0 | BA14: =AC14*$F14 -> 0 | BB14: 82111-47450 | BC14: =ROUNDUP(N14/$BC$13,0) -> 0 | BD14: =ROUNDUP(Q14/$BD$13,0) -> 0 | BE14: =ROUNDUP(T14/$BE$13,0) -> 0 | BF14: =ROUNDUP(W14/$BF$13,0) -> 0 | BG14: =ROUNDUP(Z14/$BG$13,0) -> 0 | BH14: =ROUNDUP(AC14/$BH$13,0) -> 0 | BI14: =#REF!+1 -> #REF! | BK14: 82111-47732 | BM14: 82111-47D02 A 1001
B15: ZR_HEV LHD | C15: 82111-FET00 | D15: A 0101 | E15: DUQ3 | G15: 6 | H15: 3.6741317 | I15: 2 | J15: 0 | K15: 0 | L15: =I15+K15-J15 -> 2 | M15: =VLOOKUP($C15,[1]Sheet1!$B$23:$AG$79,8,0) -> 0 | N15: =M15-L15+2 -> 0 | O15: =L15+N15-M15 -> 2 | P15: =VLOOKUP($C15,[1]Sheet1!$B$23:$AG$79,14,0) -> 0 | Q15: =P15-O15+2 -> 0 | R15: =O15+Q15-P15 -> 2 | S15: =VLOOKUP($C15,[1]Sheet1!$B$23:$AG$79,20,0) -> 0 | T15: =S15-R15+2 -> 0 | U15: =R15+T15-S15 -> 2 | V15: =VLOOKUP($C15,[1]Sheet1!$B$23:$AG$79,26,0) -> 0 | W15: =V15-U15+2 -> 0 | X15: =U15+W15-V15 -> 2 | Y15: =VLOOKUP($C15,[1]Sheet1!$B$23:$AG$79,32,0) -> 0 | Z15: =Y15-X15+2 -> 0 | AA15: =X15+Z15-Y15 -> 2 | AB15: =+Y15 -> 0 | AC15: =AB15-AA15+2 -> 0 | AD15: =AA15+AC15-AB15 -> 2 | AE15: 82111FET00 | AG15: =I15*$F15 -> 0 | AH15: =J15*$F15 -> 0 | AI15: =K15*$F15 -> 0 | AJ15: =L15*$F15 -> 0 | AK15: =J15*$F15 -> 0 | AL15: =N15*$F15 -> 0 | AM15: =O15*$F15 -> 0 | AN15: =M15*$F15 -> 0 | AO15: =Q15*$F15 -> 0 | AP15: =R15*$F15 -> 0 | AQ15: =P15*$F15 -> 0 | AR15: =T15*$F15 -> 0 | AS15: =U15*$F15 -> 0 | AT15: =S15*$F15 -> 0 | AU15: =W15*$F15 -> 0 | AV15: =X15*$F15 -> 0 | AW15: =V15*$F15 -> 0 | AX15: =Z15*$F15 -> 0 | AY15: =AA15*$F15 -> 0 | AZ15: =Y15*$F15 -> 0 | BA15: =AC15*$F15 -> 0 | BB15: 82111-47370 | BC15: =ROUNDUP(N15/$BC$13,0) -> 0 | BD15: =ROUNDUP(Q15/$BD$13,0) -> 0 | BE15: =ROUNDUP(T15/$BE$13,0) -> 0 | BF15: =ROUNDUP(W15/$BF$13,0) -> 0 | BG15: =ROUNDUP(Z15/$BG$13,0) -> 0 | BH15: =ROUNDUP(AC15/$BH$13,0) -> 0 | BI15: =#REF!+1 -> #REF! | BK15: 82111-47731 | BM15: 82111-47781 A 0101
C16: 82111-FET10 | D16: A 0101 | E16: DUP9 | G16: 6 | H16: 3.46247 | I16: 0 | J16: 0 | K16: 0 | L16: =I16+K16-J16 -> 0 | M16: =VLOOKUP($C16,[1]Sheet1!$B$23:$AG$79,8,0) -> 0 | N16: =M16-L16 -> 0 | O16: =L16+N16-M16 -> 0 | P16: =VLOOKUP($C16,[1]Sheet1!$B$23:$AG$79,14,0) -> 0 | Q16: =P16-O16 -> 0 | R16: =O16+Q16-P16 -> 0 | S16: =VLOOKUP($C16,[1]Sheet1!$B$23:$AG$79,20,0) -> 0 | T16: =S16-R16 -> 0 | U16: =R16+T16-S16 -> 0 | V16: =VLOOKUP($C16,[1]Sheet1!$B$23:$AG$79,26,0) -> 0 | W16: =V16-U16 -> 0 | X16: =U16+W16-V16 -> 0 | Y16: =VLOOKUP($C16,[1]Sheet1!$B$23:$AG$79,32,0) -> 0 | Z16: =Y16-X16 -> 0 | AA16: =X16+Z16-Y16 -> 0 | AB16: =+Y16 -> 0 | AC16: =AB16-AA16 -> 0 | AD16: =AA16+AC16-AB16 -> 0 | AE16: 82111FET10 | AG16: =I16*$F16 -> 0 | AH16: =J16*$F16 -> 0 | AI16: =K16*$F16 -> 0 | AJ16: =L16*$F16 -> 0 | AK16: =J16*$F16 -> 0 | AL16: =N16*$F16 -> 0 | AM16: =O16*$F16 -> 0 | AN16: =M16*$F16 -> 0 | AO16: =Q16*$F16 -> 0 | AP16: =R16*$F16 -> 0 | AQ16: =P16*$F16 -> 0 | AR16: =T16*$F16 -> 0 | AS16: =U16*$F16 -> 0 | AT16: =S16*$F16 -> 0 | AU16: =W16*$F16 -> 0 | AV16: =X16*$F16 -> 0 | AW16: =V16*$F16 -> 0 | AX16: =Z16*$F16 -> 0 | AY16: =AA16*$F16 -> 0 | AZ16: =Y16*$F16 -> 0 | BA16: =AC16*$F16 -> 0 | BB16: 82111-47460 | BC16: =ROUNDUP(N16/$BC$13,0) -> 0 | BD16: =ROUNDUP(Q16/$BD$13,0) -> 0 | BE16: =ROUNDUP(T16/$BE$13,0) -> 0 | BF16: =ROUNDUP(W16/$BF$13,0) -> 0 | BG16: =ROUNDUP(Z16/$BG$13,0) -> 0 | BH16: =ROUNDUP(AC16/$BH$13,0) -> 0 | BI16: =#REF!+1 -> #REF! | BK16: 82111-47743 | BM16: 82111-47D10 0011
C17: 82116-0ZY10 | D17: A 0101 | E17: DUQ2 | G17: 6 | H17: =VLOOKUP($C17,'[2]UMH Detail'!$E$4:$V$500,18,0) -> 3.3610083 | I17: 66 | J17: 264 | K17: 294 | L17: =I17+K17-J17 -> 96 | M17: =VLOOKUP($C17,[1]Sheet1!$B$23:$AG$79,8,0) -> 180 | N17: =M17-L17+12 -> 96 | O17: =L17+N17-M17 -> 12 | P17: =VLOOKUP($C17,[1]Sheet1!$B$23:$AG$79,14,0) -> 96 | Q17: =P17-O17+18 -> 102 | R17: =O17+Q17-P17 -> 18 | S17: =VLOOKUP($C17,[1]Sheet1!$B$23:$AG$79,20,0) -> 96 | T17: =S17-R17+18 -> 96 | U17: =R17+T17-S17 -> 18 | V17: =VLOOKUP($C17,[1]Sheet1!$B$23:$AG$79,26,0) -> 108 | W17: =V17-U17 -> 90 | X17: =U17+W17-V17 -> 0 | Y17: =VLOOKUP($C17,[1]Sheet1!$B$23:$AG$79,32,0) -> 84 | Z17: =Y17-X17 -> 84 | AA17: =X17+Z17-Y17 -> 0 | AB17: =+Y17 -> 84 | AC17: =AB17-AA17 -> 84 | AD17: =AA17+AC17-AB17 -> 0 | AE17: 821160ZY10 | AG17: =I17*$F17 -> 0 | AH17: =J17*$F17 -> 0 | AI17: =K17*$F17 -> 0 | AJ17: =L17*$F17 -> 0 | AK17: =J17*$F17 -> 0 | AL17: =N17*$F17 -> 0 | AM17: =O17*$F17 -> 0 | AN17: =M17*$F17 -> 0 | AO17: =Q17*$F17 -> 0 | AP17: =R17*$F17 -> 0 | AQ17: =P17*$F17 -> 0 | AR17: =T17*$F17 -> 0 | AS17: =U17*$F17 -> 0 | AT17: =S17*$F17 -> 0 | AU17: =W17*$F17 -> 0 | AV17: =X17*$F17 -> 0 | AW17: =V17*$F17 -> 0 | AX17: =Z17*$F17 -> 0 | AY17: =AA17*$F17 -> 0 | AZ17: =Y17*$F17 -> 0 | BA17: =AC17*$F17 -> 0 | BB17: 82111-47370 | BC17: =ROUNDUP(N17/$BC$13,0) -> 24 | BD17: =ROUNDUP(Q17/$BD$13,0) -> 21 | BE17: =ROUNDUP(T17/$BE$13,0) -> 24 | BF17: =ROUNDUP(W17/$BF$13,0) -> 18 | BG17: =ROUNDUP(Z17/$BG$13,0) -> 21 | BH17: =ROUNDUP(AC17/$BH$13,0) -> 21 | BI17: =#REF!+1 -> #REF! | BK17: 82111-47742 | BM17: 82111-47531 A 0001
C18: 82115-F2840 | D18: 0001 | E18: DQP1 | G18: 6 | H18: =+H44 -> 3.5295433 | I18: 0 | J18: 0 | K18: 0 | L18: =I18+K18-J18 -> 0 | M18: =VLOOKUP($C18,[1]Sheet1!$B$23:$AG$79,8,0) -> 0 | N18: =M18-L18 -> 0 | O18: =L18+N18-M18 -> 0 | P18: =VLOOKUP($C18,[1]Sheet1!$B$23:$AG$79,14,0) -> 0 | Q18: =P18-O18 -> 0 | R18: =O18+Q18-P18 -> 0 | S18: =VLOOKUP($C18,[1]Sheet1!$B$23:$AG$79,20,0) -> 0 | T18: =S18-R18 -> 0 | U18: =R18+T18-S18 -> 0 | V18: =VLOOKUP($C18,[1]Sheet1!$B$23:$AG$79,26,0) -> 0 | W18: =V18-U18 -> 0 | X18: =U18+W18-V18 -> 0 | Y18: =VLOOKUP($C18,[1]Sheet1!$B$23:$AG$79,32,0) -> 0 | Z18: =Y18-X18 -> 0 | AA18: =X18+Z18-Y18 -> 0 | AB18: =+Y18 -> 0 | AC18: =AB18-AA18 -> 0 | AD18: =AA18+AC18-AB18 -> 0 | AE18: 82115F2840 | AG18: =I18*$F18 -> 0 | AH18: =J18*$F18 -> 0 | AI18: =K18*$F18 -> 0 | AJ18: =L18*$F18 -> 0 | AK18: =J18*$F18 -> 0 | AL18: =N18*$F18 -> 0 | AM18: =O18*$F18 -> 0 | AN18: =M18*$F18 -> 0 | AO18: =Q18*$F18 -> 0 | AP18: =R18*$F18 -> 0 | AQ18: =P18*$F18 -> 0 | AR18: =T18*$F18 -> 0 | AS18: =U18*$F18 -> 0 | AT18: =S18*$F18 -> 0 | AU18: =W18*$F18 -> 0 | AV18: =X18*$F18 -> 0 | AW18: =V18*$F18 -> 0 | AX18: =Z18*$F18 -> 0 | AY18: =AA18*$F18 -> 0 | AZ18: =Y18*$F18 -> 0 | BA18: =AC18*$F18 -> 0 | BB18: 82111-47370 | BC18: =ROUNDUP(N18/$BC$13,0) -> 0 | BD18: =ROUNDUP(Q18/$BD$13,0) -> 0 | BE18: =ROUNDUP(T18/$BE$13,0) -> 0 | BF18: =ROUNDUP(W18/$BF$13,0) -> 0 | BG18: =ROUNDUP(Z18/$BG$13,0) -> 0 | BH18: =ROUNDUP(AC18/$BH$13,0) -> 0 | BI18: =#REF!+1 -> #REF! | BK18: 82111-47L10 | BM18: 82111-47742 A 0001
C19: 82116-0ZW70 | D19: A 0101 | E19: DUQ1 | G19: 6 | H19: =VLOOKUP($C19,'[2]UMH Detail'!$E$4:$V$500,18,0) -> 3.66115 | I19: 24 | J19: 132 | K19: 186 | L19: =I19+K19-J19 -> 78 | M19: =VLOOKUP($C19,[1]Sheet1!$B$23:$AG$79,8,0) -> 192 | N19: =M19-L19+36-6-6 -> 138 | O19: =L19+N19-M19 -> 24 | P19: =VLOOKUP($C19,[1]Sheet1!$B$23:$AG$79,14,0) -> 210 | Q19: =P19-O19+48-6-6 -> 222 | R19: =O19+Q19-P19 -> 36 | S19: =VLOOKUP($C19,[1]Sheet1!$B$23:$AG$79,20,0) -> 210 | T19: =S19-R19+36-6 -> 204 | U19: =R19+T19-S19 -> 30 | V19: =VLOOKUP($C19,[1]Sheet1!$B$23:$AG$79,26,0) -> 228 | W19: =V19-U19+48+12 -> 258 | X19: =U19+W19-V19 -> 60 | Y19: =VLOOKUP($C19,[1]Sheet1!$B$23:$AG$79,32,0) -> 180 | Z19: =Y19-X19+30+12 -> 162 | AA19: =X19+Z19-Y19 -> 42 | AB19: =+Y19 -> 180 | AC19: =AB19-AA19 -> 138 | AD19: =AA19+AC19-AB19 -> 0 | AE19: 821160ZW70 | AG19: =I19*$F19 -> 0 | AH19: =J19*$F19 -> 0 | AI19: =K19*$F19 -> 0 | AJ19: =L19*$F19 -> 0 | AK19: =J19*$F19 -> 0 | AL19: =N19*$F19 -> 0 | AM19: =O19*$F19 -> 0 | AN19: =M19*$F19 -> 0 | AO19: =Q19*$F19 -> 0 | AP19: =R19*$F19 -> 0 | AQ19: =P19*$F19 -> 0 | AR19: =T19*$F19 -> 0 | AS19: =U19*$F19 -> 0 | AT19: =S19*$F19 -> 0 | AU19: =W19*$F19 -> 0 | AV19: =X19*$F19 -> 0 | AW19: =V19*$F19 -> 0 | AX19: =Z19*$F19 -> 0 | AY19: =AA19*$F19 -> 0 | AZ19: =Y19*$F19 -> 0 | BA19: =AC19*$F19 -> 0 | BB19: 82111-47460 | BC19: =ROUNDUP(N19/$BC$13,0) -> 35 | BD19: =ROUNDUP(Q19/$BD$13,0) -> 45 | BE19: =ROUNDUP(T19/$BE$13,0) -> 51 | BF19: =ROUNDUP(W19/$BF$13,0) -> 52 | BG19: =ROUNDUP(Z19/$BG$13,0) -> 41 | BH19: =ROUNDUP(AC19/$BH$13,0) -> 35 | BI19: =#REF!+1 -> #REF! | BK19: 82111-47752 | BM19: 82111-47751 A 0001
B20: ZR_TNGA LHD | C20: 82115-F2390 | D20: B 0101 | E20: DUP3 | G20: 6 | H20: =VLOOKUP($C20,'[2]UMH Detail'!$E$4:$V$500,18,0) -> 3.1332317 | I20: 2 | J20: 36 | K20: 36 | L20: =I20+K20-J20 -> 2 | M20: =VLOOKUP($C20,[1]Sheet1!$B$23:$AG$79,8,0) -> 12 | N20: =M20-L20+2 -> 12 | O20: =L20+N20-M20 -> 2 | P20: =VLOOKUP($C20,[1]Sheet1!$B$23:$AG$79,14,0) -> 12 | Q20: =P20-O20+2 -> 12 | R20: =O20+Q20-P20 -> 2 | S20: =VLOOKUP($C20,[1]Sheet1!$B$23:$AG$79,20,0) -> 12 | T20: =S20-R20+2 -> 12 | U20: =R20+T20-S20 -> 2 | V20: =VLOOKUP($C20,[1]Sheet1!$B$23:$AG$79,26,0) -> 24 | W20: =V20-U20+2 -> 24 | X20: =U20+W20-V20 -> 2 | Y20: =VLOOKUP($C20,[1]Sheet1!$B$23:$AG$79,32,0) -> 6 | Z20: =Y20-X20+2 -> 6 | AA20: =X20+Z20-Y20 -> 2 | AB20: =+Y20 -> 6 | AC20: =AB20-AA20+2 -> 6 | AD20: =AA20+AC20-AB20 -> 2 | AE20: 82115F2390 | AG20: =I20*$F20 -> 0 | AH20: =J20*$F20 -> 0 | AI20: =K20*$F20 -> 0 | AJ20: =L20*$F20 -> 0 | AK20: =J20*$F20 -> 0 | AL20: =N20*$F20 -> 0 | AM20: =O20*$F20 -> 0 | AN20: =M20*$F20 -> 0 | AO20: =Q20*$F20 -> 0 | AP20: =R20*$F20 -> 0 | AQ20: =P20*$F20 -> 0 | AR20: =T20*$F20 -> 0 | AS20: =U20*$F20 -> 0 | AT20: =S20*$F20 -> 0 | AU20: =W20*$F20 -> 0 | AV20: =X20*$F20 -> 0 | AW20: =V20*$F20 -> 0 | AX20: =Z20*$F20 -> 0 | AY20: =AA20*$F20 -> 0 | AZ20: =Y20*$F20 -> 0 | BA20: =AC20*$F20 -> 0 | BB20: 82111-47370 | BC20: =ROUNDUP(N20/$BC$13,0) -> 3 | BD20: =ROUNDUP(Q20/$BD$13,0) -> 3 | BE20: =ROUNDUP(T20/$BE$13,0) -> 3 | BF20: =ROUNDUP(W20/$BF$13,0) -> 5 | BG20: =ROUNDUP(Z20/$BG$13,0) -> 2 | BH20: =ROUNDUP(AC20/$BH$13,0) -> 2 | BI20: =#REF!+1 -> #REF! | BK20: 82111-47751 | BM20: 82111-47772 A 0001
C21: 82111-FET20 | D21: A 0101 | E21: DUP7 | G21: 6 | H21: 2.9072533 | I21: 0 | J21: 0 | K21: 0 | L21: =I21+K21-J21 -> 0 | M21: =VLOOKUP($C21,[1]Sheet1!$B$23:$AG$79,8,0) -> 0 | N21: =M21-L21 -> 0 | O21: =L21+N21-M21 -> 0 | P21: =VLOOKUP($C21,[1]Sheet1!$B$23:$AG$79,14,0) -> 0 | Q21: =P21-O21 -> 0 | R21: =O21+Q21-P21 -> 0 | S21: =VLOOKUP($C21,[1]Sheet1!$B$23:$AG$79,20,0) -> 0 | T21: =S21-R21 -> 0 | U21: =R21+T21-S21 -> 0 | V21: =VLOOKUP($C21,[1]Sheet1!$B$23:$AG$79,26,0) -> 0 | W21: =V21-U21 -> 0 | X21: =U21+W21-V21 -> 0 | Y21: =VLOOKUP($C21,[1]Sheet1!$B$23:$AG$79,32,0) -> 0 | Z21: =Y21-X21 -> 0 | AA21: =X21+Z21-Y21 -> 0 | AB21: =+Y21 -> 0 | AC21: =AB21-AA21 -> 0 | AD21: =AA21+AC21-AB21 -> 0 | AE21: 82111FET20 | AG21: =I21*$F21 -> 0 | AH21: =J21*$F21 -> 0 | AI21: =K21*$F21 -> 0 | AJ21: =L21*$F21 -> 0 | AK21: =J21*$F21 -> 0 | AL21: =N21*$F21 -> 0 | AM21: =O21*$F21 -> 0 | AN21: =M21*$F21 -> 0 | AO21: =Q21*$F21 -> 0 | AP21: =R21*$F21 -> 0 | AQ21: =P21*$F21 -> 0 | AR21: =T21*$F21 -> 0 | AS21: =U21*$F21 -> 0 | AT21: =S21*$F21 -> 0 | AU21: =W21*$F21 -> 0 | AV21: =X21*$F21 -> 0 | AW21: =V21*$F21 -> 0 | AX21: =Z21*$F21 -> 0 | AY21: =AA21*$F21 -> 0 | AZ21: =Y21*$F21 -> 0 | BA21: =AC21*$F21 -> 0 | BB21: 82111-47370 | BC21: =ROUNDUP(N21/$BC$13,0) -> 0 | BD21: =ROUNDUP(Q21/$BD$13,0) -> 0 | BE21: =ROUNDUP(T21/$BE$13,0) -> 0 | BF21: =ROUNDUP(W21/$BF$13,0) -> 0 | BG21: =ROUNDUP(Z21/$BG$13,0) -> 0 | BH21: =ROUNDUP(AC21/$BH$13,0) -> 0 | BI21: =#REF!+1 -> #REF! | BK21: 82111-47532 | BM21: 82111-47804 B 0001
C22: 82111-FET30 | D22: A 0101 | E22: DUP6 | G22: 6 | H22: =VLOOKUP($C22,'[2]UMH Detail'!$E$4:$V$500,18,0) -> 2.9106067 | I22: 132 | J22: 378 | K22: 336 | L22: =I22+K22-J22 -> 90 | M22: =VLOOKUP($C22,[1]Sheet1!$B$23:$AG$79,8,0) -> 348 | N22: =M22-L22+72+12+6 -> 348 | O22: =L22+N22-M22 -> 90 | P22: =VLOOKUP($C22,[1]Sheet1!$B$23:$AG$79,14,0) -> 354 | Q22: =P22-O22+96+24 -> 384 | R22: =O22+Q22-P22 -> 120 | S22: =VLOOKUP($C22,[1]Sheet1!$B$23:$AG$79,20,0) -> 372 | T22: =S22-R22+84+24 -> 360 | U22: =R22+T22-S22 -> 108 | V22: =VLOOKUP($C22,[1]Sheet1!$B$23:$AG$79,26,0) -> 402 | W22: =V22-U22+48 -> 342 | X22: =U22+W22-V22 -> 48 | Y22: =VLOOKUP($C22,[1]Sheet1!$B$23:$AG$79,32,0) -> 324 | Z22: =Y22-X22+84+24+30 -> 414 | AA22: =X22+Z22-Y22 -> 138 | AB22: =+Y22 -> 324 | AC22: =AB22-AA22 -> 186 | AD22: =AA22+AC22-AB22 -> 0 | AE22: 82111FET30 | AG22: =I22*$F22 -> 0 | AH22: =J22*$F22 -> 0 | AI22: =K22*$F22 -> 0 | AJ22: =L22*$F22 -> 0 | AK22: =J22*$F22 -> 0 | AL22: =N22*$F22 -> 0 | AM22: =O22*$F22 -> 0 | AN22: =M22*$F22 -> 0 | AO22: =Q22*$F22 -> 0 | AP22: =R22*$F22 -> 0 | AQ22: =P22*$F22 -> 0 | AR22: =T22*$F22 -> 0 | AS22: =U22*$F22 -> 0 | AT22: =S22*$F22 -> 0 | AU22: =W22*$F22 -> 0 | AV22: =X22*$F22 -> 0 | AW22: =V22*$F22 -> 0 | AX22: =Z22*$F22 -> 0 | AY22: =AA22*$F22 -> 0 | AZ22: =Y22*$F22 -> 0 | BA22: =AC22*$F22 -> 0 | BB22: 82111-47370 | BC22: =ROUNDUP(N22/$BC$13,0) -> 87 | BD22: =ROUNDUP(Q22/$BD$13,0) -> 77 | BE22: =ROUNDUP(T22/$BE$13,0) -> 90 | BF22: =ROUNDUP(W22/$BF$13,0) -> 69 | BG22: =ROUNDUP(Z22/$BG$13,0) -> 104 | BH22: =ROUNDUP(AC22/$BH$13,0) -> 47 | BI22: =#REF!+1 -> #REF! | BK22: 82111-47531 | BM22: 82111-47834 B 0001
C23: 82111-FET40 | D23: A 0101 | E23: DUP8 | G23: 6 | H23: =VLOOKUP($C23,'[2]UMH Detail'!$E$4:$V$500,18,0) -> 2.8988 | I23: 240 | J23: 786 | K23: 696 | L23: =I23+K23-J23 -> 150 | M23: =VLOOKUP($C23,[1]Sheet1!$B$23:$AG$79,8,0) -> 582 | N23: =M23-L23+120+18+24 -> 594 | O23: =L23+N23-M23 -> 162 | P23: =VLOOKUP($C23,[1]Sheet1!$B$23:$AG$79,14,0) -> 546 | Q23: =P23-O23+162+120+36 -> 702 | R23: =O23+Q23-P23 -> 318 | S23: =VLOOKUP($C23,[1]Sheet1!$B$23:$AG$79,20,0) -> 636 | T23: =S23-R23+144+36 -> 498 | U23: =R23+T23-S23 -> 180 | V23: =VLOOKUP($C23,[1]Sheet1!$B$23:$AG$79,26,0) -> 696 | W23: =V23-U23+90+48 -> 654 | X23: =U23+W23-V23 -> 138 | Y23: =VLOOKUP($C23,[1]Sheet1!$B$23:$AG$79,32,0) -> 546 | Z23: =Y23-X23+138+24 -> 570 | AA23: =X23+Z23-Y23 -> 162 | AB23: =+Y23 -> 546 | AC23: =AB23-AA23 -> 384 | AD23: =AA23+AC23-AB23 -> 0 | AE23: 82111FET40 | AG23: =I23*$F23 -> 0 | AH23: =J23*$F23 -> 0 | AI23: =K23*$F23 -> 0 | AJ23: =L23*$F23 -> 0 | AK23: =J23*$F23 -> 0 | AL23: =N23*$F23 -> 0 | AM23: =O23*$F23 -> 0 | AN23: =M23*$F23 -> 0 | AO23: =Q23*$F23 -> 0 | AP23: =R23*$F23 -> 0 | AQ23: =P23*$F23 -> 0 | AR23: =T23*$F23 -> 0 | AS23: =U23*$F23 -> 0 | AT23: =S23*$F23 -> 0 | AU23: =W23*$F23 -> 0 | AV23: =X23*$F23 -> 0 | AW23: =V23*$F23 -> 0 | AX23: =Z23*$F23 -> 0 | AY23: =AA23*$F23 -> 0 | AZ23: =Y23*$F23 -> 0 | BA23: =AC23*$F23 -> 0 | BB23: 82111-47370 | BC23: =ROUNDUP(N23/$BC$13,0) -> 149 | BD23: =ROUNDUP(Q23/$BD$13,0) -> 141 | BE23: =ROUNDUP(T23/$BE$13,0) -> 125 | BF23: =ROUNDUP(W23/$BF$13,0) -> 131 | BG23: =ROUNDUP(Z23/$BG$13,0) -> 143 | BH23: =ROUNDUP(AC23/$BH$13,0) -> 96 | BI23: =#REF!+1 -> #REF! | BK23: 82111-47531 | BM23: 82111-47834 B 0001
C24: 82116-0ZX70 | D24: A 0101 | E24: DUP4 | G24: 6 | H24: =VLOOKUP($C24,'[3]UMH Detail'!$E$4:$V$500,18,0) -> 3.0037017 | I24: 0 | J24: 12 | K24: 12 | L24: =I24+K24-J24 -> 0 | M24: =VLOOKUP($C24,[1]Sheet1!$B$23:$AG$79,8,0) -> 0 | N24: =M24-L24 -> 0 | O24: =L24+N24-M24 -> 0 | P24: =VLOOKUP($C24,[1]Sheet1!$B$23:$AG$79,14,0) -> 6 | Q24: =P24-O24 -> 6 | R24: =O24+Q24-P24 -> 0 | S24: =VLOOKUP($C24,[1]Sheet1!$B$23:$AG$79,20,0) -> 6 | T24: =S24-R24 -> 6 | U24: =R24+T24-S24 -> 0 | V24: =VLOOKUP($C24,[1]Sheet1!$B$23:$AG$79,26,0) -> 6 | W24: =V24-U24 -> 6 | X24: =U24+W24-V24 -> 0 | Y24: =VLOOKUP($C24,[1]Sheet1!$B$23:$AG$79,32,0) -> 6 | Z24: =Y24-X24 -> 6 | AA24: =X24+Z24-Y24 -> 0 | AB24: =+Y24 -> 6 | AC24: =AB24-AA24 -> 6 | AD24: =AA24+AC24-AB24 -> 0 | AE24: 821160ZX70 | AG24: =I24*$F24 -> 0 | AH24: =J24*$F24 -> 0 | AI24: =K24*$F24 -> 0 | AJ24: =L24*$F24 -> 0 | AK24: =J24*$F24 -> 0 | AL24: =N24*$F24 -> 0 | AM24: =O24*$F24 -> 0 | AN24: =M24*$F24 -> 0 | AO24: =Q24*$F24 -> 0 | AP24: =R24*$F24 -> 0 | AQ24: =P24*$F24 -> 0 | AR24: =T24*$F24 -> 0 | AS24: =U24*$F24 -> 0 | AT24: =S24*$F24 -> 0 | AU24: =W24*$F24 -> 0 | AV24: =X24*$F24 -> 0 | AW24: =V24*$F24 -> 0 | AX24: =Z24*$F24 -> 0 | AY24: =AA24*$F24 -> 0 | AZ24: =Y24*$F24 -> 0 | BA24: =AC24*$F24 -> 0 | BB24: 82111-47370 | BC24: =ROUNDUP(N24/$BC$13,0) -> 0 | BD24: =ROUNDUP(Q24/$BD$13,0) -> 2 | BE24: =ROUNDUP(T24/$BE$13,0) -> 2 | BF24: =ROUNDUP(W24/$BF$13,0) -> 2 | BG24: =ROUNDUP(Z24/$BG$13,0) -> 2 | BH24: =ROUNDUP(AC24/$BH$13,0) -> 2 | BI24: =#REF!+1 -> #REF! | BK24: 82111-47770 | BM24: 82111-47843 B 0001
C25: 82116-0ZY00 | D25: A 0101 | E25: DUP5 | G25: 6 | H25: =VLOOKUP($C25,'[2]UMH Detail'!$E$4:$V$500,18,0) -> 2.9118 | I25: 282 | J25: 912 | K25: =852-30 -> 822 | L25: =I25+K25-J25 -> 192 | M25: =VLOOKUP($C25,[1]Sheet1!$B$23:$AG$79,8,0) -> 660 | N25: =M25-L25+132+24-6+24 -> 642 | O25: =L25+N25-M25 -> 174 | P25: =VLOOKUP($C25,[1]Sheet1!$B$23:$AG$79,14,0) -> 588 | Q25: =P25-O25+174+120+24 -> 732 | R25: =O25+Q25-P25 -> 318 | S25: =VLOOKUP($C25,[1]Sheet1!$B$23:$AG$79,20,0) -> 684 | T25: =S25-R25+150+36+48 -> 600 | U25: =R25+T25-S25 -> 234 | V25: =VLOOKUP($C25,[1]Sheet1!$B$23:$AG$79,26,0) -> 744 | W25: =V25-U25+48+102 -> 660 | X25: =U25+W25-V25 -> 150 | Y25: =VLOOKUP($C25,[1]Sheet1!$B$23:$AG$79,32,0) -> 582 | Z25: =Y25-X25+150+84+36-72 -> 630 | AA25: =X25+Z25-Y25 -> 198 | AB25: =+Y25 -> 582 | AC25: =AB25-AA25 -> 384 | AD25: =AA25+AC25-AB25 -> 0 | AE25: 821160ZY00 | AG25: =I25*$F25 -> 0 | AH25: =J25*$F25 -> 0 | AI25: =K25*$F25 -> 0 | AJ25: =L25*$F25 -> 0 | AK25: =J25*$F25 -> 0 | AL25: =N25*$F25 -> 0 | AM25: =O25*$F25 -> 0 | AN25: =M25*$F25 -> 0 | AO25: =Q25*$F25 -> 0 | AP25: =R25*$F25 -> 0 | AQ25: =P25*$F25 -> 0 | AR25: =T25*$F25 -> 0 | AS25: =U25*$F25 -> 0 | AT25: =S25*$F25 -> 0 | AU25: =W25*$F25 -> 0 | AV25: =X25*$F25 -> 0 | AW25: =V25*$F25 -> 0 | AX25: =Z25*$F25 -> 0 | AY25: =AA25*$F25 -> 0 | AZ25: =Y25*$F25 -> 0 | BA25: =AC25*$F25 -> 0 | BB25: 82111-47370 | BC25: =ROUNDUP(N25/$BC$13,0) -> 161 | BD25: =ROUNDUP(Q25/$BD$13,0) -> 147 | BE25: =ROUNDUP(T25/$BE$13,0) -> 150 | BF25: =ROUNDUP(W25/$BF$13,0) -> 132 | BG25: =ROUNDUP(Z25/$BG$13,0) -> 158 | BH25: =ROUNDUP(AC25/$BH$13,0) -> 96 | BI25: =#REF!+1 -> #REF! | BK25: 82111-47770 | BM25: 82111-47843 B 0001
B26: ZR_CONV LHD | C26: 82116-0ZW80 | D26: A 0101 | E26: DUQ4 | G26: 6 | H26: 2.9375817 | I26: 0 | J26: 0 | K26: 0 | L26: =I26+K26-J26 -> 0 | M26: =VLOOKUP($C26,[1]Sheet1!$B$23:$AG$79,8,0) -> 0 | N26: =M26-L26 -> 0 | O26: =L26+N26-M26 -> 0 | P26: =VLOOKUP($C26,[1]Sheet1!$B$23:$AG$79,14,0) -> 0 | Q26: =P26-O26 -> 0 | R26: =O26+Q26-P26 -> 0 | S26: =VLOOKUP($C26,[1]Sheet1!$B$23:$AG$79,20,0) -> 0 | T26: =S26-R26 -> 0 | U26: =R26+T26-S26 -> 0 | V26: =VLOOKUP($C26,[1]Sheet1!$B$23:$AG$79,26,0) -> 0 | W26: =V26-U26 -> 0 | X26: =U26+W26-V26 -> 0 | Y26: =VLOOKUP($C26,[1]Sheet1!$B$23:$AG$79,32,0) -> 0 | Z26: =Y26-X26 -> 0 | AA26: =X26+Z26-Y26 -> 0 | AB26: =+Y26 -> 0 | AC26: =AB26-AA26 -> 0 | AD26: =AA26+AC26-AB26 -> 0 | AE26: 821160ZW80
C27: 82116-0ZW90 | D27: A 0101 | E27: DUQ5 | G27: 6 | H27: =VLOOKUP($C27,'[2]UMH Detail'!$E$4:$V$500,18,0) -> 2.705515 | I27: 72 | J27: 270 | K27: =276 -> 276 | L27: =I27+K27-J27 -> 78 | M27: =VLOOKUP($C27,[1]Sheet1!$B$23:$AG$79,8,0) -> 384 | N27: =M27-L27+60+24+6 -> 396 | O27: =L27+N27-M27 -> 90 | P27: =VLOOKUP($C27,[1]Sheet1!$B$23:$AG$79,14,0) -> 360 | Q27: =P27-O27+114+18 -> 402 | R27: =O27+Q27-P27 -> 132 | S27: =VLOOKUP($C27,[1]Sheet1!$B$23:$AG$79,20,0) -> 450 | T27: =S27-R27+102+6 -> 426 | U27: =R27+T27-S27 -> 108 | V27: =VLOOKUP($C27,[1]Sheet1!$B$23:$AG$79,26,0) -> 498 | W27: =V27-U27 -> 390 | X27: =U27+W27-V27 -> 0 | Y27: =VLOOKUP($C27,[1]Sheet1!$B$23:$AG$79,32,0) -> 390 | Z27: =Y27-X27+48 -> 438 | AA27: =X27+Z27-Y27 -> 48 | AB27: =+Y27 -> 390 | AC27: =AB27-AA27 -> 342 | AD27: =AA27+AC27-AB27 -> 0 | AE27: 821160ZW90
C28: 82111-FE460 | D28: 0001 | E28: DWS2 | G28: 6 | H28: =VLOOKUP($C28,'[2]UMH Detail'!$E$4:$V$500,18,0) -> 2.8079483 | I28: 0 | J28: 48 | K28: 48 | L28: =I28+K28-J28 -> 0 | M28: =VLOOKUP($C28,[1]Sheet1!$B$23:$AG$79,8,0) -> 42 | N28: =M28-L28+18 -> 60 | O28: =L28+N28-M28 -> 18 | P28: =VLOOKUP($C28,[1]Sheet1!$B$23:$AG$79,14,0) -> 30 | Q28: =P28-O28 -> 12 | R28: =O28+Q28-P28 -> 0 | S28: =VLOOKUP($C28,[1]Sheet1!$B$23:$AG$79,20,0) -> 36 | T28: =S28-R28 -> 36 | U28: =R28+T28-S28 -> 0 | V28: =VLOOKUP($C28,[1]Sheet1!$B$23:$AG$79,26,0) -> 36 | W28: =V28-U28 -> 36 | X28: =U28+W28-V28 -> 0 | Y28: =VLOOKUP($C28,[1]Sheet1!$B$23:$AG$79,32,0) -> 30 | Z28: =Y28-X28 -> 30 | AA28: =X28+Z28-Y28 -> 0 | AB28: =+Y28 -> 30 | AC28: =AB28-AA28 -> 30 | AD28: =AA28+AC28-AB28 -> 0 | AE28: 82111FET50 | AG28: =I28*$F28 -> 0 | AH28: =J28*$F28 -> 0 | AI28: =K28*$F28 -> 0 | AJ28: =L28*$F28 -> 0 | AK28: =J28*$F28 -> 0 | AL28: =N28*$F28 -> 0 | AM28: =O28*$F28 -> 0 | AN28: =M28*$F28 -> 0 | AO28: =Q28*$F28 -> 0 | AP28: =R28*$F28 -> 0 | AQ28: =P28*$F28 -> 0 | AR28: =T28*$F28 -> 0 | AS28: =U28*$F28 -> 0 | AT28: =S28*$F28 -> 0 | AU28: =W28*$F28 -> 0 | AV28: =X28*$F28 -> 0 | AW28: =V28*$F28 -> 0 | AX28: =Z28*$F28 -> 0 | AY28: =AA28*$F28 -> 0 | AZ28: =Y28*$F28 -> 0 | BA28: =AC28*$F28 -> 0 | BB28: 82111-47450 | BC28: =ROUNDUP(N28/$BC$13,0) -> 15 | BD28: =ROUNDUP(Q28/$BD$13,0) -> 3 | BE28: =ROUNDUP(T28/$BE$13,0) -> 9 | BF28: =ROUNDUP(W28/$BF$13,0) -> 8 | BG28: =ROUNDUP(Z28/$BG$13,0) -> 8 | BH28: =ROUNDUP(AC28/$BH$13,0) -> 8 | BI28: =#REF!+1 -> #REF! | BK28: 82111-47732 | BM28: 82111-47D02 A 1001
C29: 82111-FE470 | D29: 0001 | E29: DWS3 | G29: 6 | H29: =VLOOKUP($C29,'[2]UMH Detail'!$E$4:$V$500,18,0) -> 2.932705 | I29: 0 | J29: 372 | K29: 372 | L29: =I29+K29-J29 -> 0 | M29: =VLOOKUP($C29,[1]Sheet1!$B$23:$AG$79,8,0) -> 12 | N29: =M29-L29+24+24 -> 60 | O29: =L29+N29-M29 -> 48 | P29: =VLOOKUP($C29,[1]Sheet1!$B$23:$AG$79,14,0) -> 180 | Q29: =P29-O29+48+48 -> 228 | R29: =O29+Q29-P29 -> 96 | S29: =VLOOKUP($C29,[1]Sheet1!$B$23:$AG$79,20,0) -> 228 | T29: =S29-R29+48 -> 180 | U29: =R29+T29-S29 -> 48 | V29: =VLOOKUP($C29,[1]Sheet1!$B$23:$AG$79,26,0) -> 210 | W29: =V29-U29 -> 162 | X29: =U29+W29-V29 -> 0 | Y29: =VLOOKUP($C29,[1]Sheet1!$B$23:$AG$79,32,0) -> 186 | Z29: =Y29-X29 -> 186 | AA29: =X29+Z29-Y29 -> 0 | AB29: =+Y29 -> 186 | AC29: =AB29-AA29 -> 186 | AD29: =AA29+AC29-AB29 -> 0 | AE29: 821160ZX80 | AG29: =I29*$F29 -> 0 | AH29: =J29*$F29 -> 0 | AI29: =K29*$F29 -> 0 | AJ29: =L29*$F29 -> 0 | AK29: =J29*$F29 -> 0 | AL29: =N29*$F29 -> 0 | AM29: =O29*$F29 -> 0 | AN29: =M29*$F29 -> 0 | AO29: =Q29*$F29 -> 0 | AP29: =R29*$F29 -> 0 | AQ29: =P29*$F29 -> 0 | AR29: =T29*$F29 -> 0 | AS29: =U29*$F29 -> 0 | AT29: =S29*$F29 -> 0 | AU29: =W29*$F29 -> 0 | AV29: =X29*$F29 -> 0 | AW29: =V29*$F29 -> 0 | AX29: =Z29*$F29 -> 0 | AY29: =AA29*$F29 -> 0 | AZ29: =Y29*$F29 -> 0 | BA29: =AC29*$F29 -> 0 | BB29: 82111-47370 | BC29: =ROUNDUP(N29/$BC$13,0) -> 15 | BD29: =ROUNDUP(Q29/$BD$13,0) -> 46 | BE29: =ROUNDUP(T29/$BE$13,0) -> 45 | BF29: =ROUNDUP(W29/$BF$13,0) -> 33 | BG29: =ROUNDUP(Z29/$BG$13,0) -> 47 | BH29: =ROUNDUP(AC29/$BH$13,0) -> 47 | BI29: =#REF!+1 -> #REF! | BK29: 82111-47731 | BM29: 82111-47781 A 0101
C30: 82116-0ZX90 | D30: A 0101 | E30: DUQ7 | G30: 6 | H30: =VLOOKUP($C30,'[2]UMH Detail'!$E$4:$V$500,18,0) -> 2.7070533 | I30: 0 | J30: 84 | K30: 84 | L30: =I30+K30-J30 -> 0 | M30: =VLOOKUP($C30,[1]Sheet1!$B$23:$AG$79,8,0) -> 12 | N30: =M30-L30 -> 12 | O30: =L30+N30-M30 -> 0 | P30: =VLOOKUP($C30,[1]Sheet1!$B$23:$AG$79,14,0) -> 30 | Q30: =P30-O30 -> 30 | R30: =O30+Q30-P30 -> 0 | S30: =VLOOKUP($C30,[1]Sheet1!$B$23:$AG$79,20,0) -> 30 | T30: =S30-R30 -> 30 | U30: =R30+T30-S30 -> 0 | V30: =VLOOKUP($C30,[1]Sheet1!$B$23:$AG$79,26,0) -> 30 | W30: =V30-U30 -> 30 | X30: =U30+W30-V30 -> 0 | Y30: =VLOOKUP($C30,[1]Sheet1!$B$23:$AG$79,32,0) -> 24 | Z30: =Y30-X30 -> 24 | AA30: =X30+Z30-Y30 -> 0 | AB30: =+Y30 -> 24 | AC30: =AB30-AA30 -> 24 | AD30: =AA30+AC30-AB30 -> 0 | AE30: 821160ZX90
A31: 824D | B31: HEV | C31: 82111-FE150 | D31: 0001 | E31: DVI1 | G31: 6 | H31: =VLOOKUP($C31,'[2]UMH Detail'!$E$4:$V$500,18,0) -> 3.6625167 | I31: 0 | J31: 42 | K31: 42 | L31: =I31+K31-J31 -> 0 | M31: =VLOOKUP($C31,[1]Sheet1!$B$23:$AG$79,8,0) -> 54 | N31: =M31-L31 -> 54 | O31: =L31+N31-M31 -> 0 | P31: =VLOOKUP($C31,[1]Sheet1!$B$23:$AG$79,14,0) -> 48 | Q31: =P31-O31 -> 48 | R31: =O31+Q31-P31 -> 0 | S31: =VLOOKUP($C31,[1]Sheet1!$B$23:$AG$79,20,0) -> 42 | T31: =S31-R31 -> 42 | U31: =R31+T31-S31 -> 0 | V31: =VLOOKUP($C31,[1]Sheet1!$B$23:$AG$79,26,0) -> 42 | W31: =V31-U31 -> 42 | X31: =U31+W31-V31 -> 0 | Y31: =VLOOKUP($C31,[1]Sheet1!$B$23:$AG$79,32,0) -> 30 | Z31: =Y31-X31 -> 30 | AA31: =X31+Z31-Y31 -> 0 | AB31: =+Y31 -> 30 | AC31: =AB31-AA31 -> 30 | AD31: =AA31+AC31-AB31 -> 0 | AE31: 82111FE150
B32: CONV | C32: 82111-FE200 | D32: 0001 | E32: DVI2 | G32: 6 | H32: =VLOOKUP($C32,'[2]UMH Detail'!$E$4:$V$500,18,0) -> 2.7844983 | I32: 0 | J32: 0 | K32: 0 | L32: =I32+K32-J32 -> 0 | M32: =VLOOKUP($C32,[1]Sheet1!$B$23:$AG$79,8,0) -> 0 | N32: =M32-L32 -> 0 | O32: =L32+N32-M32 -> 0 | P32: =VLOOKUP($C32,[1]Sheet1!$B$23:$AG$79,14,0) -> 0 | Q32: =P32-O32 -> 0 | R32: =O32+Q32-P32 -> 0 | S32: =VLOOKUP($C32,[1]Sheet1!$B$23:$AG$79,20,0) -> 0 | T32: =S32-R32 -> 0 | U32: =R32+T32-S32 -> 0 | V32: =VLOOKUP($C32,[1]Sheet1!$B$23:$AG$79,26,0) -> 0 | W32: =V32-U32 -> 0 | X32: =U32+W32-V32 -> 0 | Y32: =VLOOKUP($C32,[1]Sheet1!$B$23:$AG$79,32,0) -> 0 | Z32: =Y32-X32 -> 0 | AA32: =X32+Z32-Y32 -> 0 | AB32: =+Y32 -> 0 | AC32: =AB32-AA32 -> 0 | AD32: =AA32+AC32-AB32 -> 0 | AE32: 82111FE200 | AG32: =I32*$F32 -> 0 | AH32: =J32*$F32 -> 0 | AI32: =K32*$F32 -> 0 | AJ32: =L32*$F32 -> 0 | AK32: =J32*$F32 -> 0 | AL32: =N32*$F32 -> 0 | AM32: =O32*$F32 -> 0 | AN32: =M32*$F32 -> 0 | AO32: =Q32*$F32 -> 0 | AP32: =R32*$F32 -> 0 | AQ32: =P32*$F32 -> 0 | AR32: =T32*$F32 -> 0 | AS32: =U32*$F32 -> 0 | AT32: =S32*$F32 -> 0 | AU32: =W32*$F32 -> 0 | AV32: =X32*$F32 -> 0 | AW32: =V32*$F32 -> 0 | AX32: =Z32*$F32 -> 0 | AY32: =AA32*$F32 -> 0 | AZ32: =Y32*$F32 -> 0 | BA32: =AC32*$F32 -> 0 | BB32: 82111-47370 | BC32: =ROUNDUP(N32/$BC$13,0) -> 0 | BD32: =ROUNDUP(Q32/$BD$13,0) -> 0 | BE32: =ROUNDUP(T32/$BE$13,0) -> 0 | BF32: =ROUNDUP(W32/$BF$13,0) -> 0 | BG32: =ROUNDUP(Z32/$BG$13,0) -> 0 | BH32: =ROUNDUP(AC32/$BH$13,0) -> 0 | BI32: =#REF!+1 -> #REF! | BK32: 82111-47L10 | BM32: 82111-47742 A 0001
C33: 82111-FE210 | D33: 0001 | E33: DVI3 | G33: 6 | H33: =VLOOKUP($C33,'[2]UMH Detail'!$E$4:$V$500,18,0) -> 2.911185 | I33: 0 | J33: 16 | K33: 18 | L33: =I33+K33-J33 -> 2 | M33: =VLOOKUP($C33,[1]Sheet1!$B$23:$AG$79,8,0) -> 0 | N33: =M33-L33+2 -> 0 | O33: =L33+N33-M33 -> 2 | P33: =VLOOKUP($C33,[1]Sheet1!$B$23:$AG$79,14,0) -> 0 | Q33: =P33-O33+2 -> 0 | R33: =O33+Q33-P33 -> 2 | S33: =VLOOKUP($C33,[1]Sheet1!$B$23:$AG$79,20,0) -> 0 | T33: =S33-R33+2 -> 0 | U33: =R33+T33-S33 -> 2 | V33: =VLOOKUP($C33,[1]Sheet1!$B$23:$AG$79,26,0) -> 0 | W33: =V33-U33+2 -> 0 | X33: =U33+W33-V33 -> 2 | Y33: =VLOOKUP($C33,[1]Sheet1!$B$23:$AG$79,32,0) -> 0 | Z33: =Y33-X33+2 -> 0 | AA33: =X33+Z33-Y33 -> 2 | AB33: =+Y33 -> 0 | AC33: =AB33-AA33+2 -> 0 | AD33: =AA33+AC33-AB33 -> 2 | AE33: 82111FE210 | AG33: =I33*$F33 -> 0 | AH33: =J33*$F33 -> 0 | AI33: =K33*$F33 -> 0 | AJ33: =L33*$F33 -> 0 | AK33: =J33*$F33 -> 0 | AL33: =N33*$F33 -> 0 | AM33: =O33*$F33 -> 0 | AN33: =M33*$F33 -> 0 | AO33: =Q33*$F33 -> 0 | AP33: =R33*$F33 -> 0 | AQ33: =P33*$F33 -> 0 | AR33: =T33*$F33 -> 0 | AS33: =U33*$F33 -> 0 | AT33: =S33*$F33 -> 0 | AU33: =W33*$F33 -> 0 | AV33: =X33*$F33 -> 0 | AW33: =V33*$F33 -> 0 | AX33: =Z33*$F33 -> 0 | AY33: =AA33*$F33 -> 0 | AZ33: =Y33*$F33 -> 0 | BA33: =AC33*$F33 -> 0 | BB33: 82111-47460 | BC33: =ROUNDUP(N33/$BC$13,0) -> 0 | BD33: =ROUNDUP(Q33/$BD$13,0) -> 0 | BE33: =ROUNDUP(T33/$BE$13,0) -> 0 | BF33: =ROUNDUP(W33/$BF$13,0) -> 0 | BG33: =ROUNDUP(Z33/$BG$13,0) -> 0 | BH33: =ROUNDUP(AC33/$BH$13,0) -> 0 | BI33: =#REF!+1 -> #REF! | BK33: 82111-47752 | BM33: 82111-47751 A 0001
C34: 82111-F2W42 | D34: C 0101 | E34: DQG5 | G34: 6 | H34: =VLOOKUP($C34,[4]Sheet1!$E$334:$Z$488,18,0) -> 2.9277417 | AG34: =I34*$F34 -> 0 | AH34: =J34*$F34 -> 0 | AI34: =K34*$F34 -> 0 | AJ34: =L34*$F34 -> 0 | AK34: =J34*$F34 -> 0 | AL34: =N34*$F34 -> 0 | AM34: =O34*$F34 -> 0 | AN34: =M34*$F34 -> 0 | AO34: =Q34*$F34 -> 0 | AP34: =R34*$F34 -> 0 | AQ34: =P34*$F34 -> 0 | AR34: =T34*$F34 -> 0 | AS34: =U34*$F34 -> 0 | AT34: =S34*$F34 -> 0 | AU34: =W34*$F34 -> 0 | AV34: =X34*$F34 -> 0 | AW34: =V34*$F34 -> 0 | AX34: =Z34*$F34 -> 0 | AY34: =AA34*$F34 -> 0 | AZ34: =Y34*$F34 -> 0 | BA34: =AC34*$F34 -> 0 | BB34: 82111-47370 | BC34: =ROUNDUP(N34/$BC$13,0) -> 0 | BD34: =ROUNDUP(Q34/$BD$13,0) -> 0 | BE34: =ROUNDUP(T34/$BE$13,0) -> 0 | BF34: =ROUNDUP(W34/$BF$13,0) -> 0 | BG34: =ROUNDUP(Z34/$BG$13,0) -> 0 | BH34: =ROUNDUP(AC34/$BH$13,0) -> 0 | BI34: =#REF!+1 -> #REF! | BK34: 82111-47751 | BM34: 82111-47772 A 0001
C35: 82111-F2W92 | D35: C 0201 | E35: DUR4 | G35: 6 | AG35: =I35*$F35 -> 0 | AH35: =J35*$F35 -> 0 | AI35: =K35*$F35 -> 0 | AJ35: =L35*$F35 -> 0 | AK35: =J35*$F35 -> 0 | AL35: =N35*$F35 -> 0 | AM35: =O35*$F35 -> 0 | AN35: =M35*$F35 -> 0 | AO35: =Q35*$F35 -> 0 | AP35: =R35*$F35 -> 0 | AQ35: =P35*$F35 -> 0 | AR35: =T35*$F35 -> 0 | AS35: =U35*$F35 -> 0 | AT35: =S35*$F35 -> 0 | AU35: =W35*$F35 -> 0 | AV35: =X35*$F35 -> 0 | AW35: =V35*$F35 -> 0 | AX35: =Z35*$F35 -> 0 | AY35: =AA35*$F35 -> 0 | AZ35: =Y35*$F35 -> 0 | BA35: =AC35*$F35 -> 0 | BB35: 82111-47370 | BC35: =ROUNDUP(N35/$BC$13,0) -> 0 | BD35: =ROUNDUP(Q35/$BD$13,0) -> 0 | BE35: =ROUNDUP(T35/$BE$13,0) -> 0 | BF35: =ROUNDUP(W35/$BF$13,0) -> 0 | BG35: =ROUNDUP(Z35/$BG$13,0) -> 0 | BH35: =ROUNDUP(AC35/$BH$13,0) -> 0 | BI35: =#REF!+1 -> #REF! | BK35: 82111-47770 | BM35: 82111-47843 B 0001
C36: 82111-F2W23 | D36: B 0201 | E36: DQF8 | G36: 6 | H36: =VLOOKUP($C36,[4]Sheet1!$E$334:$Z$488,18,0) -> 2.8513367 | AG36: =I36*$F36 -> 0 | AH36: =J36*$F36 -> 0 | AI36: =K36*$F36 -> 0 | AJ36: =L36*$F36 -> 0 | AK36: =J36*$F36 -> 0 | AL36: =N36*$F36 -> 0 | AM36: =O36*$F36 -> 0 | AN36: =M36*$F36 -> 0 | AO36: =Q36*$F36 -> 0 | AP36: =R36*$F36 -> 0 | AQ36: =P36*$F36 -> 0 | AR36: =T36*$F36 -> 0 | AS36: =U36*$F36 -> 0 | AT36: =S36*$F36 -> 0 | AU36: =W36*$F36 -> 0 | AV36: =X36*$F36 -> 0 | AW36: =V36*$F36 -> 0 | AX36: =Z36*$F36 -> 0 | AY36: =AA36*$F36 -> 0 | AZ36: =Y36*$F36 -> 0 | BA36: =AC36*$F36 -> 0 | BB36: 82111-47370 | BC36: =ROUNDUP(N36/$BC$13,0) -> 0 | BD36: =ROUNDUP(Q36/$BD$13,0) -> 0 | BE36: =ROUNDUP(T36/$BE$13,0) -> 0 | BF36: =ROUNDUP(W36/$BF$13,0) -> 0 | BG36: =ROUNDUP(Z36/$BG$13,0) -> 0 | BH36: =ROUNDUP(AC36/$BH$13,0) -> 0 | BI36: =#REF!+1 -> #REF! | BK36: 82111-47770 | BM36: 82111-47843 B 0001
C37: 82111-F2W34 | D37: B 0301 | E37: DUQ9 | G37: 6
C38: 82111-F2W63 | D38: B 0201 | E38: DQG1 | G38: 6 | H38: =VLOOKUP($C38,[4]Sheet1!$E$334:$Z$488,18,0) -> 2.734875
C39: 82111-F2W83 | D39: B 0301 | E39: DUR2 | G39: 6
C40: 82115-F2Y40 | D40: B 0201 | E40: DQG3 | G40: 6 | H40: =VLOOKUP($C40,[4]Sheet1!$E$334:$Z$488,18,0) -> 2.854265
C41: 82111-F2132 | D41: B 0001 | E41: DQI5 | G41: 6 | H41: =VLOOKUP($C41,[4]Sheet1!$E$334:$Z$488,18,0) -> 3.545445
...

Sheet down rate
B1: SIX MONTH PRODUCTION PLAN ( QTY )
L2: TOYOTA PRIUS (433W ) | AB2: PREPARED
B3: S/R NO : 14-DEC-'10(PRD_52023_32G7_201101_3) | M3: Periode : DEC PROD 2010 (ACTUAL)
B4: FAX NO : EMAIL
B5: DATE :14-DEC-10 | AB5: EMU
BD6: AS 400
Z7: NSO
I9: TEMPRORARY UMH | AG9: Cutting Qty
B10: Print Date : | C10: =NOW() -> 46093.481
A11: TYPE | C11: HARNESS No. | D11: LEVEL | E11: ASSY CODE | F11: CCT. | G11: Std Pack | H11: UMH | J11: =GUM!I11 -> FEB | M11: =GUM!L11 -> MAR | P11: =GUM!O11 -> APR | S11: =GUM!R11 -> MAY | V11: =GUM!U11 -> JUN | Y11: =GUM!X11 -> JUL | AB11: =GUM!I11 -> FEB | AE11: BAL | AG11: =J11 -> FEB | AJ11: =M11 -> MAR | AM11: =P11 -> APR | AP11: =S11 -> MAY | AS11: =V11 -> JUN | AV11: =Y11 -> JUL | AY11: =AB11 -> FEB
H12: Jan~Jun | I12: Jul~Dec | J12: =VLOOKUP(J11,[8]Calender!$A$324:$I$383,9,0) -> 02/FEB ~ 25/FEB | M12: =VLOOKUP(M11,[8]Calender!$A$324:$I$383,9,0) -> 01/MAR ~ 4/APR | P12: =VLOOKUP(P11,[8]Calender!$A$324:$I$383,9,0) -> 05/APR ~ 30/APR | S12: =VLOOKUP(S11,[8]Calender!$A$324:$I$383,9,0) -> 03/MAY ~ 27/MAY | V12: =VLOOKUP(V11,[9]Calender!$A$386:$I$400,9,0) -> #N/A | Y12: =VLOOKUP(Y11,[10]Calender!$A$386:$I$424,9,0) -> #N/A | AB12: =VLOOKUP(AB11,[10]Calender!$A$386:$I$424,9,0) -> 01/FEB ~ 28/FEB | AG12: =J12 -> 02/FEB ~ 25/FEB | AJ12: =M12 -> 01/MAR ~ 4/APR | AM12: =P12 -> 05/APR ~ 30/APR | AP12: =S12 -> 03/MAY ~ 27/MAY | AS12: =V12 -> #N/A | AV12: =Y12 -> #N/A | AY12: =AB12 -> 01/FEB ~ 28/FEB | BC12: =M11 -> MAR | BD12: =P11 -> APR | BE12: =S11 -> MAY | BF12: =V11 -> JUN | BG12: =Y11 -> JUL | BH12: =AB11 -> FEB
H13: 2010 | I13: 2010 | J13: BAL | K13: DEL | L13: PROD | M13: BAL | N13: DEL | O13: PROD | P13: BAL | Q13: DEL | R13: PROD | S13: BAL | T13: DEL | U13: PROD | V13: BAL | W13: DEL | X13: PROD | Y13: BAL | Z13: DEL | AA13: PROD | AB13: BAL | AC13: DEL | AD13: PROD | AG13: =J13 -> BAL | AH13: =K13 -> DEL | AI13: =L13 -> PROD | AJ13: =M13 -> BAL | AK13: =N13 -> DEL | AL13: =O13 -> PROD | AM13: =P13 -> BAL | AN13: =Q13 -> DEL | ... BA13: =AD13 -> PROD | BC13: 5 | BD13: 4 | BE13: 4 | BF13: 5 | BG13: 4 | BH13: 4
A14: RHD | B14: DOM | C14: 82111-47330 H | D14: =VLOOKUP(C14,[11]PRIUS!$C$3:$I$26,2,0) -> 0902 | E14: =VLOOKUP(C14,[12]PRIUS!$C$3:$F$17,4,0) -> A424 | F14: 304 | G14: 6 | H14: =VLOOKUP(C14,[13]PRIUS!$C$3:$I$34,3,0) -> 4.1480633 | I14: =VLOOKUP(C14,[13]PRIUS!$C$3:$I$34,7,0) -> 4.1261 | J14: =(GUM!#REF!-(GUM!#REF!*0.2)) -> #REF! | K14: =(GUM!#REF!-(GUM!#REF!*0.2)) -> #REF! | L14: =(GUM!#REF!-(GUM!#REF!*0.2)) -> #REF! | M14: =(GUM!#REF!-(GUM!#REF!*0.2)) -> #REF! | N14: =(GUM!#REF!-(GUM!#REF!*0.2)) -> #REF! | O14: =(GUM!#REF!-(GUM!#REF!*0.2)) -> #REF! | P14: =(GUM!#REF!-(GUM!#REF!*0.2)) -> #REF! | Q14: =(GUM!#REF!-(GUM!#REF!*0.2)) -> #REF! | ... AE14: =(GUM!#REF!-(GUM!#REF!*0.2)) -> #REF! | AF14: 1 | AG14: =J14*$F14 -> #REF! | AH14: =K14*$F14 -> #REF! | AI14: =L14*$F14 -> #REF! | AJ14: =M14*$F14 -> #REF! | AK14: =K14*$F14 -> #REF! | AL14: =O14*$F14 -> #REF! | AM14: =P14*$F14 -> #REF! | AN14: =N14*$F14 -> #REF! | AO14: =R14*$F14 -> #REF! | AP14: =S14*$F14 -> #REF! | AQ14: =Q14*$F14 -> #REF! | AR14: =U14*$F14 -> #REF! | AS14: =V14*$F14 -> #REF! | AT14: =T14*$F14 -> #REF! | AU14: =X14*$F14 -> #REF! | AV14: =Y14*$F14 -> #REF! | AW14: =W14*$F14 -> #REF! | AX14: =AA14*$F14 -> #REF! | AY14: =AB14*$F14 -> #REF! | AZ14: =Z14*$F14 -> #REF! | BA14: =AD14*$F14 -> #REF! | BB14: 82111-47330 | BC14: =ROUNDUP(O14/$BC$13,0) -> #REF! | BD14: =ROUNDUP(R14/$BD$13,0) -> #REF! | BE14: =ROUNDUP(U14/$BE$13,0) -> #REF! | BF14: =ROUNDUP(X14/$BF$13,0) -> #REF! | BG14: =ROUNDUP(AA14/$BG$13,0) -> #REF! | BH14: =ROUNDUP(AD14/$BH$13,0) -> #REF! | BI14: 1
C15: 82111-47340 H | D15: =VLOOKUP(C15,[11]PRIUS!$C$3:$I$26,2,0) -> 0902 | E15: =VLOOKUP(C15,[12]PRIUS!$C$3:$F$17,4,0) -> 9911 | F15: 323 | G15: 6 | H15: =VLOOKUP(C15,[13]PRIUS!$C$3:$I$34,3,0) -> 4.27966 | I15: =VLOOKUP(C15,[13]PRIUS!$C$3:$I$34,7,0) -> 4.2541 | J15: =(GUM!#REF!-(GUM!#REF!*0.2)) -> #REF! | K15: =(GUM!#REF!-(GUM!#REF!*0.2)) -> #REF! | L15: =(GUM!#REF!-(GUM!#REF!*0.2)) -> #REF! | M15: =(GUM!#REF!-(GUM!#REF!*0.2)) -> #REF! | N15: =(GUM!#REF!-(GUM!#REF!*0.2)) -> #REF! | O15: =(GUM!#REF!-(GUM!#REF!*0.2)) -> #REF! | P15: =(GUM!#REF!-(GUM!#REF!*0.2)) -> #REF! | Q15: =(GUM!#REF!-(GUM!#REF!*0.2)) -> #REF! | ... AE15: =(GUM!#REF!-(GUM!#REF!*0.2)) -> #REF! | AF15: =AF14+1 -> 2 | AG15: =J15*$F15 -> #REF! | AH15: =K15*$F15 -> #REF! | AI15: =L15*$F15 -> #REF! | AJ15: =M15*$F15 -> #REF! | AK15: =K15*$F15 -> #REF! | AL15: =O15*$F15 -> #REF! | AM15: =P15*$F15 -> #REF! | AN15: =N15*$F15 -> #REF! | AO15: =R15*$F15 -> #REF! | AP15: =S15*$F15 -> #REF! | AQ15: =Q15*$F15 -> #REF! | AR15: =U15*$F15 -> #REF! | AS15: =V15*$F15 -> #REF! | AT15: =T15*$F15 -> #REF! | AU15: =X15*$F15 -> #REF! | AV15: =Y15*$F15 -> #REF! | AW15: =W15*$F15 -> #REF! | AX15: =AA15*$F15 -> #REF! | AY15: =AB15*$F15 -> #REF! | AZ15: =Z15*$F15 -> #REF! | BA15: =AD15*$F15 -> #REF! | BB15: 82111-47340 | BC15: =ROUNDUP(O15/$BC$13,0) -> #REF! | BD15: =ROUNDUP(R15/$BD$13,0) -> #REF! | BE15: =ROUNDUP(U15/$BE$13,0) -> #REF! | BF15: =ROUNDUP(X15/$BF$13,0) -> #REF! | BG15: =ROUNDUP(AA15/$BG$13,0) -> #REF! | BH15: =ROUNDUP(AD15/$BH$13,0) -> #REF! | BI15: =BI14+1 -> 2
C16: 82111-47350 A | D16: =VLOOKUP(C16,[11]PRIUS!$C$3:$I$26,2,0) -> 0301 | E16: =VLOOKUP(C16,[12]PRIUS!$C$3:$F$17,4,0) -> 7887 | G16: 6 | H16: =VLOOKUP(C16,[13]PRIUS!$C$3:$I$34,3,0) -> 4.25618 | I16: =VLOOKUP(C16,[13]PRIUS!$C$3:$I$34,7,0) -> 4.2483 | J16: =(GUM!#REF!-(GUM!#REF!*0.2)) -> #REF! | K16: =(GUM!#REF!-(GUM!#REF!*0.2)) -> #REF! | L16: =(GUM!#REF!-(GUM!#REF!*0.2)) -> #REF! | M16: =(GUM!#REF!-(GUM!#REF!*0.2)) -> #REF! | N16: =(GUM!#REF!-(GUM!#REF!*0.2)) -> #REF! | O16: =(GUM!#REF!-(GUM!#REF!*0.2)) -> #REF! | P16: =(GUM!#REF!-(GUM!#REF!*0.2)) -> #REF! | Q16: =(GUM!#REF!-(GUM!#REF!*0.2)) -> #REF! | ... AE16: =(GUM!#REF!-(GUM!#REF!*0.2)) -> #REF! | AF16: =AF15+1 -> 3 | AG16: =J16*$F16 -> #REF! | AH16: =K16*$F16 -> #REF! | AI16: =L16*$F16 -> #REF! | AJ16: =M16*$F16 -> #REF! | AK16: =K16*$F16 -> #REF! | AL16: =O16*$F16 -> #REF! | AM16: =P16*$F16 -> #REF! | AN16: =N16*$F16 -> #REF! | AO16: =R16*$F16 -> #REF! | AP16: =S16*$F16 -> #REF! | AQ16: =Q16*$F16 -> #REF! | AR16: =U16*$F16 -> #REF! | AS16: =V16*$F16 -> #REF! | AT16: =T16*$F16 -> #REF! | AU16: =X16*$F16 -> #REF! | AV16: =Y16*$F16 -> #REF! | AW16: =W16*$F16 -> #REF! | AX16: =AA16*$F16 -> #REF! | AY16: =AB16*$F16 -> #REF! | AZ16: =Z16*$F16 -> #REF! | BA16: =AD16*$F16 -> #REF! | BB16: 82111-47350 | BC16: =ROUNDUP(O16/$BC$13,0) -> #REF! | BD16: =ROUNDUP(R16/$BD$13,0) -> #REF! | BE16: =ROUNDUP(U16/$BE$13,0) -> #REF! | BF16: =ROUNDUP(X16/$BF$13,0) -> #REF! | BG16: =ROUNDUP(AA16/$BG$13,0) -> #REF! | BH16: =ROUNDUP(AD16/$BH$13,0) -> #REF! | BI16: =BI15+1 -> 3
B17: EC | C17: 82111-47450 H | D17: =VLOOKUP(C17,[11]PRIUS!$C$3:$I$26,2,0) -> 0902 | E17: =VLOOKUP(C17,[12]PRIUS!$C$3:$F$17,4,0) -> A426 | F17: 332 | G17: 6 | H17: =VLOOKUP(C17,[13]PRIUS!$C$3:$I$34,3,0) -> 4.3249983 | I17: =VLOOKUP(C17,[13]PRIUS!$C$3:$I$34,7,0) -> 4.2968 | J17: =(GUM!#REF!-(GUM!#REF!*0.2)) -> #REF! | K17: =(GUM!#REF!-(GUM!#REF!*0.2)) -> #REF! | L17: =(GUM!#REF!-(GUM!#REF!*0.2)) -> #REF! | M17: =(GUM!#REF!-(GUM!#REF!*0.2)) -> #REF! | N17: =(GUM!#REF!-(GUM!#REF!*0.2)) -> #REF! | O17: =(GUM!#REF!-(GUM!#REF!*0.2)) -> #REF! | P17: =(GUM!#REF!-(GUM!#REF!*0.2)) -> #REF! | Q17: =(GUM!#REF!-(GUM!#REF!*0.2)) -> #REF! | ... AE17: =(GUM!#REF!-(GUM!#REF!*0.2)) -> #REF! | AF17: =AF16+1 -> 4 | AG17: =J17*$F17 -> #REF! | AH17: =K17*$F17 -> #REF! | AI17: =L17*$F17 -> #REF! | AJ17: =M17*$F17 -> #REF! | AK17: =K17*$F17 -> #REF! | AL17: =O17*$F17 -> #REF! | AM17: =P17*$F17 -> #REF! | AN17: =N17*$F17 -> #REF! | AO17: =R17*$F17 -> #REF! | AP17: =S17*$F17 -> #REF! | AQ17: =Q17*$F17 -> #REF! | AR17: =U17*$F17 -> #REF! | AS17: =V17*$F17 -> #REF! | AT17: =T17*$F17 -> #REF! | AU17: =X17*$F17 -> #REF! | AV17: =Y17*$F17 -> #REF! | AW17: =W17*$F17 -> #REF! | AX17: =AA17*$F17 -> #REF! | AY17: =AB17*$F17 -> #REF! | AZ17: =Z17*$F17 -> #REF! | BA17: =AD17*$F17 -> #REF! | BB17: 82111-47450 | BC17: =ROUNDUP(O17/$BC$13,0) -> #REF! | BD17: =ROUNDUP(R17/$BD$13,0) -> #REF! | BE17: =ROUNDUP(U17/$BE$13,0) -> #REF! | BF17: =ROUNDUP(X17/$BF$13,0) -> #REF! | BG17: =ROUNDUP(AA17/$BG$13,0) -> #REF! | BH17: =ROUNDUP(AD17/$BH$13,0) -> #REF! | BI17: =BI16+1 -> 4
C18: 82111-47460 H | D18: =VLOOKUP(C18,[11]PRIUS!$C$3:$I$26,2,0) -> 0802 | E18: =VLOOKUP(C18,[12]PRIUS!$C$3:$F$17,4,0) -> A427 | F18: 351 | G18: 6 | H18: =VLOOKUP(C18,[13]PRIUS!$C$3:$I$34,3,0) -> 4.4175 | I18: =VLOOKUP(C18,[13]PRIUS!$C$3:$I$34,7,0) -> 4.3862 | J18: =(GUM!#REF!-(GUM!#REF!*0.2)) -> #REF! | K18: =(GUM!#REF!-(GUM!#REF!*0.2)) -> #REF! | L18: =(GUM!#REF!-(GUM!#REF!*0.2)) -> #REF! | M18: =(GUM!#REF!-(GUM!#REF!*0.2)) -> #REF! | N18: =(GUM!#REF!-(GUM!#REF!*0.2)) -> #REF! | O18: =(GUM!#REF!-(GUM!#REF!*0.2)) -> #REF! | P18: =(GUM!#REF!-(GUM!#REF!*0.2)) -> #REF! | Q18: =(GUM!#REF!-(GUM!#REF!*0.2)) -> #REF! | ... AE18: =(GUM!#REF!-(GUM!#REF!*0.2)) -> #REF! | AF18: =AF17+1 -> 5 | AG18: =J18*$F18 -> #REF! | AH18: =K18*$F18 -> #REF! | AI18: =L18*$F18 -> #REF! | AJ18: =M18*$F18 -> #REF! | AK18: =K18*$F18 -> #REF! | AL18: =O18*$F18 -> #REF! | AM18: =P18*$F18 -> #REF! | AN18: =N18*$F18 -> #REF! | AO18: =R18*$F18 -> #REF! | AP18: =S18*$F18 -> #REF! | AQ18: =Q18*$F18 -> #REF! | AR18: =U18*$F18 -> #REF! | AS18: =V18*$F18 -> #REF! | AT18: =T18*$F18 -> #REF! | AU18: =X18*$F18 -> #REF! | AV18: =Y18*$F18 -> #REF! | AW18: =W18*$F18 -> #REF! | AX18: =AA18*$F18 -> #REF! | AY18: =AB18*$F18 -> #REF! | AZ18: =Z18*$F18 -> #REF! | BA18: =AD18*$F18 -> #REF! | BB18: 82111-47460 | BC18: =ROUNDUP(O18/$BC$13,0) -> #REF! | BD18: =ROUNDUP(R18/$BD$13,0) -> #REF! | BE18: =ROUNDUP(U18/$BE$13,0) -> #REF! | BF18: =ROUNDUP(X18/$BF$13,0) -> #REF! | BG18: =ROUNDUP(AA18/$BG$13,0) -> #REF! | BH18: =ROUNDUP(AD18/$BH$13,0) -> #REF! | BI18: =BI17+1 -> 5
C19: 82111-47480 B | D19: =VLOOKUP(C19,[11]PRIUS!$C$3:$I$26,2,0) -> 0 | E19: =VLOOKUP(C19,[12]PRIUS!$C$3:$F$17,4,0) -> 8600 | F19: 301 | G19: 6 | H19: =VLOOKUP(C19,[13]PRIUS!$C$3:$I$34,3,0) -> 4.023425 | I19: =VLOOKUP(C19,[13]PRIUS!$C$3:$I$34,7,0) -> 4.023425 | J19: =(GUM!#REF!-(GUM!#REF!*0.2)) -> #REF! | K19: =(GUM!#REF!-(GUM!#REF!*0.2)) -> #REF! | L19: =(GUM!#REF!-(GUM!#REF!*0.2)) -> #REF! | M19: =(GUM!#REF!-(GUM!#REF!*0.2)) -> #REF! | N19: =(GUM!#REF!-(GUM!#REF!*0.2)) -> #REF! | O19: =(GUM!#REF!-(GUM!#REF!*0.2)) -> #REF! | P19: =(GUM!#REF!-(GUM!#REF!*0.2)) -> #REF! | Q19: =(GUM!#REF!-(GUM!#REF!*0.2)) -> #REF! | ... AE19: =(GUM!#REF!-(GUM!#REF!*0.2)) -> #REF! | AF19: =AF18+1 -> 6 | AG19: =J19*$F19 -> #REF! | AH19: =K19*$F19 -> #REF! | AI19: =L19*$F19 -> #REF! | AJ19: =M19*$F19 -> #REF! | AK19: =K19*$F19 -> #REF! | AL19: =O19*$F19 -> #REF! | AM19: =P19*$F19 -> #REF! | AN19: =N19*$F19 -> #REF! | AO19: =R19*$F19 -> #REF! | AP19: =S19*$F19 -> #REF! | AQ19: =Q19*$F19 -> #REF! | AR19: =U19*$F19 -> #REF! | AS19: =V19*$F19 -> #REF! | AT19: =T19*$F19 -> #REF! | AU19: =X19*$F19 -> #REF! | AV19: =Y19*$F19 -> #REF! | AW19: =W19*$F19 -> #REF! | AX19: =AA19*$F19 -> #REF! | AY19: =AB19*$F19 -> #REF! | AZ19: =Z19*$F19 -> #REF! | BA19: =AD19*$F19 -> #REF! | BB19: 82111-47460 | BC19: =ROUNDUP(O19/$BC$13,0) -> #REF! | BD19: =ROUNDUP(R19/$BD$13,0) -> #REF! | BE19: =ROUNDUP(U19/$BE$13,0) -> #REF! | BF19: =ROUNDUP(X19/$BF$13,0) -> #REF! | BG19: =ROUNDUP(AA19/$BG$13,0) -> #REF! | BH19: =ROUNDUP(AD19/$BH$13,0) -> #REF! | BI19: =BI18+1 -> 6
B20: EC | C20: 82111-47461 | D20: =VLOOKUP(C20,[11]PRIUS!$C$3:$I$26,2,0) -> #N/A | E20: =VLOOKUP(C20,[12]PRIUS!$C$3:$F$17,4,0) -> #N/A | F20: 332 | G20: 6 | H20: =VLOOKUP(C20,[13]PRIUS!$C$3:$I$34,3,0) -> 4.4175 | I20: =VLOOKUP(C20,[13]PRIUS!$C$3:$I$34,7,0) -> 4.3971 | J20: =(GUM!#REF!-(GUM!#REF!*0.2)) -> #REF! | K20: =(GUM!#REF!-(GUM!#REF!*0.2)) -> #REF! | L20: =(GUM!#REF!-(GUM!#REF!*0.2)) -> #REF! | M20: =(GUM!#REF!-(GUM!#REF!*0.2)) -> #REF! | N20: =(GUM!#REF!-(GUM!#REF!*0.2)) -> #REF! | O20: =(GUM!#REF!-(GUM!#REF!*0.2)) -> #REF! | P20: =(GUM!#REF!-(GUM!#REF!*0.2)) -> #REF! | Q20: =(GUM!#REF!-(GUM!#REF!*0.2)) -> #REF! | ... AE20: =(GUM!#REF!-(GUM!#REF!*0.2)) -> #REF! | AF20: =AF19+1 -> 7 | AG20: =J20*$F20 -> #REF! | AH20: =K20*$F20 -> #REF! | AI20: =L20*$F20 -> #REF! | AJ20: =M20*$F20 -> #REF! | AK20: =K20*$F20 -> #REF! | AL20: =O20*$F20 -> #REF! | AM20: =P20*$F20 -> #REF! | AN20: =N20*$F20 -> #REF! | AO20: =R20*$F20 -> #REF! | AP20: =S20*$F20 -> #REF! | AQ20: =Q20*$F20 -> #REF! | AR20: =U20*$F20 -> #REF! | AS20: =V20*$F20 -> #REF! | AT20: =T20*$F20 -> #REF! | AU20: =X20*$F20 -> #REF! | AV20: =Y20*$F20 -> #REF! | AW20: =W20*$F20 -> #REF! | AX20: =AA20*$F20 -> #REF! | AY20: =AB20*$F20 -> #REF! | AZ20: =Z20*$F20 -> #REF! | BA20: =AD20*$F20 -> #REF! | BB20: 82111-47450 | BC20: =ROUNDUP(O20/$BC$13,0) -> #REF! | BD20: =ROUNDUP(R20/$BD$13,0) -> #REF! | BE20: =ROUNDUP(U20/$BE$13,0) -> #REF! | BF20: =ROUNDUP(X20/$BF$13,0) -> #REF! | BG20: =ROUNDUP(AA20/$BG$13,0) -> #REF! | BH20: =ROUNDUP(AD20/$BH$13,0) -> #REF! | BI20: =BI19+1 -> 7
C21: 82111-47462 | D21: =VLOOKUP(C21,[11]PRIUS!$C$3:$I$26,2,0) -> #N/A | E21: =VLOOKUP(C21,[12]PRIUS!$C$3:$F$17,4,0) -> #N/A | F21: 332 | G21: 6 | H21: =VLOOKUP(C21,[13]PRIUS!$C$3:$I$34,3,0) -> 4.4175 | I21: =VLOOKUP(C21,[13]PRIUS!$C$3:$I$34,7,0) -> 4.3971 | J21: =(GUM!I14-(GUM!I14*0.2)) -> 0 | K21: =(GUM!J14-(GUM!J14*0.2)) -> 0 | L21: =(GUM!K14-(GUM!K14*0.2)) -> 0 | M21: =(GUM!L14-(GUM!L14*0.2)) -> 0 | N21: =(GUM!M14-(GUM!M14*0.2)) -> 0 | O21: =(GUM!N14-(GUM!N14*0.2)) -> 0 | P21: =(GUM!O14-(GUM!O14*0.2)) -> 0 | Q21: =(GUM!P14-(GUM!P14*0.2)) -> 0 | ... AE21: =(GUM!AD14-(GUM!AD14*0.2)) -> 0 | AF21: =AF20+1 -> 8 | AG21: =J21*$F21 -> 0 | AH21: =K21*$F21 -> 0 | AI21: =L21*$F21 -> 0 | AJ21: =M21*$F21 -> 0 | AK21: =K21*$F21 -> 0 | AL21: =O21*$F21 -> 0 | AM21: =P21*$F21 -> 0 | AN21: =N21*$F21 -> 0 | AO21: =R21*$F21 -> 0 | AP21: =S21*$F21 -> 0 | AQ21: =Q21*$F21 -> 0 | AR21: =U21*$F21 -> 0 | AS21: =V21*$F21 -> 0 | AT21: =T21*$F21 -> 0 | AU21: =X21*$F21 -> 0 | AV21: =Y21*$F21 -> 0 | AW21: =W21*$F21 -> 0 | AX21: =AA21*$F21 -> 0 | AY21: =AB21*$F21 -> 0 | AZ21: =Z21*$F21 -> 0 | BA21: =AD21*$F21 -> 0 | BB21: 82111-47450 | BC21: =ROUNDUP(O21/$BC$13,0) -> 0 | BD21: =ROUNDUP(R21/$BD$13,0) -> 0 | BE21: =ROUNDUP(U21/$BE$13,0) -> 0 | BF21: =ROUNDUP(X21/$BF$13,0) -> 0 | BG21: =ROUNDUP(AA21/$BG$13,0) -> 0 | BH21: =ROUNDUP(AD21/$BH$13,0) -> 0 | BI21: =BI20+1 -> 8
C22: 82111-47341 | D22: =VLOOKUP(C22,[11]PRIUS!$C$3:$I$26,2,0) -> 0 | E22: =VLOOKUP(C22,[12]PRIUS!$C$3:$F$17,4,0) -> #N/A | F22: 351 | G22: 6 | H22: =VLOOKUP(C22,[13]PRIUS!$C$3:$I$34,3,0) -> 4.27966 | I22: =VLOOKUP(C22,[13]PRIUS!$C$3:$I$34,7,0) -> 4.2541 | J22: =(GUM!#REF!-(GUM!#REF!*0.2)) -> #REF! | K22: =(GUM!#REF!-(GUM!#REF!*0.2)) -> #REF! | L22: =(GUM!#REF!-(GUM!#REF!*0.2)) -> #REF! | M22: =(GUM!#REF!-(GUM!#REF!*0.2)) -> #REF! | N22: =(GUM!#REF!-(GUM!#REF!*0.2)) -> #REF! | O22: =(GUM!#REF!-(GUM!#REF!*0.2)) -> #REF! | P22: =(GUM!#REF!-(GUM!#REF!*0.2)) -> #REF! | Q22: =(GUM!#REF!-(GUM!#REF!*0.2)) -> #REF! | ... AE22: =(GUM!#REF!-(GUM!#REF!*0.2)) -> #REF! | AF22: =AF21+1 -> 9 | AG22: =J22*$F22 -> #REF! | AH22: =K22*$F22 -> #REF! | AI22: =L22*$F22 -> #REF! | AJ22: =M22*$F22 -> #REF! | AK22: =K22*$F22 -> #REF! | AL22: =O22*$F22 -> #REF! | AM22: =P22*$F22 -> #REF! | AN22: =N22*$F22 -> #REF! | AO22: =R22*$F22 -> #REF! | AP22: =S22*$F22 -> #REF! | AQ22: =Q22*$F22 -> #REF! | AR22: =U22*$F22 -> #REF! | AS22: =V22*$F22 -> #REF! | AT22: =T22*$F22 -> #REF! | AU22: =X22*$F22 -> #REF! | AV22: =Y22*$F22 -> #REF! | AW22: =W22*$F22 -> #REF! | AX22: =AA22*$F22 -> #REF! | AY22: =AB22*$F22 -> #REF! | AZ22: =Z22*$F22 -> #REF! | BA22: =AD22*$F22 -> #REF! | BB22: 82111-47460 | BC22: =ROUNDUP(O22/$BC$13,0) -> #REF! | BD22: =ROUNDUP(R22/$BD$13,0) -> #REF! | BE22: =ROUNDUP(U22/$BE$13,0) -> #REF! | BF22: =ROUNDUP(X22/$BF$13,0) -> #REF! | BG22: =ROUNDUP(AA22/$BG$13,0) -> #REF! | BH22: =ROUNDUP(AD22/$BH$13,0) -> #REF! | BI22: =BI20+1 -> 8
C23: 82111-47342 | D23: =VLOOKUP(C23,[11]PRIUS!$C$3:$I$26,2,0) -> #N/A | E23: =VLOOKUP(C23,[12]PRIUS!$C$3:$F$17,4,0) -> #N/A | F23: 351 | G23: 6 | H23: =H22 -> 4.27966 | I23: =I22 -> 4.2541 | J23: =(GUM!#REF!-(GUM!#REF!*0.2)) -> #REF! | K23: =(GUM!#REF!-(GUM!#REF!*0.2)) -> #REF! | L23: =(GUM!#REF!-(GUM!#REF!*0.2)) -> #REF! | M23: =(GUM!#REF!-(GUM!#REF!*0.2)) -> #REF! | N23: =(GUM!#REF!-(GUM!#REF!*0.2)) -> #REF! | O23: =(GUM!#REF!-(GUM!#REF!*0.2)) -> #REF! | P23: =(GUM!#REF!-(GUM!#REF!*0.2)) -> #REF! | Q23: =(GUM!#REF!-(GUM!#REF!*0.2)) -> #REF! | ... AE23: =(GUM!#REF!-(GUM!#REF!*0.2)) -> #REF! | AF23: =AF22+1 -> 10 | AG23: =J23*$F23 -> #REF! | AH23: =K23*$F23 -> #REF! | AI23: =L23*$F23 -> #REF! | AJ23: =M23*$F23 -> #REF! | AK23: =K23*$F23 -> #REF! | AL23: =O23*$F23 -> #REF! | AM23: =P23*$F23 -> #REF! | AN23: =N23*$F23 -> #REF! | AO23: =R23*$F23 -> #REF! | AP23: =S23*$F23 -> #REF! | AQ23: =Q23*$F23 -> #REF! | AR23: =U23*$F23 -> #REF! | AS23: =V23*$F23 -> #REF! | AT23: =T23*$F23 -> #REF! | AU23: =X23*$F23 -> #REF! | AV23: =Y23*$F23 -> #REF! | AW23: =W23*$F23 -> #REF! | AX23: =AA23*$F23 -> #REF! | AY23: =AB23*$F23 -> #REF! | AZ23: =Z23*$F23 -> #REF! | BA23: =AD23*$F23 -> #REF! | BB23: 82111-47460 | BC23: =ROUNDUP(O23/$BC$13,0) -> #REF! | BD23: =ROUNDUP(R23/$BD$13,0) -> #REF! | BE23: =ROUNDUP(U23/$BE$13,0) -> #REF! | BF23: =ROUNDUP(X23/$BF$13,0) -> #REF! | BG23: =ROUNDUP(AA23/$BG$13,0) -> #REF! | BH23: =ROUNDUP(AD23/$BH$13,0) -> #REF! | BI23: =BI21+1 -> 9
C24: 82111-47451 | D24: =VLOOKUP(C24,[11]PRIUS!$C$3:$I$26,2,0) -> 0 | E24: =VLOOKUP(C24,[12]PRIUS!$C$3:$F$17,4,0) -> #N/A | F24: 301 | G24: 6 | H24: =VLOOKUP(C24,[13]PRIUS!$C$3:$I$34,3,0) -> 4.3249983 | I24: =VLOOKUP(C24,[13]PRIUS!$C$3:$I$34,7,0) -> 4.2968 | J24: =(GUM!#REF!-(GUM!#REF!*0.2)) -> #REF! | K24: =(GUM!#REF!-(GUM!#REF!*0.2)) -> #REF! | L24: =(GUM!#REF!-(GUM!#REF!*0.2)) -> #REF! | M24: =(GUM!#REF!-(GUM!#REF!*0.2)) -> #REF! | N24: =(GUM!#REF!-(GUM!#REF!*0.2)) -> #REF! | O24: =(GUM!#REF!-(GUM!#REF!*0.2)) -> #REF! | P24: =(GUM!#REF!-(GUM!#REF!*0.2)) -> #REF! | Q24: =(GUM!#REF!-(GUM!#REF!*0.2)) -> #REF! | ... AE24: =(GUM!#REF!-(GUM!#REF!*0.2)) -> #REF! | AF24: =AF23+1 -> 11 | AG24: =J24*$F24 -> #REF! | AH24: =K24*$F24 -> #REF! | AI24: =L24*$F24 -> #REF! | AJ24: =M24*$F24 -> #REF! | AK24: =K24*$F24 -> #REF! | AL24: =O24*$F24 -> #REF! | AM24: =P24*$F24 -> #REF! | AN24: =N24*$F24 -> #REF! | AO24: =R24*$F24 -> #REF! | AP24: =S24*$F24 -> #REF! | AQ24: =Q24*$F24 -> #REF! | AR24: =U24*$F24 -> #REF! | AS24: =V24*$F24 -> #REF! | AT24: =T24*$F24 -> #REF! | AU24: =X24*$F24 -> #REF! | AV24: =Y24*$F24 -> #REF! | AW24: =W24*$F24 -> #REF! | AX24: =AA24*$F24 -> #REF! | AY24: =AB24*$F24 -> #REF! | AZ24: =Z24*$F24 -> #REF! | BA24: =AD24*$F24 -> #REF! | BB24: 82111-47460 | BC24: =ROUNDUP(O24/$BC$13,0) -> #REF! | BD24: =ROUNDUP(R24/$BD$13,0) -> #REF! | BE24: =ROUNDUP(U24/$BE$13,0) -> #REF! | BF24: =ROUNDUP(X24/$BF$13,0) -> #REF! | BG24: =ROUNDUP(AA24/$BG$13,0) -> #REF! | BH24: =ROUNDUP(AD24/$BH$13,0) -> #REF! | BI24: =BI22+1 -> 9
C25: 82111-47360 J | D25: 0 | E25: =VLOOKUP(C25,[14]PRIUS!$C$3:$F$17,4,0) -> #N/A | F25: 309 | G25: 6 | H25: =VLOOKUP(C25,[13]PRIUS!$C$3:$I$34,3,0) -> 4.0269067 | I25: =VLOOKUP(C25,[13]PRIUS!$C$3:$I$34,7,0) -> 4.059 | J25: =(GUM!#REF!-(GUM!#REF!*0.2)) -> #REF! | K25: =(GUM!#REF!-(GUM!#REF!*0.2)) -> #REF! | L25: =(GUM!#REF!-(GUM!#REF!*0.2)) -> #REF! | M25: =(GUM!#REF!-(GUM!#REF!*0.2)) -> #REF! | N25: =(GUM!#REF!-(GUM!#REF!*0.2)) -> #REF! | O25: =(GUM!#REF!-(GUM!#REF!*0.2)) -> #REF! | P25: =(GUM!#REF!-(GUM!#REF!*0.2)) -> #REF! | Q25: =(GUM!#REF!-(GUM!#REF!*0.2)) -> #REF! | ... AE25: =(GUM!#REF!-(GUM!#REF!*0.2)) -> #REF! | AF25: =AF24+1 -> 12 | AG25: =J25*$F25 -> #REF! | AH25: =K25*$F25 -> #REF! | AI25: =L25*$F25 -> #REF! | AJ25: =M25*$F25 -> #REF! | AK25: =K25*$F25 -> #REF! | AL25: =O25*$F25 -> #REF! | AM25: =P25*$F25 -> #REF! | AN25: =N25*$F25 -> #REF! | AO25: =R25*$F25 -> #REF! | AP25: =S25*$F25 -> #REF! | AQ25: =Q25*$F25 -> #REF! | AR25: =U25*$F25 -> #REF! | AS25: =V25*$F25 -> #REF! | AT25: =T25*$F25 -> #REF! | AU25: =X25*$F25 -> #REF! | AV25: =Y25*$F25 -> #REF! | AW25: =W25*$F25 -> #REF! | AX25: =AA25*$F25 -> #REF! | AY25: =AB25*$F25 -> #REF! | AZ25: =Z25*$F25 -> #REF! | BA25: =AD25*$F25 -> #REF! | BB25: 82111-47360 | BC25: =ROUNDUP(O25/$BC$13,0) -> #REF! | BD25: =ROUNDUP(R25/$BD$13,0) -> #REF! | BE25: =ROUNDUP(U25/$BE$13,0) -> #REF! | BF25: =ROUNDUP(X25/$BF$13,0) -> #REF! | BG25: =ROUNDUP(AA25/$BG$13,0) -> #REF! | BH25: =ROUNDUP(AD25/$BH$13,0) -> #REF! | BI25: =BI24+1 -> 10
C26: 82111-47452 | D26: =VLOOKUP(C26,[11]PRIUS!$C$3:$I$26,2,0) -> #N/A | E26: =VLOOKUP(C26,[12]PRIUS!$C$3:$F$17,4,0) -> #N/A | F26: 301 | G26: 6 | H26: =VLOOKUP(C26,[13]PRIUS!$C$3:$I$34,3,0) -> 4.1480633 | I26: =VLOOKUP(C26,[13]PRIUS!$C$3:$I$34,7,0) -> 4.3161 | J26: =(GUM!I19-(GUM!I19*0.2)) -> 19.2 | K26: =(GUM!J19-(GUM!J19*0.2)) -> 105.6 | L26: =(GUM!K19-(GUM!K19*0.2)) -> 148.8 | M26: =(GUM!L19-(GUM!L19*0.2)) -> 62.4 | N26: =(GUM!M19-(GUM!M19*0.2)) -> 153.6 | O26: =(GUM!N19-(GUM!N19*0.2)) -> 110.4 | P26: =(GUM!O19-(GUM!O19*0.2)) -> 19.2 | Q26: =(GUM!P19-(GUM!P19*0.2)) -> 168 | ... AE26: =(GUM!AD19-(GUM!AD19*0.2)) -> 0 | AF26: =AF25+1 -> 13 | AG26: =J26*$F26 -> 5779.2 | AH26: =K26*$F26 -> 31785.6 | AI26: =L26*$F26 -> 44788.8 | AJ26: =M26*$F26 -> 18782.4 | AK26: =K26*$F26 -> 31785.6 | AL26: =O26*$F26 -> 33230.4 | AM26: =P26*$F26 -> 5779.2 | AN26: =N26*$F26 -> 46233.6 | AO26: =R26*$F26 -> 53457.6 | AP26: =S26*$F26 -> 8668.8 | AQ26: =Q26*$F26 -> 50568 | AR26: =U26*$F26 -> 49123.2 | AS26: =V26*$F26 -> 7224 | AT26: =T26*$F26 -> 50568 | AU26: =X26*$F26 -> 62126.4 | AV26: =Y26*$F26 -> 14448 | AW26: =W26*$F26 -> 54902.4 | AX26: =AA26*$F26 -> 39009.6 | AY26: =AB26*$F26 -> 10113.6 | AZ26: =Z26*$F26 -> 43344 | BA26: =AD26*$F26 -> 33230.4 | BB26: 82111-47460 | BC26: =ROUNDUP(O26/$BC$13,0) -> 23 | BD26: =ROUNDUP(R26/$BD$13,0) -> 45 | BE26: =ROUNDUP(U26/$BE$13,0) -> 41 | BF26: =ROUNDUP(X26/$BF$13,0) -> 42 | BG26: =ROUNDUP(AA26/$BG$13,0) -> 33 | BH26: =ROUNDUP(AD26/$BH$13,0) -> 28 | BI26: =BI24+1 -> 10
A27: LHD | B27: USA | C27: 82111-47370 J | D27: =VLOOKUP(C27,[11]PRIUS!$C$3:$I$26,2,0) -> 0401 | E27: =VLOOKUP(C27,[12]PRIUS!$C$3:$F$17,4,0) -> A430 | F27: 315 | G27: 6 | H27: =VLOOKUP(C27,[13]PRIUS!$C$3:$I$34,3,0) -> 4.1404883 | I27: =VLOOKUP(C27,[13]PRIUS!$C$3:$I$34,7,0) -> 4.1083 | J27: =(GUM!#REF!-(GUM!#REF!*0.2)) -> #REF! | K27: =(GUM!#REF!-(GUM!#REF!*0.2)) -> #REF! | L27: =(GUM!#REF!-(GUM!#REF!*0.2)) -> #REF! | M27: =(GUM!#REF!-(GUM!#REF!*0.2)) -> #REF! | N27: =(GUM!#REF!-(GUM!#REF!*0.2)) -> #REF! | O27: =(GUM!#REF!-(GUM!#REF!*0.2)) -> #REF! | P27: =(GUM!#REF!-(GUM!#REF!*0.2)) -> #REF! | Q27: =(GUM!#REF!-(GUM!#REF!*0.2)) -> #REF! | ... AE27: =(GUM!#REF!-(GUM!#REF!*0.2)) -> #REF! | AF27: =AF26+1 -> 14 | AG27: =J27*$F27 -> #REF! | AH27: =K27*$F27 -> #REF! | AI27: =L27*$F27 -> #REF! | AJ27: =M27*$F27 -> #REF! | AK27: =K27*$F27 -> #REF! | AL27: =O27*$F27 -> #REF! | AM27: =P27*$F27 -> #REF! | AN27: =N27*$F27 -> #REF! | AO27: =R27*$F27 -> #REF! | AP27: =S27*$F27 -> #REF! | AQ27: =Q27*$F27 -> #REF! | AR27: =U27*$F27 -> #REF! | AS27: =V27*$F27 -> #REF! | AT27: =T27*$F27 -> #REF! | AU27: =X27*$F27 -> #REF! | AV27: =Y27*$F27 -> #REF! | AW27: =W27*$F27 -> #REF! | AX27: =AA27*$F27 -> #REF! | AY27: =AB27*$F27 -> #REF! | AZ27: =Z27*$F27 -> #REF! | BA27: =AD27*$F27 -> #REF! | BB27: 82111-47370 | BC27: =ROUNDUP(O27/$BC$13,0) -> #REF! | BD27: =ROUNDUP(R27/$BD$13,0) -> #REF! | BE27: =ROUNDUP(U27/$BE$13,0) -> #REF! | BF27: =ROUNDUP(X27/$BF$13,0) -> #REF! | BG27: =ROUNDUP(AA27/$BG$13,0) -> #REF! | BH27: =ROUNDUP(AD27/$BH$13,0) -> #REF! | BI27: =BI25+1 -> 11
C28: 82111-47380 H | D28: =VLOOKUP(C28,[11]PRIUS!$C$3:$I$26,2,0) -> 0 | E28: =VLOOKUP(C28,[12]PRIUS!$C$3:$F$17,4,0) -> 9404 | F28: 347 | G28: 6 | H28: =VLOOKUP(C28,[13]PRIUS!$C$3:$I$34,3,0) -> 4.1453517 | I28: =VLOOKUP(C28,[13]PRIUS!$C$3:$I$34,7,0) -> 4.1453517 | J28: =(GUM!I39-(GUM!I39*0.2)) -> 0 | K28: =(GUM!J39-(GUM!J39*0.2)) -> 0 | L28: =(GUM!K39-(GUM!K39*0.2)) -> 0 | M28: =(GUM!L39-(GUM!L39*0.2)) -> 0 | N28: =(GUM!M39-(GUM!M39*0.2)) -> 0 | O28: =(GUM!N39-(GUM!N39*0.2)) -> 0 | P28: =(GUM!O39-(GUM!O39*0.2)) -> 0 | Q28: =(GUM!P39-(GUM!P39*0.2)) -> 0 | ... AE28: =(GUM!AD39-(GUM!AD39*0.2)) -> 0 | AF28: =AF27+1 -> 15 | AG28: =J28*$F28 -> 0 | AH28: =K28*$F28 -> 0 | AI28: =L28*$F28 -> 0 | AJ28: =M28*$F28 -> 0 | AK28: =K28*$F28 -> 0 | AL28: =O28*$F28 -> 0 | AM28: =P28*$F28 -> 0 | AN28: =N28*$F28 -> 0 | AO28: =R28*$F28 -> 0 | AP28: =S28*$F28 -> 0 | AQ28: =Q28*$F28 -> 0 | AR28: =U28*$F28 -> 0 | AS28: =V28*$F28 -> 0 | AT28: =T28*$F28 -> 0 | AU28: =X28*$F28 -> 0 | AV28: =Y28*$F28 -> 0 | AW28: =W28*$F28 -> 0 | AX28: =AA28*$F28 -> 0 | AY28: =AB28*$F28 -> 0 | AZ28: =Z28*$F28 -> 0 | BA28: =AD28*$F28 -> 0 | BB28: 82111-47380 | BC28: =ROUNDUP(O28/$BC$13,0) -> 0 | BD28: =ROUNDUP(R28/$BD$13,0) -> 0 | BE28: =ROUNDUP(U28/$BE$13,0) -> 0 | BF28: =ROUNDUP(X28/$BF$13,0) -> 0 | BG28: =ROUNDUP(AA28/$BG$13,0) -> 0 | BH28: =ROUNDUP(AD28/$BH$13,0) -> 0 | BI28: =BI27+1 -> 12
B29: CANADA | C29: 82111-47390 J | D29: =VLOOKUP(C29,[11]PRIUS!$C$3:$I$26,2,0) -> 0402 | E29: =VLOOKUP(C29,[12]PRIUS!$C$3:$F$17,4,0) -> A432 | F29: 321 | G29: 6 | H29: =VLOOKUP(C29,[13]PRIUS!$C$3:$I$34,3,0) -> 4.1974933 | I29: =VLOOKUP(C29,[13]PRIUS!$C$3:$I$34,7,0) -> 4.1611 | J29: =(GUM!I46-(GUM!I46*0.2)) -> 0 | K29: =(GUM!J46-(GUM!J46*0.2)) -> 0 | L29: =(GUM!K46-(GUM!K46*0.2)) -> 0 | M29: =(GUM!L46-(GUM!L46*0.2)) -> 0 | N29: =(GUM!M46-(GUM!M46*0.2)) -> 0 | O29: =(GUM!N46-(GUM!N46*0.2)) -> 0 | P29: =(GUM!O46-(GUM!O46*0.2)) -> 0 | Q29: =(GUM!P46-(GUM!P46*0.2)) -> 0 | ... AE29: =(GUM!AD46-(GUM!AD46*0.2)) -> 0 | AF29: =AF28+1 -> 16 | AG29: =J29*$F29 -> 0 | AH29: =K29*$F29 -> 0 | AI29: =L29*$F29 -> 0 | AJ29: =M29*$F29 -> 0 | AK29: =K29*$F29 -> 0 | AL29: =O29*$F29 -> 0 | AM29: =P29*$F29 -> 0 | AN29: =N29*$F29 -> 0 | AO29: =R29*$F29 -> 0 | AP29: =S29*$F29 -> 0 | AQ29: =Q29*$F29 -> 0 | AR29: =U29*$F29 -> 0 | AS29: =V29*$F29 -> 0 | AT29: =T29*$F29 -> 0 | AU29: =X29*$F29 -> 0 | AV29: =Y29*$F29 -> 0 | AW29: =W29*$F29 -> 0 | AX29: =AA29*$F29 -> 0 | AY29: =AB29*$F29 -> 0 | AZ29: =Z29*$F29 -> 0 | BA29: =AD29*$F29 -> 0 | BB29: 82111-47390 | BC29: =ROUNDUP(O29/$BC$13,0) -> 0 | BD29: =ROUNDUP(R29/$BD$13,0) -> 0 | BE29: =ROUNDUP(U29/$BE$13,0) -> 0 | BF29: =ROUNDUP(X29/$BF$13,0) -> 0 | BG29: =ROUNDUP(AA29/$BG$13,0) -> 0 | BH29: =ROUNDUP(AD29/$BH$13,0) -> 0 | BI29: =BI28+1 -> 13
