Workbook

Sheet JAI 原檔
A1: YAZAKI FAX | D1: FROM
A3: OVERSEAS NETWORK | D3: TO
A5: FAX No. | C5: ATTN : MR.
B7: SR No. | D7: JAI 2023-12-1
B9: TYC FACT | D9: TJAT
B10: OVERSEAS FACT | D10: JAI
B11: ARRIVAL PORT | D11: KAO
B12: CUST | D12: TAIWAN TOYOTA
AI13: FIRM | AM13: FIRM | AQ13: FIRM | AU13: FIRM | AZ13: FIRM | BD13: FIRM | BI13: FIRM | BM13: FIRM | BQ13: FIRM | BV13: FIRM | BZ13: FIRM | CE13: FIRM | CI13: FIRM | CM13: FIRM | CQ13: FIRM | CV13: FIRM | CZ13: FIRM | DD13: FIRM | DI13: FIRM | DM13: FIRM | DR13: FIRM | DV13: FIRM | DZ13: FIRM | EE13: FORECAST | EI13: FORECAST | EM13: FORECAST | EQ13: FORECAST
AC14: TIME CHART MONTH | AI14: =H19 -> 3 | AM14: 4 | AQ14: 5 | AU14: 6 | AZ14: 7 | BD14: 8 | BI14: 9 | BM14: 10 | BQ14: 11 | BV14: 12 | BZ14: 1 | CE14: 2 | CI14: 3 | CM14: 4 | CQ14: 5 | CV14: 6 | CZ14: 7 | DD14: 8 | DI14: 9 | DM14: 10 | DR14: 11 | DV14: 12 | DZ14: 2024/1 | EE14: 2 | EI14: 3 | EM14: 4 | EQ14: 5
AC15: ETD JAI | AI15: 44602 | AJ15: =AI15+7 -> 44609 | AK15: =AJ15+7 -> 44616 | AL15: =AK15+7 -> 44623 | AM15: =AL15+7 -> 44630 | AN15: =AM15+7 -> 44637 | AO15: =AN15+7 -> 44644 | AP15: =AO15+7 -> 44651 | AQ15: =AP15+7 -> 44658 | ... ET15: =ES15+7 -> 45407
AC16: ETD PORT SUR | AI16: 44604 | AJ16: =AI16+7 -> 44611 | AK16: =AJ16+7 -> 44618 | AL16: =AK16+7 -> 44625 | AM16: =AL16+7 -> 44632 | AN16: =AM16+7 -> 44639 | AO16: =AN16+7 -> 44646 | AP16: =AO16+7 -> 44653 | AQ16: =AP16+7 -> 44660 | ... ET16: =ES16+7 -> 45409
A17: 車型 | B17: 部位別 | AC17: ETA KAO | AI17: 44612 | AJ17: =AI17+7 -> 44619 | AK17: =AJ17+7 -> 44626 | AL17: =AK17+7 -> 44633 | AM17: =AL17+7 -> 44640 | AN17: =AM17+7 -> 44647 | AO17: =AN17+7 -> 44654 | AP17: =AO17+7 -> 44661 | AQ17: =AP17+7 -> 44668 | ... ET17: =ES17+7 -> 45417
A18: CAR | AC18: ETA TYC | AI18: 44614 | AJ18: =AI18+7 -> 44621 | AK18: =AJ18+7 -> 44628 | AL18: =AK18+7 -> 44635 | AM18: =AL18+7 -> 44642 | AN18: =AM18+7 -> 44649 | AO18: =AN18+7 -> 44656 | AP18: =AO18+7 -> 44663 | AQ18: =AP18+7 -> 44670 | ... ET18: =ES18+7 -> 45419
A19: MODEL | B19: FAMILY | C19: No. | D19: PRODUCT NO | F19: SFX | H19: 3 | I19: 4 | J19: 5 | K19: 6 | L19: 7 | M19: 8 | N19: 9 | O19: 10 | P19: 11 | Q19: 12 | R19: 2023/1 | S19: 2 | T19: 3 | U19: 4 | V19: 5 | W19: 6 | X19: 7 | Y19: 8 | Z19: 9 | AA19: 10 | AB19: 11 | AC19: 12 | AD19: 1 | AE19: 2 | AF19: 3 | AG19: 4 | AH19: 5 | AI19: 1W | AJ19: 2W | AK19: 3W | AL19: 4W | AM19: 1W | AN19: 2W | AO19: 3W | AP19: 4W | AQ19: 1W | AR19: 2W | AS19: 3W | AT19: 4W | AU19: 1W | AV19: 2W | AW19: 3W | AX19: 4W | AY19: 5W | AZ19: 1W | BA19: 2W | BB19: 3W | BC19: 4W | BD19: 1W | BE19: 2W | BF19: 3W | BG19: 4W | BH19: 5W | BI19: 1W | BJ19: 2W | BK19: 3W | BL19: 4W | BM19: 1W | BN19: 2W | BO19: 3W | BP19: 4W | BQ19: 1W | BR19: 2W | BS19: 3W | BT19: 4W | BU19: 5W | BV19: 1W | BW19: 2W | BX19: 3W | BY19: 4W | BZ19: 1W | CA19: 2W | CB19: 3W | CC19: 4W | CD19: 5W | CE19: 1W | CF19: 2W | CG19: 3W | CH19: 4W | CI19: 1W | CJ19: 2W | CK19: 3W | CL19: 4W | CM19: 1W | CN19: 2W | CO19: 3W | CP19: 4W | CQ19: 1W | CR19: 2W | CS19: 3W | CT19: 4W | CU19: 4W | CV19: 1W | CW19: 2W | CX19: 3W | CY19: 4W | CZ19: 1W | DA19: 2W | DB19: 3W | DC19: 4W | DD19: 1W | DE19: 2W | DF19: 3W | DG19: 4W | DH19: 5W | DI19: 1W | DJ19: 2W | DK19: 3W | DL19: 4W | DM19: 1W | DN19: 2W | DO19: 3W | DP19: 4W | DQ19: 5W | DR19: 1W | DS19: 2W | DT19: 3W | DU19: 4W | DV19: 1W | DW19: 2W | DX19: 3W | DY19: 4W | DZ19: 1W | EA19: 2W | EB19: 3W | EC19: 4W | ED19: 1W | EE19: 2W | EF19: 3W | EG19: 4W | EH19: 1W | EI19: 2W | EJ19: 3W | EK19: 4W | EL19: 5W | EM19: 1W | EN19: 2W | EO19: 3W | EP19: 4W | EQ19: 1W | ER19: 2W | ES19: 3W | ET19: 4W
A20: CORALLA | B20: WIRE, ENGINE ROOM MAIN | C20: 1 | D20: 82111-F2132 | E20: AT10 | F20: A02 | G20: QTY | H20: 330 | I20: 0 | J20: 0 | K20: 220 | L20: 250 | M20: 220 | N20: 310 | O20: 230 | P20: 310 | Q20: 0 | R20: 0 | S20: 0 | T20: 70 | U20: 160 | V20: 270 | W20: 190 | X20: 210 | Y20: 100 | Z20: 280 | AA20: =SUBTOTAL(9,DM20:DQ20) -> 400 | AB20: =SUBTOTAL(9,DR20:DU20) -> 450 | AC20: =SUBTOTAL(9,DV20:DY20) -> 390 | AD20: =SUBTOTAL(9,DZ20:ED20) -> 250 | AE20: =SUBTOTAL(9,EE20:EH20) -> 0 | AF20: =SUBTOTAL(9,EI20:EL20) -> 0 | AG20: =SUBTOTAL(9,EM20:EP20) -> 0 | AH20: =SUBTOTAL(9,EQ20:ET20) -> 0 | AI20: 90 | AJ20: 80 | AK20: 80 | AL20: 80 | AM20: 0 | AN20: 0 | AO20: 0 | AP20: 0 | AQ20: 0 | AR20: 0 | AS20: 0 | AT20: 0 | AU20: 0 | AV20: 60 | AW20: 60 | AX20: 50 | AY20: 50 | AZ20: 70 | BA20: 60 | BB20: 60 | BC20: 60 | BD20: 60 | BE20: 60 | BF20: 0 | BG20: 50 | BH20: 50 | BI20: 80 | BJ20: 80 | BK20: 80 | BL20: 70 | BM20: 60 | BN20: 60 | BO20: 60 | BP20: 50 | BQ20: 70 | BR20: 60 | BS20: 60 | BT20: 60 | BU20: 60 | BV20: 70 | BW20: 70 | BX20: 60 | BY20: 60 | BZ20: 0 | CA20: 0 | CB20: 0 | CC20: 0 | CD20: 0 | CE20: 0 | CF20: 0 | CG20: 0 | CH20: 0 | CI20: 0 | CJ20: 30 | CK20: 20 | CL20: 20 | CM20: 0 | CN20: 0 | CO20: 80 | CP20: 80 | CQ20: 70 | CR20: 70 | CS20: 70 | CT20: 0 | CU20: 60 | CV20: 50 | CW20: 50 | CX20: 50 | CY20: 40 | CZ20: 60 | DA20: 50 | DB20: 50 | DC20: 50 | DD20: 30 | DE20: 30 | DF20: 0 | DG20: 20 | DH20: 20 | DI20: 70 | DJ20: 70 | DK20: 70 | DL20: 70 | DM20: 80 | DN20: 80 | DO20: 80 | DP20: 80 | DQ20: 80 | DR20: 120 | DS20: 110 | DT20: 110 | DU20: 110 | DV20: 100 | DW20: 100 | DX20: 100 | DY20: 90 | DZ20: 50 | EA20: 50 | EB20: 50 | EC20: 50 | ED20: 50
G21: CUM | H21: 3010 | I21: =H21+I20 -> 3010 | J21: =I21+J20 -> 3010 | K21: =J21+K20 -> 3230 | L21: =K21+L20 -> 3480 | M21: =L21+M20 -> 3700 | N21: =M21+N20 -> 4010 | O21: =N21+O20 -> 4240 | P21: =O21+P20 -> 4550 | Q21: 0 | R21: =Q21+R20 -> 0 | S21: =R21+S20 -> 0 | T21: =S21+T20 -> 70 | U21: =T21+U20 -> 230 | V21: =U21+V20 -> 500 | W21: =V21+W20 -> 690 | X21: =W21+X20 -> 900 | Y21: =X21+Y20 -> 1000 | ... AI21: =AH21+AI20 -> 2860 | AJ21: =AH21+AJ20 -> 2850 | AK21: =AJ21+AK20 -> 2930 | AL21: =AK21+AL20 -> 3010 | AM21: =AK21+AM20 -> 2930 | AN21: =AM21+AN20 -> 2930 | AO21: =AN21+AO20 -> 2930 | AP21: =AN21+AP20 -> 2930 | AQ21: =AP21+AQ20 -> 2930 | AR21: =AQ21+AR20 -> 2930 | AS21: =AQ21+AS20 -> 2930 | AT21: =AS21+AT20 -> 2930 | AU21: =AT21+AU20 -> 2930 | AV21: =AT21+AV20 -> 2990 | AW21: =AV21+AW20 -> 3050 | AX21: =AW21+AX20 -> 3100 | AY21: =AW21+AY20 -> 3100 | AZ21: =AY21+AZ20 -> 3170 | BA21: =AZ21+BA20 -> 3230 | BB21: =AZ21+BB20 -> 3230 | BC21: =BB21+BC20 -> 3290 | BD21: =BC21+BD20 -> 3350 | BE21: =BC21+BE20 -> 3350 | BF21: =BE21+BF20 -> 3350 | BG21: =BF21+BG20 -> 3400 | BH21: =BF21+BH20 -> 3400 | BI21: =BH21+BI20 -> 3480 | BJ21: =BI21+BJ20 -> 3560 | BK21: =BI21+BK20 -> 3560 | BL21: =BK21+BL20 -> 3630 | BM21: =BL21+BM20 -> 3690 | BN21: =BL21+BN20 -> 3690 | BO21: =BN21+BO20 -> 3750 | BP21: =BO21+BP20 -> 3800 | BQ21: =BO21+BQ20 -> 3820 | BR21: =BQ21+BR20 -> 3880 | BS21: =BR21+BS20 -> 3940 | BT21: =BR21+BT20 -> 3940 | BU21: =BT21+BU20 -> 4000 | BV21: =BU21+BV20 -> 4070 | BW21: =BU21+BW20 -> 4070 | BX21: =BW21+BX20 -> 4130 | BY21: =BX21+BY20 -> 4190 | BZ21: =BX21+BZ20 -> 4130 | CA21: =BZ21+CA20 -> 4130 | CB21: =CA21+CB20 -> 4130 | CC21: =CA21+CC20 -> 4130 | CD21: =CC21+CD20 -> 4130 | CE21: =CD21+CE20 -> 4130 | CF21: =CD21+CF20 -> 4130 | CG21: =CF21+CG20 -> 4130 | CH21: =CG21+CH20 -> 4130 | CI21: =CG21+CI20 -> 4130 | CJ21: =CI21+CJ20 -> 4160 | CK21: =CJ21+CK20 -> 4180 | CL21: =CJ21+CL20 -> 4180 | CM21: =CL21+CM20 -> 4180 | CN21: =CM21+CN20 -> 4180 | CO21: =CM21+CO20 -> 4260 | CP21: =CO21+CP20 -> 4340 | CQ21: =CP21+CQ20 -> 4410 | CR21: =CP21+CR20 -> 4410 | CS21: =CR21+CS20 -> 4480 | CT21: =CS21+CT20 -> 4480 | CU21: =CS21+CU20 -> 4540 | CV21: =CU21+CV20 -> 4590 | CW21: =CV21+CW20 -> 4640 | CX21: =CV21+CX20 -> 4640 | CY21: =CX21+CY20 -> 4680 | CZ21: =CY21+CZ20 -> 4740 | DA21: =CY21+DA20 -> 4730 | DB21: =DA21+DB20 -> 4780 | DC21: =DB21+DC20 -> 4830 | DD21: =DB21+DD20 -> 4810 | DE21: =DD21+DE20 -> 4840 | DF21: =DE21+DF20 -> 4840 | DG21: =DE21+DG20 -> 4860 | DH21: =DG21+DH20 -> 4880 | DI21: =DH21+DI20 -> 4950 | DJ21: =DH21+DJ20 -> 4950 | DK21: =DJ21+DK20 -> 5020 | DL21: =DK21+DL20 -> 5090 | DM21: =DK21+DM20 -> 5100 | DN21: =DM21+DN20 -> 5180 | DO21: =DN21+DO20 -> 5260 | DP21: =DN21+DP20 -> 5260 | DQ21: =DP21+DQ20 -> 5340 | DR21: =DQ21+DR20 -> 5460 | DS21: =DQ21+DS20 -> 5450 | DT21: =DS21+DT20 -> 5560 | DU21: =DT21+DU20 -> 5670 | DV21: =DU21+DV20 -> 5770 | DW21: =DV21+DW20 -> 5870 | DX21: =DW21+DX20 -> 5970 | DY21: =DX21+DY20 -> 6060 | DZ21: =DY21+DZ20 -> 6110 | EA21: =DZ21+EA20 -> 6160 | ... ET21: =ES21+ET20 -> 6310
C22: 2 | D22: 82111-F2152 | E22: AT10 | F22: A02 | G22: QTY | H22: 10 | I22: 0 | J22: 10 | K22: 0 | L22: 0 | M22: 0 | N22: 0 | O22: 0 | P22: 10 | Q22: 0 | R22: 0 | S22: 0 | T22: 5 | U22: 0 | V22: 0 | W22: 6 | X22: 0 | Y22: 6 | Z22: 0 | AA22: =SUBTOTAL(9,DM22:DQ22) -> 0 | AB22: =SUBTOTAL(9,DR22:DU22) -> 0 | AC22: =SUBTOTAL(9,DV22:DY22) -> 6 | AD22: =SUBTOTAL(9,DZ22:ED22) -> 0 | AE22: =SUBTOTAL(9,EE22:EH22) -> 0 | AF22: =SUBTOTAL(9,EI22:EL22) -> 0 | AG22: =SUBTOTAL(9,EM22:EP22) -> 0 | AH22: =SUBTOTAL(9,EQ22:ET22) -> 0 | AI22: 10 | AJ22: 0 | AK22: 0 | AL22: 0 | AM22: 0 | AN22: 0 | AO22: 0 | AP22: 0 | AQ22: 10 | AR22: 0 | AS22: 0 | AT22: 0 | AU22: 0 | AV22: 0 | AW22: 0 | AX22: 0 | AY22: 0 | AZ22: 0 | BA22: 0 | BB22: 0 | BC22: 0 | BD22: 0 | BE22: 0 | BF22: 0 | BG22: 0 | BH22: 0 | BI22: 0 | BJ22: 0 | BK22: 0 | BL22: 0 | BM22: 0 | BN22: 0 | BO22: 0 | BP22: 0 | BQ22: 10 | BR22: 0 | BS22: 0 | BT22: 0 | BU22: 0 | BV22: 10 | BW22: 10 | BX22: 0 | BY22: 0 | BZ22: 0 | CA22: 0 | CB22: 0 | CC22: 0 | CD22: 0 | CE22: 0 | CF22: 0 | CG22: 0 | CH22: 0 | CI22: 0 | CJ22: 5 | CK22: 0 | CL22: 0 | CM22: 0 | CN22: 0 | CO22: 0 | CP22: 0 | CQ22: 0 | CR22: 0 | CS22: 0 | CT22: 0 | CU22: 0 | CV22: 6 | CW22: 0 | CX22: 0 | CY22: 0 | CZ22: 0 | DA22: 0 | DB22: 0 | DC22: 0 | DD22: 6 | DE22: 0 | DF22: 0 | DG22: 0 | DH22: 0 | DI22: 0 | DJ22: 0 | DK22: 0 | DL22: 0 | DR22: 0 | DS22: 0 | DT22: 0 | DU22: 0 | DV22: 6 | DW22: 0 | DX22: 0 | DY22: 0 | DZ22: 0 | EA22: 0 | EB22: 0 | EC22: 0 | ED22: 0
G23: CUM | H23: 60 | I23: =H23+I22 -> 60 | J23: =I23+J22 -> 70 | K23: =J23+K22 -> 70 | L23: =K23+L22 -> 70 | M23: =L23+M22 -> 70 | N23: =M23+N22 -> 70 | O23: =N23+O22 -> 70 | P23: =O23+P22 -> 80 | Q23: 0 | R23: =Q23+R22 -> 0 | S23: =R23+S22 -> 0 | T23: =S23+T22 -> 5 | U23: =T23+U22 -> 5 | V23: =U23+V22 -> 5 | W23: =V23+W22 -> 11 | X23: =W23+X22 -> 11 | Y23: =X23+Y22 -> 17 | ... AH23: =AG23+AH22 -> 23 | AI23: 60 | AJ23: =AI23+AJ22 -> 60 | AK23: =AJ23+AK22 -> 60 | AL23: =AK23+AL22 -> 60 | AM23: =AL23+AM22 -> 60 | AN23: =AM23+AN22 -> 60 | AO23: =AN23+AO22 -> 60 | AP23: =AO23+AP22 -> 60 | AQ23: =AP23+AQ22 -> 70 | ... CD23: =CC23+CD22 -> 100 | CE23: 0 | CF23: =CE23+CF22 -> 0 | CG23: =CF23+CG22 -> 0 | CH23: =CG23+CH22 -> 0 | CI23: =CH23+CI22 -> 0 | CJ23: =CI23+CJ22 -> 5 | CK23: =CJ23+CK22 -> 5 | CL23: =CK23+CL22 -> 5 | CM23: =CL23+CM22 -> 5 | ... ET23: =ES23+ET22 -> 23
C24: 3 | D24: 82111-F2W23 | E24: AT10 | F24: B02 | G24: QTY | H24: 0 | I24: 0 | J24: 0 | K24: 0 | L24: 0 | M24: 0 | N24: 0 | O24: 0 | P24: 0 | Q24: 0 | R24: 0 | S24: 0 | T24: 210 | U24: 940 | V24: 1010 | W24: 660 | X24: 910 | Y24: 240 | Z24: 780 | AA24: =SUBTOTAL(9,DM24:DQ24) -> 740 | AB24: =SUBTOTAL(9,DR24:DU24) -> 910 | AC24: =SUBTOTAL(9,DV24:DY24) -> 850 | AD24: =SUBTOTAL(9,DZ24:ED24) -> 350 | AE24: =SUBTOTAL(9,EE24:EH24) -> 0 | AF24: =SUBTOTAL(9,EI24:EL24) -> 0 | AG24: =SUBTOTAL(9,EM24:EP24) -> 0 | AH24: =SUBTOTAL(9,EQ24:ET24) -> 0 | AI24: 0 | AJ24: 0 | AK24: 0 | AL24: 0 | AM24: 0 | AN24: 0 | AO24: 0 | AP24: 0 | AQ24: 0 | AR24: 0 | AS24: 0 | AT24: 0 | AU24: 0 | AV24: 0 | AW24: 0 | AX24: 0 | AY24: 0 | AZ24: 0 | BA24: 0 | BB24: 0 | BC24: 0 | BD24: 0 | BE24: 0 | BF24: 0 | BG24: 0 | BH24: 0 | BI24: 0 | BJ24: 0 | BK24: 0 | BL24: 0 | BM24: 0 | BN24: 0 | BO24: 0 | BP24: 0 | BQ24: 0 | BR24: 0 | BS24: 0 | BT24: 0 | BU24: 0 | BV24: 0 | BW24: 0 | BX24: 0 | BY24: 0 | BZ24: 0 | CA24: 0 | CB24: 0 | CC24: 0 | CD24: 0 | CE24: 0 | CF24: 0 | CG24: 0 | CH24: 0 | CI24: 0 | CJ24: 70 | CK24: 70 | CL24: 70 | CM24: 240 | CN24: 240 | CO24: 230 | CP24: 230 | CQ24: 250 | CR24: 260 | CS24: 250 | CT24: 0 | CU24: 250 | CV24: 160 | CW24: 160 | CX24: 170 | CY24: 170 | CZ24: 230 | DA24: 230 | DB24: 230 | DC24: 220 | DD24: 60 | DE24: 60 | DF24: 0 | DG24: 60 | DH24: 60 | DI24: 200 | DJ24: 200 | DK24: 190 | DL24: 190 | DM24: 150 | DN24: 150 | DO24: 150 | DP24: 150 | DQ24: 140 | DR24: 230 | DS24: 230 | DT24: 230 | DU24: 220 | DV24: 220 | DW24: 210 | DX24: 210 | DY24: 210 | DZ24: 70 | EA24: 70 | EB24: 70 | EC24: 70 | ED24: 70
G25: CUM | H25: 0 | I25: =H25+I24 -> 0 | J25: =I25+J24 -> 0 | K25: =J25+K24 -> 0 | L25: =K25+L24 -> 0 | M25: =L25+M24 -> 0 | N25: =M25+N24 -> 0 | O25: =N25+O24 -> 0 | P25: =O25+P24 -> 0 | ... AH25: =AG25+AH24 -> 7600 | AI25: 0 | AJ25: =AI25+AJ24 -> 0 | AK25: =AJ25+AK24 -> 0 | AL25: =AK25+AL24 -> 0 | AM25: =AL25+AM24 -> 0 | AN25: =AM25+AN24 -> 0 | AO25: =AN25+AO24 -> 0 | AP25: =AO25+AP24 -> 0 | AQ25: =AP25+AQ24 -> 0 | ... ET25: =ES25+ET24 -> 7600
C26: 4 | D26: 82111-F2W34 | E26: AT10 | F26: B02 | G26: QTY | H26: 0 | I26: 0 | J26: 0 | K26: 0 | L26: 0 | M26: 0 | N26: 0 | O26: 0 | P26: 0 | Q26: 0 | R26: 0 | S26: 0 | T26: 200 | U26: 1060 | V26: 660 | W26: 600 | X26: 840 | Y26: 890 | Z26: 610 | AA26: =SUBTOTAL(9,DM26:DQ26) -> 340 | AB26: =SUBTOTAL(9,DR26:DU26) -> 340 | AC26: =SUBTOTAL(9,DV26:DY26) -> 500 | AD26: =SUBTOTAL(9,DZ26:ED26) -> 310 | AE26: =SUBTOTAL(9,EE26:EH26) -> 0 | AF26: =SUBTOTAL(9,EI26:EL26) -> 0 | AG26: =SUBTOTAL(9,EM26:EP26) -> 0 | AH26: =SUBTOTAL(9,EQ26:ET26) -> 0 | AI26: 0 | AJ26: 0 | AK26: 0 | AL26: 0 | AM26: 0 | AN26: 0 | AO26: 0 | AP26: 0 | AQ26: 0 | AR26: 0 | AS26: 0 | AT26: 0 | AU26: 0 | AV26: 0 | AW26: 0 | AX26: 0 | AY26: 0 | AZ26: 0 | BA26: 0 | BB26: 0 | BC26: 0 | BD26: 0 | BE26: 0 | BF26: 0 | BG26: 0 | BH26: 0 | BI26: 0 | BJ26: 0 | BK26: 0 | BL26: 0 | BM26: 0 | BN26: 0 | BO26: 0 | BP26: 0 | BQ26: 0 | BR26: 0 | BS26: 0 | BT26: 0 | BU26: 0 | BV26: 0 | BW26: 0 | BX26: 0 | BY26: 0 | BZ26: 0 | CA26: 0 | CB26: 0 | CC26: 0 | CD26: 0 | CE26: 0 | CF26: 0 | CG26: 0 | CH26: 0 | CI26: 0 | CJ26: 70 | CK26: 70 | CL26: 60 | CM26: 270 | CN26: 270 | CO26: 260 | CP26: 260 | CQ26: 170 | CR26: 170 | CS26: 160 | CT26: 0 | CU26: 160 | CV26: 150 | CW26: 150 | CX26: 150 | CY26: 150 | CZ26: 210 | DA26: 210 | DB26: 210 | DC26: 210 | DD26: 230 | DE26: 220 | DF26: 0 | DG26: 220 | DH26: 220 | DI26: 150 | DJ26: 150 | DK26: 150 | DL26: 160 | DM26: 70 | DN26: 70 | DO26: 70 | DP26: 70 | DQ26: 60 | DR26: 90 | DS26: 90 | DT26: 80 | DU26: 80 | DV26: 125 | DW26: 125 | DX26: 125 | DY26: 125 | DZ26: 70 | EA26: 60 | EB26: 60 | EC26: 60 | ED26: 60
G27: CUM | H27: 0 | I27: =H27+I26 -> 0 | J27: =I27+J26 -> 0 | K27: =J27+K26 -> 0 | L27: =K27+L26 -> 0 | M27: =L27+M26 -> 0 | N27: =M27+N26 -> 0 | O27: =N27+O26 -> 0 | P27: =O27+P26 -> 0 | ... AH27: =AG27+AH26 -> 6350 | AI27: 0 | AJ27: =AI27+AJ26 -> 0 | AK27: =AJ27+AK26 -> 0 | AL27: =AK27+AL26 -> 0 | AM27: =AL27+AM26 -> 0 | AN27: =AM27+AN26 -> 0 | AO27: =AN27+AO26 -> 0 | AP27: =AO27+AP26 -> 0 | AQ27: =AP27+AQ26 -> 0 | ... ET27: =ES27+ET26 -> 6350
C28: 5 | D28: 82111-F2W42 | E28: AT10 | F28: C01 | G28: QTY | H28: 0 | I28: 0 | J28: 0 | K28: 0 | L28: 0 | M28: 0 | N28: 0 | O28: 0 | P28: 0 | Q28: 0 | R28: 0 | S28: 0 | T28: 10 | U28: 0 | V28: 0 | W28: 0 | X28: 0 | Y28: 0 | Z28: 0 | AA28: =SUBTOTAL(9,DM28:DQ28) -> 0 | AB28: =SUBTOTAL(9,DR28:DU28) -> 10 | AC28: =SUBTOTAL(9,DV28:DY28) -> 10 | AD28: =SUBTOTAL(9,DZ28:ED28) -> 10 | AE28: =SUBTOTAL(9,EE28:EH28) -> 0 | AF28: =SUBTOTAL(9,EI28:EL28) -> 0 | AG28: =SUBTOTAL(9,EM28:EP28) -> 0 | AH28: =SUBTOTAL(9,EQ28:ET28) -> 0 | AI28: 0 | AJ28: 0 | AK28: 0 | AL28: 0 | AM28: 0 | AN28: 0 | AO28: 0 | AP28: 0 | AQ28: 0 | AR28: 0 | AS28: 0 | AT28: 0 | AU28: 0 | AV28: 0 | AW28: 0 | AX28: 0 | AY28: 0 | AZ28: 0 | BA28: 0 | BB28: 0 | BC28: 0 | BD28: 0 | BE28: 0 | BF28: 0 | BG28: 0 | BH28: 0 | BI28: 0 | BJ28: 0 | BK28: 0 | BL28: 0 | BM28: 0 | BN28: 0 | BO28: 0 | BP28: 0 | BQ28: 0 | BR28: 0 | BS28: 0 | BT28: 0 | BU28: 0 | BV28: 0 | BW28: 0 | BX28: 0 | BY28: 0 | BZ28: 0 | CA28: 0 | CB28: 0 | CC28: 0 | CD28: 0 | CE28: 0 | CF28: 0 | CG28: 0 | CH28: 0 | CI28: 0 | CJ28: 10 | CK28: 0 | CL28: 0 | CM28: 0 | CN28: 0 | CO28: 0 | CP28: 0 | CQ28: 0 | CR28: 0 | CS28: 0 | CT28: 0 | CU28: 0 | CV28: 0 | CW28: 0 | CX28: 0 | CY28: 0 | CZ28: 0 | DA28: 0 | DB28: 0 | DC28: 0 | DD28: 0 | DE28: 0 | DF28: 0 | DG28: 0 | DH28: 0 | DI28: 0 | DJ28: 0 | DK28: 0 | DL28: 0 | DM28: 0 | DN28: 0 | DO28: 0 | DP28: 0 | DQ28: 0 | DR28: 10 | DS28: 0 | DT28: 0 | DU28: 0 | DV28: 10 | DW28: 0 | DX28: 0 | DY28: 0 | DZ28: 10 | EA28: 0 | EB28: 0 | EC28: 0 | ED28: 0
G29: CUM | H29: 0 | I29: =H29+I28 -> 0 | J29: =I29+J28 -> 0 | K29: =J29+K28 -> 0 | L29: =K29+L28 -> 0 | M29: =L29+M28 -> 0 | N29: =M29+N28 -> 0 | O29: =N29+O28 -> 0 | P29: =O29+P28 -> 0 | ... AH29: =AG29+AH28 -> 40 | AI29: 0 | AJ29: =AI29+AJ28 -> 0 | AK29: =AJ29+AK28 -> 0 | AL29: =AK29+AL28 -> 0 | AM29: =AL29+AM28 -> 0 | AN29: =AM29+AN28 -> 0 | AO29: =AN29+AO28 -> 0 | AP29: =AO29+AP28 -> 0 | AQ29: =AP29+AQ28 -> 0 | ... ET29: =ES29+ET28 -> 40
C30: 6 | D30: 82111-F2W63 | E30: AT10 | F30: B02 | G30: QTY | H30: 0 | I30: 0 | J30: 0 | K30: 0 | L30: 0 | M30: 0 | N30: 0 | O30: 0 | P30: 0 | Q30: 0 | R30: 0 | S30: 0 | T30: 20 | U30: 80 | V30: 70 | W30: 70 | X30: 60 | Y30: 20 | Z30: 80 | AA30: =SUBTOTAL(9,DM30:DQ30) -> 50 | AB30: =SUBTOTAL(9,DR30:DU30) -> 60 | AC30: =SUBTOTAL(9,DV30:DY30) -> 60 | AD30: =SUBTOTAL(9,DZ30:ED30) -> 30 | AE30: =SUBTOTAL(9,EE30:EH30) -> 0 | AF30: =SUBTOTAL(9,EI30:EL30) -> 0 | AG30: =SUBTOTAL(9,EM30:EP30) -> 0 | AH30: =SUBTOTAL(9,EQ30:ET30) -> 0 | AI30: 0 | AJ30: 0 | AK30: 0 | AL30: 0 | AM30: 0 | AN30: 0 | AO30: 0 | AP30: 0 | AQ30: 0 | AR30: 0 | AS30: 0 | AT30: 0 | AU30: 0 | AV30: 0 | AW30: 0 | AX30: 0 | AY30: 0 | AZ30: 0 | BA30: 0 | BB30: 0 | BC30: 0 | BD30: 0 | BE30: 0 | BF30: 0 | BG30: 0 | BH30: 0 | BI30: 0 | BJ30: 0 | BK30: 0 | BL30: 0 | BM30: 0 | BN30: 0 | BO30: 0 | BP30: 0 | BQ30: 0 | BR30: 0 | BS30: 0 | BT30: 0 | BU30: 0 | BV30: 0 | BW30: 0 | BX30: 0 | BY30: 0 | BZ30: 0 | CA30: 0 | CB30: 0 | CC30: 0 | CD30: 0 | CE30: 0 | CF30: 0 | CG30: 0 | CH30: 0 | CI30: 0 | CJ30: 20 | CK30: 0 | CL30: 0 | CM30: 20 | CN30: 20 | CO30: 20 | CP30: 20 | CQ30: 20 | CR30: 10 | CS30: 20 | CT30: 0 | CU30: 20 | CV30: 20 | CW30: 10 | CX30: 20 | CY30: 20 | CZ30: 20 | DA30: 20 | DB30: 10 | DC30: 10 | DD30: 0 | DE30: 10 | DF30: 0 | DG30: 10 | DH30: 0 | DI30: 20 | DJ30: 20 | DK30: 20 | DL30: 20 | DM30: 10 | DN30: 10 | DO30: 10 | DP30: 10 | DQ30: 10 | DR30: 20 | DS30: 20 | DT30: 20 | DU30: 0 | DV30: 20 | DW30: 20 | DX30: 20 | DY30: 0 | DZ30: 20 | EA30: 10 | EB30: 0 | EC30: 0 | ED30: 0
G31: CUM | H31: 0 | I31: =H31+I30 -> 0 | J31: =I31+J30 -> 0 | K31: =J31+K30 -> 0 | L31: =K31+L30 -> 0 | M31: =L31+M30 -> 0 | N31: =M31+N30 -> 0 | O31: =N31+O30 -> 0 | P31: =O31+P30 -> 0 | ... AH31: =AG31+AH30 -> 600 | AI31: 0 | AJ31: =AI31+AJ30 -> 0 | AK31: =AJ31+AK30 -> 0 | AL31: =AK31+AL30 -> 0 | AM31: =AL31+AM30 -> 0 | AN31: =AM31+AN30 -> 0 | AO31: =AN31+AO30 -> 0 | AP31: =AO31+AP30 -> 0 | AQ31: =AP31+AQ30 -> 0 | ... ET31: =ES31+ET30 -> 600
C32: 7 | D32: 82111-F2W83 | E32: AT10 | F32: B02 | G32: QTY | H32: 0 | I32: 0 | J32: 0 | K32: 0 | L32: 0 | M32: 0 | N32: 0 | O32: 0 | P32: 0 | Q32: 0 | R32: 0 | S32: 0 | T32: 40 | U32: 110 | V32: 70 | W32: 40 | X32: 70 | Y32: 70 | Z32: 40 | AA32: =SUBTOTAL(9,DM32:DQ32) -> 60 | AB32: =SUBTOTAL(9,DR32:DU32) -> 40 | AC32: =SUBTOTAL(9,DV32:DY32) -> 110 | AD32: =SUBTOTAL(9,DZ32:ED32) -> 50 | AE32: =SUBTOTAL(9,EE32:EH32) -> 0 | AF32: =SUBTOTAL(9,EI32:EL32) -> 0 | AG32: =SUBTOTAL(9,EM32:EP32) -> 0 | AH32: =SUBTOTAL(9,EQ32:ET32) -> 0 | AI32: 0 | AJ32: 0 | AK32: 0 | AL32: 0 | AM32: 0 | AN32: 0 | AO32: 0 | AP32: 0 | AQ32: 0 | AR32: 0 | AS32: 0 | AT32: 0 | AU32: 0 | AV32: 0 | AW32: 0 | AX32: 0 | AY32: 0 | AZ32: 0 | BA32: 0 | BB32: 0 | BC32: 0 | BD32: 0 | BE32: 0 | BF32: 0 | BG32: 0 | BH32: 0 | BI32: 0 | BJ32: 0 | BK32: 0 | BL32: 0 | BM32: 0 | BN32: 0 | BO32: 0 | BP32: 0 | BQ32: 0 | BR32: 0 | BS32: 0 | BT32: 0 | BU32: 0 | BV32: 0 | BW32: 0 | BX32: 0 | BY32: 0 | BZ32: 0 | CA32: 0 | CB32: 0 | CC32: 0 | CD32: 0 | CE32: 0 | CF32: 0 | CG32: 0 | CH32: 0 | CI32: 0 | CJ32: 40 | CK32: 0 | CL32: 0 | CM32: 30 | CN32: 30 | CO32: 30 | CP32: 20 | CQ32: 20 | CR32: 20 | CS32: 20 | CT32: 0 | CU32: 10 | CV32: 10 | CW32: 10 | CX32: 10 | CY32: 10 | CZ32: 20 | DA32: 20 | DB32: 20 | DC32: 10 | DD32: 10 | DE32: 20 | DF32: 0 | DG32: 20 | DH32: 20 | DI32: 10 | DJ32: 10 | DK32: 10 | DL32: 10 | DM32: 20 | DN32: 10 | DO32: 10 | DP32: 10 | DQ32: 10 | DR32: 20 | DS32: 20 | DT32: 0 | DU32: 0 | DV32: 50 | DW32: 30 | DX32: 30 | DY32: 0 | DZ32: 20 | EA32: 20 | EB32: 10 | EC32: 0 | ED32: 0
G33: CUM | H33: 0 | I33: =H33+I32 -> 0 | J33: =I33+J32 -> 0 | K33: =J33+K32 -> 0 | L33: =K33+L32 -> 0 | M33: =L33+M32 -> 0 | N33: =M33+N32 -> 0 | O33: =N33+O32 -> 0 | P33: =O33+P32 -> 0 | ... AH33: =AG33+AH32 -> 700 | AI33: 0 | AJ33: =AI33+AJ32 -> 0 | AK33: =AJ33+AK32 -> 0 | AL33: =AK33+AL32 -> 0 | AM33: =AL33+AM32 -> 0 | AN33: =AM33+AN32 -> 0 | AO33: =AN33+AO32 -> 0 | AP33: =AO33+AP32 -> 0 | AQ33: =AP33+AQ32 -> 0 | ... ET33: =ES33+ET32 -> 700
C34: 8 | D34: 82111-F2W92 | E34: AT10 | F34: C01 | G34: QTY | H34: 0 | I34: 0 | J34: 0 | K34: 0 | L34: 0 | M34: 0 | N34: 0 | O34: 0 | P34: 0 | Q34: 0 | R34: 0 | S34: 0 | T34: 90 | U34: 500 | V34: 610 | W34: 540 | X34: 760 | Y34: 530 | Z34: 830 | AA34: =SUBTOTAL(9,DM34:DQ34) -> 770 | AB34: =SUBTOTAL(9,DR34:DU34) -> 780 | AC34: =SUBTOTAL(9,DV34:DY34) -> 680 | AD34: =SUBTOTAL(9,DZ34:ED34) -> 640 | AE34: =SUBTOTAL(9,EE34:EH34) -> 0 | AF34: =SUBTOTAL(9,EI34:EL34) -> 0 | AG34: =SUBTOTAL(9,EM34:EP34) -> 0 | AH34: =SUBTOTAL(9,EQ34:ET34) -> 0 | AI34: 0 | AJ34: 0 | AK34: 0 | AL34: 0 | AM34: 0 | AN34: 0 | AO34: 0 | AP34: 0 | AQ34: 0 | AR34: 0 | AS34: 0 | AT34: 0 | AU34: 0 | AV34: 0 | AW34: 0 | AX34: 0 | AY34: 0 | AZ34: 0 | BA34: 0 | BB34: 0 | BC34: 0 | BD34: 0 | BE34: 0 | BF34: 0 | BG34: 0 | BH34: 0 | BI34: 0 | BJ34: 0 | BK34: 0 | BL34: 0 | BM34: 0 | BN34: 0 | BO34: 0 | BP34: 0 | BQ34: 0 | BR34: 0 | BS34: 0 | BT34: 0 | BU34: 0 | BV34: 0 | BW34: 0 | BX34: 0 | BY34: 0 | BZ34: 0 | CA34: 0 | CB34: 0 | CC34: 0 | CD34: 0 | CE34: 0 | CF34: 0 | CG34: 0 | CH34: 0 | CI34: 0 | CJ34: 30 | CK34: 30 | CL34: 30 | CM34: 120 | CN34: 120 | CO34: 130 | CP34: 130 | CQ34: 150 | CR34: 150 | CS34: 150 | CT34: 0 | CU34: 160 | CV34: 140 | CW34: 130 | CX34: 130 | CY34: 140 | CZ34: 190 | DA34: 190 | DB34: 190 | DC34: 190 | DD34: 130 | DE34: 130 | DF34: 0 | DG34: 140 | DH34: 130 | DI34: 210 | DJ34: 210 | DK34: 210 | DL34: 200 | DM34: 160 | DN34: 160 | DO34: 150 | DP34: 150 | DQ34: 150 | DR34: 200 | DS34: 200 | DT34: 190 | DU34: 190 | DV34: 180 | DW34: 180 | DX34: 180 | DY34: 140 | DZ34: 150 | EA34: 150 | EB34: 150 | EC34: 95 | ED34: 95
G35: CUM | H35: 0 | I35: =H35+I34 -> 0 | J35: =I35+J34 -> 0 | K35: =J35+K34 -> 0 | L35: =K35+L34 -> 0 | M35: =L35+M34 -> 0 | N35: =M35+N34 -> 0 | O35: =N35+O34 -> 0 | P35: =O35+P34 -> 0 | ... AH35: =AG35+AH34 -> 6730 | AI35: 0 | AJ35: =AI35+AJ34 -> 0 | AK35: =AJ35+AK34 -> 0 | AL35: =AK35+AL34 -> 0 | AM35: =AL35+AM34 -> 0 | AN35: =AM35+AN34 -> 0 | AO35: =AN35+AO34 -> 0 | AP35: =AO35+AP34 -> 0 | AQ35: =AP35+AQ34 -> 0 | ... ET35: =ES35+ET34 -> 6730
C36: 9 | D36: 82111-F2X02 | E36: AT10 | F36: A02 | G36: QTY | H36: 0 | I36: 0 | J36: 0 | K36: 0 | L36: 0 | M36: 0 | N36: 0 | O36: 0 | P36: 0 | Q36: 0 | R36: 0 | S36: 0 | T36: 20 | U36: 50 | V36: 80 | W36: 80 | X36: 90 | Y36: 100 | Z36: 120 | AA36: =SUBTOTAL(9,DM36:DQ36) -> 110 | AB36: =SUBTOTAL(9,DR36:DU36) -> 200 | AC36: =SUBTOTAL(9,DV36:DY36) -> 440 | AD36: =SUBTOTAL(9,DZ36:ED36) -> 200 | AE36: =SUBTOTAL(9,EE36:EH36) -> 0 | AF36: =SUBTOTAL(9,EI36:EL36) -> 0 | AG36: =SUBTOTAL(9,EM36:EP36) -> 0 | AH36: =SUBTOTAL(9,EQ36:ET36) -> 0 | AI36: 0 | AJ36: 0 | AK36: 0 | AL36: 0 | AM36: 0 | AN36: 0 | AO36: 0 | AP36: 0 | AQ36: 0 | AR36: 0 | AS36: 0 | AT36: 0 | AU36: 0 | AV36: 0 | AW36: 0 | AX36: 0 | AY36: 0 | AZ36: 0 | BA36: 0 | BB36: 0 | BC36: 0 | BD36: 0 | BE36: 0 | BF36: 0 | BG36: 0 | BH36: 0 | BI36: 0 | BJ36: 0 | BK36: 0 | BL36: 0 | BM36: 0 | BN36: 0 | BO36: 0 | BP36: 0 | BQ36: 0 | BR36: 0 | BS36: 0 | BT36: 0 | BU36: 0 | BV36: 0 | BW36: 0 | BX36: 0 | BY36: 0 | BZ36: 0 | CA36: 0 | CB36: 0 | CC36: 0 | CD36: 0 | CE36: 0 | CF36: 0 | CG36: 0 | CH36: 0 | CI36: 0 | CJ36: 20 | CK36: 0 | CL36: 0 | CM36: 20 | CN36: 10 | CO36: 10 | CP36: 10 | CQ36: 20 | CR36: 20 | CS36: 20 | CT36: 0 | CU36: 20 | CV36: 20 | CW36: 20 | CX36: 20 | CY36: 20 | CZ36: 30 | DA36: 20 | DB36: 20 | DC36: 20 | DD36: 30 | DE36: 30 | DF36: 0 | DG36: 20 | DH36: 20 | DI36: 30 | DJ36: 30 | DK36: 30 | DL36: 30 | DM36: 30 | DN36: 20 | DO36: 20 | DP36: 20 | DQ36: 20 | DR36: 50 | DS36: 50 | DT36: 50 | DU36: 50 | DV36: 110 | DW36: 110 | DX36: 110 | DY36: 110 | DZ36: 40 | EA36: 40 | EB36: 40 | EC36: 40 | ED36: 40
G37: CUM | H37: 0 | I37: =H37+I36 -> 0 | J37: =I37+J36 -> 0 | K37: =J37+K36 -> 0 | L37: =K37+L36 -> 0 | M37: =L37+M36 -> 0 | N37: =M37+N36 -> 0 | O37: =N37+O36 -> 0 | P37: =O37+P36 -> 0 | ... AH37: =AG37+AH36 -> 1490 | AI37: 0 | AJ37: =AI37+AJ36 -> 0 | AK37: =AJ37+AK36 -> 0 | AL37: =AK37+AL36 -> 0 | AM37: =AL37+AM36 -> 0 | AN37: =AM37+AN36 -> 0 | AO37: =AN37+AO36 -> 0 | AP37: =AO37+AP36 -> 0 | AQ37: =AP37+AQ36 -> 0 | ... ET37: =ES37+ET36 -> 1490
C38: 10 | D38: 82111-F2C11 | E38: AT10 | F38: A02 | G38: QTY | H38: 0 | I38: 0 | J38: 0 | K38: 0 | L38: 0 | M38: 0 | N38: 0 | O38: 0 | P38: 0 | Q38: 0 | R38: 0 | S38: 0 | T38: 20 | U38: 70 | V38: 90 | W38: 40 | X38: 40 | Y38: 20 | Z38: 80 | AA38: =SUBTOTAL(9,DM38:DQ38) -> 80 | AB38: =SUBTOTAL(9,DR38:DU38) -> 90 | AC38: =SUBTOTAL(9,DV38:DY38) -> 80 | AD38: =SUBTOTAL(9,DZ38:ED38) -> 40 | AE38: =SUBTOTAL(9,EE38:EH38) -> 0 | AF38: =SUBTOTAL(9,EI38:EL38) -> 0 | AG38: =SUBTOTAL(9,EM38:EP38) -> 0 | AH38: =SUBTOTAL(9,EQ38:ET38) -> 0 | AI38: 0 | AJ38: 0 | AK38: 0 | AL38: 0 | AM38: 0 | AN38: 0 | AO38: 0 | AP38: 0 | AQ38: 0 | AR38: 0 | AS38: 0 | AT38: 0 | AU38: 0 | AV38: 0 | AW38: 0 | AX38: 0 | AY38: 0 | AZ38: 0 | BA38: 0 | BB38: 0 | BC38: 0 | BD38: 0 | BE38: 0 | BF38: 0 | BG38: 0 | BH38: 0 | BI38: 0 | BJ38: 0 | BK38: 0 | BL38: 0 | BM38: 0 | BN38: 0 | BO38: 0 | BP38: 0 | BQ38: 0 | BR38: 0 | BS38: 0 | BT38: 0 | BU38: 0 | BV38: 0 | BW38: 0 | BX38: 0 | BY38: 0 | BZ38: 0 | CA38: 0 | CB38: 0 | CC38: 0 | CD38: 0 | CE38: 0 | CF38: 0 | CG38: 0 | CH38: 0 | CI38: 0 | CJ38: 10 | CK38: 10 | CL38: 0 | CM38: 20 | CN38: 20 | CO38: 20 | CP38: 10 | CQ38: 20 | CR38: 20 | CS38: 20 | CT38: 0 | CU38: 30 | CV38: 10 | CW38: 10 | CX38: 10 | CY38: 10 | CZ38: 10 | DA38: 10 | DB38: 10 | DC38: 10 | DD38: 10 | DE38: 0 | DF38: 0 | DG38: 10 | DH38: 0 | DI38: 20 | DJ38: 20 | DK38: 20 | DL38: 20 | DM38: 20 | DN38: 20 | DO38: 20 | DP38: 10 | DQ38: 10 | DR38: 30 | DS38: 20 | DT38: 20 | DU38: 20 | DV38: 20 | DW38: 20 | DX38: 20 | DY38: 20 | DZ38: 20 | EA38: 20 | EB38: 0 | EC38: 0 | ED38: 0
G39: CUM | H39: 0 | I39: =H39+I38 -> 0 | J39: =I39+J38 -> 0 | K39: =J39+K38 -> 0 | L39: =K39+L38 -> 0 | M39: =L39+M38 -> 0 | N39: =M39+N38 -> 0 | O39: =N39+O38 -> 0 | P39: =O39+P38 -> 0 | ... AH39: =AG39+AH38 -> 650 | AI39: 0 | AJ39: =AI39+AJ38 -> 0 | AK39: =AJ39+AK38 -> 0 | AL39: =AK39+AL38 -> 0 | AM39: =AL39+AM38 -> 0 | AN39: =AM39+AN38 -> 0 | AO39: =AN39+AO38 -> 0 | AP39: =AO39+AP38 -> 0 | AQ39: =AP39+AQ38 -> 0 | ... ET39: =ES39+ET38 -> 650
C40: 11 | D40: 82111-F2211 | E40: AT10 | F40: B02 | G40: QTY | H40: 0 | I40: 0 | J40: 0 | K40: 0 | L40: 0 | M40: 0 | N40: 0 | O40: 0 | P40: 0 | Q40: 0 | R40: 0 | S40: 0 | T40: 0 | U40: 0 | V40: 0 | W40: 0 | X40: 0 | Y40: 0 | Z40: 0 | AA40: =SUBTOTAL(9,DM40:DQ40) -> 0 | AB40: =SUBTOTAL(9,DR40:DU40) -> 0 | AC40: =SUBTOTAL(9,DV40:DY40) -> 0 | AD40: =SUBTOTAL(9,DZ40:ED40) -> 0 | AE40: =SUBTOTAL(9,EE40:EH40) -> 0 | AF40: =SUBTOTAL(9,EI40:EL40) -> 0 | AG40: =SUBTOTAL(9,EM40:EP40) -> 0 | AH40: =SUBTOTAL(9,EQ40:ET40) -> 0 | AI40: 0 | AJ40: 0 | AK40: 0 | AL40: 0 | AM40: 0 | AN40: 0 | AO40: 0 | AP40: 0 | AQ40: 0 | AR40: 0 | AS40: 0 | AT40: 0 | AU40: 0 | AV40: 0 | AW40: 0 | AX40: 0 | AY40: 0 | AZ40: 0 | BA40: 0 | BB40: 0 | BC40: 0 | BD40: 0 | BE40: 0 | BF40: 0 | BG40: 0 | BH40: 0 | BI40: 0 | BJ40: 0 | BK40: 0 | BL40: 0 | BM40: 0 | BN40: 0 | BO40: 0 | BP40: 0 | BQ40: 0 | BR40: 0 | BS40: 0 | BT40: 0 | BU40: 0 | BV40: 0 | BW40: 0 | BX40: 0 | BY40: 0 | BZ40: 0 | CA40: 0 | CB40: 0 | CC40: 0 | CD40: 0 | CE40: 0 | CF40: 0 | CG40: 0 | CH40: 0 | CI40: 0 | CJ40: 0 | CK40: 0 | CL40: 0 | CM40: 0 | CN40: 0 | CO40: 0 | CP40: 0 | CQ40: 0 | CR40: 0 | CS40: 0 | CT40: 0 | CU40: 0 | CV40: 0 | CW40: 0 | CX40: 0 | CY40: 0 | CZ40: 0 | DA40: 0 | DB40: 0 | DC40: 0 | DD40: 0 | DE40: 0 | DF40: 0 | DG40: 0 | DH40: 0 | DI40: 0 | DJ40: 0 | DK40: 0 | DL40: 0 | DV40: 0 | DW40: 0 | DX40: 0 | DY40: 0 | DZ40: 0 | EA40: 0 | EB40: 0 | EC40: 0 | ED40: 0
G41: CUM | H41: 0 | I41: =H41+I40 -> 0 | J41: =I41+J40 -> 0 | K41: =J41+K40 -> 0 | L41: =K41+L40 -> 0 | M41: =L41+M40 -> 0 | N41: =M41+N40 -> 0 | O41: =N41+O40 -> 0 | P41: =O41+P40 -> 0 | ... AH41: =AG41+AH40 -> 0 | AI41: 0 | AJ41: =AI41+AJ40 -> 0 | AK41: =AJ41+AK40 -> 0 | AL41: =AK41+AL40 -> 0 | AM41: =AL41+AM40 -> 0 | AN41: =AM41+AN40 -> 0 | AO41: =AN41+AO40 -> 0 | AP41: =AO41+AP40 -> 0 | AQ41: =AP41+AQ40 -> 0 | ... ET41: =ES41+ET40 -> 0
C42: 12 | D42: 82111-F2220 | E42: AT10 | F42: D02 | G42: QTY | H42: 930 | I42: 540 | J42: 290 | K42: 610 | L42: 500 | M42: 800 | N42: 860 | O42: 780 | P42: 1460 | Q42: 620 | R42: 500 | S42: 560 | T42: 480 | U42: 940 | V42: 620 | W42: 630 | X42: 410 | Y42: 850 | Z42: 410 | AA42: =SUBTOTAL(9,DM42:DQ42) -> 470 | AB42: =SUBTOTAL(9,DR42:DU42) -> 540 | AC42: =SUBTOTAL(9,DV42:DY42) -> 430 | AD42: =SUBTOTAL(9,DZ42:ED42) -> 420 | AE42: =SUBTOTAL(9,EE42:EH42) -> 0 | AF42: =SUBTOTAL(9,EI42:EL42) -> 0 | AG42: =SUBTOTAL(9,EM42:EP42) -> 0 | AH42: =SUBTOTAL(9,EQ42:ET42) -> 0 | AI42: 680 | AJ42: 230 | AK42: 230 | AL42: 230 | AM42: 140 | AN42: 140 | AO42: 130 | AP42: 130 | AQ42: 80 | AR42: 70 | AS42: 70 | AT42: 70 | AU42: 0 | AV42: 160 | AW42: 150 | AX42: 150 | AY42: 150 | AZ42: 120 | BA42: 120 | BB42: 130 | BC42: 130 | BD42: 200 | BE42: 200 | BF42: 0 | BG42: 200 | BH42: 200 | BI42: 220 | BJ42: 220 | BK42: 210 | BL42: 210 | BM42: 200 | BN42: 200 | BO42: 190 | BP42: 190 | BQ42: 300 | BR42: 290 | BS42: 290 | BT42: 290 | BU42: 290 | BV42: 150 | BW42: 150 | BX42: 160 | BY42: 160 | BZ42: 120 | CA42: 120 | CB42: 130 | CC42: 0 | CD42: 130 | CE42: 0 | CF42: 190 | CG42: 190 | CH42: 180 | CI42: 120 | CJ42: 120 | CK42: 120 | CL42: 120 | CM42: 230 | CN42: 240 | CO42: 230 | CP42: 240 | CQ42: 150 | CR42: 150 | CS42: 160 | CT42: 0 | CU42: 160 | CV42: 150 | CW42: 160 | CX42: 160 | CY42: 160 | CZ42: 100 | DA42: 100 | DB42: 100 | DC42: 110 | DD42: 210 | DE42: 210 | DF42: 0 | DG42: 210 | DH42: 220 | DI42: 100 | DJ42: 100 | DK42: 100 | DL42: 110 | DM42: 100 | DN42: 100 | DO42: 90 | DP42: 90 | DQ42: 90 | DR42: 140 | DS42: 140 | DT42: 130 | DU42: 130 | DV42: 110 | DW42: 110 | DX42: 110 | DY42: 100 | DZ42: 100 | EA42: 100 | EB42: 100 | EC42: 60 | ED42: 60
G43: CUM | H43: 11864 | I43: =H43+I42 -> 12404 | J43: =I43+J42 -> 12694 | K43: =J43+K42 -> 13304 | L43: =K43+L42 -> 13804 | M43: =L43+M42 -> 14604 | N43: =M43+N42 -> 15464 | O43: =N43+O42 -> 16244 | P43: =O43+P42 -> 17704 | ... AH43: =AG43+AH42 -> 25584 | AI43: 11174 | AJ43: =AI43+AJ42 -> 11404 | AK43: =AJ43+AK42 -> 11634 | AL43: =AK43+AL42 -> 11864 | AM43: =AL43+AM42 -> 12004 | AN43: =AM43+AN42 -> 12144 | AO43: =AN43+AO42 -> 12274 | AP43: =AO43+AP42 -> 12404 | AQ43: =AP43+AQ42 -> 12484 | ... ET43: =ES43+ET42 -> 25584
C44: 13 | D44: 82111-FEQ60 | E44: AT10 | F44: C01 | G44: QTY | H44: 0 | I44: 0 | J44: 0 | K44: 0 | L44: 0 | M44: 0 | N44: 0 | O44: 0 | P44: 0 | Q44: 0 | R44: 0 | S44: 0 | T44: 70 | U44: 430 | V44: 630 | W44: 420 | X44: 710 | Y44: 440 | Z44: 820 | AA44: =SUBTOTAL(9,DM44:DQ44) -> 620 | AB44: =SUBTOTAL(9,DR44:DU44) -> 610 | AC44: =SUBTOTAL(9,DV44:DY44) -> 490 | AD44: =SUBTOTAL(9,DZ44:ED44) -> 440 | AE44: =SUBTOTAL(9,EE44:EH44) -> 0 | AF44: =SUBTOTAL(9,EI44:EL44) -> 0 | AG44: =SUBTOTAL(9,EM44:EP44) -> 0 | AH44: =SUBTOTAL(9,EQ44:ET44) -> 0 | AI44: 0 | AJ44: 0 | AK44: 0 | AL44: 0 | AM44: 0 | AN44: 0 | AO44: 0 | AP44: 0 | AQ44: 0 | AR44: 0 | AS44: 0 | AT44: 0 | AU44: 0 | AV44: 0 | AW44: 0 | AX44: 0 | AY44: 0 | AZ44: 0 | BA44: 0 | BB44: 0 | BC44: 0 | BD44: 0 | BE44: 0 | BF44: 0 | BG44: 0 | BH44: 0 | BI44: 0 | BJ44: 0 | BK44: 0 | BL44: 0 | BM44: 0 | BN44: 0 | BO44: 0 | BP44: 0 | BQ44: 0 | BR44: 0 | BS44: 0 | BT44: 0 | BU44: 0 | BV44: 0 | BW44: 0 | BX44: 0 | BY44: 0 | BZ44: 0 | CA44: 0 | CB44: 0 | CC44: 0 | CD44: 0 | CE44: 0 | CF44: 0 | CG44: 0 | CH44: 0 | CI44: 0 | CJ44: 30 | CK44: 20 | CL44: 20 | CM44: 110 | CN44: 110 | CO44: 110 | CP44: 100 | CQ44: 160 | CR44: 160 | CS44: 160 | CT44: 0 | CU44: 150 | CV44: 110 | CW44: 110 | CX44: 100 | CY44: 100 | CZ44: 170 | DA44: 180 | DB44: 180 | DC44: 180 | DD44: 110 | DE44: 110 | DF44: 0 | DG44: 110 | DH44: 110 | DI44: 200 | DJ44: 210 | DK44: 200 | DL44: 210 | DM44: 130 | DN44: 130 | DO44: 120 | DP44: 120 | DQ44: 120 | DR44: 160 | DS44: 150 | DT44: 150 | DU44: 150 | DV44: 130 | DW44: 120 | DX44: 120 | DY44: 120 | DZ44: 100 | EA44: 100 | EB44: 100 | EC44: 70 | ED44: 70
...

Sheet JAI (加新件號)
A1: YAZAKI FAX | D1: FROM
A3: OVERSEAS NETWORK | D3: TO
A5: FAX No. | C5: ATTN : MR.
B7: SR No. | D7: JAI 2026-04-01
B9: TYC FACT | D9: TJAT
B10: OVERSEAS FACT | D10: JAI
B11: ARRIVAL PORT | D11: KAO
B12: CUST | D12: TAIWAN TOYOTA | JB12: 2026/
BK13: FIRM | BO13: FIRM | BS13: FIRM | BW13: FIRM | CB13: FIRM | CF13: FIRM | CK13: FIRM | CO13: FIRM | CS13: FIRM | CX13: FIRM | DB13: FIRM | DG13: FIRM | DK13: FIRM | DO13: FIRM | DS13: FIRM | DX13: FIRM | EB13: FIRM | EF13: FIRM | EK13: FIRM | EO13: FIRM | ET13: FIRM | EX13: FIRM | FB13: FIRM | FG13: FIRM | FK13: FIRM | FO13: FIRM | FS13: FIRM | FX13: FIRM | GB13: FIRM | GF13: FIRM | GK13: FIRM | GO13: FIRM | GT13: FIRM | GX13: FIRM | HB13: FIRM | HG13: FIRM | HK13: FIRM | HO13: FIRM | HS13: FIRM | HW13: FIRM | IB13: FIRM | IF13: FIRM | IK13: FIRM | IO13: FIRM | IS13: FIRM | IW13: FIRM | JB13: FIRM | JF13: FIRM | JJ13: FIRM | JN13: FIRM | JS13: FIRM | JW13: FORECAST | KA13: FORECAST | KF13: FORECAST | KJ13: FORECAST
AK14: TIME CHART MONTH | BK14: =H19 -> 3 | BO14: 4 | BS14: 5 | BW14: 6 | CB14: 7 | CF14: 8 | CK14: 9 | CO14: 10 | CS14: 11 | CX14: 12 | DB14: 1 | DG14: 2 | DK14: 3 | DO14: 4 | DS14: 5 | DX14: 6 | EB14: 7 | EF14: 8 | EK14: 9 | EO14: 10 | ET14: 11 | EX14: 12 | FB14: 2024/1 | FG14: 2 | FK14: 3 | FO14: 4 | FS14: 5 | FX14: 6 | GB14: 7 | GF14: 8 | GK14: 9 | GO14: 10 | GT14: 11 | GX14: 12 | HB14: 1 | HG14: 2 | HK14: 3 | HO14: 4 | HS14: 5 | HW14: 6 | IB14: 7 | IF14: 8 | IK14: 9 | IO14: 10 | IS14: 11 | IW14: 12 | JB14: 1 | JF14: 2 | JJ14: 3 | JN14: 4 | JS14: 5 | JW14: 6 | KA14: 7 | KF14: 8 | KJ14: 9
AK15: ETD JAI | BK15: 44602 | BL15: =BK15+7 -> 44609 | BM15: =BL15+7 -> 44616 | BN15: =BM15+7 -> 44623 | BO15: =BN15+7 -> 44630 | BP15: =BO15+7 -> 44637 | BQ15: =BP15+7 -> 44644 | BR15: =BQ15+7 -> 44651 | BS15: =BR15+7 -> 44658 | ... HJ15: =HI15+7 -> 45687 | HK15: 45334 | HL15: 45341 | HM15: 45348 | HN15: 45356 | HO15: 45363 | HP15: 45370 | HQ15: 45377 | HR15: 45384 | HS15: 45391 | HT15: 45398 | HU15: 45405 | HV15: 45412 | HW15: 45419 | HX15: 45426 | HY15: 45433 | HZ15: 45440 | IA15: 45812 | IB15: 45819 | IC15: 45826 | ID15: 45833 | IE15: 45840 | IF15: 45847 | IG15: 45854 | IH15: 45861 | II15: 45868 | IJ15: 45875 | IK15: 45882 | IL15: 45889 | IM15: 45896 | IN15: 45903 | IO15: 45910 | IP15: 45917 | IQ15: 45924 | IR15: 45931 | IS15: 45939 | IT15: 45946 | IU15: 45953 | IV15: 45960 | IW15: 45967 | IX15: 45974 | IY15: 45981 | IZ15: 45988 | JA15: 45995 | JB15: 46002 | JC15: 46009 | JD15: 46016 | JE15: 45658 | JF15: 45665 | JG15: 45672 | JH15: 45679 | JI15: 45686 | JJ15: 45693 | JK15: 45700 | JL15: 45707 | JM15: 45714 | JN15: 45721 | JO15: 45728 | JP15: 45735 | JQ15: 45742 | JR15: 45749 | JS15: 45756 | JT15: 45763 | JU15: 45770 | JV15: 45777 | JW15: 45784 | JX15: 45791 | JY15: 45798 | JZ15: 45805 | KA15: 46177 | KB15: 46184 | KC15: 46191 | KD15: 46198 | KE15: 46205 | KF15: 46212 | KG15: 46219 | KH15: 46226 | KI15: 46233 | KJ15: 46240 | KK15: 46247 | KL15: 46254 | KM15: 46261 | KN15: 46268
AK16: ETD PORT SUR | BK16: 44604 | BL16: =BK16+7 -> 44611 | BM16: =BL16+7 -> 44618 | BN16: =BM16+7 -> 44625 | BO16: =BN16+7 -> 44632 | BP16: =BO16+7 -> 44639 | BQ16: =BP16+7 -> 44646 | BR16: =BQ16+7 -> 44653 | BS16: =BR16+7 -> 44660 | ... HJ16: =HI16+7 -> 45689 | HK16: =HK15+3 -> 45337 | HL16: =HL15+3 -> 45344 | HM16: 45717 | HN16: =HN15+3 -> 45359 | HO16: 45366 | HP16: 45373 | HQ16: 45380 | HR16: 45387 | HS16: 45394 | HT16: 45401 | HU16: 45408 | HV16: 45415 | HW16: 45422 | HX16: 45429 | HY16: 45436 | HZ16: 45443 | IA16: 45815 | IB16: 45822 | IC16: 45829 | ID16: 45836 | IE16: 45843 | IF16: 45850 | IG16: 45857 | IH16: 45864 | II16: 45871 | IJ16: 45878 | IK16: 45885 | IL16: 45892 | IM16: 45899 | IN16: 45906 | IO16: 45913 | IP16: 45920 | IQ16: 45927 | IR16: 45934 | IS16: 45941 | IT16: 45948 | IU16: 45955 | IV16: 45962 | IW16: 45969 | IX16: 45976 | IY16: 45983 | IZ16: 45990 | JA16: 45997 | JB16: 46004 | JC16: 46011 | JD16: 46018 | JE16: 45660 | JF16: 45667 | JG16: 45674 | JH16: 45681 | JI16: 45688 | JJ16: 45695 | JK16: 45702 | JL16: 45709 | JM16: 45716 | JN16: 45723 | JO16: 45730 | JP16: 45737 | JQ16: 45744 | JR16: 45751 | JS16: 45758 | JT16: 45765 | JU16: 45772 | JV16: 45779 | JW16: 45786 | JX16: 45793 | JY16: 45800 | JZ16: 45807 | KA16: 46179 | KB16: 46186 | KC16: 46193 | KD16: 46200 | KE16: 46207 | KF16: 46218 | KG16: 46225 | KH16: 46232 | KI16: 46239 | KJ16: 46242 | KK16: 46249 | KL16: 46256 | KM16: 46263 | KN16: 46270
A17: 車型 | B17: 部位別 | AK17: ETA KAO | BK17: 44612 | BL17: =BK17+7 -> 44619 | BM17: =BL17+7 -> 44626 | BN17: =BM17+7 -> 44633 | BO17: =BN17+7 -> 44640 | BP17: =BO17+7 -> 44647 | BQ17: =BP17+7 -> 44654 | BR17: =BQ17+7 -> 44661 | BS17: =BR17+7 -> 44668 | ... HJ17: =HI17+7 -> 45697 | HK17: =HK16+3 -> 45340 | HL17: =HL16+3 -> 45347 | HM17: =HM16+3 -> 45720 | HN17: =HN16+3 -> 45362 | HO17: 45369 | HP17: 45376 | HQ17: 45383 | HR17: 45390 | HS17: 45397 | HT17: 45404 | HU17: 45411 | HV17: 45418 | HW17: 45425 | HX17: 45432 | HY17: 45439 | HZ17: 45446 | IA17: 45818 | IB17: 45825 | IC17: 45832 | ID17: 45839 | IE17: 45846 | IF17: 45853 | IG17: 45860 | IH17: 45867 | II17: 45874 | IJ17: 45881 | IK17: 45888 | IL17: 45895 | IM17: 45902 | IN17: 45909 | IO17: 45916 | IP17: 45923 | IQ17: 45930 | IR17: 45937 | IS17: 45949 | IT17: 45956 | IU17: 45963 | IV17: 45970 | IW17: 45977 | IX17: 45984 | IY17: 45991 | IZ17: 45998 | JA17: 46005 | JB17: 46012 | JC17: 46019 | JD17: 45661 | JE17: 45668 | JF17: 45675 | JG17: 45682 | JH17: 45689 | JI17: 45696 | JJ17: 45703 | JK17: 45710 | JL17: 45717 | JM17: 45724 | JN17: 45731 | JO17: 45738 | JP17: 45745 | JQ17: 45752 | JR17: 45759 | JS17: 45766 | JT17: 45773 | JU17: 45780 | JV17: 45787 | JW17: 45794 | JX17: 45801 | JY17: 45808 | JZ17: 45815 | KA17: 46187 | KB17: 46194 | KC17: 46201 | KD17: 46208 | KE17: 46215 | KF17: 46220 | KG17: 46227 | KH17: 46234 | KI17: 46241 | KJ17: 46250 | KK17: 46257 | KL17: 46264 | KM17: 46271 | KN17: 46278
A18: CAR | AK18: ETA TYC | BK18: 44614 | BL18: =BK18+7 -> 44621 | BM18: =BL18+7 -> 44628 | BN18: =BM18+7 -> 44635 | BO18: =BN18+7 -> 44642 | BP18: =BO18+7 -> 44649 | BQ18: =BP18+7 -> 44656 | BR18: =BQ18+7 -> 44663 | BS18: =BR18+7 -> 44670 | ... HJ18: =HI18+7 -> 45699 | HK18: =HK17+2 -> 45342 | HL18: =HL17+2 -> 45349 | HM18: =HM17+2 -> 45722 | HN18: =HN17+2 -> 45364 | HO18: 45371 | HP18: 45378 | HQ18: 45385 | HR18: 45392 | HS18: 45399 | HT18: 45406 | HU18: 45413 | HV18: 45420 | HW18: 45427 | HX18: 45434 | HY18: 45441 | HZ18: 45448 | IA18: 45820 | IB18: 45827 | IC18: 45834 | ID18: 45841 | IE18: 45848 | IF18: 45855 | IG18: 45862 | IH18: 45869 | II18: 45876 | IJ18: 45883 | IK18: 45890 | IL18: 45897 | IM18: 45904 | IN18: 45911 | IO18: 45918 | IP18: 45925 | IQ18: 45932 | IR18: 45939 | IS18: 45951 | IT18: 45958 | IU18: 45965 | IV18: 45972 | IW18: 45979 | IX18: 45986 | IY18: 45993 | IZ18: 46000 | JA18: 46007 | JB18: 46014 | JC18: 46021 | JD18: 45663 | JE18: 45670 | JF18: 45677 | JG18: 45684 | JH18: 45691 | JI18: 45698 | JJ18: 45705 | JK18: 45712 | JL18: 45719 | JM18: 45726 | JN18: 45733 | JO18: 45740 | JP18: 45747 | JQ18: 45754 | JR18: 45761 | JS18: 45768 | JT18: 45775 | JU18: 45782 | JV18: 45789 | JW18: 45796 | JX18: 45803 | JY18: 45810 | JZ18: 45817 | KA18: 46189 | KB18: 46196 | KC18: 46203 | KD18: 46210 | KE18: 46217 | KF18: 46224 | KG18: 46231 | KH18: 46238 | KI18: 46245 | KJ18: 46252 | KK18: 46259 | KL18: 46266 | KM18: 46273 | KN18: 46280
A19: MODEL | B19: FAMILY | C19: No. | D19: PRODUCT NO | F19: SFX | H19: 3 | I19: 4 | J19: 5 | K19: 6 | L19: 7 | M19: 8 | N19: 9 | O19: 10 | P19: 11 | Q19: 12 | R19: 2023/1 | S19: 2 | T19: 3 | U19: 4 | V19: 5 | W19: 6 | X19: 7 | Y19: 8 | Z19: 9 | AA19: 10 | AB19: 11 | AC19: 12 | AD19: 1 | AE19: 2 | AF19: 3 | AG19: 4 | AH19: 5 | AI19: 6 | AJ19: 7 | AK19: 8 | AL19: 9 | AM19: 10 | AN19: 11 | AO19: 12 | AP19: 1 | AQ19: 2 | AR19: 3 | AS19: 4 | AT19: 5 | AU19: 6 | AV19: 7 | AW19: 8 | AX19: 9 | AY19: 10 | AZ19: 11 | BA19: 12 | BB19: 1 | BC19: 2 | BD19: 3 | BE19: 4 | BF19: 5 | BG19: 6 | BH19: 7 | BI19: 8 | BJ19: 9 | BK19: 1W | BL19: 2W | BM19: 3W | BN19: 4W | BO19: 1W | BP19: 2W | BQ19: 3W | BR19: 4W | BS19: 1W | BT19: 2W | BU19: 3W | BV19: 4W | BW19: 1W | BX19: 2W | BY19: 3W | BZ19: 4W | CA19: 5W | CB19: 1W | CC19: 2W | CD19: 3W | CE19: 4W | CF19: 1W | CG19: 2W | CH19: 3W | CI19: 4W | CJ19: 5W | CK19: 1W | CL19: 2W | CM19: 3W | CN19: 4W | CO19: 1W | CP19: 2W | CQ19: 3W | CR19: 4W | CS19: 1W | CT19: 2W | CU19: 3W | CV19: 4W | CW19: 5W | CX19: 1W | CY19: 2W | CZ19: 3W | DA19: 4W | DB19: 1W | DC19: 2W | DD19: 3W | DE19: 4W | DF19: 5W | DG19: 1W | DH19: 2W | DI19: 3W | DJ19: 4W | DK19: 1W | DL19: 2W | DM19: 3W | DN19: 4W | DO19: 1W | DP19: 2W | DQ19: 3W | DR19: 4W | DS19: 1W | DT19: 2W | DU19: 3W | DV19: 4W | DW19: 4W | DX19: 1W | DY19: 2W | DZ19: 3W | EA19: 4W | EB19: 1W | EC19: 2W | ED19: 3W | EE19: 4W | EF19: 1W | EG19: 2W | EH19: 3W | EI19: 4W | EJ19: 5W | EK19: 1W | EL19: 2W | EM19: 3W | EN19: 4W | EO19: 1W | EP19: 2W | EQ19: 3W | ER19: 4W | ES19: 5W | ET19: 1W | EU19: 2W | EV19: 3W | EW19: 4W | EX19: 1W | EY19: 2W | EZ19: 3W | FA19: 4W | FB19: 1W | FC19: 2W | FD19: 3W | FE19: 4W | FF19: 5W | FG19: 1W | FH19: 2W | FI19: 3W | FJ19: 4W | FK19: 1W | FL19: 2W | FM19: 3W | FN19: 4W | FO19: 1W | FP19: 2W | FQ19: 3W | FR19: 4W | FS19: 1W | FT19: 2W | FU19: 3W | FV19: 4W | FW19: 5W | FX19: 1W | FY19: 2W | FZ19: 3W | GA19: 4W | GB19: 1W | GC19: 2W | GD19: 3W | GE19: 4W | GF19: 1W | GG19: 2W | GH19: 3W | GI19: 4W | GJ19: 5W | GK19: 1W | GL19: 2W | GM19: 3W | GN19: 4W | GO19: 1W | GP19: 2W | GQ19: 3W | GR19: 4W | GS19: 5W | GT19: 1W | GU19: 2W | GV19: 3W | GW19: 4W | GX19: 1W | GY19: 2W | GZ19: 3W | HA19: 4W | HB19: 1W | HC19: 2W | HD19: 3W | HE19: 4W | HF19: 5W | HG19: 1W | HH19: 2W | HI19: 3W | HJ19: 4W | HK19: 1W | HL19: 2W | HM19: 3W | HN19: 4W | HO19: 1W | HP19: 2W | HQ19: 3W | HR19: 4W | HS19: 1W | HT19: 2W | HU19: 3W | HV19: 4W | HW19: 1W | HX19: 2W | HY19: 3W | HZ19: 4W | IA19: 5W | IB19: 1W | IC19: 2W | ID19: 3W | IE19: 4W | IF19: 1W | IG19: 2W | IH19: 3W | II19: 4W | IJ19: 5W | IK19: 1W | IL19: 2W | IM19: 3W | IN19: 4W | IO19: 1W | IP19: 2W | IQ19: 3W | IR19: 4W | IS19: 1W | IT19: 2W | IU19: 3W | IV19: 4W | IW19: 1W | IX19: 2W | IY19: 3W | IZ19: 4W | JA19: 1W | JB19: 2W | JC19: 3W | JD19: 4W | JE19: 5W | JF19: 1W | JG19: 2W | JH19: 3W | JI19: 4W | JJ19: 1W | JK19: 2W | JL19: 3W | JM19: 4W | JN19: 1W | JO19: 2W | JP19: 3W | JQ19: 4W | JR19: 5W | JS19: 1W | JT19: 2W | JU19: 3W | JV19: 4W | JW19: 1W | JX19: 2W | JY19: 3W | JZ19: 4W | KA19: 1W | KB19: 2W | KC19: 3W | KD19: 4W | KE19: 5W | KF19: 1W | KG19: 2W | KH19: 3W | KI19: 4W | KJ19: 1W | KK19: 2W | KL19: 3W | KM19: 4W | KN19: 5W
A20: CORALLA | B20: WIRE, ENGINE ROOM MAIN | C20: 1 | D20: 82111-FE150 | E20: AT10 | F20: 000 | G20: QTY | H20: 930 | I20: 540 | J20: 290 | K20: 610 | L20: 500 | M20: 800 | N20: 860 | O20: 780 | P20: 1460 | Q20: 620 | R20: 500 | S20: 560 | T20: 480 | U20: 940 | V20: 620 | W20: 630 | X20: 410 | Y20: 850 | Z20: 410 | AA20: =SUBTOTAL(9,EO20:ES20) -> 470 | AB20: =SUBTOTAL(9,ET20:EW20) -> 540 | AC20: =SUBTOTAL(9,EX20:FA20) -> 430 | AD20: =SUBTOTAL(9,FB20:FF20) -> 380 | AE20: =SUBTOTAL(9,FG20:FJ20) -> 460 | AF20: =SUBTOTAL(9,FK20:FN20) -> 390 | AG20: =SUBTOTAL(9,FO20:FR20) -> 350 | AH20: =SUBTOTAL(9,FS20:FW20) -> 500 | AI20: =SUBTOTAL(9,FX20:GA20) -> 440 | AJ20: =SUBTOTAL(9,GB20:GE20) -> 470 | AK20: =SUBTOTAL(9,GF20:GJ20) -> 830 | AL20: =SUBTOTAL(9,GK20:GN20) -> 360 | AM20: =SUBTOTAL(9,GO20:GS20) -> 6 | AN20: =SUBTOTAL(9,GT20:GW20) -> 0 | AO20: =SUM(GX20:HA20) -> 0 | AP20: =SUM(HB20:HF20) -> 0 | AQ20: =SUM(HG20:HJ20) -> 0 | AR20: =SUM(HK20:HN20) -> 0 | AS20: =SUM(HO20:HR20) -> 0 | AT20: =SUM(HS20:HV20) -> 0 | AU20: =SUM(HW20:IA20) -> 0 | AV20: =SUM(IB20:IE20) -> 0 | AW20: =SUM(IF20:IJ20) -> 0 | AX20: =SUM(IK20:IN20) -> 0 | AY20: =SUM(IO20:IR20) -> 144 | AZ20: =SUM(IS20:IV20) -> 90 | BA20: =SUM(IW20:JA20) -> 66 | BB20: =SUM(JB20:JE20) -> 6 | BC20: =SUM(JF20:JI20) -> 18 | BD20: =SUM(JJ20:JM20) -> 42 | BE20: =SUM(JN20:JR20) -> 54 | BF20: =SUM(JS20:JV20) -> 42 | BG20: =SUM(JW20:JZ20) -> 42 | BH20: =SUM(KA20:KE20) -> 36 | BI20: =SUM(KF20:KI20) -> 36 | BJ20: =SUM(KJ20:KN20) -> 42 | BK20: 680 | BL20: 230 | BM20: 230 | BN20: 230 | BO20: 140 | BP20: 140 | BQ20: 130 | BR20: 130 | BS20: 80 | BT20: 70 | BU20: 70 | BV20: 70 | BW20: 0 | BX20: 160 | BY20: 150 | BZ20: 150 | CA20: 150 | CB20: 120 | CC20: 120 | CD20: 130 | CE20: 130 | CF20: 200 | CG20: 200 | CH20: 0 | CI20: 200 | CJ20: 200 | CK20: 220 | CL20: 220 | CM20: 210 | CN20: 210 | CO20: 200 | CP20: 200 | CQ20: 190 | CR20: 190 | CS20: 300 | CT20: 290 | CU20: 290 | CV20: 290 | CW20: 290 | CX20: 150 | CY20: 150 | CZ20: 160 | DA20: 160 | DB20: 120 | DC20: 120 | DD20: 130 | DE20: 0 | DF20: 130 | DG20: 0 | DH20: 190 | DI20: 190 | DJ20: 180 | DK20: 120 | DL20: 120 | DM20: 120 | DN20: 120 | DO20: 230 | DP20: 240 | DQ20: 230 | DR20: 240 | DS20: 150 | DT20: 150 | DU20: 160 | DV20: 0 | DW20: 160 | DX20: 150 | DY20: 160 | DZ20: 160 | EA20: 160 | EB20: 100 | EC20: 100 | ED20: 100 | EE20: 110 | EF20: 210 | EG20: 210 | EH20: 0 | EI20: 210 | EJ20: 220 | EK20: 100 | EL20: 100 | EM20: 100 | EN20: 110 | EO20: 100 | EP20: 100 | EQ20: 90 | ER20: 90 | ES20: 90 | ET20: 140 | EU20: 140 | EV20: 130 | EW20: 130 | EX20: 110 | EY20: 110 | EZ20: 110 | FA20: 100 | FB20: 100 | FC20: 100 | FD20: 100 | FE20: 80 | FF20: 0 | FG20: 160 | FH20: 150 | FI20: 150 | FJ20: 0 | FK20: 100 | FL20: 100 | FM20: 90 | FN20: 100 | FO20: 80 | FP20: 110 | FQ20: 80 | FR20: 80 | FS20: 120 | FT20: 0 | FU20: 130 | FV20: 130 | FW20: 120 | FX20: 100 | FY20: 100 | FZ20: 100 | GA20: 140 | GB20: 100 | GC20: 120 | GD20: 120 | GE20: 130 | GF20: 210 | GG20: 210 | GH20: 206 | GI20: 0 | GJ20: 204 | GK20: 96 | GL20: 96 | GM20: 96 | GN20: 72 | GO20: 6 | GP20: 0 | GQ20: 0 | GR20: 0 | GS20: 0 | GT20: 0 | GU20: 0 | GV20: 0 | GW20: 0 | IL20: 0 | IM20: 0 | IN20: 0 | IO20: 42 | IP20: 42 | IQ20: 30 | IR20: 30 | IS20: 18 | IT20: 18 | IU20: 36 | IV20: 18 | IW20: 12 | IX20: 12 | IY20: 12 | IZ20: 12 | JA20: 18 | JB20: 6 | JC20: 0 | JD20: 0 | JE20: 0 | JF20: 18 | JG20: 0 | JH20: 0 | JI20: 0 | JJ20: 0 | JK20: 24 | JL20: 18 | JM20: 0 | JN20: 18 | JO20: 18 | JP20: 18 | JQ20: 0 | JR20: 0 | JS20: 18 | JT20: 12 | JU20: 12 | JV20: 0 | JW20: 24 | JX20: 18 | JY20: 0 | JZ20: 0 | KA20: 18 | KB20: 18 | KC20: 0 | KD20: 0 | KE20: 0 | KF20: 18 | KG20: 18 | KH20: 0 | KI20: 0 | KJ20: 0 | KK20: 24 | KL20: 18 | KM20: 0 | KN20: 0
D21: 2025.09.30 L/O | G21: CUM | H21: 11864 | I21: =H21+I20 -> 12404 | J21: =I21+J20 -> 12694 | K21: =J21+K20 -> 13304 | L21: =K21+L20 -> 13804 | M21: =L21+M20 -> 14604 | N21: =M21+N20 -> 15464 | O21: =N21+O20 -> 16244 | P21: =O21+P20 -> 17704 | ... AH21: =AG21+AH20 -> 27244 | AI21: =GA21 -> 27684 | AJ21: =AI21+AJ20 -> 28154 | AK21: =AJ21+AK20 -> 28984 | AL21: =AK21+AL20 -> 29344 | AM21: =AL21+AM20 -> 29350 | AN21: =AM21+AN20 -> 29350 | AO21: =AN21+AO20 -> 29350 | AP21: =AO21+AP20 -> 29350 | AQ21: =AP21+AQ20 -> 29350 | ... AU21: =AT21+AU20 -> 29350 | AV21: 0 | AW21: =AV21+AW20 -> 0 | AX21: =AW21+AX20 -> 0 | AY21: =AX21+AY20 -> 144 | AZ21: =AY21+AZ20 -> 234 | BA21: =AZ21+BA20 -> 300 | BB21: =BA21+BB20 -> 306 | BC21: =BB21+BC20 -> 324 | BD21: =BC21+BD20 -> 366 | ... BJ21: =BI21+BJ20 -> 618 | BK21: 11174 | BL21: =BK21+BL20 -> 11404 | BM21: =BL21+BM20 -> 11634 | BN21: =BM21+BN20 -> 11864 | BO21: =BN21+BO20 -> 12004 | BP21: =BO21+BP20 -> 12144 | BQ21: =BP21+BQ20 -> 12274 | BR21: =BQ21+BR20 -> 12404 | BS21: =BR21+BS20 -> 12484 | ... IA21: =HZ21+IA20 -> 29350 | IB21: 0 | IC21: =IB21+IC20 -> 0 | ID21: =IC21+ID20 -> 0 | IE21: =ID21+IE20 -> 0 | IF21: =IE21+IF20 -> 0 | IG21: =IF21+IG20 -> 0 | IH21: =IG21+IH20 -> 0 | II21: =IH21+II20 -> 0 | IJ21: =II21+IJ20 -> 0 | ... KM21: =KL21+KM20 -> 618 | KN21: =KL21+KN20 -> 618
C22: 2 | D22: 82111-FE200 | E22: AT10 | F22: 000 | G22: QTY | H22: 0 | I22: 0 | J22: 0 | K22: 0 | L22: 0 | M22: 0 | N22: 0 | O22: 0 | P22: 0 | Q22: 0 | R22: 0 | S22: 0 | T22: 70 | U22: 430 | V22: 630 | W22: 420 | X22: 710 | Y22: 440 | Z22: 820 | AA22: =SUBTOTAL(9,EO22:ES22) -> 620 | AB22: =SUBTOTAL(9,ET22:EW22) -> 610 | AC22: =SUBTOTAL(9,EX22:FA22) -> 490 | AD22: =SUBTOTAL(9,FB22:FF22) -> 450 | AE22: =SUBTOTAL(9,FG22:FJ22) -> 490 | AF22: =SUBTOTAL(9,FK22:FN22) -> 430 | AG22: =SUBTOTAL(9,FO22:FR22) -> 350 | AH22: =SUBTOTAL(9,FS22:FW22) -> 360 | AI22: =SUBTOTAL(9,FX22:GA22) -> 420 | AJ22: =SUBTOTAL(9,GB22:GE22) -> 580 | AK22: =SUBTOTAL(9,GF22:GJ22) -> 580 | AL22: =SUBTOTAL(9,GK22:GN22) -> 402 | AM22: =SUBTOTAL(9,GO22:GS22) -> 294 | AN22: =SUBTOTAL(9,GT22:GW22) -> 0 | AO22: =SUM(GX22:HA22) -> 0 | AP22: =SUM(HB22:HF22) -> 0 | AQ22: =SUM(HG22:HJ22) -> 0 | AR22: =SUM(HK22:HN22) -> 0 | AS22: =SUM(HO22:HR22) -> 0 | AT22: =SUM(HS22:HV22) -> 0 | AU22: =SUM(HW22:IA22) -> 0 | AV22: =SUM(IB22:IE22) -> 0 | AW22: =SUM(IF22:IJ22) -> 0 | AX22: =SUM(IK22:IN22) -> 0 | AY22: =SUM(IO22:IR22) -> 72 | AZ22: =SUM(IS22:IV22) -> 42 | BA22: =SUM(IW22:JA22) -> 84 | BB22: =SUM(JB22:JE22) -> 60 | BC22: =SUM(JF22:JI22) -> 36 | BD22: =SUM(JJ22:JM22) -> 0 | BE22: =SUM(JN22:JR22) -> 0 | BF22: =SUM(JS22:JV22) -> 0 | BG22: =SUM(JW22:JZ22) -> 0 | BH22: =SUM(KA22:KE22) -> 0 | BI22: =SUM(KF22:KI22) -> 0 | BJ22: =SUM(KJ22:KN22) -> 0 | BK22: 0 | BL22: 0 | BM22: 0 | BN22: 0 | BO22: 0 | BP22: 0 | BQ22: 0 | BR22: 0 | BS22: 0 | BT22: 0 | BU22: 0 | BV22: 0 | BW22: 0 | BX22: 0 | BY22: 0 | BZ22: 0 | CA22: 0 | CB22: 0 | CC22: 0 | CD22: 0 | CE22: 0 | CF22: 0 | CG22: 0 | CH22: 0 | CI22: 0 | CJ22: 0 | CK22: 0 | CL22: 0 | CM22: 0 | CN22: 0 | CO22: 0 | CP22: 0 | CQ22: 0 | CR22: 0 | CS22: 0 | CT22: 0 | CU22: 0 | CV22: 0 | CW22: 0 | CX22: 0 | CY22: 0 | CZ22: 0 | DA22: 0 | DB22: 0 | DC22: 0 | DD22: 0 | DE22: 0 | DF22: 0 | DG22: 0 | DH22: 0 | DI22: 0 | DJ22: 0 | DK22: 0 | DL22: 30 | DM22: 20 | DN22: 20 | DO22: 110 | DP22: 110 | DQ22: 110 | DR22: 100 | DS22: 160 | DT22: 160 | DU22: 160 | DV22: 0 | DW22: 150 | DX22: 110 | DY22: 110 | DZ22: 100 | EA22: 100 | EB22: 170 | EC22: 180 | ED22: 180 | EE22: 180 | EF22: 110 | EG22: 110 | EH22: 0 | EI22: 110 | EJ22: 110 | EK22: 200 | EL22: 210 | EM22: 200 | EN22: 210 | EO22: 130 | EP22: 130 | EQ22: 120 | ER22: 120 | ES22: 120 | ET22: 160 | EU22: 150 | EV22: 150 | EW22: 150 | EX22: 130 | EY22: 120 | EZ22: 120 | FA22: 120 | FB22: 90 | FC22: 90 | FD22: 90 | FE22: 90 | FF22: 90 | FG22: 160 | FH22: 160 | FI22: 170 | FJ22: 0 | FK22: 100 | FL22: 110 | FM22: 120 | FN22: 100 | FO22: 100 | FP22: 100 | FQ22: 100 | FR22: 50 | FS22: 100 | FT22: 0 | FU22: 100 | FV22: 80 | FW22: 80 | FX22: 140 | FY22: 140 | FZ22: 140 | GA22: 0 | GB22: 140 | GC22: 150 | GD22: 150 | GE22: 140 | GF22: 148 | GG22: 144 | GH22: 144 | GI22: 0 | GJ22: 144 | GK22: 96 | GL22: 78 | GM22: 78 | GN22: 150 | GO22: 150 | GP22: 144 | GQ22: 0 | GS22: 0 | GT22: 0 | GU22: 0 | GV22: 0 | GW22: 0 | IO22: 24 | IP22: 24 | IQ22: 12 | IR22: 12 | IS22: 18 | IT22: 12 | IU22: 12 | IV22: 0 | IW22: 0 | IX22: 24 | IY22: 18 | IZ22: 18 | JA22: 24 | JB22: 24 | JC22: 18 | JD22: 18 | JE22: 0 | JF22: 18 | JG22: 18 | JH22: 0 | JI22: 0 | JJ22: 0 | JK22: 0 | JL22: 0 | JM22: 0 | JN22: 0 | JO22: 0 | JP22: 0 | JQ22: 0 | JR22: 0 | JS22: 0 | JT22: 0 | JU22: 0 | JV22: 0 | JW22: 0 | JX22: 0 | JY22: 0 | JZ22: 0 | KA22: 0 | KB22: 0 | KC22: 0 | KD22: 0 | KE22: 0 | KF22: 0 | KG22: 0 | KH22: 0 | KI22: 0 | KJ22: 0 | KK22: 0 | KL22: 0 | KM22: 0 | KN22: 0
D23: 2025.09.30 L/O 2026.03.09 B/O | G23: CUM | H23: 0 | I23: =H23+I22 -> 0 | J23: =I23+J22 -> 0 | K23: =J23+K22 -> 0 | L23: =K23+L22 -> 0 | M23: =L23+M22 -> 0 | N23: =M23+N22 -> 0 | O23: =N23+O22 -> 0 | P23: =O23+P22 -> 0 | ... AH23: =AG23+AH22 -> 7320 | AI23: =GA23 -> 7740 | AJ23: =AI23+AJ22 -> 8320 | AK23: =AJ23+AK22 -> 8900 | AL23: =AK23+AL22 -> 9302 | AM23: =AL23+AM22 -> 9596 | AN23: =AM23+AN22 -> 9596 | AO23: =AN23+AO22 -> 9596 | AP23: =AO23+AP22 -> 9596 | AQ23: =AP23+AQ22 -> 9596 | ... AU23: =AT23+AU22 -> 9596 | AV23: 0 | AW23: =AV23+AW22 -> 0 | AX23: =AW23+AX22 -> 0 | AY23: =AX23+AY22 -> 72 | AZ23: =AY23+AZ22 -> 114 | BA23: =AZ23+BA22 -> 198 | BB23: =BA23+BB22 -> 258 | BC23: =BB23+BC22 -> 294 | BD23: =BC23+BD22 -> 294 | ... BJ23: =BI23+BJ22 -> 294 | BK23: 0 | BL23: =BK23+BL22 -> 0 | BM23: =BL23+BM22 -> 0 | BN23: =BM23+BN22 -> 0 | BO23: =BN23+BO22 -> 0 | BP23: =BO23+BP22 -> 0 | BQ23: =BP23+BQ22 -> 0 | BR23: =BQ23+BR22 -> 0 | BS23: =BR23+BS22 -> 0 | ... IA23: =HZ23+IA22 -> 9596 | IB23: 0 | IC23: =IB23+IC22 -> 0 | ID23: =IC23+ID22 -> 0 | IE23: =ID23+IE22 -> 0 | IF23: =IE23+IF22 -> 0 | IG23: =IF23+IG22 -> 0 | IH23: =IG23+IH22 -> 0 | II23: =IH23+II22 -> 0 | IJ23: =II23+IJ22 -> 0 | ... KM23: =KL23+KM22 -> 294 | KN23: =KL23+KN22 -> 294
C24: 3 | D24: 82111-FE210 | E24: AT10 | F24: 000 | G24: QTY | H24: 930 | I24: 540 | J24: 290 | K24: 0 | L24: 0 | M24: 560 | N24: 550 | O24: 400 | P24: 650 | R24: 0 | S24: 0 | T24: 30 | U24: 120 | V24: 170 | W24: 170 | X24: 120 | Y24: 70 | Z24: 80 | AA24: =SUBTOTAL(9,EO24:ES24) -> 80 | AB24: =SUBTOTAL(9,ET24:EW24) -> 120 | AC24: =SUBTOTAL(9,EX24:FA24) -> 130 | AD24: =SUBTOTAL(9,FB24:FF24) -> 60 | AE24: =SUBTOTAL(9,FG24:FJ24) -> 70 | AF24: =SUBTOTAL(9,FK24:FN24) -> 50 | AG24: =SUBTOTAL(9,FO24:FR24) -> 36 | AH24: =SUBTOTAL(9,FS24:FW24) -> 0 | AI24: =SUBTOTAL(9,FX24:GA24) -> 0 | AJ24: =SUBTOTAL(9,GB24:GE24) -> 0 | AK24: =SUBTOTAL(9,GF24:GJ24) -> 0 | AL24: =SUBTOTAL(9,GK24:GN24) -> 0 | AM24: =SUBTOTAL(9,GO24:GS24) -> 0 | AN24: =SUBTOTAL(9,GT24:GW24) -> 0 | AO24: =SUM(GX24:HA24) -> 0 | AP24: =SUM(HB24:HF24) -> 0 | AQ24: =SUM(HG24:HJ24) -> 0 | AR24: =SUM(HK24:HN24) -> 0 | AS24: =SUM(HO24:HR24) -> 0 | AT24: =SUM(HS24:HV24) -> 0 | AU24: =SUM(HW24:IA24) -> 0 | AV24: =SUM(IB24:IE24) -> 0 | AW24: =SUM(IF24:IJ24) -> 0 | AX24: =SUM(IK24:IN24) -> 0 | AY24: =SUM(IO24:IR24) -> 576 | AZ24: =SUM(IS24:IV24) -> 426 | BA24: =SUM(IW24:JA24) -> 570 | BB24: =SUM(JB24:JE24) -> 336 | BC24: =SUM(JF24:JI24) -> 192 | BD24: =SUM(JJ24:JM24) -> 16 | BE24: =SUM(JN24:JR24) -> 0 | BF24: =SUM(JS24:JV24) -> 0 | BG24: =SUM(JW24:JZ24) -> 0 | BH24: =SUM(KA24:KE24) -> 0 | BI24: =SUM(KF24:KI24) -> 0 | BJ24: =SUM(KJ24:KN24) -> 0 | BK24: 680 | BL24: 230 | BM24: 230 | BN24: 230 | BO24: 140 | BP24: 140 | BQ24: 130 | BR24: 130 | BS24: 80 | BT24: 70 | BU24: 70 | BV24: 70 | BW24: 0 | BX24: 0 | BY24: 0 | BZ24: 0 | CA24: 0 | CB24: 0 | CC24: 0 | CD24: 0 | CE24: 0 | CF24: 140 | CG24: 140 | CH24: 0 | CI24: 140 | CJ24: 140 | CK24: 140 | CL24: 140 | CM24: 140 | CN24: 130 | CO24: 100 | CP24: 100 | CQ24: 100 | CR24: 100 | CS24: 130 | CT24: 130 | CU24: 130 | CV24: 130 | CW24: 130 | CX24: 130 | CY24: 130 | CZ24: 140 | DA24: 140 | DB24: 0 | DC24: 0 | DD24: 0 | DE24: 0 | DF24: 0 | DG24: 0 | DH24: 0 | DI24: 0 | DJ24: 0 | DK24: 0 | DL24: 10 | DM24: 10 | DN24: 10 | DO24: 30 | DP24: 30 | DQ24: 30 | DR24: 30 | DS24: 40 | DT24: 40 | DU24: 40 | DV24: 0 | DW24: 50 | DX24: 40 | DY24: 50 | DZ24: 40 | EA24: 40 | EB24: 30 | EC24: 30 | ED24: 30 | EE24: 30 | EF24: 10 | EG24: 20 | EH24: 2 | EI24: 20 | EJ24: 20 | EK24: 20 | EL24: 20 | EM24: 20 | EN24: 20 | EO24: 20 | EP24: 20 | EQ24: 20 | ER24: 10 | ES24: 10 | ET24: 30 | EU24: 30 | EV24: 30 | EW24: 30 | EX24: 40 | EY24: 30 | EZ24: 30 | FA24: 30 | FB24: 0 | FC24: 20 | FD24: 20 | FE24: 10 | FF24: 10 | FG24: 20 | FH24: 30 | FI24: 20 | FJ24: 0 | FK24: 20 | FL24: 10 | FM24: 20 | FN24: 0 | FO24: 10 | FP24: 0 | FQ24: 0 | FR24: 26 | FS24: 0 | FT24: 0 | FU24: 0 | FV24: 0 | FW24: 0 | FX24: 0 | FY24: 0 | FZ24: 0 | GA24: 0 | GB24: 0 | GC24: 0 | GD24: 0 | GE24: 0 | GF24: 0 | GG24: 0 | GH24: 0 | GI24: 0 | GJ24: 0 | GK24: 0 | GL24: 0 | GM24: 0 | GN24: 0 | GO24: 0 | GP24: 0 | GQ24: 0 | GR24: 0 | GT24: 0 | GU24: 0 | GV24: 0 | GW24: 0 | IO24: 186 | IP24: 186 | IQ24: 102 | IR24: 102 | IS24: 108 | IT24: 108 | IU24: 108 | IV24: 102 | IW24: 102 | IX24: 114 | IY24: 114 | IZ24: 114 | JA24: 126 | JB24: 84 | JC24: 84 | JD24: 84 | JE24: 84 | JF24: 48 | JG24: 48 | JH24: 48 | JI24: 48 | JJ24: 0 | JK24: 16 | JL24: 0 | JM24: 0 | JN24: 0 | JO24: 0 | JP24: 0 | JQ24: 0 | JR24: 0 | JS24: 0 | JT24: 0 | JU24: 0 | JV24: 0 | JW24: 0 | JX24: 0 | JY24: 0 | JZ24: 0 | KA24: 0 | KB24: 0 | KC24: 0 | KD24: 0 | KE24: 0 | KF24: 0 | KG24: 0 | KH24: 0 | KI24: 0 | KJ24: 0 | KK24: 0 | KL24: 0 | KM24: 0 | KN24: 0
D25: 2025.09.30 L/O 2026.03.09 B/O | G25: CUM | H25: 11864 | I25: =H25+I24 -> 12404 | J25: =I25+J24 -> 12694 | K25: 0 | L25: =K25+L24 -> 0 | M25: =L25+M24 -> 560 | N25: =M25+N24 -> 1110 | O25: =N25+O24 -> 1510 | P25: =O25+P24 -> 2160 | Q25: 0 | R25: =Q25+R24 -> 0 | S25: =R25+S24 -> 0 | T25: =S25+T24 -> 30 | U25: =T25+U24 -> 150 | V25: =U25+V24 -> 320 | W25: =V25+W24 -> 490 | X25: =W25+X24 -> 610 | Y25: =X25+Y24 -> 680 | ... AH25: =AG25+AH24 -> 1306 | AI25: =GA25 -> 1308 | AJ25: =AI25+AJ24 -> 1308 | AK25: =AJ25+AK24 -> 1308 | AL25: =AK25+AL24 -> 1308 | AM25: =AL25+AM24 -> 1308 | AN25: =AM25+AN24 -> 1308 | AO25: =AN25+AO24 -> 1308 | AP25: =AO25+AP24 -> 1308 | AQ25: =AP25+AQ24 -> 1308 | ... AU25: =AT25+AU24 -> 1308 | AV25: 0 | AW25: =AV25+AW24 -> 0 | AX25: =AW25+AX24 -> 0 | AY25: =AX25+AY24 -> 576 | AZ25: =AY25+AZ24 -> 1002 | BA25: =AZ25+BA24 -> 1572 | BB25: =BA25+BB24 -> 1908 | BC25: =BB25+BC24 -> 2100 | BD25: =BC25+BD24 -> 2116 | ... BJ25: =BI25+BJ24 -> 2116 | BK25: 11174 | BL25: =BK25+BL24 -> 11404 | BM25: =BL25+BM24 -> 11634 | BN25: =BM25+BN24 -> 11864 | BO25: =BN25+BO24 -> 12004 | BP25: =BO25+BP24 -> 12144 | BQ25: =BP25+BQ24 -> 12274 | BR25: =BQ25+BR24 -> 12404 | BS25: =BR25+BS24 -> 12484 | ... BV25: =BU25+BV24 -> 12694 | BW25: 0 | BX25: =BW25+BX24 -> 0 | BY25: =BX25+BY24 -> 0 | BZ25: =BY25+BZ24 -> 0 | CA25: =BZ25+CA24 -> 0 | CB25: =CA25+CB24 -> 0 | CC25: =CB25+CC24 -> 0 | CD25: =CC25+CD24 -> 0 | CE25: =CD25+CE24 -> 0 | ... DA25: =CZ25+DA24 -> 2700 | DB25: 0 | DC25: =DB25+DC24 -> 0 | DD25: =DC25+DD24 -> 0 | DE25: =DD25+DE24 -> 0 | DF25: =DE25+DF24 -> 0 | DG25: =DF25+DG24 -> 0 | DH25: =DG25+DH24 -> 0 | DI25: =DH25+DI24 -> 0 | DJ25: =DI25+DJ24 -> 0 | ... IA25: =HZ25+IA24 -> 1308 | IB25: 0 | IC25: =IB25+IC24 -> 0 | ID25: =IC25+ID24 -> 0 | IE25: =ID25+IE24 -> 0 | IF25: =IE25+IF24 -> 0 | IG25: =IF25+IG24 -> 0 | IH25: =IG25+IH24 -> 0 | II25: =IH25+II24 -> 0 | IJ25: =II25+IJ24 -> 0 | ... KM25: =KL25+KM24 -> 2116 | KN25: =KL25+KN24 -> 2116
