Workbook
Name Z_5A09EF62_2088_41CB_8AC0_E952E61C3F91_.wvu.PrintArea: 'Qty & UMH GUM'!$B$1:$AE$234
Name Z_5A09EF62_2088_41CB_8AC0_E952E61C3F91_.wvu.PrintArea: 'Summ Qty & UMH'!$B$1:$AD$135
Name Z_5A09EF62_2088_41CB_8AC0_E952E61C3F91_.wvu.PrintArea: 'Summ Qty&UMH GUM '!$B$1:$AE$85
Name Z_5A09EF62_2088_41CB_8AC0_E952E61C3F91_.wvu.PrintTitles: 'Qty & UMH GUM'!$A$6:$IV$8
Name Z_5A09EF62_2088_41CB_8AC0_E952E61C3F91_.wvu.PrintTitles: 'Summ Qty & UMH'!$A$6:$IV$8
Name Z_5A09EF62_2088_41CB_8AC0_E952E61C3F91_.wvu.PrintTitles: 'Summ Qty&UMH GUM '!$A$6:$IV$8
Name Z_D6C13563_5D10_42C9_9394_960CAA966088_.wvu.PrintArea: 'Qty & UMH GUM'!$B$1:$AE$234
Name Z_D6C13563_5D10_42C9_9394_960CAA966088_.wvu.PrintArea: 'Summ Qty & UMH'!$B$1:$AD$135
Name Z_D6C13563_5D10_42C9_9394_960CAA966088_.wvu.PrintArea: 'Summ Qty&UMH GUM '!$B$1:$AE$85

Sheet Sheet1

Sheet XXXXXX

Sheet XXXXXXXX

Sheet XXXXXXXXXX

Sheet XXXXXXXXX0

Sheet Qty & UMH GUM
L1: SIX MONTH PRODUCTION PLAN ( QTY ) ACTUAL | AD1: PREPARED
A2: S/R NO : | B2: 202603-10 | O2: 900B-486D
A3: FAX NO : | B3: EMAIL | O3: 46082
A4: DATE : | B4: 46092 | T4: AZ | AD4: LSR | AG4: Cutting Qty
K5: AQ | N5: AT | Q5: AW | W5: BC | Z5: BF | AC5: BG
A6: DEST | B6: TYPE | C6: HARNESS No. | D6: LEVEL | E6: ASSY CODE | F6: CCT | G6: Std Pack | I6: UMH | J6: FEB | M6: MAR | P6: APR | S6: MAY | V6: JUN | Y6: JUL | AB6: AUG | AG6: JAN | AJ6: FEB | AM6: MAR | AP6: APR | AS6: MAY | AV6: JUN | AY6: JUL
J7: =VLOOKUP(J$6,WEEK!$A$55:$D$66,2,0) -> 02/FEB ~ 27/FEB | M7: =VLOOKUP(M$6,WEEK!$A$55:$D$66,2,0) -> 02/MAR ~ 31/MAR | P7: =VLOOKUP(P$6,WEEK!$A$55:$D$66,2,0) -> 01/APR ~ 30/APR | S7: =VLOOKUP(S$6,WEEK!$A$55:$D$66,2,0) -> 02/MAY ~ 30/MAY | V7: =VLOOKUP(V$6,WEEK!$A$55:$D$66,2,0) -> 02/JUN ~ 30/JUN | Y7: =VLOOKUP(Y$6,WEEK!$A$55:$D$66,2,0) -> 01/JUL ~ 31/JUL | AB7: =VLOOKUP(AB$6,WEEK!$A$55:$D$66,2,0) -> 03/AUG ~ 31/AUG | AG7: 27/DEC ~ 23/JAN | AJ7: 24/JAN ~ 20/FEB | AM7: 21/FEB ~ 27/MAR | AP7: 28/MAR ~ 24/APR | AS7: 25/APR ~ 22/MAY | AV7: 23/MAY ~ 26/JUN | AY7: 27/JUN ~ 24/JUL
J8: BAL | K8: DEL | L8: PROD | M8: BAL | N8: DEL | O8: PROD | P8: BAL | Q8: DEL | R8: PROD | S8: BAL | T8: DEL | U8: PROD | V8: BAL | W8: DEL | X8: PROD | Y8: BAL | Z8: DEL | AA8: PROD | AB8: BAL | AC8: DEL | AD8: PROD | AG8: BAL | AH8: DEL | AI8: PROD | AJ8: BAL | AK8: DEL | AL8: PROD | AM8: BAL | AN8: DEL | AO8: PROD | AP8: BAL | AQ8: DEL | AR8: PROD | AS8: BAL | AT8: DEL | AU8: PROD | AV8: BAL | AW8: DEL | AX8: PROD | AY8: BAL | AZ8: DEL | BA8: PROD
A9: 613D | B9: HEV-LHD | C9: 82111-4DT30 | I9: 5.69724 | J9: 0 | K9: =VLOOKUP($C9,#REF!,9,0) -> #REF! | L9: =IF(J9>K9,0,K9-J9) -> 0 | M9: =J9+L9-K9 -> #REF! | N9: =VLOOKUP($C9,#REF!,9,0) -> #REF! | O9: =IF(M9>N9,0,N9-M9) -> #REF! | P9: =M9+O9-N9 -> #REF! | Q9: =VLOOKUP($C9,#REF!,15,0) -> #REF! | R9: =IF(P9>Q9,0,Q9-P9) -> #REF! | S9: =P9+R9-Q9 -> #REF! | T9: =VLOOKUP($C9,#REF!,21,0) -> #REF! | U9: =IF(S9>T9,0,T9-S9) -> #REF! | V9: =S9+U9-T9 -> #REF! | W9: =VLOOKUP($C9,#REF!,27,0) -> #REF! | X9: =IF(V9>W9,0,W9-V9) -> #REF! | Y9: =V9+X9-W9 -> #REF! | Z9: =VLOOKUP($C9,#REF!,33,0) -> #REF! | AA9: =IF(Y9>Z9,0,Z9-Y9) -> #REF! | AB9: =Y9+AA9-Z9 -> #REF! | AC9: =VLOOKUP($C9,#REF!,39,0) -> #REF! | AD9: =IF(AB9>AC9,0,AC9-AB9) -> #REF! | AG9: =J9*F9 -> 0 | AH9: =K9*F9 -> #REF! | AI9: =L9*F9 -> 0 | AJ9: =M9*F9 -> #REF! | AK9: =N9*F9 -> #REF! | AL9: =O9*F9 -> #REF! | AM9: =P9*F9 -> #REF! | AN9: =Q9*F9 -> #REF! | AO9: =R9*F9 -> #REF! | AP9: =S9*F9 -> #REF! | AQ9: =T9*F9 -> #REF! | AR9: =U9*F9 -> #REF! | AS9: =V9*F9 -> #REF! | AT9: =W9*F9 -> #REF! | AU9: =X9*F9 -> #REF! | AV9: =Y9*F9 -> #REF! | AW9: =Z9*F9 -> #REF! | AX9: =AA9*F9 -> #REF! | AY9: =AB9*F9 -> #REF! | AZ9: =AC9*F9 -> #REF! | BA9: =AD9*F9 -> #REF!
B10: HEV-LHD | C10: 82111-4DT40 | I10: 6.6366733 | J10: 0 | K10: =VLOOKUP($C10,#REF!,9,0) -> #REF! | L10: =IF(J10>K10,0,K10-J10) -> 0 | M10: =J10+L10-K10 -> #REF! | N10: =VLOOKUP($C10,#REF!,9,0) -> #REF! | O10: =IF(M10>N10,0,N10-M10) -> #REF! | P10: =M10+O10-N10 -> #REF! | Q10: =VLOOKUP($C10,#REF!,15,0) -> #REF! | R10: =IF(P10>Q10,0,Q10-P10) -> #REF! | S10: =P10+R10-Q10 -> #REF! | T10: =VLOOKUP($C10,#REF!,21,0) -> #REF! | U10: =IF(S10>T10,0,T10-S10) -> #REF! | V10: =S10+U10-T10 -> #REF! | W10: =VLOOKUP($C10,#REF!,27,0) -> #REF! | X10: =IF(V10>W10,0,W10-V10) -> #REF! | Y10: =V10+X10-W10 -> #REF! | Z10: =VLOOKUP($C10,#REF!,33,0) -> #REF! | AA10: =IF(Y10>Z10,0,Z10-Y10) -> #REF! | AB10: =Y10+AA10-Z10 -> #REF! | AC10: =VLOOKUP($C10,#REF!,39,0) -> #REF! | AD10: =IF(AB10>AC10,0,AC10-AB10) -> #REF! | AG10: =J10*F10 -> 0 | AH10: =K10*F10 -> #REF! | AI10: =L10*F10 -> 0 | AJ10: =M10*F10 -> #REF! | AK10: =N10*F10 -> #REF! | AL10: =O10*F10 -> #REF! | AM10: =P10*F10 -> #REF! | AN10: =Q10*F10 -> #REF! | AO10: =R10*F10 -> #REF! | AP10: =S10*F10 -> #REF! | AQ10: =T10*F10 -> #REF! | AR10: =U10*F10 -> #REF! | AS10: =V10*F10 -> #REF! | AT10: =W10*F10 -> #REF! | AU10: =X10*F10 -> #REF! | AV10: =Y10*F10 -> #REF! | AW10: =Z10*F10 -> #REF! | AX10: =AA10*F10 -> #REF! | AY10: =AB10*F10 -> #REF! | AZ10: =AC10*F10 -> #REF! | BA10: =AD10*F10 -> #REF!
B11: HEV-LHD | C11: 82111-4DT50 | I11: 6.63118 | J11: 0 | K11: =VLOOKUP($C11,#REF!,9,0) -> #REF! | L11: =IF(J11>K11,0,K11-J11) -> 0 | M11: =J11+L11-K11 -> #REF! | N11: =VLOOKUP($C11,#REF!,9,0) -> #REF! | O11: =IF(M11>N11,0,N11-M11) -> #REF! | P11: =M11+O11-N11 -> #REF! | Q11: =VLOOKUP($C11,#REF!,15,0) -> #REF! | R11: =IF(P11>Q11,0,Q11-P11) -> #REF! | S11: =P11+R11-Q11 -> #REF! | T11: =VLOOKUP($C11,#REF!,21,0) -> #REF! | U11: =IF(S11>T11,0,T11-S11) -> #REF! | V11: =S11+U11-T11 -> #REF! | W11: =VLOOKUP($C11,#REF!,27,0) -> #REF! | X11: =IF(V11>W11,0,W11-V11) -> #REF! | Y11: =V11+X11-W11 -> #REF! | Z11: =VLOOKUP($C11,#REF!,33,0) -> #REF! | AA11: =IF(Y11>Z11,0,Z11-Y11) -> #REF! | AB11: =Y11+AA11-Z11 -> #REF! | AC11: =VLOOKUP($C11,#REF!,39,0) -> #REF! | AD11: =IF(AB11>AC11,0,AC11-AB11) -> #REF! | AG11: =J11*F11 -> 0 | AH11: =K11*F11 -> #REF! | AI11: =L11*F11 -> 0 | AJ11: =M11*F11 -> #REF! | AK11: =N11*F11 -> #REF! | AL11: =O11*F11 -> #REF! | AM11: =P11*F11 -> #REF! | AN11: =Q11*F11 -> #REF! | AO11: =R11*F11 -> #REF! | AP11: =S11*F11 -> #REF! | AQ11: =T11*F11 -> #REF! | AR11: =U11*F11 -> #REF! | AS11: =V11*F11 -> #REF! | AT11: =W11*F11 -> #REF! | AU11: =X11*F11 -> #REF! | AV11: =Y11*F11 -> #REF! | AW11: =Z11*F11 -> #REF! | AX11: =AA11*F11 -> #REF! | AY11: =AB11*F11 -> #REF! | AZ11: =AC11*F11 -> #REF! | BA11: =AD11*F11 -> #REF!
B12: GAS-LHD | C12: 82111-4DT60 | I12: 5.3516667 | J12: 0 | K12: =VLOOKUP($C12,#REF!,9,0) -> #REF! | L12: =IF(J12>K12,0,K12-J12) -> 0 | M12: =J12+L12-K12 -> #REF! | N12: =VLOOKUP($C12,#REF!,9,0) -> #REF! | O12: =IF(M12>N12,0,N12-M12) -> #REF! | P12: =M12+O12-N12 -> #REF! | Q12: =VLOOKUP($C12,#REF!,15,0) -> #REF! | R12: =IF(P12>Q12,0,Q12-P12) -> #REF! | S12: =P12+R12-Q12 -> #REF! | T12: =VLOOKUP($C12,#REF!,21,0) -> #REF! | U12: =IF(S12>T12,0,T12-S12) -> #REF! | V12: =S12+U12-T12 -> #REF! | W12: =VLOOKUP($C12,#REF!,27,0) -> #REF! | X12: =IF(V12>W12,0,W12-V12) -> #REF! | Y12: =V12+X12-W12 -> #REF! | Z12: =VLOOKUP($C12,#REF!,33,0) -> #REF! | AA12: =IF(Y12>Z12,0,Z12-Y12) -> #REF! | AB12: =Y12+AA12-Z12 -> #REF! | AC12: =VLOOKUP($C12,#REF!,39,0) -> #REF! | AD12: =IF(AB12>AC12,0,AC12-AB12) -> #REF! | AG12: =J12*F12 -> 0 | AH12: =K12*F12 -> #REF! | AI12: =L12*F12 -> 0 | AJ12: =M12*F12 -> #REF! | AK12: =N12*F12 -> #REF! | AL12: =O12*F12 -> #REF! | AM12: =P12*F12 -> #REF! | AN12: =Q12*F12 -> #REF! | AO12: =R12*F12 -> #REF! | AP12: =S12*F12 -> #REF! | AQ12: =T12*F12 -> #REF! | AR12: =U12*F12 -> #REF! | AS12: =V12*F12 -> #REF! | AT12: =W12*F12 -> #REF! | AU12: =X12*F12 -> #REF! | AV12: =Y12*F12 -> #REF! | AW12: =Z12*F12 -> #REF! | AX12: =AA12*F12 -> #REF! | AY12: =AB12*F12 -> #REF! | AZ12: =AC12*F12 -> #REF! | BA12: =AD12*F12 -> #REF!
B13: HEV-LHD | C13: 82111-4DT70 | I13: 6.03334 | J13: 0 | K13: =VLOOKUP($C13,#REF!,9,0) -> #REF! | L13: =IF(J13>K13,0,K13-J13) -> 0 | M13: =J13+L13-K13 -> #REF! | N13: =VLOOKUP($C13,#REF!,9,0) -> #REF! | O13: =IF(M13>N13,0,N13-M13) -> #REF! | P13: =M13+O13-N13 -> #REF! | Q13: =VLOOKUP($C13,#REF!,15,0) -> #REF! | R13: =IF(P13>Q13,0,Q13-P13) -> #REF! | S13: =P13+R13-Q13 -> #REF! | T13: =VLOOKUP($C13,#REF!,21,0) -> #REF! | U13: =IF(S13>T13,0,T13-S13) -> #REF! | V13: =S13+U13-T13 -> #REF! | W13: =VLOOKUP($C13,#REF!,27,0) -> #REF! | X13: =IF(V13>W13,0,W13-V13) -> #REF! | Y13: =V13+X13-W13 -> #REF! | Z13: =VLOOKUP($C13,#REF!,33,0) -> #REF! | AA13: =IF(Y13>Z13,0,Z13-Y13) -> #REF! | AB13: =Y13+AA13-Z13 -> #REF! | AC13: =VLOOKUP($C13,#REF!,39,0) -> #REF! | AD13: =IF(AB13>AC13,0,AC13-AB13) -> #REF! | AG13: =J13*F13 -> 0 | AH13: =K13*F13 -> #REF! | AI13: =L13*F13 -> 0 | AJ13: =M13*F13 -> #REF! | AK13: =N13*F13 -> #REF! | AL13: =O13*F13 -> #REF! | AM13: =P13*F13 -> #REF! | AN13: =Q13*F13 -> #REF! | AO13: =R13*F13 -> #REF! | AP13: =S13*F13 -> #REF! | AQ13: =T13*F13 -> #REF! | AR13: =U13*F13 -> #REF! | AS13: =V13*F13 -> #REF! | AT13: =W13*F13 -> #REF! | AU13: =X13*F13 -> #REF! | AV13: =Y13*F13 -> #REF! | AW13: =Z13*F13 -> #REF! | AX13: =AA13*F13 -> #REF! | AY13: =AB13*F13 -> #REF! | AZ13: =AC13*F13 -> #REF! | BA13: =AD13*F13 -> #REF!
B14: HEV-LHD | C14: 82111-4DT80 | I14: 5.962445 | J14: 0 | K14: =VLOOKUP($C14,#REF!,9,0) -> #REF! | L14: =IF(J14>K14,0,K14-J14) -> 0 | M14: =J14+L14-K14 -> #REF! | N14: =VLOOKUP($C14,#REF!,9,0) -> #REF! | O14: =IF(M14>N14,0,N14-M14) -> #REF! | P14: =M14+O14-N14 -> #REF! | Q14: =VLOOKUP($C14,#REF!,15,0) -> #REF! | R14: =IF(P14>Q14,0,Q14-P14) -> #REF! | S14: =P14+R14-Q14 -> #REF! | T14: =VLOOKUP($C14,#REF!,21,0) -> #REF! | U14: =IF(S14>T14,0,T14-S14) -> #REF! | V14: =S14+U14-T14 -> #REF! | W14: =VLOOKUP($C14,#REF!,27,0) -> #REF! | X14: =IF(V14>W14,0,W14-V14) -> #REF! | Y14: =V14+X14-W14 -> #REF! | Z14: =VLOOKUP($C14,#REF!,33,0) -> #REF! | AA14: =IF(Y14>Z14,0,Z14-Y14) -> #REF! | AB14: =Y14+AA14-Z14 -> #REF! | AC14: =VLOOKUP($C14,#REF!,39,0) -> #REF! | AD14: =IF(AB14>AC14,0,AC14-AB14) -> #REF! | AG14: =J14*F14 -> 0 | AH14: =K14*F14 -> #REF! | AI14: =L14*F14 -> 0 | AJ14: =M14*F14 -> #REF! | AK14: =N14*F14 -> #REF! | AL14: =O14*F14 -> #REF! | AM14: =P14*F14 -> #REF! | AN14: =Q14*F14 -> #REF! | AO14: =R14*F14 -> #REF! | AP14: =S14*F14 -> #REF! | AQ14: =T14*F14 -> #REF! | AR14: =U14*F14 -> #REF! | AS14: =V14*F14 -> #REF! | AT14: =W14*F14 -> #REF! | AU14: =X14*F14 -> #REF! | AV14: =Y14*F14 -> #REF! | AW14: =Z14*F14 -> #REF! | AX14: =AA14*F14 -> #REF! | AY14: =AB14*F14 -> #REF! | AZ14: =AC14*F14 -> #REF! | BA14: =AD14*F14 -> #REF!
B15: HEV-LHD | C15: 82111-4DT90 | I15: 5.9974267 | J15: 0 | K15: =VLOOKUP($C15,#REF!,9,0) -> #REF! | L15: =IF(J15>K15,0,K15-J15) -> 0 | M15: =J15+L15-K15 -> #REF! | N15: =VLOOKUP($C15,#REF!,9,0) -> #REF! | O15: =IF(M15>N15,0,N15-M15) -> #REF! | P15: =M15+O15-N15 -> #REF! | Q15: =VLOOKUP($C15,#REF!,15,0) -> #REF! | R15: =IF(P15>Q15,0,Q15-P15) -> #REF! | S15: =P15+R15-Q15 -> #REF! | T15: =VLOOKUP($C15,#REF!,21,0) -> #REF! | U15: =IF(S15>T15,0,T15-S15) -> #REF! | V15: =S15+U15-T15 -> #REF! | W15: =VLOOKUP($C15,#REF!,27,0) -> #REF! | X15: =IF(V15>W15,0,W15-V15) -> #REF! | Y15: =V15+X15-W15 -> #REF! | Z15: =VLOOKUP($C15,#REF!,33,0) -> #REF! | AA15: =IF(Y15>Z15,0,Z15-Y15) -> #REF! | AB15: =Y15+AA15-Z15 -> #REF! | AC15: =VLOOKUP($C15,#REF!,39,0) -> #REF! | AD15: =IF(AB15>AC15,0,AC15-AB15) -> #REF! | AG15: =J15*F15 -> 0 | AH15: =K15*F15 -> #REF! | AI15: =L15*F15 -> 0 | AJ15: =M15*F15 -> #REF! | AK15: =N15*F15 -> #REF! | AL15: =O15*F15 -> #REF! | AM15: =P15*F15 -> #REF! | AN15: =Q15*F15 -> #REF! | AO15: =R15*F15 -> #REF! | AP15: =S15*F15 -> #REF! | AQ15: =T15*F15 -> #REF! | AR15: =U15*F15 -> #REF! | AS15: =V15*F15 -> #REF! | AT15: =W15*F15 -> #REF! | AU15: =X15*F15 -> #REF! | AV15: =Y15*F15 -> #REF! | AW15: =Z15*F15 -> #REF! | AX15: =AA15*F15 -> #REF! | AY15: =AB15*F15 -> #REF! | AZ15: =AC15*F15 -> #REF! | BA15: =AD15*F15 -> #REF!
B16: HEV-LHD | C16: 82111-4DU00 | I16: 5.96211 | J16: 0 | K16: =VLOOKUP($C16,#REF!,9,0) -> #REF! | L16: =IF(J16>K16,0,K16-J16) -> 0 | M16: =J16+L16-K16 -> #REF! | N16: =VLOOKUP($C16,#REF!,9,0) -> #REF! | O16: =IF(M16>N16,0,N16-M16) -> #REF! | P16: =M16+O16-N16 -> #REF! | Q16: =VLOOKUP($C16,#REF!,15,0) -> #REF! | R16: =IF(P16>Q16,0,Q16-P16) -> #REF! | S16: =P16+R16-Q16 -> #REF! | T16: =VLOOKUP($C16,#REF!,21,0) -> #REF! | U16: =IF(S16>T16,0,T16-S16) -> #REF! | V16: =S16+U16-T16 -> #REF! | W16: =VLOOKUP($C16,#REF!,27,0) -> #REF! | X16: =IF(V16>W16,0,W16-V16) -> #REF! | Y16: =V16+X16-W16 -> #REF! | Z16: =VLOOKUP($C16,#REF!,33,0) -> #REF! | AA16: =IF(Y16>Z16,0,Z16-Y16) -> #REF! | AB16: =Y16+AA16-Z16 -> #REF! | AC16: =VLOOKUP($C16,#REF!,39,0) -> #REF! | AD16: =IF(AB16>AC16,0,AC16-AB16) -> #REF! | AG16: =J16*F16 -> 0 | AH16: =K16*F16 -> #REF! | AI16: =L16*F16 -> 0 | AJ16: =M16*F16 -> #REF! | AK16: =N16*F16 -> #REF! | AL16: =O16*F16 -> #REF! | AM16: =P16*F16 -> #REF! | AN16: =Q16*F16 -> #REF! | AO16: =R16*F16 -> #REF! | AP16: =S16*F16 -> #REF! | AQ16: =T16*F16 -> #REF! | AR16: =U16*F16 -> #REF! | AS16: =V16*F16 -> #REF! | AT16: =W16*F16 -> #REF! | AU16: =X16*F16 -> #REF! | AV16: =Y16*F16 -> #REF! | AW16: =Z16*F16 -> #REF! | AX16: =AA16*F16 -> #REF! | AY16: =AB16*F16 -> #REF! | AZ16: =AC16*F16 -> #REF! | BA16: =AD16*F16 -> #REF!
B17: HEV-LHD | C17: 82111-4DU10 | I17: 5.8925217 | J17: 0 | K17: =VLOOKUP($C17,#REF!,9,0) -> #REF! | L17: =IF(J17>K17,0,K17-J17) -> 0 | M17: =J17+L17-K17 -> #REF! | N17: =VLOOKUP($C17,#REF!,9,0) -> #REF! | O17: =IF(M17>N17,0,N17-M17) -> #REF! | P17: =M17+O17-N17 -> #REF! | Q17: =VLOOKUP($C17,#REF!,15,0) -> #REF! | R17: =IF(P17>Q17,0,Q17-P17) -> #REF! | S17: =P17+R17-Q17 -> #REF! | T17: =VLOOKUP($C17,#REF!,21,0) -> #REF! | U17: =IF(S17>T17,0,T17-S17) -> #REF! | V17: =S17+U17-T17 -> #REF! | W17: =VLOOKUP($C17,#REF!,27,0) -> #REF! | X17: =IF(V17>W17,0,W17-V17) -> #REF! | Y17: =V17+X17-W17 -> #REF! | Z17: =VLOOKUP($C17,#REF!,33,0) -> #REF! | AA17: =IF(Y17>Z17,0,Z17-Y17) -> #REF! | AB17: =Y17+AA17-Z17 -> #REF! | AC17: =VLOOKUP($C17,#REF!,39,0) -> #REF! | AD17: =IF(AB17>AC17,0,AC17-AB17) -> #REF! | AG17: =J17*F17 -> 0 | AH17: =K17*F17 -> #REF! | AI17: =L17*F17 -> 0 | AJ17: =M17*F17 -> #REF! | AK17: =N17*F17 -> #REF! | AL17: =O17*F17 -> #REF! | AM17: =P17*F17 -> #REF! | AN17: =Q17*F17 -> #REF! | AO17: =R17*F17 -> #REF! | AP17: =S17*F17 -> #REF! | AQ17: =T17*F17 -> #REF! | AR17: =U17*F17 -> #REF! | AS17: =V17*F17 -> #REF! | AT17: =W17*F17 -> #REF! | AU17: =X17*F17 -> #REF! | AV17: =Y17*F17 -> #REF! | AW17: =Z17*F17 -> #REF! | AX17: =AA17*F17 -> #REF! | AY17: =AB17*F17 -> #REF! | AZ17: =AC17*F17 -> #REF! | BA17: =AD17*F17 -> #REF!
B18: HEV-LHD | C18: 82111-4DU20 | I18: =VLOOKUP(C18,#REF!,18,0) -> #REF! | J18: 0 | K18: =VLOOKUP($C18,#REF!,9,0) -> #REF! | L18: =IF(J18>K18,0,K18-J18) -> 0 | M18: =J18+L18-K18 -> #REF! | N18: =VLOOKUP($C18,#REF!,9,0) -> #REF! | O18: =IF(M18>N18,0,N18-M18) -> #REF! | P18: =M18+O18-N18 -> #REF! | Q18: =VLOOKUP($C18,#REF!,15,0) -> #REF! | R18: =IF(P18>Q18,0,Q18-P18) -> #REF! | S18: =P18+R18-Q18 -> #REF! | T18: =VLOOKUP($C18,#REF!,21,0) -> #REF! | U18: =IF(S18>T18,0,T18-S18) -> #REF! | V18: =S18+U18-T18 -> #REF! | W18: =VLOOKUP($C18,#REF!,27,0) -> #REF! | X18: =IF(V18>W18,0,W18-V18) -> #REF! | Y18: =V18+X18-W18 -> #REF! | Z18: =VLOOKUP($C18,#REF!,33,0) -> #REF! | AA18: =IF(Y18>Z18,0,Z18-Y18) -> #REF! | AB18: =Y18+AA18-Z18 -> #REF! | AC18: =VLOOKUP($C18,#REF!,39,0) -> #REF! | AD18: =IF(AB18>AC18,0,AC18-AB18) -> #REF! | AG18: =J18*F18 -> 0 | AH18: =K18*F18 -> #REF! | AI18: =L18*F18 -> 0 | AJ18: =M18*F18 -> #REF! | AK18: =N18*F18 -> #REF! | AL18: =O18*F18 -> #REF! | AM18: =P18*F18 -> #REF! | AN18: =Q18*F18 -> #REF! | AO18: =R18*F18 -> #REF! | AP18: =S18*F18 -> #REF! | AQ18: =T18*F18 -> #REF! | AR18: =U18*F18 -> #REF! | AS18: =V18*F18 -> #REF! | AT18: =W18*F18 -> #REF! | AU18: =X18*F18 -> #REF! | AV18: =Y18*F18 -> #REF! | AW18: =Z18*F18 -> #REF! | AX18: =AA18*F18 -> #REF! | AY18: =AB18*F18 -> #REF! | AZ18: =AC18*F18 -> #REF! | BA18: =AD18*F18 -> #REF!
B19: HEV-LHD | C19: 82111-4DU30 | I19: =VLOOKUP(C19,#REF!,18,0) -> #REF! | J19: 0 | K19: =VLOOKUP($C19,#REF!,9,0) -> #REF! | L19: =IF(J19>K19,0,K19-J19) -> 0 | M19: =J19+L19-K19 -> #REF! | N19: =VLOOKUP($C19,#REF!,9,0) -> #REF! | O19: =IF(M19>N19,0,N19-M19) -> #REF! | P19: =M19+O19-N19 -> #REF! | Q19: =VLOOKUP($C19,#REF!,15,0) -> #REF! | R19: =IF(P19>Q19,0,Q19-P19) -> #REF! | S19: =P19+R19-Q19 -> #REF! | T19: =VLOOKUP($C19,#REF!,21,0) -> #REF! | U19: =IF(S19>T19,0,T19-S19) -> #REF! | V19: =S19+U19-T19 -> #REF! | W19: =VLOOKUP($C19,#REF!,27,0) -> #REF! | X19: =IF(V19>W19,0,W19-V19) -> #REF! | Y19: =V19+X19-W19 -> #REF! | Z19: =VLOOKUP($C19,#REF!,33,0) -> #REF! | AA19: =IF(Y19>Z19,0,Z19-Y19) -> #REF! | AB19: =Y19+AA19-Z19 -> #REF! | AC19: =VLOOKUP($C19,#REF!,39,0) -> #REF! | AD19: =IF(AB19>AC19,0,AC19-AB19) -> #REF! | AG19: =J19*F19 -> 0 | AH19: =K19*F19 -> #REF! | AI19: =L19*F19 -> 0 | AJ19: =M19*F19 -> #REF! | AK19: =N19*F19 -> #REF! | AL19: =O19*F19 -> #REF! | AM19: =P19*F19 -> #REF! | AN19: =Q19*F19 -> #REF! | AO19: =R19*F19 -> #REF! | AP19: =S19*F19 -> #REF! | AQ19: =T19*F19 -> #REF! | AR19: =U19*F19 -> #REF! | AS19: =V19*F19 -> #REF! | AT19: =W19*F19 -> #REF! | AU19: =X19*F19 -> #REF! | AV19: =Y19*F19 -> #REF! | AW19: =Z19*F19 -> #REF! | AX19: =AA19*F19 -> #REF! | AY19: =AB19*F19 -> #REF! | AZ19: =AC19*F19 -> #REF! | BA19: =AD19*F19 -> #REF!
B20: HEV-LHD | C20: 82111-4DU40 | I20: =VLOOKUP(C20,#REF!,18,0) -> #REF! | J20: 0 | K20: =VLOOKUP($C20,#REF!,9,0) -> #REF! | L20: =IF(J20>K20,0,K20-J20) -> 0 | M20: =J20+L20-K20 -> #REF! | N20: =VLOOKUP($C20,#REF!,9,0) -> #REF! | O20: =IF(M20>N20,0,N20-M20) -> #REF! | P20: =M20+O20-N20 -> #REF! | Q20: =VLOOKUP($C20,#REF!,15,0) -> #REF! | R20: =IF(P20>Q20,0,Q20-P20) -> #REF! | S20: =P20+R20-Q20 -> #REF! | T20: =VLOOKUP($C20,#REF!,21,0) -> #REF! | U20: =IF(S20>T20,0,T20-S20) -> #REF! | V20: =S20+U20-T20 -> #REF! | W20: =VLOOKUP($C20,#REF!,27,0) -> #REF! | X20: =IF(V20>W20,0,W20-V20) -> #REF! | Y20: =V20+X20-W20 -> #REF! | Z20: =VLOOKUP($C20,#REF!,33,0) -> #REF! | AA20: =IF(Y20>Z20,0,Z20-Y20) -> #REF! | AB20: =Y20+AA20-Z20 -> #REF! | AC20: =VLOOKUP($C20,#REF!,39,0) -> #REF! | AD20: =IF(AB20>AC20,0,AC20-AB20) -> #REF! | AG20: =J20*F20 -> 0 | AH20: =K20*F20 -> #REF! | AI20: =L20*F20 -> 0 | AJ20: =M20*F20 -> #REF! | AK20: =N20*F20 -> #REF! | AL20: =O20*F20 -> #REF! | AM20: =P20*F20 -> #REF! | AN20: =Q20*F20 -> #REF! | AO20: =R20*F20 -> #REF! | AP20: =S20*F20 -> #REF! | AQ20: =T20*F20 -> #REF! | AR20: =U20*F20 -> #REF! | AS20: =V20*F20 -> #REF! | AT20: =W20*F20 -> #REF! | AU20: =X20*F20 -> #REF! | AV20: =Y20*F20 -> #REF! | AW20: =Z20*F20 -> #REF! | AX20: =AA20*F20 -> #REF! | AY20: =AB20*F20 -> #REF! | AZ20: =AC20*F20 -> #REF! | BA20: =AD20*F20 -> #REF!
B21: HEV-RHD | C21: 82111-4DU60 | I21: =VLOOKUP(C21,#REF!,18,0) -> #REF! | J21: 7 | K21: =VLOOKUP($C21,#REF!,9,0) -> #REF! | L21: =IF(J21>K21,0,K21-J21) -> 0 | M21: =J21+L21-K21 -> #REF! | N21: =VLOOKUP($C21,#REF!,9,0) -> #REF! | O21: =IF(M21>N21,0,N21-M21) -> #REF! | P21: =M21+O21-N21 -> #REF! | Q21: =VLOOKUP($C21,#REF!,15,0) -> #REF! | R21: =IF(P21>Q21,0,Q21-P21) -> #REF! | S21: =P21+R21-Q21 -> #REF! | T21: =VLOOKUP($C21,#REF!,21,0) -> #REF! | U21: =IF(S21>T21,0,T21-S21) -> #REF! | V21: =S21+U21-T21 -> #REF! | W21: =VLOOKUP($C21,#REF!,27,0) -> #REF! | X21: =IF(V21>W21,0,W21-V21) -> #REF! | Y21: =V21+X21-W21 -> #REF! | Z21: =VLOOKUP($C21,#REF!,33,0) -> #REF! | AA21: =IF(Y21>Z21,0,Z21-Y21) -> #REF! | AB21: =Y21+AA21-Z21 -> #REF! | AC21: =VLOOKUP($C21,#REF!,39,0) -> #REF! | AD21: =IF(AB21>AC21,0,AC21-AB21) -> #REF! | AG21: =J21*F21 -> 0 | AH21: =K21*F21 -> #REF! | AI21: =L21*F21 -> 0 | AJ21: =M21*F21 -> #REF! | AK21: =N21*F21 -> #REF! | AL21: =O21*F21 -> #REF! | AM21: =P21*F21 -> #REF! | AN21: =Q21*F21 -> #REF! | AO21: =R21*F21 -> #REF! | AP21: =S21*F21 -> #REF! | AQ21: =T21*F21 -> #REF! | AR21: =U21*F21 -> #REF! | AS21: =V21*F21 -> #REF! | AT21: =W21*F21 -> #REF! | AU21: =X21*F21 -> #REF! | AV21: =Y21*F21 -> #REF! | AW21: =Z21*F21 -> #REF! | AX21: =AA21*F21 -> #REF! | AY21: =AB21*F21 -> #REF! | AZ21: =AC21*F21 -> #REF! | BA21: =AD21*F21 -> #REF!
B22: HEV-RHD | C22: 82111-4DU70 | I22: =VLOOKUP(C22,#REF!,18,0) -> #REF! | J22: 0 | K22: =VLOOKUP($C22,#REF!,9,0) -> #REF! | L22: =IF(J22>K22,0,K22-J22) -> 0 | M22: =J22+L22-K22 -> #REF! | N22: =VLOOKUP($C22,#REF!,9,0) -> #REF! | O22: =IF(M22>N22,0,N22-M22) -> #REF! | P22: =M22+O22-N22 -> #REF! | Q22: =VLOOKUP($C22,#REF!,15,0) -> #REF! | R22: =IF(P22>Q22,0,Q22-P22) -> #REF! | S22: =P22+R22-Q22 -> #REF! | T22: =VLOOKUP($C22,#REF!,21,0) -> #REF! | U22: =IF(S22>T22,0,T22-S22) -> #REF! | V22: =S22+U22-T22 -> #REF! | W22: =VLOOKUP($C22,#REF!,27,0) -> #REF! | X22: =IF(V22>W22,0,W22-V22) -> #REF! | Y22: =V22+X22-W22 -> #REF! | Z22: =VLOOKUP($C22,#REF!,33,0) -> #REF! | AA22: =IF(Y22>Z22,0,Z22-Y22) -> #REF! | AB22: =Y22+AA22-Z22 -> #REF! | AC22: =VLOOKUP($C22,#REF!,39,0) -> #REF! | AD22: =IF(AB22>AC22,0,AC22-AB22) -> #REF! | AG22: =J22*F22 -> 0 | AH22: =K22*F22 -> #REF! | AI22: =L22*F22 -> 0 | AJ22: =M22*F22 -> #REF! | AK22: =N22*F22 -> #REF! | AL22: =O22*F22 -> #REF! | AM22: =P22*F22 -> #REF! | AN22: =Q22*F22 -> #REF! | AO22: =R22*F22 -> #REF! | AP22: =S22*F22 -> #REF! | AQ22: =T22*F22 -> #REF! | AR22: =U22*F22 -> #REF! | AS22: =V22*F22 -> #REF! | AT22: =W22*F22 -> #REF! | AU22: =X22*F22 -> #REF! | AV22: =Y22*F22 -> #REF! | AW22: =Z22*F22 -> #REF! | AX22: =AA22*F22 -> #REF! | AY22: =AB22*F22 -> #REF! | AZ22: =AC22*F22 -> #REF! | BA22: =AD22*F22 -> #REF!
B23: HEV-RHD | C23: 82111-4DU80 | I23: =VLOOKUP(C23,#REF!,18,0) -> #REF! | J23: 2 | K23: =VLOOKUP($C23,#REF!,9,0) -> #REF! | L23: =IF(J23>K23,0,K23-J23) -> 0 | M23: =J23+L23-K23 -> #REF! | N23: =VLOOKUP($C23,#REF!,9,0) -> #REF! | O23: =IF(M23>N23,0,N23-M23) -> #REF! | P23: =M23+O23-N23 -> #REF! | Q23: =VLOOKUP($C23,#REF!,15,0) -> #REF! | R23: =IF(P23>Q23,0,Q23-P23) -> #REF! | S23: =P23+R23-Q23 -> #REF! | T23: =VLOOKUP($C23,#REF!,21,0) -> #REF! | U23: =IF(S23>T23,0,T23-S23) -> #REF! | V23: =S23+U23-T23 -> #REF! | W23: =VLOOKUP($C23,#REF!,27,0) -> #REF! | X23: =IF(V23>W23,0,W23-V23) -> #REF! | Y23: =V23+X23-W23 -> #REF! | Z23: =VLOOKUP($C23,#REF!,33,0) -> #REF! | AA23: =IF(Y23>Z23,0,Z23-Y23) -> #REF! | AB23: =Y23+AA23-Z23 -> #REF! | AC23: =VLOOKUP($C23,#REF!,39,0) -> #REF! | AD23: =IF(AB23>AC23,0,AC23-AB23) -> #REF! | AG23: =J23*F23 -> 0 | AH23: =K23*F23 -> #REF! | AI23: =L23*F23 -> 0 | AJ23: =M23*F23 -> #REF! | AK23: =N23*F23 -> #REF! | AL23: =O23*F23 -> #REF! | AM23: =P23*F23 -> #REF! | AN23: =Q23*F23 -> #REF! | AO23: =R23*F23 -> #REF! | AP23: =S23*F23 -> #REF! | AQ23: =T23*F23 -> #REF! | AR23: =U23*F23 -> #REF! | AS23: =V23*F23 -> #REF! | AT23: =W23*F23 -> #REF! | AU23: =X23*F23 -> #REF! | AV23: =Y23*F23 -> #REF! | AW23: =Z23*F23 -> #REF! | AX23: =AA23*F23 -> #REF! | AY23: =AB23*F23 -> #REF! | AZ23: =AC23*F23 -> #REF! | BA23: =AD23*F23 -> #REF!
B24: HEV-RHD | C24: 82111-4DU90 | I24: =VLOOKUP(C24,#REF!,18,0) -> #REF! | J24: 0 | K24: =VLOOKUP($C24,#REF!,9,0) -> #REF! | L24: =IF(J24>K24,0,K24-J24) -> 0 | M24: =J24+L24-K24 -> #REF! | N24: =VLOOKUP($C24,#REF!,9,0) -> #REF! | O24: =IF(M24>N24,0,N24-M24) -> #REF! | P24: =M24+O24-N24 -> #REF! | Q24: =VLOOKUP($C24,#REF!,15,0) -> #REF! | R24: =IF(P24>Q24,0,Q24-P24) -> #REF! | S24: =P24+R24-Q24 -> #REF! | T24: =VLOOKUP($C24,#REF!,21,0) -> #REF! | U24: =IF(S24>T24,0,T24-S24) -> #REF! | V24: =S24+U24-T24 -> #REF! | W24: =VLOOKUP($C24,#REF!,27,0) -> #REF! | X24: =IF(V24>W24,0,W24-V24) -> #REF! | Y24: =V24+X24-W24 -> #REF! | Z24: =VLOOKUP($C24,#REF!,33,0) -> #REF! | AA24: =IF(Y24>Z24,0,Z24-Y24) -> #REF! | AB24: =Y24+AA24-Z24 -> #REF! | AC24: =VLOOKUP($C24,#REF!,39,0) -> #REF! | AD24: =IF(AB24>AC24,0,AC24-AB24) -> #REF! | AG24: =J24*F24 -> 0 | AH24: =K24*F24 -> #REF! | AI24: =L24*F24 -> 0 | AJ24: =M24*F24 -> #REF! | AK24: =N24*F24 -> #REF! | AL24: =O24*F24 -> #REF! | AM24: =P24*F24 -> #REF! | AN24: =Q24*F24 -> #REF! | AO24: =R24*F24 -> #REF! | AP24: =S24*F24 -> #REF! | AQ24: =T24*F24 -> #REF! | AR24: =U24*F24 -> #REF! | AS24: =V24*F24 -> #REF! | AT24: =W24*F24 -> #REF! | AU24: =X24*F24 -> #REF! | AV24: =Y24*F24 -> #REF! | AW24: =Z24*F24 -> #REF! | AX24: =AA24*F24 -> #REF! | AY24: =AB24*F24 -> #REF! | AZ24: =AC24*F24 -> #REF! | BA24: =AD24*F24 -> #REF!
B25: GAS-LHD | C25: 82111-4DV00 | I25: =VLOOKUP(C25,#REF!,18,0) -> #REF! | J25: 0 | K25: =VLOOKUP($C25,#REF!,9,0) -> #REF! | L25: =IF(J25>K25,0,K25-J25) -> 0 | M25: =J25+L25-K25 -> #REF! | N25: =VLOOKUP($C25,#REF!,9,0) -> #REF! | O25: =IF(M25>N25,0,N25-M25) -> #REF! | P25: =M25+O25-N25 -> #REF! | Q25: =VLOOKUP($C25,#REF!,15,0) -> #REF! | R25: =IF(P25>Q25,0,Q25-P25) -> #REF! | S25: =P25+R25-Q25 -> #REF! | T25: =VLOOKUP($C25,#REF!,21,0) -> #REF! | U25: =IF(S25>T25,0,T25-S25) -> #REF! | V25: =S25+U25-T25 -> #REF! | W25: =VLOOKUP($C25,#REF!,27,0) -> #REF! | X25: =IF(V25>W25,0,W25-V25) -> #REF! | Y25: =V25+X25-W25 -> #REF! | Z25: =VLOOKUP($C25,#REF!,33,0) -> #REF! | AA25: =IF(Y25>Z25,0,Z25-Y25) -> #REF! | AB25: =Y25+AA25-Z25 -> #REF! | AC25: =VLOOKUP($C25,#REF!,39,0) -> #REF! | AD25: =IF(AB25>AC25,0,AC25-AB25) -> #REF! | AG25: =J25*F25 -> 0 | AH25: =K25*F25 -> #REF! | AI25: =L25*F25 -> 0 | AJ25: =M25*F25 -> #REF! | AK25: =N25*F25 -> #REF! | AL25: =O25*F25 -> #REF! | AM25: =P25*F25 -> #REF! | AN25: =Q25*F25 -> #REF! | AO25: =R25*F25 -> #REF! | AP25: =S25*F25 -> #REF! | AQ25: =T25*F25 -> #REF! | AR25: =U25*F25 -> #REF! | AS25: =V25*F25 -> #REF! | AT25: =W25*F25 -> #REF! | AU25: =X25*F25 -> #REF! | AV25: =Y25*F25 -> #REF! | AW25: =Z25*F25 -> #REF! | AX25: =AA25*F25 -> #REF! | AY25: =AB25*F25 -> #REF! | AZ25: =AC25*F25 -> #REF! | BA25: =AD25*F25 -> #REF!
B26: HEV-LHD | C26: 82111-4DV10 | I26: =VLOOKUP(C26,#REF!,18,0) -> #REF! | J26: 0 | K26: =VLOOKUP($C26,#REF!,9,0) -> #REF! | L26: =IF(J26>K26,0,K26-J26) -> 0 | M26: =J26+L26-K26 -> #REF! | N26: =VLOOKUP($C26,#REF!,9,0) -> #REF! | O26: =IF(M26>N26,0,N26-M26) -> #REF! | P26: =M26+O26-N26 -> #REF! | Q26: =VLOOKUP($C26,#REF!,15,0) -> #REF! | R26: =IF(P26>Q26,0,Q26-P26) -> #REF! | S26: =P26+R26-Q26 -> #REF! | T26: =VLOOKUP($C26,#REF!,21,0) -> #REF! | U26: =IF(S26>T26,0,T26-S26) -> #REF! | V26: =S26+U26-T26 -> #REF! | W26: =VLOOKUP($C26,#REF!,27,0) -> #REF! | X26: =IF(V26>W26,0,W26-V26) -> #REF! | Y26: =V26+X26-W26 -> #REF! | Z26: =VLOOKUP($C26,#REF!,33,0) -> #REF! | AA26: =IF(Y26>Z26,0,Z26-Y26) -> #REF! | AB26: =Y26+AA26-Z26 -> #REF! | AC26: =VLOOKUP($C26,#REF!,39,0) -> #REF! | AD26: =IF(AB26>AC26,0,AC26-AB26) -> #REF! | AG26: =J26*F26 -> 0 | AH26: =K26*F26 -> #REF! | AI26: =L26*F26 -> 0 | AJ26: =M26*F26 -> #REF! | AK26: =N26*F26 -> #REF! | AL26: =O26*F26 -> #REF! | AM26: =P26*F26 -> #REF! | AN26: =Q26*F26 -> #REF! | AO26: =R26*F26 -> #REF! | AP26: =S26*F26 -> #REF! | AQ26: =T26*F26 -> #REF! | AR26: =U26*F26 -> #REF! | AS26: =V26*F26 -> #REF! | AT26: =W26*F26 -> #REF! | AU26: =X26*F26 -> #REF! | AV26: =Y26*F26 -> #REF! | AW26: =Z26*F26 -> #REF! | AX26: =AA26*F26 -> #REF! | AY26: =AB26*F26 -> #REF! | AZ26: =AC26*F26 -> #REF! | BA26: =AD26*F26 -> #REF!
B27: HEV-RHD | C27: 82111-4DV30 | I27: =VLOOKUP(C27,#REF!,18,0) -> #REF! | J27: 0 | K27: =VLOOKUP($C27,#REF!,9,0) -> #REF! | L27: =IF(J27>K27,0,K27-J27) -> 0 | M27: =J27+L27-K27 -> #REF! | N27: =VLOOKUP($C27,#REF!,9,0) -> #REF! | O27: =IF(M27>N27,0,N27-M27) -> #REF! | P27: =M27+O27-N27 -> #REF! | Q27: =VLOOKUP($C27,#REF!,15,0) -> #REF! | R27: =IF(P27>Q27,0,Q27-P27) -> #REF! | S27: =P27+R27-Q27 -> #REF! | T27: =VLOOKUP($C27,#REF!,21,0) -> #REF! | U27: =IF(S27>T27,0,T27-S27) -> #REF! | V27: =S27+U27-T27 -> #REF! | W27: =VLOOKUP($C27,#REF!,27,0) -> #REF! | X27: =IF(V27>W27,0,W27-V27) -> #REF! | Y27: =V27+X27-W27 -> #REF! | Z27: =VLOOKUP($C27,#REF!,33,0) -> #REF! | AA27: =IF(Y27>Z27,0,Z27-Y27) -> #REF! | AB27: =Y27+AA27-Z27 -> #REF! | AC27: =VLOOKUP($C27,#REF!,39,0) -> #REF! | AD27: =IF(AB27>AC27,0,AC27-AB27) -> #REF! | AG27: =J27*F27 -> 0 | AH27: =K27*F27 -> #REF! | AI27: =L27*F27 -> 0 | AJ27: =M27*F27 -> #REF! | AK27: =N27*F27 -> #REF! | AL27: =O27*F27 -> #REF! | AM27: =P27*F27 -> #REF! | AN27: =Q27*F27 -> #REF! | AO27: =R27*F27 -> #REF! | AP27: =S27*F27 -> #REF! | AQ27: =T27*F27 -> #REF! | AR27: =U27*F27 -> #REF! | AS27: =V27*F27 -> #REF! | AT27: =W27*F27 -> #REF! | AU27: =X27*F27 -> #REF! | AV27: =Y27*F27 -> #REF! | AW27: =Z27*F27 -> #REF! | AX27: =AA27*F27 -> #REF! | AY27: =AB27*F27 -> #REF! | AZ27: =AC27*F27 -> #REF! | BA27: =AD27*F27 -> #REF!
I28: =VLOOKUP(C28,#REF!,18,0) -> #REF! | L28: =IF(J28>K28,0,K28-J28) -> 0 | O28: =IF(M28>N28,0,N28-M28) -> 0 | R28: =IF(P28>Q28,0,Q28-P28) -> 0 | U28: =IF(S28>T28,0,T28-S28) -> 0 | X28: =IF(V28>W28,0,W28-V28) -> 0 | AG28: =J28*F28 -> 0 | AH28: =K28*F28 -> 0 | AI28: =L28*F28 -> 0 | AJ28: =M28*F28 -> 0 | AK28: =N28*F28 -> 0 | AL28: =O28*F28 -> 0 | AM28: =P28*F28 -> 0 | AN28: =Q28*F28 -> 0 | AO28: =R28*F28 -> 0 | AP28: =S28*F28 -> 0 | AQ28: =T28*F28 -> 0 | AR28: =U28*F28 -> 0 | AS28: =V28*F28 -> 0 | AT28: =W28*F28 -> 0 | AU28: =X28*F28 -> 0 | AV28: =Y28*F28 -> 0 | AW28: =Z28*F28 -> 0 | AX28: =AA28*F28 -> 0 | AY28: =AB28*F28 -> 0 | AZ28: =AC28*F28 -> 0 | BA28: =AD28*F28 -> 0
I29: =VLOOKUP(C29,#REF!,18,0) -> #REF! | L29: =IF(J29>K29,0,K29-J29) -> 0 | O29: =IF(M29>N29,0,N29-M29) -> 0 | R29: =IF(P29>Q29,0,Q29-P29) -> 0 | U29: =IF(S29>T29,0,T29-S29) -> 0 | X29: =IF(V29>W29,0,W29-V29) -> 0 | AG29: =J29*F29 -> 0 | AH29: =K29*F29 -> 0 | AI29: =L29*F29 -> 0 | AJ29: =M29*F29 -> 0 | AK29: =N29*F29 -> 0 | AL29: =O29*F29 -> 0 | AM29: =P29*F29 -> 0 | AN29: =Q29*F29 -> 0 | AO29: =R29*F29 -> 0 | AP29: =S29*F29 -> 0 | AQ29: =T29*F29 -> 0 | AR29: =U29*F29 -> 0 | AS29: =V29*F29 -> 0 | AT29: =W29*F29 -> 0 | AU29: =X29*F29 -> 0 | AV29: =Y29*F29 -> 0 | AW29: =Z29*F29 -> 0 | AX29: =AA29*F29 -> 0 | AY29: =AB29*F29 -> 0 | AZ29: =AC29*F29 -> 0 | BA29: =AD29*F29 -> 0
I30: =VLOOKUP(C30,#REF!,18,0) -> #REF! | L30: =IF(J30>K30,0,K30-J30) -> 0 | O30: =IF(M30>N30,0,N30-M30) -> 0 | R30: =IF(P30>Q30,0,Q30-P30) -> 0 | U30: =IF(S30>T30,0,T30-S30) -> 0 | X30: =IF(V30>W30,0,W30-V30) -> 0 | AG30: =J30*F30 -> 0 | AH30: =K30*F30 -> 0 | AI30: =L30*F30 -> 0 | AJ30: =M30*F30 -> 0 | AK30: =N30*F30 -> 0 | AL30: =O30*F30 -> 0 | AM30: =P30*F30 -> 0 | AN30: =Q30*F30 -> 0 | AO30: =R30*F30 -> 0 | AP30: =S30*F30 -> 0 | AQ30: =T30*F30 -> 0 | AR30: =U30*F30 -> 0 | AS30: =V30*F30 -> 0 | AT30: =W30*F30 -> 0 | AU30: =X30*F30 -> 0 | AV30: =Y30*F30 -> 0 | AW30: =Z30*F30 -> 0 | AX30: =AA30*F30 -> 0 | AY30: =AB30*F30 -> 0 | AZ30: =AC30*F30 -> 0 | BA30: =AD30*F30 -> 0
I31: =VLOOKUP(C31,#REF!,18,0) -> #REF! | L31: =IF(J31>K31,0,K31-J31) -> 0 | O31: =IF(M31>N31,0,N31-M31) -> 0 | R31: =IF(P31>Q31,0,Q31-P31) -> 0 | U31: =IF(S31>T31,0,T31-S31) -> 0 | X31: =IF(V31>W31,0,W31-V31) -> 0 | AG31: =J31*F31 -> 0 | AH31: =K31*F31 -> 0 | AI31: =L31*F31 -> 0 | AJ31: =M31*F31 -> 0 | AK31: =N31*F31 -> 0 | AL31: =O31*F31 -> 0 | AM31: =P31*F31 -> 0 | AN31: =Q31*F31 -> 0 | AO31: =R31*F31 -> 0 | AP31: =S31*F31 -> 0 | AQ31: =T31*F31 -> 0 | AR31: =U31*F31 -> 0 | AS31: =V31*F31 -> 0 | AT31: =W31*F31 -> 0 | AU31: =X31*F31 -> 0 | AV31: =Y31*F31 -> 0 | AW31: =Z31*F31 -> 0 | AX31: =AA31*F31 -> 0 | AY31: =AB31*F31 -> 0 | AZ31: =AC31*F31 -> 0 | BA31: =AD31*F31 -> 0
I32: =VLOOKUP(C32,#REF!,18,0) -> #REF! | L32: =IF(J32>K32,0,K32-J32) -> 0 | O32: =IF(M32>N32,0,N32-M32) -> 0 | R32: =IF(P32>Q32,0,Q32-P32) -> 0 | U32: =IF(S32>T32,0,T32-S32) -> 0 | X32: =IF(V32>W32,0,W32-V32) -> 0 | AG32: =J32*F32 -> 0 | AH32: =K32*F32 -> 0 | AI32: =L32*F32 -> 0 | AJ32: =M32*F32 -> 0 | AK32: =N32*F32 -> 0 | AL32: =O32*F32 -> 0 | AM32: =P32*F32 -> 0 | AN32: =Q32*F32 -> 0 | AO32: =R32*F32 -> 0 | AP32: =S32*F32 -> 0 | AQ32: =T32*F32 -> 0 | AR32: =U32*F32 -> 0 | AS32: =V32*F32 -> 0 | AT32: =W32*F32 -> 0 | AU32: =X32*F32 -> 0 | AV32: =Y32*F32 -> 0 | AW32: =Z32*F32 -> 0 | AX32: =AA32*F32 -> 0 | AY32: =AB32*F32 -> 0 | AZ32: =AC32*F32 -> 0 | BA32: =AD32*F32 -> 0
I33: =VLOOKUP(C33,#REF!,18,0) -> #REF! | L33: =IF(J33>K33,0,K33-J33) -> 0 | O33: =IF(M33>N33,0,N33-M33) -> 0 | R33: =IF(P33>Q33,0,Q33-P33) -> 0 | U33: =IF(S33>T33,0,T33-S33) -> 0 | X33: =IF(V33>W33,0,W33-V33) -> 0 | AG33: =J33*F33 -> 0 | AH33: =K33*F33 -> 0 | AI33: =L33*F33 -> 0 | AJ33: =M33*F33 -> 0 | AK33: =N33*F33 -> 0 | AL33: =O33*F33 -> 0 | AM33: =P33*F33 -> 0 | AN33: =Q33*F33 -> 0 | AO33: =R33*F33 -> 0 | AP33: =S33*F33 -> 0 | AQ33: =T33*F33 -> 0 | AR33: =U33*F33 -> 0 | AS33: =V33*F33 -> 0 | AT33: =W33*F33 -> 0 | AU33: =X33*F33 -> 0 | AV33: =Y33*F33 -> 0 | AW33: =Z33*F33 -> 0 | AX33: =AA33*F33 -> 0 | AY33: =AB33*F33 -> 0 | AZ33: =AC33*F33 -> 0 | BA33: =AD33*F33 -> 0
I34: =VLOOKUP(C34,#REF!,18,0) -> #REF! | L34: =IF(J34>K34,0,K34-J34) -> 0 | O34: =IF(M34>N34,0,N34-M34) -> 0 | R34: =IF(P34>Q34,0,Q34-P34) -> 0 | U34: =IF(S34>T34,0,T34-S34) -> 0 | X34: =IF(V34>W34,0,W34-V34) -> 0 | AG34: =J34*F34 -> 0 | AH34: =K34*F34 -> 0 | AI34: =L34*F34 -> 0 | AJ34: =M34*F34 -> 0 | AK34: =N34*F34 -> 0 | AL34: =O34*F34 -> 0 | AM34: =P34*F34 -> 0 | AN34: =Q34*F34 -> 0 | AO34: =R34*F34 -> 0 | AP34: =S34*F34 -> 0 | AQ34: =T34*F34 -> 0 | AR34: =U34*F34 -> 0 | AS34: =V34*F34 -> 0 | AT34: =W34*F34 -> 0 | AU34: =X34*F34 -> 0 | AV34: =Y34*F34 -> 0 | AW34: =Z34*F34 -> 0 | AX34: =AA34*F34 -> 0 | AY34: =AB34*F34 -> 0 | AZ34: =AC34*F34 -> 0 | BA34: =AD34*F34 -> 0
I35: =VLOOKUP(C35,#REF!,18,0) -> #REF! | L35: =IF(J35>K35,0,K35-J35) -> 0 | O35: =IF(M35>N35,0,N35-M35) -> 0 | R35: =IF(P35>Q35,0,Q35-P35) -> 0 | U35: =IF(S35>T35,0,T35-S35) -> 0 | X35: =IF(V35>W35,0,W35-V35) -> 0 | AG35: =J35*F35 -> 0 | AH35: =K35*F35 -> 0 | AI35: =L35*F35 -> 0 | AJ35: =M35*F35 -> 0 | AK35: =N35*F35 -> 0 | AL35: =O35*F35 -> 0 | AM35: =P35*F35 -> 0 | AN35: =Q35*F35 -> 0 | AO35: =R35*F35 -> 0 | AP35: =S35*F35 -> 0 | AQ35: =T35*F35 -> 0 | AR35: =U35*F35 -> 0 | AS35: =V35*F35 -> 0 | AT35: =W35*F35 -> 0 | AU35: =X35*F35 -> 0 | AV35: =Y35*F35 -> 0 | AW35: =Z35*F35 -> 0 | AX35: =AA35*F35 -> 0 | AY35: =AB35*F35 -> 0 | AZ35: =AC35*F35 -> 0 | BA35: =AD35*F35 -> 0
A36: 486D | B36: HEV-LHD | C36: 82111-4DG90 | J36: 0 | K36: =VLOOKUP($C36,#REF!,9,0) -> #REF! | L36: =IF(J36>K36,0,K36-J36) -> 0 | M36: =J36+L36-K36 -> #REF! | N36: =VLOOKUP($C36,#REF!,9,0) -> #REF! | O36: =IF(M36>N36,0,N36-M36) -> #REF! | P36: =M36+O36-N36 -> #REF! | Q36: =VLOOKUP($C36,#REF!,15,0) -> #REF! | R36: =IF(P36>Q36,0,Q36-P36) -> #REF! | S36: =P36+R36-Q36 -> #REF! | T36: =VLOOKUP($C36,#REF!,21,0) -> #REF! | U36: =IF(S36>T36,0,T36-S36) -> #REF! | V36: =S36+U36-T36 -> #REF! | W36: =VLOOKUP($C36,#REF!,27,0) -> #REF! | X36: =IF(V36>W36,0,W36-V36) -> #REF! | Y36: =V36+X36-W36 -> #REF! | Z36: =VLOOKUP($C36,#REF!,33,0) -> #REF! | AA36: =IF(Y36>Z36,0,Z36-Y36) -> #REF! | AB36: =Y36+AA36-Z36 -> #REF! | AC36: =VLOOKUP($C36,#REF!,39,0) -> #REF! | AD36: =IF(AB36>AC36,0,AC36-AB36) -> #REF! | AG36: =J36*F36 -> 0 | AH36: =K36*F36 -> #REF! | AI36: =L36*F36 -> 0 | AJ36: =M36*F36 -> #REF! | AK36: =N36*F36 -> #REF! | AL36: =O36*F36 -> #REF! | AM36: =P36*F36 -> #REF! | AN36: =Q36*F36 -> #REF! | AO36: =R36*F36 -> #REF! | AP36: =S36*F36 -> #REF! | AQ36: =T36*F36 -> #REF! | AR36: =U36*F36 -> #REF! | AS36: =V36*F36 -> #REF! | AT36: =W36*F36 -> #REF! | AU36: =X36*F36 -> #REF! | AV36: =Y36*F36 -> #REF! | AW36: =Z36*F36 -> #REF! | AX36: =AA36*F36 -> #REF! | AY36: =AB36*F36 -> #REF! | AZ36: =AC36*F36 -> #REF! | BA36: =AD36*F36 -> #REF!
B37: HEV-LHD | C37: 82111-4DJ00 | J37: 0 | K37: =VLOOKUP($C37,#REF!,9,0) -> #REF! | L37: =IF(J37>K37,0,K37-J37) -> 0 | M37: =J37+L37-K37 -> #REF! | N37: =VLOOKUP($C37,#REF!,9,0) -> #REF! | O37: =IF(M37>N37,0,N37-M37) -> #REF! | P37: =M37+O37-N37 -> #REF! | Q37: =VLOOKUP($C37,#REF!,15,0) -> #REF! | R37: =IF(P37>Q37,0,Q37-P37) -> #REF! | S37: =P37+R37-Q37 -> #REF! | T37: =VLOOKUP($C37,#REF!,21,0) -> #REF! | U37: =IF(S37>T37,0,T37-S37) -> #REF! | V37: =S37+U37-T37 -> #REF! | W37: =VLOOKUP($C37,#REF!,27,0) -> #REF! | X37: =IF(V37>W37,0,W37-V37) -> #REF! | Y37: =V37+X37-W37 -> #REF! | Z37: =VLOOKUP($C37,#REF!,33,0) -> #REF! | AA37: =IF(Y37>Z37,0,Z37-Y37) -> #REF! | AB37: =Y37+AA37-Z37 -> #REF! | AC37: =VLOOKUP($C37,#REF!,39,0) -> #REF! | AD37: =IF(AB37>AC37,0,AC37-AB37) -> #REF! | AG37: =J37*F37 -> 0 | AH37: =K37*F37 -> #REF! | AI37: =L37*F37 -> 0 | AJ37: =M37*F37 -> #REF! | AK37: =N37*F37 -> #REF! | AL37: =O37*F37 -> #REF! | AM37: =P37*F37 -> #REF! | AN37: =Q37*F37 -> #REF! | AO37: =R37*F37 -> #REF! | AP37: =S37*F37 -> #REF! | AQ37: =T37*F37 -> #REF! | AR37: =U37*F37 -> #REF! | AS37: =V37*F37 -> #REF! | AT37: =W37*F37 -> #REF! | AU37: =X37*F37 -> #REF! | AV37: =Y37*F37 -> #REF! | AW37: =Z37*F37 -> #REF! | AX37: =AA37*F37 -> #REF! | AY37: =AB37*F37 -> #REF! | AZ37: =AC37*F37 -> #REF! | BA37: =AD37*F37 -> #REF!
B38: GAS-LHD | C38: 82111-4DL51 | I38: =VLOOKUP(C38,#REF!,18,0) -> #REF! | J38: 0 | K38: =VLOOKUP($C38,#REF!,9,0) -> #REF! | L38: =IF(J38>K38,0,K38-J38) -> 0 | M38: =J38+L38-K38 -> #REF! | N38: =VLOOKUP($C38,#REF!,9,0) -> #REF! | O38: =IF(M38>N38,0,N38-M38) -> #REF! | P38: =M38+O38-N38 -> #REF! | Q38: =VLOOKUP($C38,#REF!,15,0) -> #REF! | R38: =IF(P38>Q38,0,Q38-P38) -> #REF! | S38: =P38+R38-Q38 -> #REF! | T38: =VLOOKUP($C38,#REF!,21,0) -> #REF! | U38: =IF(S38>T38,0,T38-S38) -> #REF! | V38: =S38+U38-T38 -> #REF! | W38: =VLOOKUP($C38,#REF!,27,0) -> #REF! | X38: =IF(V38>W38,0,W38-V38) -> #REF! | Y38: =V38+X38-W38 -> #REF! | Z38: =VLOOKUP($C38,#REF!,33,0) -> #REF! | AA38: =IF(Y38>Z38,0,Z38-Y38) -> #REF! | AB38: =Y38+AA38-Z38 -> #REF! | AC38: =VLOOKUP($C38,#REF!,39,0) -> #REF! | AD38: =IF(AB38>AC38,0,AC38-AB38) -> #REF! | AG38: =J38*F38 -> 0 | AH38: =K38*F38 -> #REF! | AI38: =L38*F38 -> 0 | AJ38: =M38*F38 -> #REF! | AK38: =N38*F38 -> #REF! | AL38: =O38*F38 -> #REF! | AM38: =P38*F38 -> #REF! | AN38: =Q38*F38 -> #REF! | AO38: =R38*F38 -> #REF! | AP38: =S38*F38 -> #REF! | AQ38: =T38*F38 -> #REF! | AR38: =U38*F38 -> #REF! | AS38: =V38*F38 -> #REF! | AT38: =W38*F38 -> #REF! | AU38: =X38*F38 -> #REF! | AV38: =Y38*F38 -> #REF! | AW38: =Z38*F38 -> #REF! | AX38: =AA38*F38 -> #REF! | AY38: =AB38*F38 -> #REF! | AZ38: =AC38*F38 -> #REF! | BA38: =AD38*F38 -> #REF!
B39: GAS-LHD | C39: 82111-4DL61 | J39: 0 | K39: =VLOOKUP($C39,#REF!,9,0) -> #REF! | L39: =IF(J39>K39,0,K39-J39) -> 0 | M39: =J39+L39-K39 -> #REF! | N39: =VLOOKUP($C39,#REF!,9,0) -> #REF! | O39: =IF(M39>N39,0,N39-M39) -> #REF! | P39: =M39+O39-N39 -> #REF! | Q39: =VLOOKUP($C39,#REF!,15,0) -> #REF! | R39: =IF(P39>Q39,0,Q39-P39) -> #REF! | S39: =P39+R39-Q39 -> #REF! | T39: =VLOOKUP($C39,#REF!,21,0) -> #REF! | U39: =IF(S39>T39,0,T39-S39) -> #REF! | V39: =S39+U39-T39 -> #REF! | W39: =VLOOKUP($C39,#REF!,27,0) -> #REF! | X39: =IF(V39>W39,0,W39-V39) -> #REF! | Y39: =V39+X39-W39 -> #REF! | Z39: =VLOOKUP($C39,#REF!,33,0) -> #REF! | AA39: =IF(Y39>Z39,0,Z39-Y39) -> #REF! | AB39: =Y39+AA39-Z39 -> #REF! | AC39: =VLOOKUP($C39,#REF!,39,0) -> #REF! | AD39: =IF(AB39>AC39,0,AC39-AB39) -> #REF! | AG39: =J39*F39 -> 0 | AH39: =K39*F39 -> #REF! | AI39: =L39*F39 -> 0 | AJ39: =M39*F39 -> #REF! | AK39: =N39*F39 -> #REF! | AL39: =O39*F39 -> #REF! | AM39: =P39*F39 -> #REF! | AN39: =Q39*F39 -> #REF! | AO39: =R39*F39 -> #REF! | AP39: =S39*F39 -> #REF! | AQ39: =T39*F39 -> #REF! | AR39: =U39*F39 -> #REF! | AS39: =V39*F39 -> #REF! | AT39: =W39*F39 -> #REF! | AU39: =X39*F39 -> #REF! | AV39: =Y39*F39 -> #REF! | AW39: =Z39*F39 -> #REF! | AX39: =AA39*F39 -> #REF! | AY39: =AB39*F39 -> #REF! | AZ39: =AC39*F39 -> #REF! | BA39: =AD39*F39 -> #REF!
B40: GAS-LHD | C40: 82111-4DL71 | I40: =VLOOKUP(C40,#REF!,18,0) -> #REF! | J40: 0 | K40: =VLOOKUP($C40,#REF!,9,0) -> #REF! | L40: =IF(J40>K40,0,K40-J40) -> 0 | M40: =J40+L40-K40 -> #REF! | N40: =VLOOKUP($C40,#REF!,9,0) -> #REF! | O40: =IF(M40>N40,0,N40-M40) -> #REF! | P40: =M40+O40-N40 -> #REF! | Q40: =VLOOKUP($C40,#REF!,15,0) -> #REF! | R40: =IF(P40>Q40,0,Q40-P40) -> #REF! | S40: =P40+R40-Q40 -> #REF! | T40: =VLOOKUP($C40,#REF!,21,0) -> #REF! | U40: =IF(S40>T40,0,T40-S40) -> #REF! | V40: =S40+U40-T40 -> #REF! | W40: =VLOOKUP($C40,#REF!,27,0) -> #REF! | X40: =IF(V40>W40,0,W40-V40) -> #REF! | Y40: =V40+X40-W40 -> #REF! | Z40: =VLOOKUP($C40,#REF!,33,0) -> #REF! | AA40: =IF(Y40>Z40,0,Z40-Y40) -> #REF! | AB40: =Y40+AA40-Z40 -> #REF! | AC40: =VLOOKUP($C40,#REF!,39,0) -> #REF! | AD40: =IF(AB40>AC40,0,AC40-AB40) -> #REF! | AG40: =J40*F40 -> 0 | AH40: =K40*F40 -> #REF! | AI40: =L40*F40 -> 0 | AJ40: =M40*F40 -> #REF! | AK40: =N40*F40 -> #REF! | AL40: =O40*F40 -> #REF! | AM40: =P40*F40 -> #REF! | AN40: =Q40*F40 -> #REF! | AO40: =R40*F40 -> #REF! | AP40: =S40*F40 -> #REF! | AQ40: =T40*F40 -> #REF! | AR40: =U40*F40 -> #REF! | AS40: =V40*F40 -> #REF! | AT40: =W40*F40 -> #REF! | AU40: =X40*F40 -> #REF! | AV40: =Y40*F40 -> #REF! | AW40: =Z40*F40 -> #REF! | AX40: =AA40*F40 -> #REF! | AY40: =AB40*F40 -> #REF! | AZ40: =AC40*F40 -> #REF! | BA40: =AD40*F40 -> #REF!
...

Sheet Summ Qty&UMH GUM 
M1: SIX MONTH PRODUCTION PLAN ( QTY ) | AD1: PREPARED
A2: ='Qty & UMH GUM'!A2:C2 -> S/R NO : | B2: ='Qty & UMH GUM'!B2 -> 202603-10 | O2: ='Qty & UMH GUM'!O2 -> 900B-486D
A3: ='Qty & UMH GUM'!A3:C3 -> FAX NO : | B3: ='Qty & UMH GUM'!B3 -> EMAIL | O3: ='Qty & UMH GUM'!O3 -> 46082
A4: ='Qty & UMH GUM'!A4:C4 -> DATE : | B4: ='Qty & UMH GUM'!B4 -> 46092 | R4: #REF! | X4: #REF! | AD4: ='Qty & UMH GUM'!AD4:AE4 -> LSR | AG4: Cutting Qty
C5: =NOW() -> 46196.165 | U5: ='Qty & UMH GUM'!U5
A6: DEST | B6: TYPE | C6: HARNESS No. | D6: LEVEL | E6: ASSY CODE | F6: CCT | G6: Std Pack | H6: UMH GUM JUL-DEC | I6: UMH GUM JAN - JUN | J6: ='Qty & UMH GUM'!J6 -> FEB | M6: ='Qty & UMH GUM'!M6 -> MAR | P6: ='Qty & UMH GUM'!P6 -> APR | S6: ='Qty & UMH GUM'!S6 -> MAY | V6: ='Qty & UMH GUM'!V6 -> JUN | Y6: ='Qty & UMH GUM'!Y6 -> JUL | AB6: ='Qty & UMH GUM'!AB6 -> AUG | AE6: BAL | AG6: JAN | AJ6: FEB | AM6: MAR | AP6: APR | AS6: MAY | AV6: JUN | AY6: JUL
J7: ='Qty & UMH GUM'!J7 -> 02/FEB ~ 27/FEB | M7: ='Qty & UMH GUM'!M7 -> 02/MAR ~ 31/MAR | P7: ='Qty & UMH GUM'!P7 -> 01/APR ~ 30/APR | S7: ='Qty & UMH GUM'!S7 -> 02/MAY ~ 30/MAY | V7: ='Qty & UMH GUM'!V7 -> 02/JUN ~ 30/JUN | Y7: ='Qty & UMH GUM'!Y7 -> 01/JUL ~ 31/JUL | AB7: ='Qty & UMH GUM'!AB7 -> 03/AUG ~ 31/AUG | AG7: 27/DEC ~ 23/JAN | AJ7: 24/JAN ~ 20/FEB | AM7: 21/FEB ~ 27/MAR | AP7: 28/MAR ~ 24/APR | AS7: 25/APR ~ 22/MAY | AV7: 23/MAY ~ 26/JUN | AY7: 27/JUN ~ 24/JUL
J8: BAL | K8: DEL | L8: PROD | M8: BAL | N8: DEL | O8: PROD | P8: BAL | Q8: DEL | R8: PROD | S8: BAL | T8: DEL | U8: PROD | V8: BAL | W8: DEL | X8: PROD | Y8: BAL | Z8: DEL | AA8: PROD | AB8: BAL | AC8: DEL | AD8: PROD | AG8: BAL | AH8: DEL | AI8: PROD | AJ8: BAL | AK8: DEL | AL8: PROD | AM8: BAL | AN8: DEL | AO8: PROD | AP8: BAL | AQ8: DEL | AR8: PROD | AS8: BAL | AT8: DEL | AU8: PROD | AV8: BAL | AW8: DEL | AX8: PROD | AY8: BAL | AZ8: DEL | BA8: PROD
A9: NASHVILLE & CANTON TK09 | C9: #REF! | D9: #REF! | F9: #REF! | G9: #REF! | H9: #REF! | J9: #REF! | K9: #REF! | L9: #REF! | M9: #REF! | N9: #REF! | O9: #REF! | P9: #REF! | Q9: #REF! | R9: #REF! | S9: #REF! | T9: #REF! | U9: #REF! | V9: #REF! | W9: #REF! | X9: #REF! | Y9: #REF! | Z9: #REF! | AA9: #REF! | AB9: #REF! | AC9: #REF! | AD9: #REF! | AE9: #REF! | AG9: =J9*F9 -> #REF! | AH9: =K9*F9 -> #REF! | AI9: =L9*F9 -> #REF! | AJ9: =M9*F9 -> #REF! | AK9: =N9*F9 -> #REF! | AL9: =O9*F9 -> #REF! | AM9: =P9*F9 -> #REF! | AN9: =Q9*F9 -> #REF! | AO9: =R9*F9 -> #REF! | AP9: =S9*F9 -> #REF! | AQ9: =T9*F9 -> #REF! | AR9: =U9*F9 -> #REF! | AS9: =V9*F9 -> #REF! | AT9: =W9*F9 -> #REF! | AU9: =X9*F9 -> #REF! | AV9: =Y9*F9 -> #REF! | AW9: =Z9*F9 -> #REF! | AX9: =AA9*F9 -> #REF! | AY9: =AB9*F9 -> #REF! | AZ9: =AC9*F9 -> #REF! | BA9: =AD9*F9 -> #REF!
C10: #REF! | D10: #REF! | F10: #REF! | G10: #REF! | H10: #REF! | J10: #REF! | K10: #REF! | L10: #REF! | M10: #REF! | N10: #REF! | O10: #REF! | P10: #REF! | Q10: #REF! | R10: #REF! | S10: #REF! | T10: #REF! | U10: #REF! | V10: #REF! | W10: #REF! | X10: #REF! | Y10: #REF! | Z10: #REF! | AA10: #REF! | AB10: #REF! | AC10: #REF! | AD10: #REF! | AE10: #REF! | AG10: =J10*F10 -> #REF! | AH10: =K10*F10 -> #REF! | AI10: =L10*F10 -> #REF! | AJ10: =M10*F10 -> #REF! | AK10: =N10*F10 -> #REF! | AL10: =O10*F10 -> #REF! | AM10: =P10*F10 -> #REF! | AN10: =Q10*F10 -> #REF! | AO10: =R10*F10 -> #REF! | AP10: =S10*F10 -> #REF! | AQ10: =T10*F10 -> #REF! | AR10: =U10*F10 -> #REF! | AS10: =V10*F10 -> #REF! | AT10: =W10*F10 -> #REF! | AU10: =X10*F10 -> #REF! | AV10: =Y10*F10 -> #REF! | AW10: =Z10*F10 -> #REF! | AX10: =AA10*F10 -> #REF! | AY10: =AB10*F10 -> #REF! | AZ10: =AC10*F10 -> #REF! | BA10: =AD10*F10 -> #REF!
C11: #REF! | D11: #REF! | F11: #REF! | G11: #REF! | H11: #REF! | J11: #REF! | K11: #REF! | L11: #REF! | M11: #REF! | N11: #REF! | O11: #REF! | P11: #REF! | Q11: #REF! | R11: #REF! | S11: #REF! | T11: #REF! | U11: #REF! | V11: #REF! | W11: #REF! | X11: #REF! | Y11: #REF! | Z11: #REF! | AA11: #REF! | AB11: #REF! | AC11: #REF! | AD11: #REF! | AE11: #REF! | AG11: =J11*F11 -> #REF! | AH11: =K11*F11 -> #REF! | AI11: =L11*F11 -> #REF! | AJ11: =M11*F11 -> #REF! | AK11: =N11*F11 -> #REF! | AL11: =O11*F11 -> #REF! | AM11: =P11*F11 -> #REF! | AN11: =Q11*F11 -> #REF! | AO11: =R11*F11 -> #REF! | AP11: =S11*F11 -> #REF! | AQ11: =T11*F11 -> #REF! | AR11: =U11*F11 -> #REF! | AS11: =V11*F11 -> #REF! | AT11: =W11*F11 -> #REF! | AU11: =X11*F11 -> #REF! | AV11: =Y11*F11 -> #REF! | AW11: =Z11*F11 -> #REF! | AX11: =AA11*F11 -> #REF! | AY11: =AB11*F11 -> #REF! | AZ11: =AC11*F11 -> #REF! | BA11: =AD11*F11 -> #REF!
C12: #REF! | D12: #REF! | F12: #REF! | G12: #REF! | H12: #REF! | J12: #REF! | K12: #REF! | L12: #REF! | M12: #REF! | N12: #REF! | O12: #REF! | P12: #REF! | Q12: #REF! | R12: #REF! | S12: #REF! | T12: #REF! | U12: #REF! | V12: #REF! | W12: #REF! | X12: #REF! | Y12: #REF! | Z12: #REF! | AA12: #REF! | AB12: #REF! | AC12: #REF! | AD12: #REF! | AE12: #REF! | AG12: =J12*F12 -> #REF! | AH12: =K12*F12 -> #REF! | AI12: =L12*F12 -> #REF! | AJ12: =M12*F12 -> #REF! | AK12: =N12*F12 -> #REF! | AL12: =O12*F12 -> #REF! | AM12: =P12*F12 -> #REF! | AN12: =Q12*F12 -> #REF! | AO12: =R12*F12 -> #REF! | AP12: =S12*F12 -> #REF! | AQ12: =T12*F12 -> #REF! | AR12: =U12*F12 -> #REF! | AS12: =V12*F12 -> #REF! | AT12: =W12*F12 -> #REF! | AU12: =X12*F12 -> #REF! | AV12: =Y12*F12 -> #REF! | AW12: =Z12*F12 -> #REF! | AX12: =AA12*F12 -> #REF! | AY12: =AB12*F12 -> #REF! | AZ12: =AC12*F12 -> #REF! | BA12: =AD12*F12 -> #REF!
C13: #REF! | D13: #REF! | F13: #REF! | G13: #REF! | H13: #REF! | J13: #REF! | K13: #REF! | L13: #REF! | M13: #REF! | N13: #REF! | O13: #REF! | P13: #REF! | Q13: #REF! | R13: #REF! | S13: #REF! | T13: #REF! | U13: #REF! | V13: #REF! | W13: #REF! | X13: #REF! | Y13: #REF! | Z13: #REF! | AA13: #REF! | AB13: #REF! | AC13: #REF! | AD13: #REF! | AE13: #REF! | AG13: =J13*F13 -> #REF! | AH13: =K13*F13 -> #REF! | AI13: =L13*F13 -> #REF! | AJ13: =M13*F13 -> #REF! | AK13: =N13*F13 -> #REF! | AL13: =O13*F13 -> #REF! | AM13: =P13*F13 -> #REF! | AN13: =Q13*F13 -> #REF! | AO13: =R13*F13 -> #REF! | AP13: =S13*F13 -> #REF! | AQ13: =T13*F13 -> #REF! | AR13: =U13*F13 -> #REF! | AS13: =V13*F13 -> #REF! | AT13: =W13*F13 -> #REF! | AU13: =X13*F13 -> #REF! | AV13: =Y13*F13 -> #REF! | AW13: =Z13*F13 -> #REF! | AX13: =AA13*F13 -> #REF! | AY13: =AB13*F13 -> #REF! | AZ13: =AC13*F13 -> #REF! | BA13: =AD13*F13 -> #REF!
C14: #REF! | D14: #REF! | F14: #REF! | G14: #REF! | H14: #REF! | J14: #REF! | K14: #REF! | L14: #REF! | M14: #REF! | N14: #REF! | O14: #REF! | P14: #REF! | Q14: #REF! | R14: #REF! | S14: #REF! | T14: #REF! | U14: #REF! | V14: #REF! | W14: #REF! | X14: #REF! | Y14: #REF! | Z14: #REF! | AA14: #REF! | AB14: #REF! | AC14: #REF! | AD14: #REF! | AE14: #REF! | AG14: =J14*F14 -> #REF! | AH14: =K14*F14 -> #REF! | AI14: =L14*F14 -> #REF! | AJ14: =M14*F14 -> #REF! | AK14: =N14*F14 -> #REF! | AL14: =O14*F14 -> #REF! | AM14: =P14*F14 -> #REF! | AN14: =Q14*F14 -> #REF! | AO14: =R14*F14 -> #REF! | AP14: =S14*F14 -> #REF! | AQ14: =T14*F14 -> #REF! | AR14: =U14*F14 -> #REF! | AS14: =V14*F14 -> #REF! | AT14: =W14*F14 -> #REF! | AU14: =X14*F14 -> #REF! | AV14: =Y14*F14 -> #REF! | AW14: =Z14*F14 -> #REF! | AX14: =AA14*F14 -> #REF! | AY14: =AB14*F14 -> #REF! | AZ14: =AC14*F14 -> #REF! | BA14: =AD14*F14 -> #REF!
C15: #REF! | D15: #REF! | F15: #REF! | G15: #REF! | H15: #REF! | J15: #REF! | K15: #REF! | L15: #REF! | M15: #REF! | N15: #REF! | O15: #REF! | P15: #REF! | Q15: #REF! | R15: #REF! | S15: #REF! | T15: #REF! | U15: #REF! | V15: #REF! | W15: #REF! | X15: #REF! | Y15: #REF! | Z15: #REF! | AA15: #REF! | AB15: #REF! | AC15: #REF! | AD15: #REF! | AE15: #REF! | AG15: =J15*F15 -> #REF! | AH15: =K15*F15 -> #REF! | AI15: =L15*F15 -> #REF! | AJ15: =M15*F15 -> #REF! | AK15: =N15*F15 -> #REF! | AL15: =O15*F15 -> #REF! | AM15: =P15*F15 -> #REF! | AN15: =Q15*F15 -> #REF! | AO15: =R15*F15 -> #REF! | AP15: =S15*F15 -> #REF! | AQ15: =T15*F15 -> #REF! | AR15: =U15*F15 -> #REF! | AS15: =V15*F15 -> #REF! | AT15: =W15*F15 -> #REF! | AU15: =X15*F15 -> #REF! | AV15: =Y15*F15 -> #REF! | AW15: =Z15*F15 -> #REF! | AX15: =AA15*F15 -> #REF! | AY15: =AB15*F15 -> #REF! | AZ15: =AC15*F15 -> #REF! | BA15: =AD15*F15 -> #REF!
B16: GCC | C16: ='Qty & UMH GUM'!C9 -> 82111-4DT30 | D16: ='Qty & UMH GUM'!D9 | F16: ='Qty & UMH GUM'!F9 | G16: ='Qty & UMH GUM'!G9 | H16: ='Qty & UMH GUM'!H9 | J16: ='Qty & UMH GUM'!J9 -> 0 | K16: ='Qty & UMH GUM'!K9 -> #REF! | L16: ='Qty & UMH GUM'!L9 -> 0 | M16: ='Qty & UMH GUM'!M9 -> #REF! | N16: ='Qty & UMH GUM'!N9 -> #REF! | O16: ='Qty & UMH GUM'!O9 -> #REF! | P16: ='Qty & UMH GUM'!P9 -> #REF! | Q16: ='Qty & UMH GUM'!Q9 -> #REF! | ... AE16: ='Qty & UMH GUM'!AE9 | AG16: =J16*F16 -> 0 | AH16: =K16*F16 -> #REF! | AI16: =L16*F16 -> 0 | AJ16: =M16*F16 -> #REF! | AK16: =N16*F16 -> #REF! | AL16: =O16*F16 -> #REF! | AM16: =P16*F16 -> #REF! | AN16: =Q16*F16 -> #REF! | AO16: =R16*F16 -> #REF! | AP16: =S16*F16 -> #REF! | AQ16: =T16*F16 -> #REF! | AR16: =U16*F16 -> #REF! | AS16: =V16*F16 -> #REF! | AT16: =W16*F16 -> #REF! | AU16: =X16*F16 -> #REF! | AV16: =Y16*F16 -> #REF! | AW16: =Z16*F16 -> #REF! | AX16: =AA16*F16 -> #REF! | AY16: =AB16*F16 -> #REF! | AZ16: =AC16*F16 -> #REF! | BA16: =AD16*F16 -> #REF!
C17: #REF! | D17: #REF! | F17: #REF! | G17: #REF! | H17: #REF! | J17: #REF! | K17: #REF! | L17: #REF! | M17: #REF! | N17: #REF! | O17: #REF! | P17: #REF! | Q17: #REF! | R17: #REF! | S17: #REF! | T17: #REF! | U17: #REF! | V17: #REF! | W17: #REF! | X17: #REF! | Y17: #REF! | Z17: #REF! | AA17: #REF! | AB17: #REF! | AC17: #REF! | AD17: #REF! | AE17: #REF! | AG17: =J17*F17 -> #REF! | AH17: =K17*F17 -> #REF! | AI17: =L17*F17 -> #REF! | AJ17: =M17*F17 -> #REF! | AK17: =N17*F17 -> #REF! | AL17: =O17*F17 -> #REF! | AM17: =P17*F17 -> #REF! | AN17: =Q17*F17 -> #REF! | AO17: =R17*F17 -> #REF! | AP17: =S17*F17 -> #REF! | AQ17: =T17*F17 -> #REF! | AR17: =U17*F17 -> #REF! | AS17: =V17*F17 -> #REF! | AT17: =W17*F17 -> #REF! | AU17: =X17*F17 -> #REF! | AV17: =Y17*F17 -> #REF! | AW17: =Z17*F17 -> #REF! | AX17: =AA17*F17 -> #REF! | AY17: =AB17*F17 -> #REF! | AZ17: =AC17*F17 -> #REF! | BA17: =AD17*F17 -> #REF!
C18: #REF! | D18: #REF! | F18: #REF! | G18: #REF! | H18: #REF! | J18: #REF! | K18: #REF! | L18: #REF! | M18: #REF! | N18: #REF! | O18: #REF! | P18: #REF! | Q18: #REF! | R18: #REF! | S18: #REF! | T18: #REF! | U18: #REF! | V18: #REF! | W18: #REF! | X18: #REF! | Y18: #REF! | Z18: #REF! | AA18: #REF! | AB18: #REF! | AC18: #REF! | AD18: #REF! | AE18: #REF! | AG18: =J18*F18 -> #REF! | AH18: =K18*F18 -> #REF! | AI18: =L18*F18 -> #REF! | AJ18: =M18*F18 -> #REF! | AK18: =N18*F18 -> #REF! | AL18: =O18*F18 -> #REF! | AM18: =P18*F18 -> #REF! | AN18: =Q18*F18 -> #REF! | AO18: =R18*F18 -> #REF! | AP18: =S18*F18 -> #REF! | AQ18: =T18*F18 -> #REF! | AR18: =U18*F18 -> #REF! | AS18: =V18*F18 -> #REF! | AT18: =W18*F18 -> #REF! | AU18: =X18*F18 -> #REF! | AV18: =Y18*F18 -> #REF! | AW18: =Z18*F18 -> #REF! | AX18: =AA18*F18 -> #REF! | AY18: =AB18*F18 -> #REF! | AZ18: =AC18*F18 -> #REF! | BA18: =AD18*F18 -> #REF!
C19: #REF! | D19: #REF! | F19: #REF! | G19: #REF! | H19: #REF! | J19: #REF! | K19: #REF! | L19: #REF! | M19: #REF! | N19: #REF! | O19: #REF! | P19: #REF! | Q19: #REF! | R19: #REF! | S19: #REF! | T19: #REF! | U19: #REF! | V19: #REF! | W19: #REF! | X19: #REF! | Y19: #REF! | Z19: #REF! | AA19: #REF! | AB19: #REF! | AC19: #REF! | AD19: #REF! | AE19: #REF!
C20: #REF! | D20: #REF! | F20: #REF! | G20: #REF! | H20: #REF! | J20: #REF! | K20: #REF! | L20: #REF! | M20: #REF! | N20: #REF! | O20: #REF! | P20: #REF! | Q20: #REF! | R20: #REF! | S20: #REF! | T20: #REF! | U20: #REF! | V20: #REF! | W20: #REF! | X20: #REF! | Y20: #REF! | Z20: #REF! | AA20: #REF! | AB20: #REF! | AC20: #REF! | AD20: #REF! | AE20: #REF!
C21: #REF! | D21: #REF! | F21: #REF! | G21: #REF! | H21: #REF! | J21: #REF! | K21: #REF! | L21: #REF! | M21: #REF! | N21: #REF! | O21: #REF! | P21: #REF! | Q21: #REF! | R21: #REF! | S21: #REF! | T21: #REF! | U21: #REF! | V21: #REF! | W21: #REF! | X21: #REF! | Y21: #REF! | Z21: #REF! | AA21: #REF! | AB21: #REF! | AC21: #REF! | AD21: #REF! | AE21: #REF! | AG21: =J21*F21 -> #REF! | AH21: =K21*F21 -> #REF! | AI21: =L21*F21 -> #REF! | AJ21: =M21*F21 -> #REF! | AK21: =N21*F21 -> #REF! | AL21: =O21*F21 -> #REF! | AM21: =P21*F21 -> #REF! | AN21: =Q21*F21 -> #REF! | AO21: =R21*F21 -> #REF! | AP21: =S21*F21 -> #REF! | AQ21: =T21*F21 -> #REF! | AR21: =U21*F21 -> #REF! | AS21: =V21*F21 -> #REF! | AT21: =W21*F21 -> #REF! | AU21: =X21*F21 -> #REF! | AV21: =Y21*F21 -> #REF! | AW21: =Z21*F21 -> #REF! | AX21: =AA21*F21 -> #REF! | AY21: =AB21*F21 -> #REF! | AZ21: =AC21*F21 -> #REF! | BA21: =AD21*F21 -> #REF!
C22: #REF! | D22: #REF! | F22: #REF! | G22: #REF! | H22: #REF! | J22: #REF! | K22: #REF! | L22: #REF! | M22: #REF! | N22: #REF! | O22: #REF! | P22: #REF! | Q22: #REF! | R22: #REF! | S22: #REF! | T22: #REF! | U22: #REF! | V22: #REF! | W22: #REF! | X22: #REF! | Y22: #REF! | Z22: #REF! | AA22: #REF! | AB22: #REF! | AC22: #REF! | AD22: #REF! | AE22: #REF! | AG22: =J22*F22 -> #REF! | AH22: =K22*F22 -> #REF! | AI22: =L22*F22 -> #REF! | AJ22: =M22*F22 -> #REF! | AK22: =N22*F22 -> #REF! | AL22: =O22*F22 -> #REF! | AM22: =P22*F22 -> #REF! | AN22: =Q22*F22 -> #REF! | AO22: =R22*F22 -> #REF! | AP22: =S22*F22 -> #REF! | AQ22: =T22*F22 -> #REF! | AR22: =U22*F22 -> #REF! | AS22: =V22*F22 -> #REF! | AT22: =W22*F22 -> #REF! | AU22: =X22*F22 -> #REF! | AV22: =Y22*F22 -> #REF! | AW22: =Z22*F22 -> #REF! | AX22: =AA22*F22 -> #REF! | AY22: =AB22*F22 -> #REF! | AZ22: =AC22*F22 -> #REF! | BA22: =AD22*F22 -> #REF!
C23: #REF! | D23: #REF! | F23: #REF! | G23: #REF! | H23: #REF! | J23: #REF! | K23: #REF! | L23: #REF! | M23: #REF! | N23: #REF! | O23: #REF! | P23: #REF! | Q23: #REF! | R23: #REF! | S23: #REF! | T23: #REF! | U23: #REF! | V23: #REF! | W23: #REF! | X23: #REF! | Y23: #REF! | Z23: #REF! | AA23: #REF! | AB23: #REF! | AC23: #REF! | AD23: #REF! | AE23: #REF! | AG23: =J23*F23 -> #REF! | AH23: =K23*F23 -> #REF! | AI23: =L23*F23 -> #REF! | AJ23: =M23*F23 -> #REF! | AK23: =N23*F23 -> #REF! | AL23: =O23*F23 -> #REF! | AM23: =P23*F23 -> #REF! | AN23: =Q23*F23 -> #REF! | AO23: =R23*F23 -> #REF! | AP23: =S23*F23 -> #REF! | AQ23: =T23*F23 -> #REF! | AR23: =U23*F23 -> #REF! | AS23: =V23*F23 -> #REF! | AT23: =W23*F23 -> #REF! | AU23: =X23*F23 -> #REF! | AV23: =Y23*F23 -> #REF! | AW23: =Z23*F23 -> #REF! | AX23: =AA23*F23 -> #REF! | AY23: =AB23*F23 -> #REF! | AZ23: =AC23*F23 -> #REF! | BA23: =AD23*F23 -> #REF!
C24: TOTAL ALL | J24: =SUM(J9:J23) -> #REF! | K24: =SUM(K9:K23) -> #REF! | L24: =SUM(L9:L23) -> #REF! | M24: =SUM(M9:M23) -> #REF! | N24: =SUM(N9:N23) -> #REF! | O24: =SUM(O9:O23) -> #REF! | P24: =SUM(P9:P23) -> #REF! | Q24: =SUM(Q9:Q23) -> #REF! | ... AE24: =SUM(AE9:AE23) -> #REF! | AG24: =SUM(AG9:AG23) -> #REF! | AH24: =SUM(AH9:AH23) -> #REF! | AI24: =SUM(AI9:AI23) -> #REF! | AJ24: =SUM(AJ9:AJ23) -> #REF! | AK24: =SUM(AK9:AK23) -> #REF! | AL24: =SUM(AL9:AL23) -> #REF! | AM24: =SUM(AM9:AM23) -> #REF! | AN24: =SUM(AN9:AN23) -> #REF! | ... BA24: =SUM(BA9:BA23) -> #REF!
C25: Working Days | J25: =J6 -> FEB | M25: =M6 -> MAR | P25: =P6 -> APR | S25: =S6 -> MAY | V25: =V6 -> JUN | Y25: =Y6 -> JUL | AB25: =AB6 -> AUG
C26: Working Days Normal | J26: ='Qty & UMH GUM'!J100:L100 -> 20 | M26: ='Qty & UMH GUM'!M100:O100 -> 23 | P26: ='Qty & UMH GUM'!P100:R100 -> 17 | S26: ='Qty & UMH GUM'!S100:U100 -> 21 | V26: ='Qty & UMH GUM'!V100:X100 -> 21 | Y26: ='Qty & UMH GUM'!Y100:AA100 -> 20 | AB26: ='Qty & UMH GUM'!AB100:AD100 -> 20
M27: SIX MONTH PRODUCTION PLAN ( UMH ) | AG27: Joined MY11 to 3 assy terbesar MY10
A28: =A2 -> S/R NO : | B28: =B2 -> 202603-10 | O28: =O2 -> 900B-486D
A29: =A3 -> FAX NO : | B29: =B3 -> EMAIL | O29: =O3 -> 46082
A30: =A4 -> DATE : | B30: =B4 -> 46092
C31: =NOW() -> 46196.165 | U31: =U5
A32: =A6 -> DEST | B32: =B6 -> TYPE | C32: =C6 -> HARNESS No. | D32: =D6 -> LEVEL | E32: =E6 -> ASSY CODE | F32: =F6 -> CCT | G32: =G6 -> Std Pack | H32: =H6 -> UMH GUM JUL-DEC | I32: UMH GUM JAN - JUL | J32: =J6 -> FEB | L32: =L6 | M32: =M6 -> MAR | O32: =O6 | P32: =P6 -> APR | R32: =R6 | S32: =S6 -> MAY | U32: =U6 | V32: =V6 -> JUN | X32: =X6 | Y32: =Y6 -> JUL | AA32: =AA6 | AB32: =AB6 -> AUG | AD32: =AD6 | AE32: =AE6 -> BAL
J33: =J7 -> 02/FEB ~ 27/FEB | L33: =L7 | M33: =M7 -> 02/MAR ~ 31/MAR | O33: =O7 | P33: =P7 -> 01/APR ~ 30/APR | R33: =R7 | S33: =S7 -> 02/MAY ~ 30/MAY | U33: =U7 | V33: =V7 -> 02/JUN ~ 30/JUN | X33: =X7 | Y33: =Y7 -> 01/JUL ~ 31/JUL | AA33: =AA7 | AB33: =AB7 -> 03/AUG ~ 31/AUG | AD33: =AD7
J34: =J8 -> BAL | L34: =L8 -> PROD | M34: =J8 -> BAL | N34: =K8 -> DEL | O34: =L8 -> PROD | P34: =M8 -> BAL | Q34: =N8 -> DEL | R34: =O8 -> PROD | S34: =P8 -> BAL | T34: =Q8 -> DEL | ... AD34: =AA8 -> PROD
A35: =+A9 -> NASHVILLE & CANTON TK09 | C35: =C9 -> #REF! | D35: =D9 -> #REF! | E35: =E9 | F35: =F9 -> #REF! | G35: =G9 -> #REF! | H35: =H9 -> #REF! | J35: =$H35*J9 -> #REF! | K35: =$H35*K9 -> #REF! | L35: =$H35*L9 -> #REF! | M35: =$H35*M9 -> #REF! | N35: =$H35*N9 -> #REF! | O35: =$H35*O9 -> #REF! | P35: =$H35*P9 -> #REF! | Q35: =$H35*Q9 -> #REF! | ... AE35: =$H35*AE9 -> #REF!
C36: =C10 -> #REF! | D36: =D10 -> #REF! | E36: =E10 | F36: =F10 -> #REF! | G36: =G10 -> #REF! | H36: =H10 -> #REF! | J36: =$H36*J10 -> #REF! | K36: =$H36*K10 -> #REF! | L36: =$H36*L10 -> #REF! | M36: =$H36*M10 -> #REF! | N36: =$H36*N10 -> #REF! | O36: =$H36*O10 -> #REF! | P36: =$H36*P10 -> #REF! | Q36: =$H36*Q10 -> #REF! | ... AE36: =$H36*AE10 -> #REF!
C37: =C11 -> #REF! | D37: =D11 -> #REF! | E37: =E11 | F37: =F11 -> #REF! | G37: =G11 -> #REF! | H37: =H11 -> #REF! | J37: =$H37*J11 -> #REF! | K37: =$H37*K11 -> #REF! | L37: =$H37*L11 -> #REF! | M37: =$H37*M11 -> #REF! | N37: =$H37*N11 -> #REF! | O37: =$H37*O11 -> #REF! | P37: =$H37*P11 -> #REF! | Q37: =$H37*Q11 -> #REF! | ... AE37: =$H37*AE11 -> #REF!
C38: =C12 -> #REF! | D38: =D12 -> #REF! | E38: =E12 | F38: =F12 -> #REF! | G38: =G12 -> #REF! | H38: =H12 -> #REF! | J38: =$H38*J12 -> #REF! | K38: =$H38*K12 -> #REF! | L38: =$H38*L12 -> #REF! | M38: =$H38*M12 -> #REF! | N38: =$H38*N12 -> #REF! | O38: =$H38*O12 -> #REF! | P38: =$H38*P12 -> #REF! | Q38: =$H38*Q12 -> #REF! | ... AE38: =$H38*AE12 -> #REF!
C39: =C13 -> #REF! | D39: =D13 -> #REF! | E39: =E13 | F39: =F13 -> #REF! | G39: =G13 -> #REF! | H39: =H13 -> #REF! | J39: =$H39*J13 -> #REF! | K39: =$H39*K13 -> #REF! | L39: =$H39*L13 -> #REF! | M39: =$H39*M13 -> #REF! | N39: =$H39*N13 -> #REF! | O39: =$H39*O13 -> #REF! | P39: =$H39*P13 -> #REF! | Q39: =$H39*Q13 -> #REF! | ... AE39: =$H39*AE13 -> #REF!
C40: =C14 -> #REF! | D40: =D14 -> #REF! | E40: =E14 | F40: =F14 -> #REF! | G40: =G14 -> #REF! | H40: =H14 -> #REF! | J40: =$H40*J14 -> #REF! | K40: =$H40*K14 -> #REF! | L40: =$H40*L14 -> #REF! | M40: =$H40*M14 -> #REF! | N40: =$H40*N14 -> #REF! | O40: =$H40*O14 -> #REF! | P40: =$H40*P14 -> #REF! | Q40: =$H40*Q14 -> #REF! | ... AE40: =$H40*AE14 -> #REF!
...

Sheet AS400 JEMBATAN
A2: S/R NO : | B2: ='Qty & UMH GUM'!B2 -> 202603-10
A3: DATE : | B3: ='Qty & UMH GUM'!B4 -> 46092
D4: =VLOOKUP(D$6,WEEK!$A$55:$D$66,4,0) -> 5 | M4: =VLOOKUP(M$6,WEEK!$A$55:$D$66,4,0) -> 4 | V4: =VLOOKUP(V$6,WEEK!$A$55:$D$66,4,0) -> 4 | AE4: =VLOOKUP(AE$6,WEEK!$A$55:$D$66,4,0) -> 5 | AN4: =VLOOKUP(AN$6,WEEK!$A$55:$D$66,4,0) -> 4
A5: Printed : | B5: =NOW() -> 46196.165 | D5: Q | M5: T | V5: W | AE5: Z | AN5: AC
A6: TYPE | B6: HARNESS No. | C6: LEVEL | D6: ='Qty & UMH GUM'!P6 -> APR | M6: ='Qty & UMH GUM'!S6 -> MAY | V6: ='Qty & UMH GUM'!V6 -> JUN | AE6: ='Qty & UMH GUM'!Y6 -> JUL | AN6: ='Qty & UMH GUM'!AB6 -> AUG
