Workbook
Name ProdLines: [1]Chart!$A$66:$A$66

Sheet NOTES
B2: JAI Meeting Notes from 01/05
B24: Release Notes from 01/05
B40: JAI Meeting Notes from 01/08
B53: Release Notes from 01/10
B64: Release Notes from 01/15
B74: Release Notes from 01/22
B90: Release Notes from 01/29
B99: Release Notes from 02/05
B109: Release Notes from 02/12
B117: Release Notes from 02/19
B124: Release Notes from 02/26
B133: Release Notes from 03/04
... B149: Release Notes from 03/18

Sheet SUMMARY
A1: 1 | B1: =+A1+1 -> 2 | C1: =+B1+1 -> 3 | D1: =+C1+1 -> 4 | E1: =+D1+1 -> 5 | F1: =+E1+1 -> 6 | G1: =+F1+1 -> 7 | H1: =+G1+1 -> 8 | I1: =+H1+1 -> 9 | ... BN1: =+BM1+1 -> 66
A2: =+'[2]Final SR'!BJ10 -> ETD Date | B2: =+'Final SR'!BK10 -> 46041 | C2: =+'Final SR'!BL10 -> 46048 | D2: =+'Final SR'!BM10 -> 46055 | E2: =+'Final SR'!BN10 -> 46062 | F2: =+'Final SR'!BO10 -> 46069 | G2: =+'Final SR'!BP10 -> 46076 | H2: =+'Final SR'!BQ10 -> 46083 | I2: =+'Final SR'!BR10 -> 46090 | ... BN2: =+'Final SR'!DW10 -> 0
A3: =+'[2]Final SR'!BJ11 -> ETA Date | B3: =+'Final SR'!BK11 -> 46083 | C3: =+'Final SR'!BL11 -> 46090 | D3: =+'Final SR'!BM11 -> 46097 | E3: =+'Final SR'!BN11 -> 46104 | F3: =+'Final SR'!BO11 -> 46111 | G3: =+'Final SR'!BP11 -> 46118 | H3: =+'Final SR'!BQ11 -> 46125 | I3: =+'Final SR'!BR11 -> 46132 | ... BN3: =+'Final SR'!DW11 -> DEC
A4: Row Labels | B4: Sum of 2-Mar | C4: Sum of 9-Mar | D4: Sum of 16-Mar | E4: Sum of 23-Mar | F4: Sum of 30-Mar | G4: Sum of 6-Apr | H4: Sum of 13-Apr | I4: Sum of 20-Apr | J4: Sum of 27-Apr | K4: Sum of 4-May | L4: Sum of 11-May | M4: Sum of 18-May | N4: Sum of 25-May | O4: Sum of 1-Jun | P4: Sum of 8-Jun | Q4: Sum of 15-Jun | R4: Sum of 22-Jun | S4: Sum of 29-Jun | T4: Sum of 6-Jul | U4: Sum of 13-Jul | V4: Sum of 20-Jul | W4: Sum of 27-Jul | X4: Sum of 3-Aug | Y4: Sum of 10-Aug | Z4: Sum of 17-Aug | AA4: Sum of 24-Aug | AB4: Sum of 31-Aug | AC4: Sum of 7-Sep | AD4: Sum of 14-Sep | AE4: Sum of 21-Sep | AF4: Sum of 28-Sep | AG4: Sum of 5-Oct | AH4: Sum of 12-Oct | AI4: Sum of 19-Oct | AJ4: Sum of 26-Oct | AK4: Sum of 2-Nov | AL4: Sum of 9-Nov | AM4: Sum of 16-Nov | AN4: Sum of 23-Nov | AO4: Sum of 30-Nov | AP4: Sum of 7-Dec | AQ4: Sum of 14-Dec | AR4: Sum of 21-Dec | AS4: Sum of 28-Dec | AT4: Sum of 4-Jan | AU4: Sum of 11-Jan | AV4: Sum of 12-Jan | AW4: Sum of 19-Jan | AX4: Sum of 26-Jan | AY4: Sum of 2-Feb | AZ4: Sum of 9-Feb | BA4: Sum of 16-Feb
A5: 82115-0E310 | B5: 0 | C5: 0 | D5: 0 | E5: 0 | F5: 0 | G5: 0 | H5: 0 | I5: 0 | J5: 0 | K5: 0 | L5: 0 | M5: 0 | N5: 0 | O5: 0 | P5: 0 | Q5: 0 | R5: 0 | S5: 0 | T5: 0 | U5: 0 | V5: 0 | W5: 0 | X5: 0 | Y5: 0 | Z5: 0 | AA5: 0 | AB5: 0 | AC5: 0 | AD5: 0 | AE5: 0 | AF5: 0 | AG5: 0 | AH5: 0 | AI5: 0 | AJ5: 0 | AK5: 0 | AL5: 0 | AM5: 0 | AN5: 0 | AO5: 0 | AP5: 0 | AQ5: 0 | AR5: 0 | AS5: 0 | AT5: 0 | AU5: 0 | AV5: 0 | AW5: 0 | AX5: 0 | AY5: 0 | AZ5: 0 | BA5: 0 | BC5: =SUM(B5:C5) -> 0 | BD5: =SUM(D5:G5) -> 0 | BE5: =SUM(H5:K5) -> 0 | BF5: =SUM(L5:P5) -> 0 | BG5: =SUM(Q5:T5) -> 0 | BH5: =SUM(U5:X5) -> 0 | BI5: =SUM(Y5:AC5) -> 0 | BJ5: =SUM(AD5:AG5) -> 0 | BK5: =SUM(AH5:AL5) -> 0 | BL5: =SUM(AM5:AP5) -> 0 | BM5: =SUM(AQ5:AT5) -> 0 | BN5: =SUM(AU5:AY5) -> 0
A6: 82115-0E310 B | B6: 0 | C6: 0 | D6: 0 | E6: 0 | F6: 0 | G6: 0 | H6: 0 | I6: 0 | J6: 0 | K6: 0 | L6: 0 | M6: 0 | N6: 0 | O6: 0 | P6: 0 | Q6: 0 | R6: 0 | S6: 0 | T6: 0 | U6: 0 | V6: 0 | W6: 0 | X6: 0 | Y6: 0 | Z6: 0 | AA6: 0 | AB6: 0 | AC6: 0 | AD6: 0 | AE6: 0 | AF6: 0 | AG6: 0 | AH6: 0 | AI6: 0 | AJ6: 0 | AK6: 0 | AL6: 0 | AM6: 0 | AN6: 0 | AO6: 0 | AP6: 0 | AQ6: 0 | AR6: 0 | AS6: 0 | AT6: 0 | AU6: 0 | AV6: 0 | AW6: 0 | AX6: 0 | AY6: 0 | AZ6: 0 | BA6: 0 | BC6: =SUM(B6:C6) -> 0 | BD6: =SUM(D6:G6) -> 0 | BE6: =SUM(H6:K6) -> 0 | BF6: =SUM(L6:P6) -> 0 | BG6: =SUM(Q6:T6) -> 0 | BH6: =SUM(U6:X6) -> 0 | BI6: =SUM(Y6:AC6) -> 0 | BJ6: =SUM(AD6:AG6) -> 0 | BK6: =SUM(AH6:AL6) -> 0 | BL6: =SUM(AM6:AP6) -> 0 | BM6: =SUM(AQ6:AT6) -> 0 | BN6: =SUM(AU6:AY6) -> 0
A7: 82115-0E440 L | B7: 260 | C7: 364 | D7: 380 | E7: 600 | F7: 936 | G7: 476 | H7: 128 | I7: 0 | J7: 0 | K7: 0 | L7: 0 | M7: 0 | N7: 0 | O7: 0 | P7: 0 | Q7: 0 | R7: 0 | S7: 0 | T7: 0 | U7: 0 | V7: 0 | W7: 0 | X7: 0 | Y7: 0 | Z7: 0 | AA7: 0 | AB7: 0 | AC7: 0 | AD7: 0 | AE7: 0 | AF7: 0 | AG7: 0 | AH7: 0 | AI7: 0 | AJ7: 0 | AK7: 0 | AL7: 0 | AM7: 0 | AN7: 0 | AO7: 0 | AP7: 0 | AQ7: 0 | AR7: 0 | AS7: 0 | AT7: 0 | AU7: 0 | AV7: 0 | AW7: 0 | AX7: 0 | AY7: 0 | AZ7: 0 | BA7: 0 | BC7: =SUM(B7:C7) -> 624 | BD7: =SUM(D7:G7) -> 2392 | BE7: =SUM(H7:K7) -> 128 | BF7: =SUM(L7:P7) -> 0 | BG7: =SUM(Q7:T7) -> 0 | BH7: =SUM(U7:X7) -> 0 | BI7: =SUM(Y7:AC7) -> 0 | BJ7: =SUM(AD7:AG7) -> 0 | BK7: =SUM(AH7:AL7) -> 0 | BL7: =SUM(AM7:AP7) -> 0 | BM7: =SUM(AQ7:AT7) -> 0 | BN7: =SUM(AU7:AY7) -> 0
A8: 82115-0E440 M | B8: 0 | C8: 0 | D8: 0 | E8: 0 | F8: 0 | G8: 0 | H8: 192 | I8: 428 | J8: 0 | K8: 416 | L8: 412 | M8: 364 | N8: 360 | O8: 224 | P8: 168 | Q8: 168 | R8: 220 | S8: 308 | T8: 304 | U8: 308 | V8: 260 | W8: 260 | X8: 212 | Y8: 296 | Z8: 176 | AA8: 252 | AB8: 352 | AC8: 352 | AD8: 492 | AE8: 492 | AF8: 492 | AG8: 492 | AH8: 492 | AI8: 492 | AJ8: 492 | AK8: 492 | AL8: 492 | AM8: 492 | AN8: 492 | AO8: 492 | AP8: 492 | AQ8: 492 | AR8: 492 | AS8: 492 | AT8: 492 | AU8: 492 | AV8: 492 | AW8: 492 | AX8: 492 | AY8: 492 | AZ8: 492 | BA8: 492 | BC8: =SUM(B8:C8) -> 0 | BD8: =SUM(D8:G8) -> 0 | BE8: =SUM(H8:K8) -> 1036 | BF8: =SUM(L8:P8) -> 1528 | BG8: =SUM(Q8:T8) -> 1000 | BH8: =SUM(U8:X8) -> 1040 | BI8: =SUM(Y8:AC8) -> 1428 | BJ8: =SUM(AD8:AG8) -> 1968 | BK8: =SUM(AH8:AL8) -> 2460 | BL8: =SUM(AM8:AP8) -> 1968 | BM8: =SUM(AQ8:AT8) -> 1968 | BN8: =SUM(AU8:AY8) -> 2460
A9: 82115-0E440. | B9: 1224 | C9: 0 | D9: 0 | E9: 0 | F9: 0 | G9: 0 | H9: 0 | I9: 0 | J9: 0 | K9: 0 | L9: 0 | M9: 0 | N9: 0 | O9: 0 | P9: 0 | Q9: 0 | R9: 0 | S9: 0 | T9: 0 | U9: 0 | V9: 0 | W9: 0 | X9: 0 | Y9: 0 | Z9: 0 | AA9: 0 | AB9: 0 | AC9: 0 | AD9: 0 | AE9: 0 | AF9: 0 | AG9: 0 | AH9: 0 | AI9: 0 | AJ9: 0 | AK9: 0 | AL9: 0 | AM9: 0 | AN9: 0 | AO9: 0 | AP9: 0 | AQ9: 0 | AR9: 0 | AS9: 0 | AT9: 0 | AU9: 0 | AV9: 0 | AW9: 0 | AX9: 0 | AY9: 0 | AZ9: 0 | BA9: 0 | BC9: =SUM(B9:C9) -> 1224 | BD9: =SUM(D9:G9) -> 0 | BE9: =SUM(H9:K9) -> 0 | BF9: =SUM(L9:P9) -> 0 | BG9: =SUM(Q9:T9) -> 0 | BH9: =SUM(U9:X9) -> 0 | BI9: =SUM(Y9:AC9) -> 0 | BJ9: =SUM(AD9:AG9) -> 0 | BK9: =SUM(AH9:AL9) -> 0 | BL9: =SUM(AM9:AP9) -> 0 | BM9: =SUM(AQ9:AT9) -> 0 | BN9: =SUM(AU9:AY9) -> 0
A10: 82115-0E450 L | B10: 196 | C10: 240 | D10: 64 | E10: 448 | F10: 196 | G10: 216 | H10: 72 | I10: 0 | J10: 0 | K10: 0 | L10: 0 | M10: 0 | N10: 0 | O10: 0 | P10: 0 | Q10: 0 | R10: 0 | S10: 0 | T10: 0 | U10: 0 | V10: 0 | W10: 0 | X10: 0 | Y10: 0 | Z10: 0 | AA10: 0 | AB10: 0 | AC10: 0 | AD10: 0 | AE10: 0 | AF10: 0 | AG10: 0 | AH10: 0 | AI10: 0 | AJ10: 0 | AK10: 0 | AL10: 0 | AM10: 0 | AN10: 0 | AO10: 0 | AP10: 0 | AQ10: 0 | AR10: 0 | AS10: 0 | AT10: 0 | AU10: 0 | AV10: 0 | AW10: 0 | AX10: 0 | AY10: 0 | AZ10: 0 | BA10: 0 | BC10: =SUM(B10:C10) -> 436 | BD10: =SUM(D10:G10) -> 924 | BE10: =SUM(H10:K10) -> 72 | BF10: =SUM(L10:P10) -> 0 | BG10: =SUM(Q10:T10) -> 0 | BH10: =SUM(U10:X10) -> 0 | BI10: =SUM(Y10:AC10) -> 0 | BJ10: =SUM(AD10:AG10) -> 0 | BK10: =SUM(AH10:AL10) -> 0 | BL10: =SUM(AM10:AP10) -> 0 | BM10: =SUM(AQ10:AT10) -> 0 | BN10: =SUM(AU10:AY10) -> 0
A11: 82115-0E450 M | B11: 0 | C11: 0 | D11: 0 | E11: 0 | F11: 0 | G11: 0 | H11: 100 | I11: 264 | J11: 0 | K11: 364 | L11: 188 | M11: 188 | N11: 176 | O11: 108 | P11: 84 | Q11: 80 | R11: 108 | S11: 152 | T11: 148 | U11: 148 | V11: 120 | W11: 160 | X11: 104 | Y11: 144 | Z11: 60 | AA11: 120 | AB11: 172 | AC11: 172 | AD11: 276 | AE11: 204 | AF11: 204 | AG11: 204 | AH11: 204 | AI11: 204 | AJ11: 204 | AK11: 204 | AL11: 204 | AM11: 204 | AN11: 204 | AO11: 204 | AP11: 204 | AQ11: 204 | AR11: 204 | AS11: 204 | AT11: 204 | AU11: 204 | AV11: 204 | AW11: 204 | AX11: 204 | AY11: 204 | AZ11: 204 | BA11: 204 | BC11: =SUM(B11:C11) -> 0 | BD11: =SUM(D11:G11) -> 0 | BE11: =SUM(H11:K11) -> 728 | BF11: =SUM(L11:P11) -> 744 | BG11: =SUM(Q11:T11) -> 488 | BH11: =SUM(U11:X11) -> 532 | BI11: =SUM(Y11:AC11) -> 668 | BJ11: =SUM(AD11:AG11) -> 888 | BK11: =SUM(AH11:AL11) -> 1020 | BL11: =SUM(AM11:AP11) -> 816 | BM11: =SUM(AQ11:AT11) -> 816 | BN11: =SUM(AU11:AY11) -> 1020
A12: 82115-0E450. | B12: 276 | C12: 176 | D12: 0 | E12: 0 | F12: 0 | G12: 0 | H12: 0 | I12: 0 | J12: 0 | K12: 0 | L12: 0 | M12: 0 | N12: 0 | O12: 0 | P12: 0 | Q12: 0 | R12: 0 | S12: 0 | T12: 0 | U12: 0 | V12: 0 | W12: 0 | X12: 0 | Y12: 0 | Z12: 0 | AA12: 0 | AB12: 0 | AC12: 0 | AD12: 0 | AE12: 0 | AF12: 0 | AG12: 0 | AH12: 0 | AI12: 0 | AJ12: 0 | AK12: 0 | AL12: 0 | AM12: 0 | AN12: 0 | AO12: 0 | AP12: 0 | AQ12: 0 | AR12: 0 | AS12: 0 | AT12: 0 | AU12: 0 | AV12: 0 | AW12: 0 | AX12: 0 | AY12: 0 | AZ12: 0 | BA12: 0 | BC12: =SUM(B12:C12) -> 452 | BD12: =SUM(D12:G12) -> 0 | BE12: =SUM(H12:K12) -> 0 | BF12: =SUM(L12:P12) -> 0 | BG12: =SUM(Q12:T12) -> 0 | BH12: =SUM(U12:X12) -> 0 | BI12: =SUM(Y12:AC12) -> 0 | BJ12: =SUM(AD12:AG12) -> 0 | BK12: =SUM(AH12:AL12) -> 0 | BL12: =SUM(AM12:AP12) -> 0 | BM12: =SUM(AQ12:AT12) -> 0 | BN12: =SUM(AU12:AY12) -> 0
A13: 82115-0E460 L | B13: 204 | C13: 408 | D13: 504 | E13: 0 | F13: 264 | G13: 380 | H13: 792 | I13: 0 | J13: 0 | K13: 0 | L13: 0 | M13: 0 | N13: 0 | O13: 0 | P13: 0 | Q13: 0 | R13: 0 | S13: 0 | T13: 0 | U13: 0 | V13: 0 | W13: 0 | X13: 0 | Y13: 0 | Z13: 0 | AA13: 0 | AB13: 0 | AC13: 0 | AD13: 0 | AE13: 0 | AF13: 0 | AG13: 0 | AH13: 0 | AI13: 0 | AJ13: 0 | AK13: 0 | AL13: 0 | AM13: 0 | AN13: 0 | AO13: 0 | AP13: 0 | AQ13: 0 | AR13: 0 | AS13: 0 | AT13: 0 | AU13: 0 | AV13: 0 | AW13: 0 | AX13: 0 | AY13: 0 | AZ13: 0 | BA13: 0 | BC13: =SUM(B13:C13) -> 612 | BD13: =SUM(D13:G13) -> 1148 | BE13: =SUM(H13:K13) -> 792 | BF13: =SUM(L13:P13) -> 0 | BG13: =SUM(Q13:T13) -> 0 | BH13: =SUM(U13:X13) -> 0 | BI13: =SUM(Y13:AC13) -> 0 | BJ13: =SUM(AD13:AG13) -> 0 | BK13: =SUM(AH13:AL13) -> 0 | BL13: =SUM(AM13:AP13) -> 0 | BM13: =SUM(AQ13:AT13) -> 0 | BN13: =SUM(AU13:AY13) -> 0
A14: 82115-0E460 M | B14: 0 | C14: 0 | D14: 0 | E14: 0 | F14: 0 | G14: 0 | H14: 12 | I14: 532 | J14: 0 | K14: 480 | L14: 500 | M14: 392 | N14: 328 | O14: 240 | P14: 180 | Q14: 180 | R14: 236 | S14: 328 | T14: 328 | U14: 328 | V14: 280 | W14: 276 | X14: 232 | Y14: 312 | Z14: 196 | AA14: 264 | AB14: 384 | AC14: 372 | AD14: 536 | AE14: 524 | AF14: 524 | AG14: 524 | AH14: 524 | AI14: 524 | AJ14: 524 | AK14: 524 | AL14: 524 | AM14: 524 | AN14: 524 | AO14: 524 | AP14: 524 | AQ14: 524 | AR14: 524 | AS14: 524 | AT14: 524 | AU14: 524 | AV14: 524 | AW14: 524 | AX14: 524 | AY14: 524 | AZ14: 524 | BA14: 524 | BC14: =SUM(B14:C14) -> 0 | BD14: =SUM(D14:G14) -> 0 | BE14: =SUM(H14:K14) -> 1024 | BF14: =SUM(L14:P14) -> 1640 | BG14: =SUM(Q14:T14) -> 1072 | BH14: =SUM(U14:X14) -> 1116 | BI14: =SUM(Y14:AC14) -> 1528 | BJ14: =SUM(AD14:AG14) -> 2108 | BK14: =SUM(AH14:AL14) -> 2620 | BL14: =SUM(AM14:AP14) -> 2096 | BM14: =SUM(AQ14:AT14) -> 2096 | BN14: =SUM(AU14:AY14) -> 2620
A15: 82115-0E460. | B15: 896 | C15: 0 | D15: 0 | E15: 0 | F15: 0 | G15: 0 | H15: 0 | I15: 0 | J15: 0 | K15: 0 | L15: 0 | M15: 0 | N15: 0 | O15: 0 | P15: 0 | Q15: 0 | R15: 0 | S15: 0 | T15: 0 | U15: 0 | V15: 0 | W15: 0 | X15: 0 | Y15: 0 | Z15: 0 | AA15: 0 | AB15: 0 | AC15: 0 | AD15: 0 | AE15: 0 | AF15: 0 | AG15: 0 | AH15: 0 | AI15: 0 | AJ15: 0 | AK15: 0 | AL15: 0 | AM15: 0 | AN15: 0 | AO15: 0 | AP15: 0 | AQ15: 0 | AR15: 0 | AS15: 0 | AT15: 0 | AU15: 0 | AV15: 0 | AW15: 0 | AX15: 0 | AY15: 0 | AZ15: 0 | BA15: 0 | BC15: =SUM(B15:C15) -> 896 | BD15: =SUM(D15:G15) -> 0 | BE15: =SUM(H15:K15) -> 0 | BF15: =SUM(L15:P15) -> 0 | BG15: =SUM(Q15:T15) -> 0 | BH15: =SUM(U15:X15) -> 0 | BI15: =SUM(Y15:AC15) -> 0 | BJ15: =SUM(AD15:AG15) -> 0 | BK15: =SUM(AH15:AL15) -> 0 | BL15: =SUM(AM15:AP15) -> 0 | BM15: =SUM(AQ15:AT15) -> 0 | BN15: =SUM(AU15:AY15) -> 0
A16: 82115-0E480 K | B16: 788 | C16: 348 | D16: 348 | E16: 348 | F16: 348 | G16: 348 | H16: 520 | I16: 524 | J16: 0 | K16: 596 | L16: 248 | M16: 248 | N16: 248 | O16: 248 | P16: 248 | Q16: 248 | R16: 248 | S16: 248 | T16: 248 | U16: 248 | V16: 248 | W16: 248 | X16: 248 | Y16: 248 | Z16: 248 | AA16: 248 | AB16: 248 | AC16: 248 | AD16: 248 | AE16: 248 | AF16: 248 | AG16: 248 | AH16: 248 | AI16: 248 | AJ16: 248 | AK16: 248 | AL16: 248 | AM16: 248 | AN16: 248 | AO16: 248 | AP16: 248 | AQ16: 248 | AR16: 248 | AS16: 248 | AT16: 248 | AU16: 248 | AV16: 248 | AW16: 248 | AX16: 248 | AY16: 248 | AZ16: 248 | BA16: 248 | BC16: =SUM(B16:C16) -> 1136 | BD16: =SUM(D16:G16) -> 1392 | BE16: =SUM(H16:K16) -> 1640 | BF16: =SUM(L16:P16) -> 1240 | BG16: =SUM(Q16:T16) -> 992 | BH16: =SUM(U16:X16) -> 992 | BI16: =SUM(Y16:AC16) -> 1240 | BJ16: =SUM(AD16:AG16) -> 992 | BK16: =SUM(AH16:AL16) -> 1240 | BL16: =SUM(AM16:AP16) -> 992 | BM16: =SUM(AQ16:AT16) -> 992 | BN16: =SUM(AU16:AY16) -> 1240
... A45: 82115-0EZ90 B | B45: 216 | C45: 0 | D45: 0 | E45: 0 | F45: 0 | G45: 0 | H45: 0 | I45: 0 | J45: 0 | K45: 0 | L45: 0 | M45: 0 | N45: 0 | O45: 0 | P45: 0 | Q45: 0 | R45: 0 | S45: 0 | T45: 0 | U45: 0 | V45: 0 | W45: 0 | X45: 0 | Y45: 0 | Z45: 0 | AA45: 0 | AB45: 0 | AC45: 0 | AD45: 0 | AE45: 0 | AF45: 0 | AG45: 0 | AH45: 0 | AI45: 0 | AJ45: 0 | AK45: 0 | AL45: 0 | AM45: 0 | AN45: 0 | AO45: 0 | AP45: 0 | AQ45: 0 | AR45: 0 | AS45: 0 | AT45: 0 | AU45: 0 | AV45: 0 | AW45: 0 | AX45: 0 | AY45: 0 | AZ45: 0 | BA45: 0 | BC45: =SUM(B45:C45) -> 216 | BD45: =SUM(D45:G45) -> 0 | BE45: =SUM(H45:K45) -> 0 | BF45: =SUM(L45:P45) -> 0 | BG45: =SUM(Q45:T45) -> 0 | BH45: =SUM(U45:X45) -> 0 | BI45: =SUM(Y45:AC45) -> 0 | BJ45: =SUM(AD45:AG45) -> 0 | BK45: =SUM(AH45:AL45) -> 0 | BL45: =SUM(AM45:AP45) -> 0 | BM45: =SUM(AQ45:AT45) -> 0 | BN45: =SUM(AU45:AY45) -> 0
A46: (blank) | BC46: =SUM(B46:C46) -> 0 | BD46: =SUM(D46:G46) -> 0 | BE46: =SUM(H46:K46) -> 0 | BF46: =SUM(L46:P46) -> 0 | BG46: =SUM(Q46:T46) -> 0 | BH46: =SUM(U46:X46) -> 0 | BI46: =SUM(Y46:AC46) -> 0 | BJ46: =SUM(AD46:AG46) -> 0 | BK46: =SUM(AH46:AL46) -> 0 | BL46: =SUM(AM46:AP46) -> 0 | BM46: =SUM(AQ46:AT46) -> 0 | BN46: =SUM(AU46:AY46) -> 0
A47: 82115-0EA10 J | B47: 1444 | C47: 0 | D47: 0 | E47: 0 | F47: 0 | G47: 0 | H47: 0 | I47: 0 | J47: 0 | K47: 0 | L47: 0 | M47: 0 | N47: 0 | O47: 0 | P47: 0 | Q47: 0 | R47: 0 | S47: 0 | T47: 0 | U47: 0 | V47: 0 | W47: 0 | X47: 0 | Y47: 0 | Z47: 0 | AA47: 0 | AB47: 0 | AC47: 0 | AD47: 0 | AE47: 0 | AF47: 0 | AG47: 0 | AH47: 0 | AI47: 0 | AJ47: 0 | AK47: 0 | AL47: 0 | AM47: 0 | AN47: 0 | AO47: 0 | AP47: 0 | AQ47: 0 | AR47: 0 | AS47: 0 | AT47: 0 | AU47: 0 | AV47: 0 | AW47: 0 | AX47: 0 | AY47: 0 | AZ47: 0 | BA47: 0 | BC47: =SUM(B47:C47) -> 1444 | BD47: =SUM(D47:G47) -> 0 | BE47: =SUM(H47:K47) -> 0 | BF47: =SUM(L47:P47) -> 0 | BG47: =SUM(Q47:T47) -> 0 | BH47: =SUM(U47:X47) -> 0 | BI47: =SUM(Y47:AC47) -> 0 | BJ47: =SUM(AD47:AG47) -> 0 | BK47: =SUM(AH47:AL47) -> 0 | BL47: =SUM(AM47:AP47) -> 0 | BM47: =SUM(AQ47:AT47) -> 0 | BN47: =SUM(AU47:AY47) -> 0
A48: 82115-0E490 J | B48: 372 | C48: 0 | D48: 0 | E48: 0 | F48: 0 | G48: 0 | H48: 0 | I48: 0 | J48: 0 | K48: 0 | L48: 0 | M48: 0 | N48: 0 | O48: 0 | P48: 0 | Q48: 0 | R48: 0 | S48: 0 | T48: 0 | U48: 0 | V48: 0 | W48: 0 | X48: 0 | Y48: 0 | Z48: 0 | AA48: 0 | AB48: 0 | AC48: 0 | AD48: 0 | AE48: 0 | AF48: 0 | AG48: 0 | AH48: 0 | AI48: 0 | AJ48: 0 | AK48: 0 | AL48: 0 | AM48: 0 | AN48: 0 | AO48: 0 | AP48: 0 | AQ48: 0 | AR48: 0 | AS48: 0 | AT48: 0 | AU48: 0 | AV48: 0 | AW48: 0 | AX48: 0 | AY48: 0 | AZ48: 0 | BA48: 0 | BC48: =SUM(B48:C48) -> 372 | BD48: =SUM(D48:G48) -> 0 | BE48: =SUM(H48:K48) -> 0 | BF48: =SUM(L48:P48) -> 0 | BG48: =SUM(Q48:T48) -> 0 | BH48: =SUM(U48:X48) -> 0 | BI48: =SUM(Y48:AC48) -> 0 | BJ48: =SUM(AD48:AG48) -> 0 | BK48: =SUM(AH48:AL48) -> 0 | BL48: =SUM(AM48:AP48) -> 0 | BM48: =SUM(AQ48:AT48) -> 0 | BN48: =SUM(AU48:AY48) -> 0
A49: Grand Total | B49: 9848 | C49: 3896 | D49: 3112 | E49: 3816 | F49: 4448 | G49: 3732 | H49: 4940 | I49: 5024 | J49: 0 | K49: 3200 | L49: 3200 | M49: 3196 | N49: 2560 | O49: 2424 | P49: 1764 | Q49: 1804 | R49: 2500 | S49: 3100 | T49: 3088 | U49: 3100 | V49: 2464 | W49: 2544 | X49: 2512 | Y49: 2988 | Z49: 2120 | AA49: 2816 | AB49: 3236 | AC49: 3236 | AD49: 4212 | AE49: 4108 | AF49: 4008 | AG49: 4008 | AH49: 4008 | AI49: 4008 | AJ49: 4008 | AK49: 4008 | AL49: 4008 | AM49: 4008 | AN49: 4008 | AO49: 4008 | AP49: 4008 | AQ49: 4008 | AR49: 4008 | AS49: 4008 | AT49: 4008 | AU49: 4008 | AV49: 4008 | AW49: 4008 | AX49: 4008 | AY49: 4008 | AZ49: 4008 | BA49: 4008 | BC49: =SUM(B49:C49) -> 13744 | BD49: =SUM(D49:G49) -> 15108 | BE49: =SUM(H49:K49) -> 13164 | BF49: =SUM(L49:P49) -> 13144 | BG49: =SUM(Q49:T49) -> 10492 | BH49: =SUM(U49:X49) -> 10620 | BI49: =SUM(Y49:AC49) -> 14396 | BJ49: =SUM(AD49:AG49) -> 16336 | BK49: =SUM(AH49:AL49) -> 20040 | BL49: =SUM(AM49:AP49) -> 16032 | BM49: =SUM(AQ49:AT49) -> 16032 | BN49: =SUM(AU49:AY49) -> 20040
A50: GAS 200D | B50: =SUM(B7:B15,B28:B30) -> 3840 | C50: =SUM(C7:C15,C28:C30) -> 1596 | D50: =SUM(D7:D15,D28:D30) -> 1240 | E50: =SUM(E7:E15,E28:E30) -> 1228 | F50: =SUM(F7:F15,F28:F30) -> 1636 | G50: =SUM(G7:G15,G28:G30) -> 1536 | H50: =SUM(H7:H15,H28:H30) -> 2064 | I50: =SUM(I7:I15,I28:I30) -> 1684 | ... BA50: =SUM(BA7:BA15,BA28:BA30) -> 1744 | BC50: =SUM(B50:C50) -> 5436 | BD50: =SUM(D50:G50) -> 5640 | BE50: =SUM(H50:K50) -> 5472 | BF50: =SUM(L50:P50) -> 5556 | BG50: =SUM(Q50:T50) -> 3640 | BH50: =SUM(U50:X50) -> 3800 | BI50: =SUM(Y50:AC50) -> 5164 | BJ50: =SUM(AD50:AG50) -> 7072 | BK50: =SUM(AH50:AL50) -> 8720 | BL50: =SUM(AM50:AP50) -> 6976 | BM50: =SUM(AQ50:AT50) -> 6976 | BN50: =SUM(AU50:AY50) -> 8720
A51: HEV 200D | B51: =SUM(B16:B17,B31,B47:B48) -> 3196 | C51: =SUM(C16:C17,C31,C47:C48) -> 1112 | D51: =SUM(D16:D17,D31,D47:D48) -> 836 | E51: =SUM(E16:E17,E31,E47:E48) -> 1168 | F51: =SUM(F16:F17,F31,F47:F48) -> 1520 | G51: =SUM(G16:G17,G31,G47:G48) -> 1044 | H51: =SUM(H16:H17,H31,H47:H48) -> 1224 | I51: =SUM(I16:I17,I31,I47:I48) -> 1304 | ... BA51: =SUM(BA16:BA17,BA31,BA47:BA48) -> 1104 | BC51: =SUM(B51:C51) -> 4308 | BD51: =SUM(D51:G51) -> 4568 | BE51: =SUM(H51:K51) -> 3672 | BF51: =SUM(L51:P51) -> 3440 | BG51: =SUM(Q51:T51) -> 3200 | BH51: =SUM(U51:X51) -> 3276 | BI51: =SUM(Y51:AC51) -> 4160 | BJ51: =SUM(AD51:AG51) -> 4440 | BK51: =SUM(AH51:AL51) -> 5520 | BL51: =SUM(AM51:AP51) -> 4416 | BM51: =SUM(AQ51:AT51) -> 4416 | BN51: =SUM(AU51:AY51) -> 5520
A52: TOTAL | B52: =+B50+B51 -> 7036 | C52: =+C50+C51 -> 2708 | D52: =+D50+D51 -> 2076 | E52: =+E50+E51 -> 2396 | F52: =+F50+F51 -> 3156 | G52: =+G50+G51 -> 2580 | H52: =+H50+H51 -> 3288 | I52: =+I50+I51 -> 2988 | ... BA52: =+BA50+BA51 -> 2848 | BC52: =SUM(B52:C52) -> 9744 | BD52: =SUM(D52:G52) -> 10208 | BE52: =SUM(H52:K52) -> 9144 | BF52: =SUM(L52:P52) -> 8996 | BG52: =SUM(Q52:T52) -> 6840 | BH52: =SUM(U52:X52) -> 7076 | BI52: =SUM(Y52:AC52) -> 9324 | BJ52: =SUM(AD52:AG52) -> 11512 | BK52: =SUM(AH52:AL52) -> 14240 | BL52: =SUM(AM52:AP52) -> 11392 | BM52: =SUM(AQ52:AT52) -> 11392 | BN52: =SUM(AU52:AY52) -> 14240
A53: GAS 564D | B53: =SUM(B5:B6,B18:B27,B32:B46) -> 2812 | C53: =SUM(C5:C6,C18:C27,C32:C46) -> 1188 | D53: =SUM(D5:D6,D18:D27,D32:D46) -> 1036 | E53: =SUM(E5:E6,E18:E27,E32:E46) -> 1420 | F53: =SUM(F5:F6,F18:F27,F32:F46) -> 1292 | G53: =SUM(G5:G6,G18:G27,G32:G46) -> 1152 | H53: =SUM(H5:H6,H18:H27,H32:H46) -> 1652 | I53: =SUM(I5:I6,I18:I27,I32:I46) -> 2036 | ... BA53: =SUM(BA5:BA6,BA18:BA27,BA32:BA46) -> 1160 | BC53: =SUM(B53:C53) -> 4000 | BD53: =SUM(D53:G53) -> 4900 | BE53: =SUM(H53:K53) -> 4020 | BF53: =SUM(L53:P53) -> 4148 | BG53: =SUM(Q53:T53) -> 3652 | BH53: =SUM(U53:X53) -> 3544 | BI53: =SUM(Y53:AC53) -> 5072 | BJ53: =SUM(AD53:AG53) -> 4824 | BK53: =SUM(AH53:AL53) -> 5800 | BL53: =SUM(AM53:AP53) -> 4640 | BM53: =SUM(AQ53:AT53) -> 4640 | BN53: =SUM(AU53:AY53) -> 5800
A54: TOTAL | B54: =+B53 -> 2812 | C54: =+C53 -> 1188 | D54: =+D53 -> 1036 | E54: =+E53 -> 1420 | F54: =+F53 -> 1292 | G54: =+G53 -> 1152 | H54: =+H53 -> 1652 | I54: =+I53 -> 2036 | ... BA54: =+BA53 -> 1160 | BC54: =SUM(B54:C54) -> 4000 | BD54: =SUM(D54:G54) -> 4900 | BE54: =SUM(H54:K54) -> 4020 | BF54: =SUM(L54:P54) -> 4148 | BG54: =SUM(Q54:T54) -> 3652 | BH54: =SUM(U54:X54) -> 3544 | BI54: =SUM(Y54:AC54) -> 5072 | BJ54: =SUM(AD54:AG54) -> 4824 | BK54: =SUM(AH54:AL54) -> 5800 | BL54: =SUM(AM54:AP54) -> 4640 | BM54: =SUM(AQ54:AT54) -> 4640 | BN54: =SUM(AU54:AY54) -> 5800
A55: TOTAL SR | B55: =+B52+B54 -> 9848 | C55: =+C52+C54 -> 3896 | D55: =+D52+D54 -> 3112 | E55: =+E52+E54 -> 3816 | F55: =+F52+F54 -> 4448 | G55: =+G52+G54 -> 3732 | H55: =+H52+H54 -> 4940 | I55: =+I52+I54 -> 5024 | ... BA55: =+BA52+BA54 -> 4008 | BC55: =SUM(B55:C55) -> 13744 | BD55: =SUM(D55:G55) -> 15108 | BE55: =SUM(H55:K55) -> 13164 | BF55: =SUM(L55:P55) -> 13144 | BG55: =SUM(Q55:T55) -> 10492 | BH55: =SUM(U55:X55) -> 10620 | BI55: =SUM(Y55:AC55) -> 14396 | BJ55: =SUM(AD55:AG55) -> 16336 | BK55: =SUM(AH55:AL55) -> 20040 | BL55: =SUM(AM55:AP55) -> 16032 | BM55: =SUM(AQ55:AT55) -> 16032 | BN55: =SUM(AU55:AY55) -> 20040
A56: TOTAL SR | B56: =SUM(B5:B48) -> 9848 | C56: =SUM(C5:C48) -> 3896 | D56: =SUM(D5:D48) -> 3112 | E56: =SUM(E5:E48) -> 3816 | F56: =SUM(F5:F48) -> 4448 | G56: =SUM(G5:G48) -> 3732 | H56: =SUM(H5:H48) -> 4940 | I56: =SUM(I5:I48) -> 5024 | ... BA56: =SUM(BA5:BA48) -> 4008 | BC56: =SUM(B56:C56) -> 13744 | BD56: =SUM(D56:G56) -> 15108 | BE56: =SUM(H56:K56) -> 13164 | BF56: =SUM(L56:P56) -> 13144 | BG56: =SUM(Q56:T56) -> 10492 | BH56: =SUM(U56:X56) -> 10620 | BI56: =SUM(Y56:AC56) -> 14396 | BJ56: =SUM(AD56:AG56) -> 16336 | BK56: =SUM(AH56:AL56) -> 20040 | BL56: =SUM(AM56:AP56) -> 16032 | BM56: =SUM(AQ56:AT56) -> 16032 | BN56: =SUM(AU56:AY56) -> 20040
A57: COMPARE SR | B57: =IF(B55=B56,"OK","N-OK") -> OK | C57: =IF(C55=C56,"OK","N-OK") -> OK | D57: =IF(D55=D56,"OK","N-OK") -> OK | E57: =IF(E55=E56,"OK","N-OK") -> OK | F57: =IF(F55=F56,"OK","N-OK") -> OK | G57: =IF(G55=G56,"OK","N-OK") -> OK | H57: =IF(H55=H56,"OK","N-OK") -> OK | I57: =IF(I55=I56,"OK","N-OK") -> OK | ... BA57: =IF(BA55=BA56,"OK","N-OK") -> OK | BC57: =IF(BC55=BC56,"OK","N-OK") -> OK | BD57: =IF(BD55=BD56,"OK","N-OK") -> OK | BE57: =IF(BE55=BE56,"OK","N-OK") -> OK | BF57: =IF(BF55=BF56,"OK","N-OK") -> OK | BG57: =IF(BG55=BG56,"OK","N-OK") -> OK | BH57: =IF(BH55=BH56,"OK","N-OK") -> OK | BI57: =IF(BI55=BI56,"OK","N-OK") -> OK | BJ57: =IF(BJ55=BJ56,"OK","N-OK") -> OK | ... BN57: =IF(BN55=BN56,"OK","N-OK") -> OK
B59: =+'Final SR'!J437 -> 9848 | C59: =+'Final SR'!K437 -> 3896 | D59: =+'Final SR'!L437 -> 3112 | E59: =+'Final SR'!M437 -> 3816 | F59: =+'Final SR'!N437 -> 4448 | G59: =+'Final SR'!O437 -> 3732 | H59: =+'Final SR'!P437 -> 4940 | I59: =+'Final SR'!Q437 -> 5024 | ... BA59: =+'Final SR'!BI437 -> 4008
B60: =B59=B56 -> TRUE | C60: =C59=C56 -> TRUE | D60: =D59=D56 -> TRUE | E60: =E59=E56 -> TRUE | F60: =F59=F56 -> TRUE | G60: =G59=G56 -> TRUE | H60: =H59=H56 -> TRUE | I60: =I59=I56 -> TRUE | ... BA60: =BA59=BA56 -> TRUE
A62: TOTAL GAS | B62: =+B50+B53 -> 6652 | C62: =+C50+C53 -> 2784 | D62: =+D50+D53 -> 2276 | E62: =+E50+E53 -> 2648 | F62: =+F50+F53 -> 2928 | G62: =+G50+G53 -> 2688 | H62: =+H50+H53 -> 3716 | I62: =+I50+I53 -> 3720 | ... BN62: =+BN50+BN53 -> 14520
A63: TOTAL HEV | B63: =+B51 -> 3196 | C63: =+C51 -> 1112 | D63: =+D51 -> 836 | E63: =+E51 -> 1168 | F63: =+F51 -> 1520 | G63: =+G51 -> 1044 | H63: =+H51 -> 1224 | I63: =+I51 -> 1304 | ... BN63: =+BN51 -> 5520

Sheet Final SR
A1: 1 | F1: Yazaki North America, Inc. | P1: Boxes | Q1: =Q437/4 -> 1256 | R1: =R437/4 -> 0 | S1: =S437/4 -> 800 | T1: =T437/4 -> 800 | U1: =U437/4 -> 799 | V1: =V437/4 -> 640 | W1: =W437/4 -> 606 | X1: =X437/4 -> 441 | ... BI1: =BI437/4 -> 1002
A2: 2 | F2: Supplier Shipping Release | P2: 40FT | Q2: =Q1/160 -> 7.85 | R2: =R1/160 -> 0 | S2: =S1/160 -> 5 | T2: =T1/160 -> 5 | U2: =U1/160 -> 4.99375 | V2: =V1/160 -> 4 | W2: =W1/160 -> 3.7875 | X2: =X1/160 -> 2.75625 | ... BI2: =BI1/160 -> 6.2625
A3: 3 | Q3: SHIP | R3: FAB | Z3: RAW
A4: 4 | F4: Ordering Plant | G4: 1090 | H4: Ordering Plant Name | I4: Memphis | L4: Product Group | N4: NONE | P4: 46083 | Q4: 46090 | R4: 46097 | S4: 46104 | T4: 46111 | U4: 46118 | V4: 46125 | W4: 46132 | X4: 46139 | Y4: 46146 | Z4: 46153 | AA4: 46160 | AB4: 46167 | AC4: 46174 | AD4: 46181 | AE4: 46188 | AF4: 46195 | AG4: 46202 | AH4: 46209 | AI4: 46216 | AJ4: 46223 | AK4: 46230 | AL4: 46237 | AM4: 46244 | AN4: 46251 | AO4: 46258 | AP4: 46265 | AQ4: 46272 | AR4: 46279 | AS4: 46286 | AT4: 46293 | AU4: 46300 | AV4: 46307 | AW4: 46314 | AX4: 46321 | AY4: 46328 | AZ4: 46335 | BA4: 46342 | BB4: 46349 | BC4: 46356 | BD4: 46363 | BE4: 46370 | BF4: 46377 | BG4: 46384 | BH4: 46391 | BI4: 46398
A5: 5 | F5: Vendor | G5: 6000224 | H5: Vendor Name | I5: PT JATIM AUTOCOMP INDONESIA | L5: Date Created | N5: 46086
A7: =+A6+1 -> 1 | B7: =IF(F7=$F$7,G8,B6) -> F0013546309 | C7: =IF(F7=$F$7,G9,C6) -> 82115-0EA10 J | D7: =VLOOKUP(B7,'Timing Table'!B:G,6,0) -> #N/A | E7: =VLOOKUP(B7,'Timing Table'!B:D,3,0) -> #N/A | F7: PSA# | G7: 5501017964 | H7: Release# | I7: 93 | J7: BEAMS ID | K7: 1177750 | M7: Release Date | O7: 46086 | P7: Std. Pack | Q7: 4
A8: =+A7+1 -> 2 | B8: =IF(F8=$F$7,G9,B7) -> F0013546309 | C8: =IF(F8=$F$7,G10,C7) -> 82115-0EA10 J | D8: =VLOOKUP(B8,'Timing Table'!B:G,6,0) -> #N/A | E8: =VLOOKUP(B8,'Timing Table'!B:D,3,0) -> #N/A | F8: YNA Part# | G8: F0013546309 | H8: YNA Part Description | I8: 82115-0EA10_J1 491D HV-2025 82115 | M8: Model Year | N8: 2025 | O8: Eng. Revision | Q8: J1 | BJ8: =BI8+1 -> 1 | BK8: =BJ8+1 -> 2 | BL8: =BK8+1 -> 3 | BM8: =BL8+1 -> 4 | BN8: =BM8+1 -> 5 | BO8: =BN8+1 -> 6 | BP8: =BO8+1 -> 7 | BQ8: =BP8+1 -> 8 | ... DW8: =DV8+1 -> 66
A9: =+A8+1 -> 3 | B9: =IF(F9=$F$7,G10,B8) -> F0013546309 | C9: =IF(F9=$F$7,G11,C8) -> 82115-0EA10 J | D9: =VLOOKUP(B9,'Timing Table'!B:G,6,0) -> #N/A | E9: =VLOOKUP(B9,'Timing Table'!B:D,3,0) -> #N/A | F9: Customer Part# | G9: 82115-0EA10 J | H9: PIA Part# | Q9: SHIP | R9: FAB | Z9: RAW
A10: =+A9+1 -> 4 | B10: =IF(F10=$F$7,G11,B9) -> F0013546309 | C10: =IF(F10=$F$7,G12,C9) -> 82115-0EA10 J | D10: =VLOOKUP(B10,'Timing Table'!B:G,6,0) -> #N/A | E10: =VLOOKUP(B10,'Timing Table'!B:D,3,0) -> #N/A | F10: High Fab | G10: 21448 | H10: B | I10: ETD Date | J10: 46041 | K10: 46048 | L10: 46055 | M10: 46062 | N10: 46069 | O10: 46076 | P10: 46083 | Q10: 46090 | R10: 46097 | S10: 46104 | T10: 46111 | U10: 46118 | V10: 46125 | W10: 46132 | X10: 46139 | Y10: 46146 | Z10: 46153 | AA10: 46160 | AB10: 46167 | AC10: 46174 | AD10: 46181 | AE10: 46188 | AF10: 46195 | AG10: 46202 | AH10: 46209 | AI10: 46216 | AJ10: 46223 | AK10: 46230 | AL10: 46237 | AM10: 46244 | AN10: 46251 | AO10: 46258 | AP10: 46265 | AQ10: 46272 | AR10: 46279 | AS10: 46286 | AT10: 46293 | AU10: 46300 | AV10: 46307 | AW10: 46314 | AX10: 46321 | AY10: 46328 | AZ10: 46335 | BA10: 46342 | BB10: 46349 | BC10: 46356 | BD10: 46363 | BE10: 46370 | BF10: 46377 | BG10: 46384 | BH10: 46391 | BI10: 46398 | BJ10: =+I10 -> ETD Date | BK10: =+J10 -> 46041 | BL10: =+K10 -> 46048 | BM10: =+L10 -> 46055 | BN10: =+M10 -> 46062 | BO10: =+N10 -> 46069 | BP10: =+O10 -> 46076 | BQ10: =+P10 -> 46083 | ... DJ10: =+BI10 -> 46398
A11: =+A10+1 -> 5 | B11: =IF(F11=$F$7,G12,B10) -> F0013546309 | C11: =IF(F11=$F$7,G13,C10) -> 82115-0EA10 J | D11: =VLOOKUP(B11,'Timing Table'!B:G,6,0) -> #N/A | E11: =VLOOKUP(B11,'Timing Table'!B:D,3,0) -> #N/A | F11: High Raw | G11: 22720 | I11: ETA Date | J11: 46083 | K11: 46090 | L11: 46097 | M11: 46104 | N11: 46111 | O11: 46118 | P11: 46125 | Q11: 46132 | R11: 46139 | S11: 46146 | T11: 46153 | U11: 46160 | V11: 46167 | W11: 46174 | X11: 46181 | Y11: 46188 | Z11: 46195 | AA11: 46202 | AB11: 46209 | AC11: 46216 | AD11: 46223 | AE11: 46230 | AF11: 46237 | AG11: 46244 | AH11: 46251 | AI11: 46258 | AJ11: 46265 | AK11: 46272 | AL11: 46279 | AM11: 46286 | AN11: 46293 | AO11: 46300 | AP11: 46307 | AQ11: 46314 | AR11: 46321 | AS11: 46328 | AT11: 46335 | AU11: 46342 | AV11: 46349 | AW11: 46356 | AX11: 46363 | AY11: 46370 | AZ11: 46377 | BA11: 46384 | BB11: 46391 | BC11: 46398 | BD11: 46399 | BE11: 46406 | BF11: 46413 | BG11: 46420 | BH11: 46427 | BI11: =+BH11+7 -> 46434 | BJ11: =+I11 -> ETA Date | BK11: =+J11 -> 46083 | BL11: =+K11 -> 46090 | BM11: =+L11 -> 46097 | BN11: =+M11 -> 46104 | BO11: =+N11 -> 46111 | BP11: =+O11 -> 46118 | BQ11: =+P11 -> 46125 | ... DJ11: =+BI11 -> 46434 | DL11: JAN | DM11: FEB | DN11: MAR | DO11: APR | DP11: MAY | DQ11: JUN | DR11: JUL | DS11: AUG | DT11: SEP | DU11: OCT | DV11: NOV | DW11: DEC
A12: =+A11+1 -> 6 | B12: =IF(F12=$F$7,G13,B11) -> F0013546309 | C12: =IF(F12=$F$7,G14,C11) -> 82115-0EA10 J | D12: =VLOOKUP(B12,'Timing Table'!B:G,6,0) -> #N/A | E12: =VLOOKUP(B12,'Timing Table'!B:D,3,0) -> #N/A | F12: Car line | G12: GRAND HIGHLANDER HYBRID 200D | H12: 82115-0EA10 | I12: Net | J12: 1444 | K12: 0 | L12: 0 | M12: 0 | N12: 0 | O12: 0 | P12: 0 | Q12: 0 | R12: 0 | S12: 0 | T12: 0 | U12: 0 | V12: 0 | W12: 0 | X12: 0 | Y12: 0 | Z12: 0 | AA12: 0 | AB12: 0 | AC12: 0 | AD12: 0 | AE12: 0 | AF12: 0 | AG12: 0 | AH12: 0 | AI12: 0 | AJ12: 0 | AK12: 0 | AL12: 0 | AM12: 0 | AN12: 0 | AO12: 0 | AP12: 0 | AQ12: 0 | AR12: 0 | AS12: 0 | AT12: 0 | AU12: 0 | AV12: 0 | AW12: 0 | AX12: 0 | AY12: 0 | AZ12: 0 | BA12: 0 | BB12: 0 | BC12: 0 | BD12: 0 | BE12: 0 | BF12: 0 | BG12: 0 | BH12: 0 | BI12: 0 | BJ12: =+G9 -> 82115-0EA10 J | BK12: =+J12 -> 1444 | BL12: =+K12 -> 0 | BM12: =+L12 -> 0 | BN12: =+M12 -> 0 | BO12: =+N12 -> 0 | BP12: =+O12 -> 0 | BQ12: =+P12 -> 0 | BR12: =+Q12 -> 0 | ... DJ12: =+BI12 -> 0 | DL12: =SUM(BK12:BL12) -> 1444 | DM12: =SUM(BM12:BP12) -> 0 | DN12: =SUM(BQ12:BT12) -> 0 | DO12: =SUM(BU12:BY12) -> 0 | DP12: =SUM(BZ12:CC12) -> 0 | DQ12: =SUM(CD12:CG12) -> 0 | DR12: =SUM(CH12:CL12) -> 0 | DS12: =SUM(CM12:CP12) -> 0 | DT12: =SUM(CQ12:CU12) -> 0 | DU12: =SUM(CV12:CY12) -> 0 | DV12: =SUM(CZ12:DC12) -> 0 | DW12: =SUM(DD12:DH12) -> 0
A13: =+A12+1 -> 7 | B13: =IF(F13=$F$7,G14,B12) -> F0013546309 | C13: =IF(F13=$F$7,G15,C12) -> 82115-0EA10 J | D13: =VLOOKUP(B13,'Timing Table'!B:G,6,0) -> #N/A | E13: =VLOOKUP(B13,'Timing Table'!B:D,3,0) -> #N/A | F13: Family | G13: 82115 | H13: 82115-0EA10 | I13: Cum | J13: 21448 | K13: 21448 | L13: 21448 | M13: 21448 | N13: 21448 | O13: 21448 | P13: 21448 | Q13: 21448 | R13: 21448 | S13: 21448 | T13: 21448 | U13: 21448 | V13: 21448 | W13: 21448 | X13: 21448 | Y13: 21448 | Z13: 21448 | AA13: 21448 | AB13: 21448 | AC13: 21448 | AD13: 21448 | AE13: 21448 | AF13: 21448 | AG13: 21448 | AH13: 21448 | AI13: 21448 | AJ13: 21448 | AK13: 21448 | AL13: 21448 | AM13: 21448 | AN13: 21448 | AO13: 21448 | AP13: 21448 | AQ13: 21448 | AR13: 21448 | AS13: 21448 | AT13: 21448 | AU13: 21448 | AV13: 21448 | AW13: 21448 | AX13: 21448 | AY13: 21448 | AZ13: 21448 | BA13: 21448 | BB13: 21448 | BC13: 21448 | BD13: 21448 | BE13: 21448 | BF13: 21448 | BG13: 21448 | BH13: 21448 | BI13: 21448 | DL13: =SUM(BK13:BL13) -> 0 | DM13: =SUM(BM13:BP13) -> 0 | DN13: =SUM(BQ13:BT13) -> 0 | DO13: =SUM(BU13:BY13) -> 0 | DP13: =SUM(BZ13:CC13) -> 0 | DQ13: =SUM(CD13:CG13) -> 0 | DR13: =SUM(CH13:CL13) -> 0 | DS13: =SUM(CM13:CP13) -> 0 | DT13: =SUM(CQ13:CU13) -> 0 | DU13: =SUM(CV13:CY13) -> 0 | DV13: =SUM(CZ13:DC13) -> 0 | DW13: =SUM(DD13:DH13) -> 0
A14: =+A13+1 -> 8 | B14: =IF(F14=$F$7,G15,B13) -> F0013546309 | C14: =IF(F14=$F$7,G16,C13) -> 82115-0EA10 J | D14: =VLOOKUP(B14,'Timing Table'!B:G,6,0) -> #N/A | E14: =VLOOKUP(B14,'Timing Table'!B:D,3,0) -> #N/A | F14: Cum Received | G14: 20004 | H14: Last Goods Receipt Invoice | J14: JAOJ60001B | DL14: =SUM(BK14:BL14) -> 0 | DM14: =SUM(BM14:BP14) -> 0 | DN14: =SUM(BQ14:BT14) -> 0 | DO14: =SUM(BU14:BY14) -> 0 | DP14: =SUM(BZ14:CC14) -> 0 | DQ14: =SUM(CD14:CG14) -> 0 | DR14: =SUM(CH14:CL14) -> 0 | DS14: =SUM(CM14:CP14) -> 0 | DT14: =SUM(CQ14:CU14) -> 0 | DU14: =SUM(CV14:CY14) -> 0 | DV14: =SUM(CZ14:DC14) -> 0 | DW14: =SUM(DD14:DH14) -> 0
A15: =+A14+1 -> 9 | B15: =IF(F15=$F$7,G16,B14) -> F0013546309 | C15: =IF(F15=$F$7,G17,C14) -> 82115-0EA10 J | D15: =VLOOKUP(B15,'Timing Table'!B:G,6,0) -> #N/A | E15: =VLOOKUP(B15,'Timing Table'!B:D,3,0) -> #N/A | F15: Comments | DL15: =SUM(BK15:BL15) -> 0 | DM15: =SUM(BM15:BP15) -> 0 | DN15: =SUM(BQ15:BT15) -> 0 | DO15: =SUM(BU15:BY15) -> 0 | DP15: =SUM(BZ15:CC15) -> 0 | DQ15: =SUM(CD15:CG15) -> 0 | DR15: =SUM(CH15:CL15) -> 0 | DS15: =SUM(CM15:CP15) -> 0 | DT15: =SUM(CQ15:CU15) -> 0 | DU15: =SUM(CV15:CY15) -> 0 | DV15: =SUM(CZ15:DC15) -> 0 | DW15: =SUM(DD15:DH15) -> 0
A16: =+A15+1 -> 10 | B16: =IF(F16=$F$7,G17,B15) -> F0013546309 | C16: =IF(F16=$F$7,G18,C15) -> 82115-0EA10 J | D16: =VLOOKUP(B16,'Timing Table'!B:G,6,0) -> #N/A | E16: =VLOOKUP(B16,'Timing Table'!B:D,3,0) -> #N/A | DL16: =SUM(BK16:BL16) -> 0 | DM16: =SUM(BM16:BP16) -> 0 | DN16: =SUM(BQ16:BT16) -> 0 | DO16: =SUM(BU16:BY16) -> 0 | DP16: =SUM(BZ16:CC16) -> 0 | DQ16: =SUM(CD16:CG16) -> 0 | DR16: =SUM(CH16:CL16) -> 0 | DS16: =SUM(CM16:CP16) -> 0 | DT16: =SUM(CQ16:CU16) -> 0 | DU16: =SUM(CV16:CY16) -> 0 | DV16: =SUM(CZ16:DC16) -> 0 | DW16: =SUM(DD16:DH16) -> 0
A17: =+A16+1 -> 11 | B17: =IF(F17=$F$7,G18,B16) -> F0013546310 | C17: =IF(F17=$F$7,G19,C16) -> 82115-0EA10 K | D17: =VLOOKUP(B17,'Timing Table'!B:G,6,0) -> #N/A | E17: =VLOOKUP(B17,'Timing Table'!B:D,3,0) -> #N/A | F17: PSA# | G17: 5501060671 | H17: Release# | I17: 18 | J17: BEAMS ID | K17: 1179886 | M17: Release Date | O17: 46086 | P17: Std. Pack | Q17: 4 | DL17: =SUM(BK17:BL17) -> 0 | DM17: =SUM(BM17:BP17) -> 0 | DN17: =SUM(BQ17:BT17) -> 0 | DO17: =SUM(BU17:BY17) -> 0 | DP17: =SUM(BZ17:CC17) -> 0 | DQ17: =SUM(CD17:CG17) -> 0 | DR17: =SUM(CH17:CL17) -> 0 | DS17: =SUM(CM17:CP17) -> 0 | DT17: =SUM(CQ17:CU17) -> 0 | DU17: =SUM(CV17:CY17) -> 0 | DV17: =SUM(CZ17:DC17) -> 0 | DW17: =SUM(DD17:DH17) -> 0
A18: =+A17+1 -> 12 | B18: =IF(F18=$F$7,G19,B17) -> F0013546310 | C18: =IF(F18=$F$7,G20,C17) -> 82115-0EA10 K | D18: =VLOOKUP(B18,'Timing Table'!B:G,6,0) -> #N/A | E18: =VLOOKUP(B18,'Timing Table'!B:D,3,0) -> #N/A | F18: YNA Part# | G18: F0013546310 | H18: YNA Part Description | I18: 82115-0EA10_K0 491D-2025 82115 | M18: Model Year | N18: 2023 | O18: Eng. Revision | Q18: K0 | DL18: =SUM(BK18:BL18) -> 0 | DM18: =SUM(BM18:BP18) -> 0 | DN18: =SUM(BQ18:BT18) -> 0 | DO18: =SUM(BU18:BY18) -> 0 | DP18: =SUM(BZ18:CC18) -> 0 | DQ18: =SUM(CD18:CG18) -> 0 | DR18: =SUM(CH18:CL18) -> 0 | DS18: =SUM(CM18:CP18) -> 0 | DT18: =SUM(CQ18:CU18) -> 0 | DU18: =SUM(CV18:CY18) -> 0 | DV18: =SUM(CZ18:DC18) -> 0 | DW18: =SUM(DD18:DH18) -> 0
A19: =+A18+1 -> 13 | B19: =IF(F19=$F$7,G20,B18) -> F0013546310 | C19: =IF(F19=$F$7,G21,C18) -> 82115-0EA10 K | D19: =VLOOKUP(B19,'Timing Table'!B:G,6,0) -> #N/A | E19: =VLOOKUP(B19,'Timing Table'!B:D,3,0) -> #N/A | F19: Customer Part# | G19: 82115-0EA10 K | H19: PIA Part# | Q19: SHIP | R19: FAB | Z19: RAW | DL19: =SUM(BK19:BL19) -> 0 | DM19: =SUM(BM19:BP19) -> 0 | DN19: =SUM(BQ19:BT19) -> 0 | DO19: =SUM(BU19:BY19) -> 0 | DP19: =SUM(BZ19:CC19) -> 0 | DQ19: =SUM(CD19:CG19) -> 0 | DR19: =SUM(CH19:CL19) -> 0 | DS19: =SUM(CM19:CP19) -> 0 | DT19: =SUM(CQ19:CU19) -> 0 | DU19: =SUM(CV19:CY19) -> 0 | DV19: =SUM(CZ19:DC19) -> 0 | DW19: =SUM(DD19:DH19) -> 0
A20: =+A19+1 -> 14 | B20: =IF(F20=$F$7,G21,B19) -> F0013546310 | C20: =IF(F20=$F$7,G22,C19) -> 82115-0EA10 K | D20: =VLOOKUP(B20,'Timing Table'!B:G,6,0) -> #N/A | E20: =VLOOKUP(B20,'Timing Table'!B:D,3,0) -> #N/A | F20: High Fab | G20: 5536 | H20: B | I20: ETD Date | J20: 46041 | K20: 46048 | L20: 46055 | M20: 46062 | N20: 46069 | O20: 46076 | P20: 46083 | Q20: 46090 | R20: 46097 | S20: 46104 | T20: 46111 | U20: 46118 | V20: 46125 | W20: 46132 | X20: 46139 | Y20: 46146 | Z20: 46153 | AA20: 46160 | AB20: 46167 | AC20: 46174 | AD20: 46181 | AE20: 46188 | AF20: 46195 | AG20: 46202 | AH20: 46209 | AI20: 46216 | AJ20: 46223 | AK20: 46230 | AL20: 46237 | AM20: 46244 | AN20: 46251 | AO20: 46258 | AP20: 46265 | AQ20: 46272 | AR20: 46279 | AS20: 46286 | AT20: 46293 | AU20: 46300 | AV20: 46307 | AW20: 46314 | AX20: 46321 | AY20: 46328 | AZ20: 46335 | BA20: 46342 | BB20: 46349 | BC20: 46356 | BD20: 46363 | BE20: 46370 | BF20: 46377 | BG20: 46384 | BH20: 46391 | BI20: 46398 | DL20: =SUM(BK20:BL20) -> 0 | DM20: =SUM(BM20:BP20) -> 0 | DN20: =SUM(BQ20:BT20) -> 0 | DO20: =SUM(BU20:BY20) -> 0 | DP20: =SUM(BZ20:CC20) -> 0 | DQ20: =SUM(CD20:CG20) -> 0 | DR20: =SUM(CH20:CL20) -> 0 | DS20: =SUM(CM20:CP20) -> 0 | DT20: =SUM(CQ20:CU20) -> 0 | DU20: =SUM(CV20:CY20) -> 0 | DV20: =SUM(CZ20:DC20) -> 0 | DW20: =SUM(DD20:DH20) -> 0
A21: =+A20+1 -> 15 | B21: =IF(F21=$F$7,G22,B20) -> F0013546310 | C21: =IF(F21=$F$7,G23,C20) -> 82115-0EA10 K | D21: =VLOOKUP(B21,'Timing Table'!B:G,6,0) -> #N/A | E21: =VLOOKUP(B21,'Timing Table'!B:D,3,0) -> #N/A | F21: High Raw | G21: 8080 | I21: ETA Date | DL21: =SUM(BK21:BL21) -> 0 | DM21: =SUM(BM21:BP21) -> 0 | DN21: =SUM(BQ21:BT21) -> 0 | DO21: =SUM(BU21:BY21) -> 0 | DP21: =SUM(BZ21:CC21) -> 0 | DQ21: =SUM(CD21:CG21) -> 0 | DR21: =SUM(CH21:CL21) -> 0 | DS21: =SUM(CM21:CP21) -> 0 | DT21: =SUM(CQ21:CU21) -> 0 | DU21: =SUM(CV21:CY21) -> 0 | DV21: =SUM(CZ21:DC21) -> 0 | DW21: =SUM(DD21:DH21) -> 0
A22: =+A21+1 -> 16 | B22: =IF(F22=$F$7,G23,B21) -> F0013546310 | C22: =IF(F22=$F$7,G24,C21) -> 82115-0EA10 K | D22: =VLOOKUP(B22,'Timing Table'!B:G,6,0) -> #N/A | E22: =VLOOKUP(B22,'Timing Table'!B:D,3,0) -> #N/A | F22: Car line | G22: GRAND HIGHLANDER HYBRID 200D | H22: 82115-0EA10 | I22: Net | J22: 456 | K22: 680 | L22: 320 | M22: 592 | N22: 1172 | O22: 640 | P22: 400 | Q22: 780 | R22: 0 | S22: 496 | T22: 228 | U22: 512 | V22: 284 | W22: 480 | X22: 304 | Y22: 304 | Z22: 432 | AA22: 564 | AB22: 564 | AC22: 568 | AD22: 476 | AE22: 480 | AF22: 392 | AG22: 544 | AH22: 324 | AI22: 556 | AJ22: 528 | AK22: 532 | AL22: 732 | AM22: 736 | AN22: 736 | AO22: 736 | AP22: 736 | AQ22: 736 | AR22: 736 | AS22: 736 | AT22: 736 | AU22: 736 | AV22: 736 | AW22: 736 | AX22: 736 | AY22: 736 | AZ22: 736 | BA22: 736 | BB22: 736 | BC22: 736 | BD22: 736 | BE22: 736 | BF22: 736 | BG22: 736 | BH22: 736 | BI22: 736 | BJ22: =+G19 -> 82115-0EA10 K | BK22: =+J22 -> 456 | BL22: =+K22 -> 680 | BM22: =+L22 -> 320 | BN22: =+M22 -> 592 | BO22: =+N22 -> 1172 | BP22: =+O22 -> 640 | BQ22: =+P22 -> 400 | BR22: =+Q22 -> 780 | ... DJ22: =+BI22 -> 736 | DL22: =SUM(BK22:BL22) -> 1136 | DM22: =SUM(BM22:BP22) -> 2724 | DN22: =SUM(BQ22:BT22) -> 1676 | DO22: =SUM(BU22:BY22) -> 1808 | DP22: =SUM(BZ22:CC22) -> 1864 | DQ22: =SUM(CD22:CG22) -> 1916 | DR22: =SUM(CH22:CL22) -> 2484 | DS22: =SUM(CM22:CP22) -> 2940 | DT22: =SUM(CQ22:CU22) -> 3680 | DU22: =SUM(CV22:CY22) -> 2944 | DV22: =SUM(CZ22:DC22) -> 2944 | DW22: =SUM(DD22:DH22) -> 3680
A23: =+A22+1 -> 17 | B23: =IF(F23=$F$7,G24,B22) -> F0013546310 | C23: =IF(F23=$F$7,G25,C22) -> 82115-0EA10 K | D23: =VLOOKUP(B23,'Timing Table'!B:G,6,0) -> #N/A | E23: =VLOOKUP(B23,'Timing Table'!B:D,3,0) -> #N/A | F23: Family | G23: 82115 | H23: 82115-0EA10 | I23: Cum | J23: 456 | K23: 1136 | L23: 1456 | M23: 2048 | N23: 3220 | O23: 3860 | P23: 4260 | Q23: 5040 | R23: 5040 | S23: 5536 | T23: 5764 | U23: 6276 | V23: 6560 | W23: 7040 | X23: 7344 | Y23: 7648 | Z23: 8080 | AA23: 8644 | AB23: 9208 | AC23: 9776 | AD23: 10252 | AE23: 10732 | AF23: 11124 | AG23: 11668 | AH23: 11992 | AI23: 12548 | AJ23: 13076 | AK23: 13608 | AL23: 14340 | AM23: 15076 | AN23: 15812 | AO23: 16548 | AP23: 17284 | AQ23: 18020 | AR23: 18756 | AS23: 19492 | AT23: 20228 | AU23: 20964 | AV23: 21700 | AW23: 22436 | AX23: 23172 | AY23: 23908 | AZ23: 24644 | BA23: 25380 | BB23: 26116 | BC23: 26852 | BD23: 27588 | BE23: 28324 | BF23: 29060 | BG23: 29796 | BH23: 30532 | BI23: 31268 | DL23: =SUM(BK23:BL23) -> 0 | DM23: =SUM(BM23:BP23) -> 0 | DN23: =SUM(BQ23:BT23) -> 0 | DO23: =SUM(BU23:BY23) -> 0 | DP23: =SUM(BZ23:CC23) -> 0 | DQ23: =SUM(CD23:CG23) -> 0 | DR23: =SUM(CH23:CL23) -> 0 | DS23: =SUM(CM23:CP23) -> 0 | DT23: =SUM(CQ23:CU23) -> 0 | DU23: =SUM(CV23:CY23) -> 0 | DV23: =SUM(CZ23:DC23) -> 0 | DW23: =SUM(DD23:DH23) -> 0
A24: =+A23+1 -> 18 | B24: =IF(F24=$F$7,G25,B23) -> F0013546310 | C24: =IF(F24=$F$7,G26,C23) -> 82115-0EA10 K | D24: =VLOOKUP(B24,'Timing Table'!B:G,6,0) -> #N/A | E24: =VLOOKUP(B24,'Timing Table'!B:D,3,0) -> #N/A | F24: Cum Received | G24: 0 | H24: Last Goods Receipt Invoice | Q24: 0.95 | DL24: =SUM(BK24:BL24) -> 0 | DM24: =SUM(BM24:BP24) -> 0 | DN24: =SUM(BQ24:BT24) -> 0 | DO24: =SUM(BU24:BY24) -> 0 | DP24: =SUM(BZ24:CC24) -> 0 | DQ24: =SUM(CD24:CG24) -> 0 | DR24: =SUM(CH24:CL24) -> 0 | DS24: =SUM(CM24:CP24) -> 0 | DT24: =SUM(CQ24:CU24) -> 0 | DU24: =SUM(CV24:CY24) -> 0 | DV24: =SUM(CZ24:DC24) -> 0 | DW24: =SUM(DD24:DH24) -> 0
A25: =+A24+1 -> 19 | B25: =IF(F25=$F$7,G26,B24) -> F0013546310 | C25: =IF(F25=$F$7,G27,C24) -> 82115-0EA10 K | D25: =VLOOKUP(B25,'Timing Table'!B:G,6,0) -> #N/A | E25: =VLOOKUP(B25,'Timing Table'!B:D,3,0) -> #N/A | F25: Comments | Q25: SNPs: 95 | DL25: =SUM(BK25:BL25) -> 0 | DM25: =SUM(BM25:BP25) -> 0 | DN25: =SUM(BQ25:BT25) -> 0 | DO25: =SUM(BU25:BY25) -> 0 | DP25: =SUM(BZ25:CC25) -> 0 | DQ25: =SUM(CD25:CG25) -> 0 | DR25: =SUM(CH25:CL25) -> 0 | DS25: =SUM(CM25:CP25) -> 0 | DT25: =SUM(CQ25:CU25) -> 0 | DU25: =SUM(CV25:CY25) -> 0 | DV25: =SUM(CZ25:DC25) -> 0 | DW25: =SUM(DD25:DH25) -> 0
A26: =+A25+1 -> 20 | B26: =IF(F26=$F$7,G27,B25) -> F0013546310 | C26: =IF(F26=$F$7,G28,C25) -> 82115-0EA10 K | D26: =VLOOKUP(B26,'Timing Table'!B:G,6,0) -> #N/A | E26: =VLOOKUP(B26,'Timing Table'!B:D,3,0) -> #N/A | DL26: =SUM(BK26:BL26) -> 0 | DM26: =SUM(BM26:BP26) -> 0 | DN26: =SUM(BQ26:BT26) -> 0 | DO26: =SUM(BU26:BY26) -> 0 | DP26: =SUM(BZ26:CC26) -> 0 | DQ26: =SUM(CD26:CG26) -> 0 | DR26: =SUM(CH26:CL26) -> 0 | DS26: =SUM(CM26:CP26) -> 0 | DT26: =SUM(CQ26:CU26) -> 0 | DU26: =SUM(CV26:CY26) -> 0 | DV26: =SUM(CZ26:DC26) -> 0 | DW26: =SUM(DD26:DH26) -> 0
A27: =+A26+1 -> 21 | B27: =IF(F27=$F$7,G28,B26) -> F0013546510 | C27: =IF(F27=$F$7,G29,C26) -> 82115-0E480 K | D27: =VLOOKUP(B27,'Timing Table'!B:G,6,0) -> #N/A | E27: =VLOOKUP(B27,'Timing Table'!B:D,3,0) -> #N/A | F27: PSA# | G27: 5501044286 | H27: Release# | I27: 51 | J27: BEAMS ID | K27: 1179884 | M27: Release Date | O27: 46086 | P27: Std. Pack | Q27: 4 | DL27: =SUM(BK27:BL27) -> 0 | DM27: =SUM(BM27:BP27) -> 0 | DN27: =SUM(BQ27:BT27) -> 0 | DO27: =SUM(BU27:BY27) -> 0 | DP27: =SUM(BZ27:CC27) -> 0 | DQ27: =SUM(CD27:CG27) -> 0 | DR27: =SUM(CH27:CL27) -> 0 | DS27: =SUM(CM27:CP27) -> 0 | DT27: =SUM(CQ27:CU27) -> 0 | DU27: =SUM(CV27:CY27) -> 0 | DV27: =SUM(CZ27:DC27) -> 0 | DW27: =SUM(DD27:DH27) -> 0
A28: =+A27+1 -> 22 | B28: =IF(F28=$F$7,G29,B27) -> F0013546510 | C28: =IF(F28=$F$7,G30,C27) -> 82115-0E480 K | D28: =VLOOKUP(B28,'Timing Table'!B:G,6,0) -> #N/A | E28: =VLOOKUP(B28,'Timing Table'!B:D,3,0) -> #N/A | F28: YNA Part# | G28: F0013546510 | H28: YNA Part Description | I28: 82115-0E480_K0 491D-2025 82115 | M28: Model Year | N28: 2023 | O28: Eng. Revision | Q28: K0 | DL28: =SUM(BK28:BL28) -> 0 | DM28: =SUM(BM28:BP28) -> 0 | DN28: =SUM(BQ28:BT28) -> 0 | DO28: =SUM(BU28:BY28) -> 0 | DP28: =SUM(BZ28:CC28) -> 0 | DQ28: =SUM(CD28:CG28) -> 0 | DR28: =SUM(CH28:CL28) -> 0 | DS28: =SUM(CM28:CP28) -> 0 | DT28: =SUM(CQ28:CU28) -> 0 | DU28: =SUM(CV28:CY28) -> 0 | DV28: =SUM(CZ28:DC28) -> 0 | DW28: =SUM(DD28:DH28) -> 0
A29: =+A28+1 -> 23 | B29: =IF(F29=$F$7,G30,B28) -> F0013546510 | C29: =IF(F29=$F$7,G31,C28) -> 82115-0E480 K | D29: =VLOOKUP(B29,'Timing Table'!B:G,6,0) -> #N/A | E29: =VLOOKUP(B29,'Timing Table'!B:D,3,0) -> #N/A | F29: Customer Part# | G29: 82115-0E480 K | H29: PIA Part# | Q29: SHIP | R29: FAB | Z29: RAW | DL29: =SUM(BK29:BL29) -> 0 | DM29: =SUM(BM29:BP29) -> 0 | DN29: =SUM(BQ29:BT29) -> 0 | DO29: =SUM(BU29:BY29) -> 0 | DP29: =SUM(BZ29:CC29) -> 0 | DQ29: =SUM(CD29:CG29) -> 0 | DR29: =SUM(CH29:CL29) -> 0 | DS29: =SUM(CM29:CP29) -> 0 | DT29: =SUM(CQ29:CU29) -> 0 | DU29: =SUM(CV29:CY29) -> 0 | DV29: =SUM(CZ29:DC29) -> 0 | DW29: =SUM(DD29:DH29) -> 0
A30: =+A29+1 -> 24 | B30: =IF(F30=$F$7,G31,B29) -> F0013546510 | C30: =IF(F30=$F$7,G32,C29) -> 82115-0E480 K | D30: =VLOOKUP(B30,'Timing Table'!B:G,6,0) -> #N/A | E30: =VLOOKUP(B30,'Timing Table'!B:D,3,0) -> #N/A | F30: High Fab | G30: 7576 | I30: ETD Date | J30: 46041 | K30: 46048 | L30: 46055 | M30: 46062 | N30: 46069 | O30: 46076 | P30: 46083 | Q30: 46090 | R30: 46097 | S30: 46104 | T30: 46111 | U30: 46118 | V30: 46125 | W30: 46132 | X30: 46139 | Y30: 46146 | Z30: 46153 | AA30: 46160 | AB30: 46167 | AC30: 46174 | AD30: 46181 | AE30: 46188 | AF30: 46195 | AG30: 46202 | AH30: 46209 | AI30: 46216 | AJ30: 46223 | AK30: 46230 | AL30: 46237 | AM30: 46244 | AN30: 46251 | AO30: 46258 | AP30: 46265 | AQ30: 46272 | AR30: 46279 | AS30: 46286 | AT30: 46293 | AU30: 46300 | AV30: 46307 | AW30: 46314 | AX30: 46321 | AY30: 46328 | AZ30: 46335 | BA30: 46342 | BB30: 46349 | BC30: 46356 | BD30: 46363 | BE30: 46370 | BF30: 46377 | BG30: 46384 | BH30: 46391 | BI30: 46398 | DL30: =SUM(BK30:BL30) -> 0 | DM30: =SUM(BM30:BP30) -> 0 | DN30: =SUM(BQ30:BT30) -> 0 | DO30: =SUM(BU30:BY30) -> 0 | DP30: =SUM(BZ30:CC30) -> 0 | DQ30: =SUM(CD30:CG30) -> 0 | DR30: =SUM(CH30:CL30) -> 0 | DS30: =SUM(CM30:CP30) -> 0 | DT30: =SUM(CQ30:CU30) -> 0 | DU30: =SUM(CV30:CY30) -> 0 | DV30: =SUM(CZ30:DC30) -> 0 | DW30: =SUM(DD30:DH30) -> 0
A31: =+A30+1 -> 25 | B31: =IF(F31=$F$7,G32,B30) -> F0013546510 | C31: =IF(F31=$F$7,G33,C30) -> 82115-0E480 K | D31: =VLOOKUP(B31,'Timing Table'!B:G,6,0) -> #N/A | E31: =VLOOKUP(B31,'Timing Table'!B:D,3,0) -> #N/A | F31: High Raw | G31: 9836 | I31: ETA Date | DL31: =SUM(BK31:BL31) -> 0 | DM31: =SUM(BM31:BP31) -> 0 | DN31: =SUM(BQ31:BT31) -> 0 | DO31: =SUM(BU31:BY31) -> 0 | DP31: =SUM(BZ31:CC31) -> 0 | DQ31: =SUM(CD31:CG31) -> 0 | DR31: =SUM(CH31:CL31) -> 0 | DS31: =SUM(CM31:CP31) -> 0 | DT31: =SUM(CQ31:CU31) -> 0 | DU31: =SUM(CV31:CY31) -> 0 | DV31: =SUM(CZ31:DC31) -> 0 | DW31: =SUM(DD31:DH31) -> 0
A32: =+A31+1 -> 26 | B32: =IF(F32=$F$7,G33,B31) -> F0013546510 | C32: =IF(F32=$F$7,G34,C31) -> 82115-0E480 K | D32: =VLOOKUP(B32,'Timing Table'!B:G,6,0) -> #N/A | E32: =VLOOKUP(B32,'Timing Table'!B:D,3,0) -> #N/A | F32: Car line | G32: GRAND HIGHLANDER HYBRID 491D | H32: 82115-0E480 | I32: Net | J32: 788 | K32: 348 | L32: 348 | M32: 348 | N32: 348 | O32: 348 | P32: 520 | Q32: 524 | R32: 0 | S32: 596 | T32: 248 | U32: 248 | V32: 248 | W32: 248 | X32: 248 | Y32: 248 | Z32: 248 | AA32: 248 | AB32: 248 | AC32: 248 | AD32: 248 | AE32: 248 | AF32: 248 | AG32: 248 | AH32: 248 | AI32: 248 | AJ32: 248 | AK32: 248 | AL32: 248 | AM32: 248 | AN32: 248 | AO32: 248 | AP32: 248 | AQ32: 248 | AR32: 248 | AS32: 248 | AT32: 248 | AU32: 248 | AV32: 248 | AW32: 248 | AX32: 248 | AY32: 248 | AZ32: 248 | BA32: 248 | BB32: 248 | BC32: 248 | BD32: 248 | BE32: 248 | BF32: 248 | BG32: 248 | BH32: 248 | BI32: 248 | BJ32: =+G29 -> 82115-0E480 K | BK32: =+J32 -> 788 | BL32: =+K32 -> 348 | BM32: =+L32 -> 348 | BN32: =+M32 -> 348 | BO32: =+N32 -> 348 | BP32: =+O32 -> 348 | BQ32: =+P32 -> 520 | BR32: =+Q32 -> 524 | ... DJ32: =+BI32 -> 248 | DL32: =SUM(BK32:BL32) -> 1136 | DM32: =SUM(BM32:BP32) -> 1392 | DN32: =SUM(BQ32:BT32) -> 1640 | DO32: =SUM(BU32:BY32) -> 1240 | DP32: =SUM(BZ32:CC32) -> 992 | DQ32: =SUM(CD32:CG32) -> 992 | DR32: =SUM(CH32:CL32) -> 1240 | DS32: =SUM(CM32:CP32) -> 992 | DT32: =SUM(CQ32:CU32) -> 1240 | DU32: =SUM(CV32:CY32) -> 992 | DV32: =SUM(CZ32:DC32) -> 992 | DW32: =SUM(DD32:DH32) -> 1240
A33: =+A32+1 -> 27 | B33: =IF(F33=$F$7,G34,B32) -> F0013546510 | C33: =IF(F33=$F$7,G35,C32) -> 82115-0E480 K | D33: =VLOOKUP(B33,'Timing Table'!B:G,6,0) -> #N/A | E33: =VLOOKUP(B33,'Timing Table'!B:D,3,0) -> #N/A | F33: Family | G33: 82115 | H33: 82115-0E480 | I33: Cum | J33: 4444 | K33: 4792 | L33: 5140 | M33: 5488 | N33: 5836 | O33: 6184 | P33: 6704 | Q33: 7228 | R33: 7228 | S33: 7824 | T33: 8072 | U33: 8320 | V33: 8568 | W33: 8816 | X33: 9064 | Y33: 9312 | Z33: 9560 | AA33: 9808 | AB33: 10056 | AC33: 10304 | AD33: 10552 | AE33: 10800 | AF33: 11048 | AG33: 11296 | AH33: 11544 | AI33: 11792 | AJ33: 12040 | AK33: 12288 | AL33: 12536 | AM33: 12784 | AN33: 13032 | AO33: 13280 | AP33: 13528 | AQ33: 13776 | AR33: 14024 | AS33: 14272 | AT33: 14520 | AU33: 14768 | AV33: 15016 | AW33: 15264 | AX33: 15512 | AY33: 15760 | AZ33: 16008 | BA33: 16256 | BB33: 16504 | BC33: 16752 | BD33: 17000 | BE33: 17248 | BF33: 17496 | BG33: 17744 | BH33: 17992 | BI33: 18240 | DL33: =SUM(BK33:BL33) -> 0 | DM33: =SUM(BM33:BP33) -> 0 | DN33: =SUM(BQ33:BT33) -> 0 | DO33: =SUM(BU33:BY33) -> 0 | DP33: =SUM(BZ33:CC33) -> 0 | DQ33: =SUM(CD33:CG33) -> 0 | DR33: =SUM(CH33:CL33) -> 0 | DS33: =SUM(CM33:CP33) -> 0 | DT33: =SUM(CQ33:CU33) -> 0 | DU33: =SUM(CV33:CY33) -> 0 | DV33: =SUM(CZ33:DC33) -> 0 | DW33: =SUM(DD33:DH33) -> 0
A34: =+A33+1 -> 28 | B34: =IF(F34=$F$7,G35,B33) -> F0013546510 | C34: =IF(F34=$F$7,G36,C33) -> 82115-0E480 K | D34: =VLOOKUP(B34,'Timing Table'!B:G,6,0) -> #N/A | E34: =VLOOKUP(B34,'Timing Table'!B:D,3,0) -> #N/A | F34: Cum Received | G34: 3656 | H34: Last Goods Receipt Invoice | J34: JAOJ50240B | Q34: 0.0076923077 | DL34: =SUM(BK34:BL34) -> 0 | DM34: =SUM(BM34:BP34) -> 0 | DN34: =SUM(BQ34:BT34) -> 0 | DO34: =SUM(BU34:BY34) -> 0 | DP34: =SUM(BZ34:CC34) -> 0 | DQ34: =SUM(CD34:CG34) -> 0 | DR34: =SUM(CH34:CL34) -> 0 | DS34: =SUM(CM34:CP34) -> 0 | DT34: =SUM(CQ34:CU34) -> 0 | DU34: =SUM(CV34:CY34) -> 0 | DV34: =SUM(CZ34:DC34) -> 0 | DW34: =SUM(DD34:DH34) -> 0
A35: =+A34+1 -> 29 | B35: =IF(F35=$F$7,G36,B34) -> F0013546510 | C35: =IF(F35=$F$7,#REF!,C34) -> 82115-0E480 K | D35: =VLOOKUP(B35,'Timing Table'!B:G,6,0) -> #N/A | E35: =VLOOKUP(B35,'Timing Table'!B:D,3,0) -> #N/A | F35: Comments | Q35: SNPs: 1 | DL35: =SUM(BK35:BL35) -> 0 | DM35: =SUM(BM35:BP35) -> 0 | DN35: =SUM(BQ35:BT35) -> 0 | DO35: =SUM(BU35:BY35) -> 0 | DP35: =SUM(BZ35:CC35) -> 0 | DQ35: =SUM(CD35:CG35) -> 0 | DR35: =SUM(CH35:CL35) -> 0 | DS35: =SUM(CM35:CP35) -> 0 | DT35: =SUM(CQ35:CU35) -> 0 | DU35: =SUM(CV35:CY35) -> 0 | DV35: =SUM(CZ35:DC35) -> 0 | DW35: =SUM(DD35:DH35) -> 0
A36: =+A35+1 -> 30 | B36: =IF(F36=$F$7,#REF!,B35) -> F0013546510 | C36: =IF(F36=$F$7,#REF!,C35) -> 82115-0E480 K | D36: =VLOOKUP(B36,'Timing Table'!B:G,6,0) -> #N/A | E36: =VLOOKUP(B36,'Timing Table'!B:D,3,0) -> #N/A | DL36: =SUM(BK36:BL36) -> 0 | DM36: =SUM(BM36:BP36) -> 0 | DN36: =SUM(BQ36:BT36) -> 0 | DO36: =SUM(BU36:BY36) -> 0 | DP36: =SUM(BZ36:CC36) -> 0 | DQ36: =SUM(CD36:CG36) -> 0 | DR36: =SUM(CH36:CL36) -> 0 | DS36: =SUM(CM36:CP36) -> 0 | DT36: =SUM(CQ36:CU36) -> 0 | DU36: =SUM(CV36:CY36) -> 0 | DV36: =SUM(CZ36:DC36) -> 0 | DW36: =SUM(DD36:DH36) -> 0
A37: =+A36+1 -> 31 | B37: =IF(F37=$F$7,G38,#REF!) -> F0013547309 | C37: =IF(F37=$F$7,G39,#REF!) -> 82115-0E490 J | D37: =VLOOKUP(B37,'Timing Table'!B:G,6,0) -> #N/A | E37: =VLOOKUP(B37,'Timing Table'!B:D,3,0) -> #N/A | F37: PSA# | G37: 5501017963 | H37: Release# | I37: 91 | J37: BEAMS ID | K37: 1177749 | M37: Release Date | O37: 46086 | P37: Std. Pack | Q37: 4 | DL37: =SUM(BK37:BL37) -> 0 | DM37: =SUM(BM37:BP37) -> 0 | DN37: =SUM(BQ37:BT37) -> 0 | DO37: =SUM(BU37:BY37) -> 0 | DP37: =SUM(BZ37:CC37) -> 0 | DQ37: =SUM(CD37:CG37) -> 0 | DR37: =SUM(CH37:CL37) -> 0 | DS37: =SUM(CM37:CP37) -> 0 | DT37: =SUM(CQ37:CU37) -> 0 | DU37: =SUM(CV37:CY37) -> 0 | DV37: =SUM(CZ37:DC37) -> 0 | DW37: =SUM(DD37:DH37) -> 0
A38: =+A37+1 -> 32 | B38: =IF(F38=$F$7,G39,B37) -> F0013547309 | C38: =IF(F38=$F$7,G40,C37) -> 82115-0E490 J | D38: =VLOOKUP(B38,'Timing Table'!B:G,6,0) -> #N/A | E38: =VLOOKUP(B38,'Timing Table'!B:D,3,0) -> #N/A | F38: YNA Part# | G38: F0013547309 | H38: YNA Part Description | I38: 82115-0E490_J1 491D HV-2025 82115 | M38: Model Year | N38: 2023 | O38: Eng. Revision | Q38: J1 | DL38: =SUM(BK38:BL38) -> 0 | DM38: =SUM(BM38:BP38) -> 0 | DN38: =SUM(BQ38:BT38) -> 0 | DO38: =SUM(BU38:BY38) -> 0 | DP38: =SUM(BZ38:CC38) -> 0 | DQ38: =SUM(CD38:CG38) -> 0 | DR38: =SUM(CH38:CL38) -> 0 | DS38: =SUM(CM38:CP38) -> 0 | DT38: =SUM(CQ38:CU38) -> 0 | DU38: =SUM(CV38:CY38) -> 0 | DV38: =SUM(CZ38:DC38) -> 0 | DW38: =SUM(DD38:DH38) -> 0
A39: =+A38+1 -> 33 | B39: =IF(F39=$F$7,G40,B38) -> F0013547309 | C39: =IF(F39=$F$7,G41,C38) -> 82115-0E490 J | D39: =VLOOKUP(B39,'Timing Table'!B:G,6,0) -> #N/A | E39: =VLOOKUP(B39,'Timing Table'!B:D,3,0) -> #N/A | F39: Customer Part# | G39: 82115-0E490 J | H39: PIA Part# | Q39: SHIP | R39: FAB | Z39: RAW | DL39: =SUM(BK39:BL39) -> 0 | DM39: =SUM(BM39:BP39) -> 0 | DN39: =SUM(BQ39:BT39) -> 0 | DO39: =SUM(BU39:BY39) -> 0 | DP39: =SUM(BZ39:CC39) -> 0 | DQ39: =SUM(CD39:CG39) -> 0 | DR39: =SUM(CH39:CL39) -> 0 | DS39: =SUM(CM39:CP39) -> 0 | DT39: =SUM(CQ39:CU39) -> 0 | DU39: =SUM(CV39:CY39) -> 0 | DV39: =SUM(CZ39:DC39) -> 0 | DW39: =SUM(DD39:DH39) -> 0
A40: =+A39+1 -> 34 | B40: =IF(F40=$F$7,G41,B39) -> F0013547309 | C40: =IF(F40=$F$7,G42,C39) -> 82115-0E490 J | D40: =VLOOKUP(B40,'Timing Table'!B:G,6,0) -> #N/A | E40: =VLOOKUP(B40,'Timing Table'!B:D,3,0) -> #N/A | F40: High Fab | G40: 4940 | H40: C | I40: ETD Date | J40: 46041 | K40: 46048 | L40: 46055 | M40: 46062 | N40: 46069 | O40: 46076 | P40: 46083 | Q40: 46090 | R40: 46097 | S40: 46104 | T40: 46111 | U40: 46118 | V40: 46125 | W40: 46132 | X40: 46139 | Y40: 46146 | Z40: 46153 | AA40: 46160 | AB40: 46167 | AC40: 46174 | AD40: 46181 | AE40: 46188 | AF40: 46195 | AG40: 46202 | AH40: 46209 | AI40: 46216 | AJ40: 46223 | AK40: 46230 | AL40: 46237 | AM40: 46244 | AN40: 46251 | AO40: 46258 | AP40: 46265 | AQ40: 46272 | AR40: 46279 | AS40: 46286 | AT40: 46293 | AU40: 46300 | AV40: 46307 | AW40: 46314 | AX40: 46321 | AY40: 46328 | AZ40: 46335 | BA40: 46342 | BB40: 46349 | BC40: 46356 | BD40: 46363 | BE40: 46370 | BF40: 46377 | BG40: 46384 | BH40: 46391 | BI40: 46398 | DL40: =SUM(BK40:BL40) -> 0 | DM40: =SUM(BM40:BP40) -> 0 | DN40: =SUM(BQ40:BT40) -> 0 | DO40: =SUM(BU40:BY40) -> 0 | DP40: =SUM(BZ40:CC40) -> 0 | DQ40: =SUM(CD40:CG40) -> 0 | DR40: =SUM(CH40:CL40) -> 0 | DS40: =SUM(CM40:CP40) -> 0 | DT40: =SUM(CQ40:CU40) -> 0 | DU40: =SUM(CV40:CY40) -> 0 | DV40: =SUM(CZ40:DC40) -> 0 | DW40: =SUM(DD40:DH40) -> 0
A41: =+A40+1 -> 35 | B41: =IF(F41=$F$7,G42,B40) -> F0013547309 | C41: =IF(F41=$F$7,G43,C40) -> 82115-0E490 J | D41: =VLOOKUP(B41,'Timing Table'!B:G,6,0) -> #N/A | E41: =VLOOKUP(B41,'Timing Table'!B:D,3,0) -> #N/A | F41: High Raw | G41: 5128 | I41: ETA Date | DL41: =SUM(BK41:BL41) -> 0 | DM41: =SUM(BM41:BP41) -> 0 | DN41: =SUM(BQ41:BT41) -> 0 | DO41: =SUM(BU41:BY41) -> 0 | DP41: =SUM(BZ41:CC41) -> 0 | DQ41: =SUM(CD41:CG41) -> 0 | DR41: =SUM(CH41:CL41) -> 0 | DS41: =SUM(CM41:CP41) -> 0 | DT41: =SUM(CQ41:CU41) -> 0 | DU41: =SUM(CV41:CY41) -> 0 | DV41: =SUM(CZ41:DC41) -> 0 | DW41: =SUM(DD41:DH41) -> 0
...

Sheet Sheet1
B2: F0013546307 | C2: 82115-0EA10_H0 200D Hybrid-2023 82115
B3: F0013547307 | C3: 82115-0E490_H0 200D Hybrid-2023 82115
B4: F0013547807 | C4: 82115-0EA00_H0 200D-2023 82115
B5: F0013547907 | C5: 82115-0E440_H0 200D-2023 82115
B6: F0013548007 | C6: 82115-0E460_H0 200D-2023 82115
B7: F0013548107 | C7: 82115-0E450_H0 200D-2023 82115
B8: F0014825701 | C8: 82115-0E310_A0 564D-2025 82115
B9: F0014825801 | C9: 82115-0EZ80_A0 564D-2025 82115
B10: F0014825901 | C10: 82115-0EZ30_A0 564D-2025 82115
B11: F0014826001 | C11: 82115-0EZ60_A0 564D-2025 82115
B12: F0014826101 | C12: 82115-0EZ40_A0 564D-2025 82115
B13: F0014826201 | C13: 82115-0EZ90_A0 564D-2025 82115
... B24: F0014827301 | C24: 82115-0E511_A0 564D-2025 82115

Sheet JAI TOTALs
C2: ETD Date | E2: ='Final SR'!$J$10 -> 46041 | F2: =E2+7 -> 46048 | G2: =F2+7 -> 46055 | H2: =G2+7 -> 46062 | I2: =H2+7 -> 46069 | J2: =I2+7 -> 46076 | K2: =J2+7 -> 46083 | L2: =K2+7 -> 46090 | M2: =L2+7 -> 46097 | ... AH2: =AG2+7 -> 46244
L4: SHIP | M4: FAB | U4: RAW
A5: Family Totals | B5: 220D- GAS | C5: Net Family Totals | E5: =SUMIFS('Final SR'!J:J,'Final SR'!$E:$E,TOTALss!$B6,'Final SR'!$I:$I,'Final SR'!$I$12) -> 0 | F5: =SUMIFS('Final SR'!K:K,'Final SR'!$E:$E,TOTALss!$B6,'Final SR'!$I:$I,'Final SR'!$I$12) -> 0 | G5: =SUMIFS('Final SR'!L:L,'Final SR'!$E:$E,TOTALss!$B6,'Final SR'!$I:$I,'Final SR'!$I$12) -> 0 | H5: =SUMIFS('Final SR'!M:M,'Final SR'!$E:$E,TOTALss!$B6,'Final SR'!$I:$I,'Final SR'!$I$12) -> 0 | I5: =SUMIFS('Final SR'!N:N,'Final SR'!$E:$E,TOTALss!$B6,'Final SR'!$I:$I,'Final SR'!$I$12) -> 0 | J5: =SUMIFS('Final SR'!O:O,'Final SR'!$E:$E,TOTALss!$B6,'Final SR'!$I:$I,'Final SR'!$I$12) -> 0 | K5: =SUMIFS('Final SR'!P:P,'Final SR'!$E:$E,TOTALss!$B6,'Final SR'!$I:$I,'Final SR'!$I$12) -> 0 | L5: =SUMIFS('Final SR'!Q:Q,'Final SR'!$E:$E,TOTALss!$B6,'Final SR'!$I:$I,'Final SR'!$I$12) -> 0 | M5: =SUMIFS('Final SR'!R:R,'Final SR'!$E:$E,TOTALss!$B6,'Final SR'!$I:$I,'Final SR'!$I$12) -> 0 | N5: =SUMIFS('Final SR'!S:S,'Final SR'!$E:$E,TOTALss!$B6,'Final SR'!$I:$I,'Final SR'!$I$12) -> 0 | O5: =SUMIFS('Final SR'!T:T,'Final SR'!$E:$E,TOTALss!$B6,'Final SR'!$I:$I,'Final SR'!$I$12) -> 0 | P5: =SUMIFS('Final SR'!U:U,'Final SR'!$E:$E,TOTALss!$B6,'Final SR'!$I:$I,'Final SR'!$I$12) -> 0 | Q5: =SUMIFS('Final SR'!V:V,'Final SR'!$E:$E,TOTALss!$B6,'Final SR'!$I:$I,'Final SR'!$I$12) -> 0 | R5: =SUMIFS('Final SR'!W:W,'Final SR'!$E:$E,TOTALss!$B6,'Final SR'!$I:$I,'Final SR'!$I$12) -> 0 | S5: =SUMIFS('Final SR'!X:X,'Final SR'!$E:$E,TOTALss!$B6,'Final SR'!$I:$I,'Final SR'!$I$12) -> 0 | T5: =SUMIFS('Final SR'!Y:Y,'Final SR'!$E:$E,TOTALss!$B6,'Final SR'!$I:$I,'Final SR'!$I$12) -> 0 | U5: =SUMIFS('Final SR'!Z:Z,'Final SR'!$E:$E,TOTALss!$B6,'Final SR'!$I:$I,'Final SR'!$I$12) -> 0 | V5: =SUMIFS('Final SR'!AA:AA,'Final SR'!$E:$E,TOTALss!$B6,'Final SR'!$I:$I,'Final SR'!$I$12) -> 0 | W5: =SUMIFS('Final SR'!AB:AB,'Final SR'!$E:$E,TOTALss!$B6,'Final SR'!$I:$I,'Final SR'!$I$12) -> 0 | X5: =SUMIFS('Final SR'!AC:AC,'Final SR'!$E:$E,TOTALss!$B6,'Final SR'!$I:$I,'Final SR'!$I$12) -> 0 | Y5: =SUMIFS('Final SR'!AD:AD,'Final SR'!$E:$E,TOTALss!$B6,'Final SR'!$I:$I,'Final SR'!$I$12) -> 0 | Z5: =SUMIFS('Final SR'!AE:AE,'Final SR'!$E:$E,TOTALss!$B6,'Final SR'!$I:$I,'Final SR'!$I$12) -> 0 | AA5: =SUMIFS('Final SR'!AF:AF,'Final SR'!$E:$E,TOTALss!$B6,'Final SR'!$I:$I,'Final SR'!$I$12) -> 0 | AB5: =SUMIFS('Final SR'!AG:AG,'Final SR'!$E:$E,TOTALss!$B6,'Final SR'!$I:$I,'Final SR'!$I$12) -> 0 | AC5: =SUMIFS('Final SR'!AH:AH,'Final SR'!$E:$E,TOTALss!$B6,'Final SR'!$I:$I,'Final SR'!$I$12) -> 0 | AD5: =SUMIFS('Final SR'!AI:AI,'Final SR'!$E:$E,TOTALss!$B6,'Final SR'!$I:$I,'Final SR'!$I$12) -> 0 | AE5: =SUMIFS('Final SR'!AJ:AJ,'Final SR'!$E:$E,TOTALss!$B6,'Final SR'!$I:$I,'Final SR'!$I$12) -> 0 | AF5: =SUMIFS('Final SR'!AK:AK,'Final SR'!$E:$E,TOTALss!$B6,'Final SR'!$I:$I,'Final SR'!$I$12) -> 0 | AG5: =SUMIFS('Final SR'!AL:AL,'Final SR'!$E:$E,TOTALss!$B6,'Final SR'!$I:$I,'Final SR'!$I$12) -> 0 | AH5: =SUMIFS('Final SR'!AM:AM,'Final SR'!$E:$E,TOTALss!$B6,'Final SR'!$I:$I,'Final SR'!$I$12) -> 0
C6: Cum Family Totals | E6: =+E5+D6 -> 0 | F6: =+F5+E6 -> 0 | G6: =+G5+F6 -> 0 | H6: =+H5+G6 -> 0 | I6: =+I5+H6 -> 0 | J6: =+J5+I6 -> 0 | K6: =+K5+J6 -> 0 | L6: =+L5+K6 -> 0 | ... AH6: =+AH5+AG6 -> 0
L7: SHIP | M7: FAB | U7: RAW
K8: SHIP | L8: FAB
G9: =B5 -> 220D- GAS | H9: THIS WEEK | I9: NET | J9: =K5 -> 0 | K9: =L5 -> 0 | L9: =M5 -> 0 | M9: =K9=K11 -> FALSE | N9: =K10-K12 -> 0
I10: CUM | J10: =K6 -> 0 | K10: 10186 | L10: =M6 -> 0 | M10: =K10=K12 -> TRUE
H11: LAST SR | I11: NET | K11: 752
I12: CUM | K12: 10186
L14: SHIP | M14: FAB | U14: RAW
