Workbook

Sheet GUM
K1: SIX MONTH PRODUCTION PLAN ( QTY )
K2: TOYOTA 491D.564D | AA2: PREPARED
B3: S/R NO : JAI SR 3-2-2026 | K3: Periode : MAR PRODUCTION 2026
B4: FAX NO : EMAIL
Y7: NSO
C9: 1 | D9: =+C9+1 -> 2 | E9: =+D9+1 -> 3 | F9: =+E9+1 -> 4 | G9: =+F9+1 -> 5 | H9: =+G9+1 -> 6 | I9: =+H9+1 -> 7 | J9: =+I9+1 -> 8 | K9: =+J9+1 -> 9 | ... AD9: =+AC9+1 -> 28
B10: Print Date : | C10: =NOW() -> 46195.105
A11: TYPE | C11: HARNESS No. | D11: LEVEL | E11: ASSY CODE | F11: CCT | G11: Std Pack | H11: JAN - JUN | I11: FEB | L11: MAR | O11: APR | R11: MAY | U11: JUN | X11: JUL | AA11: AUG | AD11: BAL
H12: UMH | I12: =VLOOKUP(I11,WEEK!A2:D13,2,0) -> 02/FEB ~ 27/FEB | L12: =VLOOKUP(L11,WEEK!A2:D13,2,0) -> 02/MAR ~ 31/MAR | O12: =VLOOKUP(O11,WEEK!A2:D13,2,0) -> 01/APR ~ 30/APR | R12: =VLOOKUP(R11,WEEK!A2:D13,2,0) -> 02/MAY ~ 30/MAY | U12: =VLOOKUP(U11,WEEK!A2:D13,2,0) -> 02/JUN ~ 30/JUN | X12: =VLOOKUP(X11,WEEK!$A$2:$D13,2,0) -> 01/JUL ~ 31/JUL | AA12: =VLOOKUP(AA11,WEEK!$A$2:$D13,2,0) -> 03/AUG ~ 31/AUG
I13: BAL | J13: DEL | K13: PROD | L13: BAL | M13: DEL | N13: PROD | O13: BAL | P13: DEL | Q13: PROD | R13: BAL | S13: DEL | T13: PROD | U13: BAL | V13: DEL | W13: PROD | X13: BAL | Y13: DEL | Z13: PROD | AA13: BAL | AB13: DEL | AC13: PROD
A14: LHD HEV | B14: 200D | C14: 82115-0E470 | D14: H 0001 | E14: DS72 | G14: 4 | H14: 0 | I14: 0 | J14: 0 | K14: 0 | L14: =I14+K14-J14 -> 0 | N14: =M14-L14 -> 0 | O14: =L14+N14-M14 -> 0 | Q14: =P14-O14 -> 0 | R14: =O14+Q14-P14 -> 0 | T14: =S14-R14 -> 0 | U14: =R14+T14-S14 -> 0 | W14: =V14-U14 -> 0 | X14: =U14+W14-V14 -> 0 | Z14: =Y14-X14+100-100+64-64 -> 0 | AA14: =X14+Z14-Y14 -> 0 | AB14: =+Y14 | AC14: =AB14-AA14 -> 0 | AD14: =AA14+AC14-AB14 -> 0
C15: 82115-0E480 G | D15: G 0101 | E15: DS04 | G15: 4 | H15: 4.7863717 | I15: 0 | J15: 0 | K15: 0 | L15: =I15+K15-J15 -> 0 | N15: =M15-L15 -> 0 | O15: =L15+N15-M15 -> 0 | Q15: =P15-O15 -> 0 | R15: =O15+Q15-P15 -> 0 | T15: =S15-R15 -> 0 | U15: =R15+T15-S15 -> 0 | W15: =V15-U15 -> 0 | X15: =U15+W15-V15 -> 0 | Z15: =Y15-X15 -> 0 | AA15: =X15+Z15-Y15 -> 0 | AB15: =+Y15 | AC15: =AB15-AA15 -> 0 | AD15: =AA15+AC15-AB15 -> 0
C16: 82115-0E490 H | D16: H 0001 | E16: DS74 | G16: 4 | H16: =VLOOKUP($C16,#REF!,18,0) -> #REF! | I16: 0 | J16: 0 | K16: 0 | L16: =I16+K16-J16 -> 0 | M16: 0 | N16: =M16-L16 -> 0 | O16: =L16+N16-M16 -> 0 | P16: 0 | Q16: =P16-O16 -> 0 | R16: =O16+Q16-P16 -> 0 | S16: 0 | T16: =S16-R16 -> 0 | U16: =R16+T16-S16 -> 0 | V16: 0 | W16: =V16-U16 -> 0 | X16: =U16+W16-V16 -> 0 | Y16: 0 | Z16: =Y16-X16 -> 0 | AA16: =X16+Z16-Y16 -> 0 | AB16: 0 | AC16: =AB16-AA16 -> 0 | AD16: =AA16+AC16-AB16 -> 0
C17: 82115-0EA10 H | D17: H 0001 | E17: DS75 | G17: 4 | H17: =VLOOKUP($C17,#REF!,18,0) -> #REF! | I17: 0 | J17: 0 | K17: 0 | L17: =I17+K17-J17 -> 0 | M17: 0 | N17: =M17-L17 -> 0 | O17: =L17+N17-M17 -> 0 | P17: 0 | Q17: =P17-O17 -> 0 | R17: =O17+Q17-P17 -> 0 | S17: 0 | T17: =S17-R17 -> 0 | U17: =R17+T17-S17 -> 0 | V17: 0 | W17: =V17-U17 -> 0 | X17: =U17+W17-V17 -> 0 | Y17: 0 | Z17: =Y17-X17 -> 0 | AA17: =X17+Z17-Y17 -> 0 | AB17: 0 | AC17: =AB17-AA17 -> 0 | AD17: =AA17+AC17-AB17 -> 0
B18: 491D | C18: 82115-0E480 | D18: J 0101 | E18: DSY3 | G18: 4 | H18: =+H30 -> #REF! | I18: 0 | J18: 0 | K18: 0 | L18: =I18+K18-J18 -> 0 | M18: 0 | N18: =M18-L18 -> 0 | O18: =L18+N18-M18 -> 0 | P18: 0 | Q18: =P18-O18 -> 0 | R18: =O18+Q18-P18 -> 0 | S18: 0 | T18: =S18-R18 -> 0 | U18: =R18+T18-S18 -> 0 | V18: 0 | W18: =V18-U18 -> 0 | X18: =U18+W18-V18 -> 0 | Y18: 0 | Z18: =Y18-X18 -> 0 | AA18: =X18+Z18-Y18 -> 0 | AB18: 0 | AC18: =AB18-AA18 -> 0 | AD18: =AA18+AC18-AB18 -> 0
C19: 82115-0E490 K | D19: K 0001 | E19: DZ01 | G19: 4 | H19: =VLOOKUP(C19,#REF!,18,0) -> #REF! | I19: 0 | J19: 452 | K19: 452 | L19: =I19+K19-J19 -> 0 | M19: =VLOOKUP($C19,#REF!,57,0) -> #REF! | N19: =M19-L19+52-8 -> #REF! | O19: =L19+N19-M19 -> #REF! | P19: =VLOOKUP($C19,#REF!,58,0) -> #REF! | Q19: =P19-O19 -> #REF! | R19: =O19+Q19-P19 -> #REF! | S19: =VLOOKUP($C19,#REF!,59,0) -> #REF! | T19: =S19-R19 -> #REF! | U19: =R19+T19-S19 -> #REF! | V19: =VLOOKUP($C19,#REF!,60,0) -> #REF! | W19: =V19-U19 -> #REF! | X19: =U19+W19-V19 -> #REF! | Y19: =VLOOKUP($C19,#REF!,61,0) -> #REF! | Z19: =Y19-X19 -> #REF! | AA19: =X19+Z19-Y19 -> #REF! | AB19: =VLOOKUP($C19,#REF!,62,0) -> #REF! | AC19: =AB19-AA19 -> #REF! | AD19: =AA19+AC19-AB19 -> #REF!
C20: 82115-0EA10 K | D20: K 0001 | E20: DZ02 | G20: 4 | H20: =VLOOKUP(C20,#REF!,18,0) -> #REF! | I20: 336 | J20: 2724 | K20: 2724 | L20: =I20+K20-J20 -> 336 | M20: =VLOOKUP($C20,#REF!,57,0) -> #REF! | N20: =M20-L20+368-8-4-148 -> #REF! | O20: =L20+N20-M20 -> #REF! | P20: =VLOOKUP($C20,#REF!,58,0) -> #REF! | Q20: =P20-O20+212 -> #REF! | R20: =O20+Q20-P20 -> #REF! | S20: =VLOOKUP($C20,#REF!,59,0) -> #REF! | T20: =S20-R20+432-200 -> #REF! | U20: =R20+T20-S20 -> #REF! | V20: =VLOOKUP($C20,#REF!,60,0) -> #REF! | W20: =V20-U20+736-200 -> #REF! | X20: =U20+W20-V20 -> #REF! | Y20: =VLOOKUP($C20,#REF!,61,0) -> #REF! | Z20: =Y20-X20+496 -> #REF! | AA20: =X20+Z20-Y20 -> #REF! | AB20: =VLOOKUP($C20,#REF!,62,0) -> #REF! | AC20: =AB20-AA20 -> #REF! | AD20: =AA20+AC20-AB20 -> #REF!
C21: 82115-0E600 | D21: H 0201 | E21: DS10 | G21: 4 | K21: 0 | N21: =M21-L21 -> 0 | Q21: =P21-O21 -> 0 | T21: =S21-R21 -> 0 | W21: =V21-U21 -> 0 | Z21: =Y21-X21 -> 0 | AD21: =AA21+AC21-AB21 -> 0
C22: 82115-0E610 | D22: H 0201 | E22: DS11 | G22: 4 | K22: 0 | N22: =M22-L22 -> 0 | Q22: =P22-O22 -> 0 | T22: =S22-R22 -> 0 | W22: =V22-U22 -> 0 | Z22: =Y22-X22 -> 0 | AD22: =AA22+AC22-AB22 -> 0
C23: 82115-0E620 | D23: H 0201 | E23: DS12 | G23: 4 | K23: 0 | N23: =M23-L23 -> 0 | Q23: =P23-O23 -> 0 | T23: =S23-R23 -> 0 | W23: =V23-U23 -> 0 | Z23: =Y23-X23 -> 0 | AD23: =AA23+AC23-AB23 -> 0
C24: 82115-0EA40 | D24: H 0201 | E24: DS13 | G24: 4 | K24: 0 | N24: =M24-L24 -> 0 | Q24: =P24-O24 -> 0 | T24: =S24-R24 -> 0 | W24: =V24-U24 -> 0 | Z24: =Y24-X24 -> 0 | AD24: =AA24+AC24-AB24 -> 0
C25: 82115-0EA50 | D25: H 0201 | E25: DS14 | G25: 4 | K25: 0 | N25: =M25-L25 -> 0 | Q25: =P25-O25 -> 0 | T25: =S25-R25 -> 0 | W25: =V25-U25 -> 0 | Z25: =Y25-X25 -> 0 | AD25: =AA25+AC25-AB25 -> 0
C26: 82115-0EA60 | D26: H 0201 | E26: DS15 | G26: 4 | K26: 0 | N26: =M26-L26 -> 0 | Q26: =P26-O26 -> 0 | T26: =S26-R26 -> 0 | W26: =V26-U26 -> 0 | Z26: =Y26-X26 -> 0 | AD26: =AA26+AC26-AB26 -> 0
C27: 82115-0EA70 | D27: H 0201 | E27: DS16 | G27: 4 | K27: 0 | N27: =M27-L27 -> 0 | Q27: =P27-O27 -> 0 | T27: =S27-R27 -> 0 | W27: =V27-U27 -> 0 | Z27: =Y27-X27 -> 0 | AD27: =AA27+AC27-AB27 -> 0
C28: 82115-0EG40 | D28: H 0201 | E28: DS17 | G28: 4 | K28: 0 | N28: =M28-L28 -> 0 | Q28: =P28-O28 -> 0 | T28: =S28-R28 -> 0 | W28: =V28-U28 -> 0 | Z28: =Y28-X28 -> 0 | AD28: =AA28+AC28-AB28 -> 0
C29: 82115-0E470 F | D29: G 0001 | E29: DOI4 | G29: 4 | K29: 0 | N29: =M29-L29 -> 0 | Q29: =P29-O29 -> 0 | T29: =S29-R29 -> 0 | W29: =V29-U29 -> 0 | Z29: =Y29-X29 -> 0 | AD29: =AA29+AC29-AB29 -> 0
C30: 82115-0E480 K | D30: K 0301 | E30: DVB1 | G30: 4 | H30: =VLOOKUP(C30,#REF!,18,0) -> #REF! | I30: 96 | J30: 1392 | K30: 1680 | L30: =I30+K30-J30 -> 384 | M30: =VLOOKUP($C30,#REF!,57,0) -> #REF! | N30: =M30-L30+208 -> #REF! | O30: =L30+N30-M30 -> #REF! | P30: =VLOOKUP($C30,#REF!,58,0) -> #REF! | Q30: =P30-O30+200 -> #REF! | R30: =O30+Q30-P30 -> #REF! | S30: =VLOOKUP($C30,#REF!,59,0) -> #REF! | T30: =S30-R30+200 -> #REF! | U30: =R30+T30-S30 -> #REF! | V30: =VLOOKUP($C30,#REF!,60,0) -> #REF! | W30: =V30-U30+200 -> #REF! | X30: =U30+W30-V30 -> #REF! | Y30: =VLOOKUP($C30,#REF!,61,0) -> #REF! | Z30: =Y30-X30+200 -> #REF! | AA30: =X30+Z30-Y30 -> #REF! | AB30: =VLOOKUP($C30,#REF!,62,0) -> #REF! | AC30: =AB30-AA30 -> #REF! | AD30: =AA30+AC30-AB30 -> #REF! | AE30: 821150E480
C31: 82115-0E490 J | D31: J 1101 | E31: DVB2 | G31: 4 | H31: =VLOOKUP(C31,#REF!,18,0) -> #REF! | I31: 0 | J31: 0 | K31: 0 | L31: =I31+K31-J31 -> 0 | M31: =VLOOKUP($C31,#REF!,57,0) -> #REF! | N31: =M31-L31 -> #REF! | O31: =L31+N31-M31 -> #REF! | P31: =VLOOKUP($C31,#REF!,58,0) -> #REF! | Q31: =P31-O31 -> #REF! | R31: =O31+Q31-P31 -> #REF! | S31: =VLOOKUP($C31,#REF!,59,0) -> #REF! | T31: =S31-R31 -> #REF! | U31: =R31+T31-S31 -> #REF! | V31: =VLOOKUP($C31,#REF!,60,0) -> #REF! | W31: =V31-U31 -> #REF! | X31: =U31+W31-V31 -> #REF! | Y31: =VLOOKUP($C31,#REF!,61,0) -> #REF! | Z31: =Y31-X31 -> #REF! | AA31: =X31+Z31-Y31 -> #REF! | AB31: =VLOOKUP($C31,#REF!,62,0) -> #REF! | AC31: =AB31-AA31 -> #REF! | AD31: =AA31+AC31-AB31 -> #REF! | AE31: 82115-0E490 H
C32: 82115-0EA10 J | D32: J 1101 | E32: DVB3 | G32: 4 | H32: =VLOOKUP(C32,#REF!,18,0) -> #REF! | I32: 0 | J32: 0 | K32: 0 | L32: =I32+K32-J32 -> 0 | M32: =VLOOKUP($C32,#REF!,57,0) -> #REF! | N32: =M32-L32 -> #REF! | O32: =L32+N32-M32 -> #REF! | P32: =VLOOKUP($C32,#REF!,58,0) -> #REF! | Q32: =P32-O32 -> #REF! | R32: =O32+Q32-P32 -> #REF! | S32: =VLOOKUP($C32,#REF!,59,0) -> #REF! | T32: =S32-R32 -> #REF! | U32: =R32+T32-S32 -> #REF! | V32: =VLOOKUP($C32,#REF!,60,0) -> #REF! | W32: =V32-U32 -> #REF! | X32: =U32+W32-V32 -> #REF! | Y32: =VLOOKUP($C32,#REF!,61,0) -> #REF! | Z32: =Y32-X32 -> #REF! | AA32: =X32+Z32-Y32 -> #REF! | AB32: =VLOOKUP($C32,#REF!,62,0) -> #REF! | AC32: =AB32-AA32 -> #REF! | AD32: =AA32+AC32-AB32 -> #REF! | AE32: 82115-0EA10 H
C33: 82115-0E570 G | D33: G 1001 | E33: DOJ8 | G33: 4 | K33: 0 | N33: =M33-L33 -> 0 | Q33: =P33-O33 -> 0 | T33: =S33-R33 -> 0 | W33: =V33-U33 -> 0 | Z33: =Y33-X33 -> 0 | AD33: =AA33+AC33-AB33 -> 0
C34: 82115-0E580 G | D34: G 1001 | E34: DOJ9 | G34: 4 | K34: 0 | N34: =M34-L34 -> 0 | Q34: =P34-O34 -> 0 | T34: =S34-R34 -> 0 | W34: =V34-U34 -> 0 | Z34: =Y34-X34 -> 0 | AD34: =AA34+AC34-AB34 -> 0
C35: 82115-0E590 G | D35: G 1001 | E35: DOK1 | G35: 4 | K35: 0 | N35: =M35-L35 -> 0 | Q35: =P35-O35 -> 0 | T35: =S35-R35 -> 0 | W35: =V35-U35 -> 0 | Z35: =Y35-X35 -> 0 | AD35: =AA35+AC35-AB35 -> 0
C36: 82115-0E600 G | D36: G 1001 | E36: DOK2 | G36: 4 | K36: 0 | N36: =M36-L36 -> 0 | Q36: =P36-O36 -> 0 | T36: =S36-R36 -> 0 | W36: =V36-U36 -> 0 | Z36: =Y36-X36 -> 0 | AD36: =AA36+AC36-AB36 -> 0
C37: 82115-0E610 G | D37: G 1001 | E37: DOK3 | G37: 4 | K37: 0 | N37: =M37-L37 -> 0 | Q37: =P37-O37 -> 0 | T37: =S37-R37 -> 0 | W37: =V37-U37 -> 0 | Z37: =Y37-X37 -> 0 | AD37: =AA37+AC37-AB37 -> 0
C38: 82115-0E620 G | D38: G 1001 | E38: DOK4 | G38: 4 | K38: 0 | N38: =M38-L38 -> 0 | Q38: =P38-O38 -> 0 | T38: =S38-R38 -> 0 | W38: =V38-U38 -> 0 | Z38: =Y38-X38 -> 0 | AD38: =AA38+AC38-AB38 -> 0
C39: 82115-0EA40 G | D39: G 1001 | E39: DOK5 | G39: 4 | K39: 0 | N39: =M39-L39 -> 0 | Q39: =P39-O39 -> 0 | T39: =S39-R39 -> 0 | W39: =V39-U39 -> 0 | Z39: =Y39-X39 -> 0 | AD39: =AA39+AC39-AB39 -> 0
C40: 82115-0EA50 G | D40: G 1001 | E40: DOK6 | G40: 4 | K40: 0 | N40: =M40-L40 -> 0 | Q40: =P40-O40 -> 0 | T40: =S40-R40 -> 0 | W40: =V40-U40 -> 0 | Z40: =Y40-X40 -> 0 | AD40: =AA40+AC40-AB40 -> 0
C41: 82115-0EA60 G | D41: G 1001 | E41: DOK7 | G41: 4 | K41: 0 | N41: =M41-L41 -> 0 | Q41: =P41-O41 -> 0 | T41: =S41-R41 -> 0 | W41: =V41-U41 -> 0 | Z41: =Y41-X41 -> 0 | AD41: =AA41+AC41-AB41 -> 0
C42: 82115-0EA70 G | D42: G 1001 | E42: DOK8 | G42: 4 | K42: 0 | N42: =M42-L42 -> 0 | Q42: =P42-O42 -> 0 | T42: =S42-R42 -> 0 | W42: =V42-U42 -> 0 | Z42: =Y42-X42 -> 0 | AD42: =AA42+AC42-AB42 -> 0
C43: 82115-0EG40 G | D43: G 1001 | E43: DOK9 | G43: 4 | K43: 0 | N43: =M43-L43 -> 0 | Q43: =P43-O43 -> 0 | T43: =S43-R43 -> 0 | W43: =V43-U43 -> 0 | Z43: =Y43-X43 -> 0 | AD43: =AA43+AC43-AB43 -> 0
...

Sheet down rate
B1: SIX MONTH PRODUCTION PLAN ( QTY )
L2: TOYOTA PRIUS (433W ) | AB2: PREPARED
B3: S/R NO : 14-DEC-'10(PRD_52023_32G7_201101_3) | M3: Periode : DEC PROD 2010 (ACTUAL)
B4: FAX NO : EMAIL
B5: DATE :14-DEC-10 | AB5: EMU
BD6: AS 400
Z7: NSO
I9: TEMPRORARY UMH | AG9: Cutting Qty
B10: Print Date : | C10: =NOW() -> 46195.105
A11: TYPE | C11: HARNESS No. | D11: LEVEL | E11: ASSY CODE | F11: CCT. | G11: Std Pack | H11: UMH | J11: =GUM!I11 -> FEB | M11: =GUM!L11 -> MAR | P11: =GUM!O11 -> APR | S11: =GUM!R11 -> MAY | V11: =GUM!U11 -> JUN | Y11: =GUM!X11 -> JUL | AB11: =GUM!I11 -> FEB | AE11: BAL | AG11: =J11 -> FEB | AJ11: =M11 -> MAR | AM11: =P11 -> APR | AP11: =S11 -> MAY | AS11: =V11 -> JUN | AV11: =Y11 -> JUL | AY11: =AB11 -> FEB
H12: Jan~Jun | I12: Jul~Dec | J12: =VLOOKUP(J11,#REF!,9,0) -> #REF! | M12: =VLOOKUP(M11,#REF!,9,0) -> #REF! | P12: =VLOOKUP(P11,#REF!,9,0) -> #REF! | S12: =VLOOKUP(S11,#REF!,9,0) -> #REF! | V12: =VLOOKUP(V11,#REF!,9,0) -> #REF! | Y12: =VLOOKUP(Y11,#REF!,9,0) -> #REF! | AB12: =VLOOKUP(AB11,#REF!,9,0) -> #REF! | AG12: =J12 -> #REF! | AJ12: =M12 -> #REF! | AM12: =P12 -> #REF! | AP12: =S12 -> #REF! | AS12: =V12 -> #REF! | AV12: =Y12 -> #REF! | AY12: =AB12 -> #REF! | BC12: =M11 -> MAR | BD12: =P11 -> APR | BE12: =S11 -> MAY | BF12: =V11 -> JUN | BG12: =Y11 -> JUL | BH12: =AB11 -> FEB
H13: 2010 | I13: 2010 | J13: BAL | K13: DEL | L13: PROD | M13: BAL | N13: DEL | O13: PROD | P13: BAL | Q13: DEL | R13: PROD | S13: BAL | T13: DEL | U13: PROD | V13: BAL | W13: DEL | X13: PROD | Y13: BAL | Z13: DEL | AA13: PROD | AB13: BAL | AC13: DEL | AD13: PROD | AG13: =J13 -> BAL | AH13: =K13 -> DEL | AI13: =L13 -> PROD | AJ13: =M13 -> BAL | AK13: =N13 -> DEL | AL13: =O13 -> PROD | AM13: =P13 -> BAL | AN13: =Q13 -> DEL | ... BA13: =AD13 -> PROD | BC13: 5 | BD13: 4 | BE13: 4 | BF13: 5 | BG13: 4 | BH13: 4
A14: RHD | B14: DOM | C14: 82111-47330 H | D14: =VLOOKUP(C14,#REF!,2,0) -> #REF! | E14: =VLOOKUP(C14,#REF!,4,0) -> #REF! | F14: 304 | G14: 6 | H14: =VLOOKUP(C14,#REF!,3,0) -> #REF! | I14: =VLOOKUP(C14,#REF!,7,0) -> #REF! | J14: #REF! | K14: #REF! | L14: #REF! | M14: #REF! | N14: #REF! | O14: #REF! | P14: #REF! | Q14: #REF! | R14: #REF! | S14: #REF! | T14: #REF! | U14: #REF! | V14: #REF! | W14: #REF! | X14: #REF! | Y14: #REF! | Z14: #REF! | AA14: #REF! | AB14: #REF! | AC14: #REF! | AD14: #REF! | AE14: #REF! | AF14: 1 | AG14: =J14*$F14 -> #REF! | AH14: =K14*$F14 -> #REF! | AI14: =L14*$F14 -> #REF! | AJ14: =M14*$F14 -> #REF! | AK14: =K14*$F14 -> #REF! | AL14: =O14*$F14 -> #REF! | AM14: =P14*$F14 -> #REF! | AN14: =N14*$F14 -> #REF! | AO14: =R14*$F14 -> #REF! | AP14: =S14*$F14 -> #REF! | AQ14: =Q14*$F14 -> #REF! | AR14: =U14*$F14 -> #REF! | AS14: =V14*$F14 -> #REF! | AT14: =T14*$F14 -> #REF! | AU14: =X14*$F14 -> #REF! | AV14: =Y14*$F14 -> #REF! | AW14: =W14*$F14 -> #REF! | AX14: =AA14*$F14 -> #REF! | AY14: =AB14*$F14 -> #REF! | AZ14: =Z14*$F14 -> #REF! | BA14: =AD14*$F14 -> #REF! | BB14: 82111-47330 | BC14: =ROUNDUP(O14/$BC$13,0) -> #REF! | BD14: =ROUNDUP(R14/$BD$13,0) -> #REF! | BE14: =ROUNDUP(U14/$BE$13,0) -> #REF! | BF14: =ROUNDUP(X14/$BF$13,0) -> #REF! | BG14: =ROUNDUP(AA14/$BG$13,0) -> #REF! | BH14: =ROUNDUP(AD14/$BH$13,0) -> #REF! | BI14: 1
C15: 82111-47340 H | D15: =VLOOKUP(C15,#REF!,2,0) -> #REF! | E15: =VLOOKUP(C15,#REF!,4,0) -> #REF! | F15: 323 | G15: 6 | H15: =VLOOKUP(C15,#REF!,3,0) -> #REF! | I15: =VLOOKUP(C15,#REF!,7,0) -> #REF! | J15: #REF! | K15: #REF! | L15: #REF! | M15: #REF! | N15: #REF! | O15: #REF! | P15: #REF! | Q15: #REF! | R15: #REF! | S15: #REF! | T15: #REF! | U15: #REF! | V15: #REF! | W15: #REF! | X15: #REF! | Y15: #REF! | Z15: #REF! | AA15: #REF! | AB15: #REF! | AC15: #REF! | AD15: #REF! | AE15: #REF! | AF15: =AF14+1 -> 2 | AG15: =J15*$F15 -> #REF! | AH15: =K15*$F15 -> #REF! | AI15: =L15*$F15 -> #REF! | AJ15: =M15*$F15 -> #REF! | AK15: =K15*$F15 -> #REF! | AL15: =O15*$F15 -> #REF! | AM15: =P15*$F15 -> #REF! | AN15: =N15*$F15 -> #REF! | AO15: =R15*$F15 -> #REF! | AP15: =S15*$F15 -> #REF! | AQ15: =Q15*$F15 -> #REF! | AR15: =U15*$F15 -> #REF! | AS15: =V15*$F15 -> #REF! | AT15: =T15*$F15 -> #REF! | AU15: =X15*$F15 -> #REF! | AV15: =Y15*$F15 -> #REF! | AW15: =W15*$F15 -> #REF! | AX15: =AA15*$F15 -> #REF! | AY15: =AB15*$F15 -> #REF! | AZ15: =Z15*$F15 -> #REF! | BA15: =AD15*$F15 -> #REF! | BB15: 82111-47340 | BC15: =ROUNDUP(O15/$BC$13,0) -> #REF! | BD15: =ROUNDUP(R15/$BD$13,0) -> #REF! | BE15: =ROUNDUP(U15/$BE$13,0) -> #REF! | BF15: =ROUNDUP(X15/$BF$13,0) -> #REF! | BG15: =ROUNDUP(AA15/$BG$13,0) -> #REF! | BH15: =ROUNDUP(AD15/$BH$13,0) -> #REF! | BI15: =BI14+1 -> 2
C16: 82111-47350 A | D16: =VLOOKUP(C16,#REF!,2,0) -> #REF! | E16: =VLOOKUP(C16,#REF!,4,0) -> #REF! | G16: 6 | H16: =VLOOKUP(C16,#REF!,3,0) -> #REF! | I16: =VLOOKUP(C16,#REF!,7,0) -> #REF! | J16: #REF! | K16: #REF! | L16: #REF! | M16: #REF! | N16: #REF! | O16: #REF! | P16: #REF! | Q16: #REF! | R16: #REF! | S16: #REF! | T16: #REF! | U16: #REF! | V16: #REF! | W16: #REF! | X16: #REF! | Y16: #REF! | Z16: #REF! | AA16: #REF! | AB16: #REF! | AC16: #REF! | AD16: #REF! | AE16: #REF! | AF16: =AF15+1 -> 3 | AG16: =J16*$F16 -> #REF! | AH16: =K16*$F16 -> #REF! | AI16: =L16*$F16 -> #REF! | AJ16: =M16*$F16 -> #REF! | AK16: =K16*$F16 -> #REF! | AL16: =O16*$F16 -> #REF! | AM16: =P16*$F16 -> #REF! | AN16: =N16*$F16 -> #REF! | AO16: =R16*$F16 -> #REF! | AP16: =S16*$F16 -> #REF! | AQ16: =Q16*$F16 -> #REF! | AR16: =U16*$F16 -> #REF! | AS16: =V16*$F16 -> #REF! | AT16: =T16*$F16 -> #REF! | AU16: =X16*$F16 -> #REF! | AV16: =Y16*$F16 -> #REF! | AW16: =W16*$F16 -> #REF! | AX16: =AA16*$F16 -> #REF! | AY16: =AB16*$F16 -> #REF! | AZ16: =Z16*$F16 -> #REF! | BA16: =AD16*$F16 -> #REF! | BB16: 82111-47350 | BC16: =ROUNDUP(O16/$BC$13,0) -> #REF! | BD16: =ROUNDUP(R16/$BD$13,0) -> #REF! | BE16: =ROUNDUP(U16/$BE$13,0) -> #REF! | BF16: =ROUNDUP(X16/$BF$13,0) -> #REF! | BG16: =ROUNDUP(AA16/$BG$13,0) -> #REF! | BH16: =ROUNDUP(AD16/$BH$13,0) -> #REF! | BI16: =BI15+1 -> 3
B17: EC | C17: 82111-47450 H | D17: =VLOOKUP(C17,#REF!,2,0) -> #REF! | E17: =VLOOKUP(C17,#REF!,4,0) -> #REF! | F17: 332 | G17: 6 | H17: =VLOOKUP(C17,#REF!,3,0) -> #REF! | I17: =VLOOKUP(C17,#REF!,7,0) -> #REF! | J17: #REF! | K17: #REF! | L17: #REF! | M17: #REF! | N17: #REF! | O17: #REF! | P17: #REF! | Q17: #REF! | R17: #REF! | S17: #REF! | T17: #REF! | U17: #REF! | V17: #REF! | W17: #REF! | X17: #REF! | Y17: #REF! | Z17: #REF! | AA17: #REF! | AB17: #REF! | AC17: #REF! | AD17: #REF! | AE17: #REF! | AF17: =AF16+1 -> 4 | AG17: =J17*$F17 -> #REF! | AH17: =K17*$F17 -> #REF! | AI17: =L17*$F17 -> #REF! | AJ17: =M17*$F17 -> #REF! | AK17: =K17*$F17 -> #REF! | AL17: =O17*$F17 -> #REF! | AM17: =P17*$F17 -> #REF! | AN17: =N17*$F17 -> #REF! | AO17: =R17*$F17 -> #REF! | AP17: =S17*$F17 -> #REF! | AQ17: =Q17*$F17 -> #REF! | AR17: =U17*$F17 -> #REF! | AS17: =V17*$F17 -> #REF! | AT17: =T17*$F17 -> #REF! | AU17: =X17*$F17 -> #REF! | AV17: =Y17*$F17 -> #REF! | AW17: =W17*$F17 -> #REF! | AX17: =AA17*$F17 -> #REF! | AY17: =AB17*$F17 -> #REF! | AZ17: =Z17*$F17 -> #REF! | BA17: =AD17*$F17 -> #REF! | BB17: 82111-47450 | BC17: =ROUNDUP(O17/$BC$13,0) -> #REF! | BD17: =ROUNDUP(R17/$BD$13,0) -> #REF! | BE17: =ROUNDUP(U17/$BE$13,0) -> #REF! | BF17: =ROUNDUP(X17/$BF$13,0) -> #REF! | BG17: =ROUNDUP(AA17/$BG$13,0) -> #REF! | BH17: =ROUNDUP(AD17/$BH$13,0) -> #REF! | BI17: =BI16+1 -> 4
C18: 82111-47460 H | D18: =VLOOKUP(C18,#REF!,2,0) -> #REF! | E18: =VLOOKUP(C18,#REF!,4,0) -> #REF! | F18: 351 | G18: 6 | H18: =VLOOKUP(C18,#REF!,3,0) -> #REF! | I18: =VLOOKUP(C18,#REF!,7,0) -> #REF! | J18: #REF! | K18: #REF! | L18: #REF! | M18: #REF! | N18: #REF! | O18: #REF! | P18: #REF! | Q18: #REF! | R18: #REF! | S18: #REF! | T18: #REF! | U18: #REF! | V18: #REF! | W18: #REF! | X18: #REF! | Y18: #REF! | Z18: #REF! | AA18: #REF! | AB18: #REF! | AC18: #REF! | AD18: #REF! | AE18: #REF! | AF18: =AF17+1 -> 5 | AG18: =J18*$F18 -> #REF! | AH18: =K18*$F18 -> #REF! | AI18: =L18*$F18 -> #REF! | AJ18: =M18*$F18 -> #REF! | AK18: =K18*$F18 -> #REF! | AL18: =O18*$F18 -> #REF! | AM18: =P18*$F18 -> #REF! | AN18: =N18*$F18 -> #REF! | AO18: =R18*$F18 -> #REF! | AP18: =S18*$F18 -> #REF! | AQ18: =Q18*$F18 -> #REF! | AR18: =U18*$F18 -> #REF! | AS18: =V18*$F18 -> #REF! | AT18: =T18*$F18 -> #REF! | AU18: =X18*$F18 -> #REF! | AV18: =Y18*$F18 -> #REF! | AW18: =W18*$F18 -> #REF! | AX18: =AA18*$F18 -> #REF! | AY18: =AB18*$F18 -> #REF! | AZ18: =Z18*$F18 -> #REF! | BA18: =AD18*$F18 -> #REF! | BB18: 82111-47460 | BC18: =ROUNDUP(O18/$BC$13,0) -> #REF! | BD18: =ROUNDUP(R18/$BD$13,0) -> #REF! | BE18: =ROUNDUP(U18/$BE$13,0) -> #REF! | BF18: =ROUNDUP(X18/$BF$13,0) -> #REF! | BG18: =ROUNDUP(AA18/$BG$13,0) -> #REF! | BH18: =ROUNDUP(AD18/$BH$13,0) -> #REF! | BI18: =BI17+1 -> 5
C19: 82111-47480 B | D19: =VLOOKUP(C19,#REF!,2,0) -> #REF! | E19: =VLOOKUP(C19,#REF!,4,0) -> #REF! | F19: 301 | G19: 6 | H19: =VLOOKUP(C19,#REF!,3,0) -> #REF! | I19: =VLOOKUP(C19,#REF!,7,0) -> #REF! | J19: #REF! | K19: #REF! | L19: #REF! | M19: #REF! | N19: #REF! | O19: #REF! | P19: #REF! | Q19: #REF! | R19: #REF! | S19: #REF! | T19: #REF! | U19: #REF! | V19: #REF! | W19: #REF! | X19: #REF! | Y19: #REF! | Z19: #REF! | AA19: #REF! | AB19: #REF! | AC19: #REF! | AD19: #REF! | AE19: #REF! | AF19: =AF18+1 -> 6 | AG19: =J19*$F19 -> #REF! | AH19: =K19*$F19 -> #REF! | AI19: =L19*$F19 -> #REF! | AJ19: =M19*$F19 -> #REF! | AK19: =K19*$F19 -> #REF! | AL19: =O19*$F19 -> #REF! | AM19: =P19*$F19 -> #REF! | AN19: =N19*$F19 -> #REF! | AO19: =R19*$F19 -> #REF! | AP19: =S19*$F19 -> #REF! | AQ19: =Q19*$F19 -> #REF! | AR19: =U19*$F19 -> #REF! | AS19: =V19*$F19 -> #REF! | AT19: =T19*$F19 -> #REF! | AU19: =X19*$F19 -> #REF! | AV19: =Y19*$F19 -> #REF! | AW19: =W19*$F19 -> #REF! | AX19: =AA19*$F19 -> #REF! | AY19: =AB19*$F19 -> #REF! | AZ19: =Z19*$F19 -> #REF! | BA19: =AD19*$F19 -> #REF! | BB19: 82111-47460 | BC19: =ROUNDUP(O19/$BC$13,0) -> #REF! | BD19: =ROUNDUP(R19/$BD$13,0) -> #REF! | BE19: =ROUNDUP(U19/$BE$13,0) -> #REF! | BF19: =ROUNDUP(X19/$BF$13,0) -> #REF! | BG19: =ROUNDUP(AA19/$BG$13,0) -> #REF! | BH19: =ROUNDUP(AD19/$BH$13,0) -> #REF! | BI19: =BI18+1 -> 6
B20: EC | C20: 82111-47461 | D20: =VLOOKUP(C20,#REF!,2,0) -> #REF! | E20: =VLOOKUP(C20,#REF!,4,0) -> #REF! | F20: 332 | G20: 6 | H20: =VLOOKUP(C20,#REF!,3,0) -> #REF! | I20: =VLOOKUP(C20,#REF!,7,0) -> #REF! | J20: #REF! | K20: #REF! | L20: #REF! | M20: #REF! | N20: #REF! | O20: #REF! | P20: #REF! | Q20: #REF! | R20: #REF! | S20: #REF! | T20: #REF! | U20: #REF! | V20: #REF! | W20: #REF! | X20: #REF! | Y20: #REF! | Z20: #REF! | AA20: #REF! | AB20: #REF! | AC20: #REF! | AD20: #REF! | AE20: #REF! | AF20: =AF19+1 -> 7 | AG20: =J20*$F20 -> #REF! | AH20: =K20*$F20 -> #REF! | AI20: =L20*$F20 -> #REF! | AJ20: =M20*$F20 -> #REF! | AK20: =K20*$F20 -> #REF! | AL20: =O20*$F20 -> #REF! | AM20: =P20*$F20 -> #REF! | AN20: =N20*$F20 -> #REF! | AO20: =R20*$F20 -> #REF! | AP20: =S20*$F20 -> #REF! | AQ20: =Q20*$F20 -> #REF! | AR20: =U20*$F20 -> #REF! | AS20: =V20*$F20 -> #REF! | AT20: =T20*$F20 -> #REF! | AU20: =X20*$F20 -> #REF! | AV20: =Y20*$F20 -> #REF! | AW20: =W20*$F20 -> #REF! | AX20: =AA20*$F20 -> #REF! | AY20: =AB20*$F20 -> #REF! | AZ20: =Z20*$F20 -> #REF! | BA20: =AD20*$F20 -> #REF! | BB20: 82111-47450 | BC20: =ROUNDUP(O20/$BC$13,0) -> #REF! | BD20: =ROUNDUP(R20/$BD$13,0) -> #REF! | BE20: =ROUNDUP(U20/$BE$13,0) -> #REF! | BF20: =ROUNDUP(X20/$BF$13,0) -> #REF! | BG20: =ROUNDUP(AA20/$BG$13,0) -> #REF! | BH20: =ROUNDUP(AD20/$BH$13,0) -> #REF! | BI20: =BI19+1 -> 7
C21: 82111-47462 | D21: =VLOOKUP(C21,#REF!,2,0) -> #REF! | E21: =VLOOKUP(C21,#REF!,4,0) -> #REF! | F21: 332 | G21: 6 | H21: =VLOOKUP(C21,#REF!,3,0) -> #REF! | I21: =VLOOKUP(C21,#REF!,7,0) -> #REF! | J21: #REF! | K21: #REF! | L21: #REF! | M21: #REF! | N21: #REF! | O21: #REF! | P21: #REF! | Q21: #REF! | R21: #REF! | S21: #REF! | T21: #REF! | U21: #REF! | V21: #REF! | W21: #REF! | X21: #REF! | Y21: #REF! | Z21: #REF! | AA21: #REF! | AB21: #REF! | AC21: #REF! | AD21: #REF! | AE21: #REF! | AF21: =AF20+1 -> 8 | AG21: =J21*$F21 -> #REF! | AH21: =K21*$F21 -> #REF! | AI21: =L21*$F21 -> #REF! | AJ21: =M21*$F21 -> #REF! | AK21: =K21*$F21 -> #REF! | AL21: =O21*$F21 -> #REF! | AM21: =P21*$F21 -> #REF! | AN21: =N21*$F21 -> #REF! | AO21: =R21*$F21 -> #REF! | AP21: =S21*$F21 -> #REF! | AQ21: =Q21*$F21 -> #REF! | AR21: =U21*$F21 -> #REF! | AS21: =V21*$F21 -> #REF! | AT21: =T21*$F21 -> #REF! | AU21: =X21*$F21 -> #REF! | AV21: =Y21*$F21 -> #REF! | AW21: =W21*$F21 -> #REF! | AX21: =AA21*$F21 -> #REF! | AY21: =AB21*$F21 -> #REF! | AZ21: =Z21*$F21 -> #REF! | BA21: =AD21*$F21 -> #REF! | BB21: 82111-47450 | BC21: =ROUNDUP(O21/$BC$13,0) -> #REF! | BD21: =ROUNDUP(R21/$BD$13,0) -> #REF! | BE21: =ROUNDUP(U21/$BE$13,0) -> #REF! | BF21: =ROUNDUP(X21/$BF$13,0) -> #REF! | BG21: =ROUNDUP(AA21/$BG$13,0) -> #REF! | BH21: =ROUNDUP(AD21/$BH$13,0) -> #REF! | BI21: =BI20+1 -> 8
C22: 82111-47341 | D22: =VLOOKUP(C22,#REF!,2,0) -> #REF! | E22: =VLOOKUP(C22,#REF!,4,0) -> #REF! | F22: 351 | G22: 6 | H22: =VLOOKUP(C22,#REF!,3,0) -> #REF! | I22: =VLOOKUP(C22,#REF!,7,0) -> #REF! | J22: #REF! | K22: #REF! | L22: #REF! | M22: #REF! | N22: #REF! | O22: #REF! | P22: #REF! | Q22: #REF! | R22: #REF! | S22: #REF! | T22: #REF! | U22: #REF! | V22: #REF! | W22: #REF! | X22: #REF! | Y22: #REF! | Z22: #REF! | AA22: #REF! | AB22: #REF! | AC22: #REF! | AD22: #REF! | AE22: #REF! | AF22: =AF21+1 -> 9 | AG22: =J22*$F22 -> #REF! | AH22: =K22*$F22 -> #REF! | AI22: =L22*$F22 -> #REF! | AJ22: =M22*$F22 -> #REF! | AK22: =K22*$F22 -> #REF! | AL22: =O22*$F22 -> #REF! | AM22: =P22*$F22 -> #REF! | AN22: =N22*$F22 -> #REF! | AO22: =R22*$F22 -> #REF! | AP22: =S22*$F22 -> #REF! | AQ22: =Q22*$F22 -> #REF! | AR22: =U22*$F22 -> #REF! | AS22: =V22*$F22 -> #REF! | AT22: =T22*$F22 -> #REF! | AU22: =X22*$F22 -> #REF! | AV22: =Y22*$F22 -> #REF! | AW22: =W22*$F22 -> #REF! | AX22: =AA22*$F22 -> #REF! | AY22: =AB22*$F22 -> #REF! | AZ22: =Z22*$F22 -> #REF! | BA22: =AD22*$F22 -> #REF! | BB22: 82111-47460 | BC22: =ROUNDUP(O22/$BC$13,0) -> #REF! | BD22: =ROUNDUP(R22/$BD$13,0) -> #REF! | BE22: =ROUNDUP(U22/$BE$13,0) -> #REF! | BF22: =ROUNDUP(X22/$BF$13,0) -> #REF! | BG22: =ROUNDUP(AA22/$BG$13,0) -> #REF! | BH22: =ROUNDUP(AD22/$BH$13,0) -> #REF! | BI22: =BI20+1 -> 8
C23: 82111-47342 | D23: =VLOOKUP(C23,#REF!,2,0) -> #REF! | E23: =VLOOKUP(C23,#REF!,4,0) -> #REF! | F23: 351 | G23: 6 | H23: =H22 -> #REF! | I23: =I22 -> #REF! | J23: =(GUM!I14-(GUM!I14*0.2)) -> 0 | K23: =(GUM!J14-(GUM!J14*0.2)) -> 0 | L23: =(GUM!K14-(GUM!K14*0.2)) -> 0 | M23: =(GUM!L14-(GUM!L14*0.2)) -> 0 | N23: =(GUM!M14-(GUM!M14*0.2)) -> 0 | O23: =(GUM!N14-(GUM!N14*0.2)) -> 0 | P23: =(GUM!O14-(GUM!O14*0.2)) -> 0 | Q23: =(GUM!P14-(GUM!P14*0.2)) -> 0 | ... AE23: =(GUM!AD14-(GUM!AD14*0.2)) -> 0 | AF23: =AF22+1 -> 10 | AG23: =J23*$F23 -> 0 | AH23: =K23*$F23 -> 0 | AI23: =L23*$F23 -> 0 | AJ23: =M23*$F23 -> 0 | AK23: =K23*$F23 -> 0 | AL23: =O23*$F23 -> 0 | AM23: =P23*$F23 -> 0 | AN23: =N23*$F23 -> 0 | AO23: =R23*$F23 -> 0 | AP23: =S23*$F23 -> 0 | AQ23: =Q23*$F23 -> 0 | AR23: =U23*$F23 -> 0 | AS23: =V23*$F23 -> 0 | AT23: =T23*$F23 -> 0 | AU23: =X23*$F23 -> 0 | AV23: =Y23*$F23 -> 0 | AW23: =W23*$F23 -> 0 | AX23: =AA23*$F23 -> 0 | AY23: =AB23*$F23 -> 0 | AZ23: =Z23*$F23 -> 0 | BA23: =AD23*$F23 -> 0 | BB23: 82111-47460 | BC23: =ROUNDUP(O23/$BC$13,0) -> 0 | BD23: =ROUNDUP(R23/$BD$13,0) -> 0 | BE23: =ROUNDUP(U23/$BE$13,0) -> 0 | BF23: =ROUNDUP(X23/$BF$13,0) -> 0 | BG23: =ROUNDUP(AA23/$BG$13,0) -> 0 | BH23: =ROUNDUP(AD23/$BH$13,0) -> 0 | BI23: =BI21+1 -> 9
C24: 82111-47451 | D24: =VLOOKUP(C24,#REF!,2,0) -> #REF! | E24: =VLOOKUP(C24,#REF!,4,0) -> #REF! | F24: 301 | G24: 6 | H24: =VLOOKUP(C24,#REF!,3,0) -> #REF! | I24: =VLOOKUP(C24,#REF!,7,0) -> #REF! | J24: #REF! | K24: #REF! | L24: #REF! | M24: #REF! | N24: #REF! | O24: #REF! | P24: #REF! | Q24: #REF! | R24: #REF! | S24: #REF! | T24: #REF! | U24: #REF! | V24: #REF! | W24: #REF! | X24: #REF! | Y24: #REF! | Z24: #REF! | AA24: #REF! | AB24: #REF! | AC24: #REF! | AD24: #REF! | AE24: #REF! | AF24: =AF23+1 -> 11 | AG24: =J24*$F24 -> #REF! | AH24: =K24*$F24 -> #REF! | AI24: =L24*$F24 -> #REF! | AJ24: =M24*$F24 -> #REF! | AK24: =K24*$F24 -> #REF! | AL24: =O24*$F24 -> #REF! | AM24: =P24*$F24 -> #REF! | AN24: =N24*$F24 -> #REF! | AO24: =R24*$F24 -> #REF! | AP24: =S24*$F24 -> #REF! | AQ24: =Q24*$F24 -> #REF! | AR24: =U24*$F24 -> #REF! | AS24: =V24*$F24 -> #REF! | AT24: =T24*$F24 -> #REF! | AU24: =X24*$F24 -> #REF! | AV24: =Y24*$F24 -> #REF! | AW24: =W24*$F24 -> #REF! | AX24: =AA24*$F24 -> #REF! | AY24: =AB24*$F24 -> #REF! | AZ24: =Z24*$F24 -> #REF! | BA24: =AD24*$F24 -> #REF! | BB24: 82111-47460 | BC24: =ROUNDUP(O24/$BC$13,0) -> #REF! | BD24: =ROUNDUP(R24/$BD$13,0) -> #REF! | BE24: =ROUNDUP(U24/$BE$13,0) -> #REF! | BF24: =ROUNDUP(X24/$BF$13,0) -> #REF! | BG24: =ROUNDUP(AA24/$BG$13,0) -> #REF! | BH24: =ROUNDUP(AD24/$BH$13,0) -> #REF! | BI24: =BI22+1 -> 9
C25: 82111-47360 J | D25: 0 | E25: =VLOOKUP(C25,#REF!,4,0) -> #REF! | F25: 309 | G25: 6 | H25: =VLOOKUP(C25,#REF!,3,0) -> #REF! | I25: =VLOOKUP(C25,#REF!,7,0) -> #REF! | J25: #REF! | K25: #REF! | L25: #REF! | M25: #REF! | N25: #REF! | O25: #REF! | P25: #REF! | Q25: #REF! | R25: #REF! | S25: #REF! | T25: #REF! | U25: #REF! | V25: #REF! | W25: #REF! | X25: #REF! | Y25: #REF! | Z25: #REF! | AA25: #REF! | AB25: #REF! | AC25: #REF! | AD25: #REF! | AE25: #REF! | AF25: =AF24+1 -> 12 | AG25: =J25*$F25 -> #REF! | AH25: =K25*$F25 -> #REF! | AI25: =L25*$F25 -> #REF! | AJ25: =M25*$F25 -> #REF! | AK25: =K25*$F25 -> #REF! | AL25: =O25*$F25 -> #REF! | AM25: =P25*$F25 -> #REF! | AN25: =N25*$F25 -> #REF! | AO25: =R25*$F25 -> #REF! | AP25: =S25*$F25 -> #REF! | AQ25: =Q25*$F25 -> #REF! | AR25: =U25*$F25 -> #REF! | AS25: =V25*$F25 -> #REF! | AT25: =T25*$F25 -> #REF! | AU25: =X25*$F25 -> #REF! | AV25: =Y25*$F25 -> #REF! | AW25: =W25*$F25 -> #REF! | AX25: =AA25*$F25 -> #REF! | AY25: =AB25*$F25 -> #REF! | AZ25: =Z25*$F25 -> #REF! | BA25: =AD25*$F25 -> #REF! | BB25: 82111-47360 | BC25: =ROUNDUP(O25/$BC$13,0) -> #REF! | BD25: =ROUNDUP(R25/$BD$13,0) -> #REF! | BE25: =ROUNDUP(U25/$BE$13,0) -> #REF! | BF25: =ROUNDUP(X25/$BF$13,0) -> #REF! | BG25: =ROUNDUP(AA25/$BG$13,0) -> #REF! | BH25: =ROUNDUP(AD25/$BH$13,0) -> #REF! | BI25: =BI24+1 -> 10
C26: 82111-47452 | D26: =VLOOKUP(C26,#REF!,2,0) -> #REF! | E26: =VLOOKUP(C26,#REF!,4,0) -> #REF! | F26: 301 | G26: 6 | H26: =VLOOKUP(C26,#REF!,3,0) -> #REF! | I26: =VLOOKUP(C26,#REF!,7,0) -> #REF! | J26: =(GUM!I18-(GUM!I18*0.2)) -> 0 | K26: =(GUM!J18-(GUM!J18*0.2)) -> 0 | L26: =(GUM!K18-(GUM!K18*0.2)) -> 0 | M26: =(GUM!L18-(GUM!L18*0.2)) -> 0 | N26: =(GUM!M18-(GUM!M18*0.2)) -> 0 | O26: =(GUM!N18-(GUM!N18*0.2)) -> 0 | P26: =(GUM!O18-(GUM!O18*0.2)) -> 0 | Q26: =(GUM!P18-(GUM!P18*0.2)) -> 0 | ... AE26: =(GUM!AD18-(GUM!AD18*0.2)) -> 0 | AF26: =AF25+1 -> 13 | AG26: =J26*$F26 -> 0 | AH26: =K26*$F26 -> 0 | AI26: =L26*$F26 -> 0 | AJ26: =M26*$F26 -> 0 | AK26: =K26*$F26 -> 0 | AL26: =O26*$F26 -> 0 | AM26: =P26*$F26 -> 0 | AN26: =N26*$F26 -> 0 | AO26: =R26*$F26 -> 0 | AP26: =S26*$F26 -> 0 | AQ26: =Q26*$F26 -> 0 | AR26: =U26*$F26 -> 0 | AS26: =V26*$F26 -> 0 | AT26: =T26*$F26 -> 0 | AU26: =X26*$F26 -> 0 | AV26: =Y26*$F26 -> 0 | AW26: =W26*$F26 -> 0 | AX26: =AA26*$F26 -> 0 | AY26: =AB26*$F26 -> 0 | AZ26: =Z26*$F26 -> 0 | BA26: =AD26*$F26 -> 0 | BB26: 82111-47460 | BC26: =ROUNDUP(O26/$BC$13,0) -> 0 | BD26: =ROUNDUP(R26/$BD$13,0) -> 0 | BE26: =ROUNDUP(U26/$BE$13,0) -> 0 | BF26: =ROUNDUP(X26/$BF$13,0) -> 0 | BG26: =ROUNDUP(AA26/$BG$13,0) -> 0 | BH26: =ROUNDUP(AD26/$BH$13,0) -> 0 | BI26: =BI24+1 -> 10
A27: LHD | B27: USA | C27: 82111-47370 J | D27: =VLOOKUP(C27,#REF!,2,0) -> #REF! | E27: =VLOOKUP(C27,#REF!,4,0) -> #REF! | F27: 315 | G27: 6 | H27: =VLOOKUP(C27,#REF!,3,0) -> #REF! | I27: =VLOOKUP(C27,#REF!,7,0) -> #REF! | J27: =(GUM!I44-(GUM!I44*0.2)) -> 0 | K27: =(GUM!J44-(GUM!J44*0.2)) -> 0 | L27: =(GUM!K44-(GUM!K44*0.2)) -> 0 | M27: =(GUM!L44-(GUM!L44*0.2)) -> 0 | N27: =(GUM!M44-(GUM!M44*0.2)) -> 0 | O27: =(GUM!N44-(GUM!N44*0.2)) -> 0 | P27: =(GUM!O44-(GUM!O44*0.2)) -> 0 | Q27: =(GUM!P44-(GUM!P44*0.2)) -> 0 | ... AE27: =(GUM!AD44-(GUM!AD44*0.2)) -> 0 | AF27: =AF26+1 -> 14 | AG27: =J27*$F27 -> 0 | AH27: =K27*$F27 -> 0 | AI27: =L27*$F27 -> 0 | AJ27: =M27*$F27 -> 0 | AK27: =K27*$F27 -> 0 | AL27: =O27*$F27 -> 0 | AM27: =P27*$F27 -> 0 | AN27: =N27*$F27 -> 0 | AO27: =R27*$F27 -> 0 | AP27: =S27*$F27 -> 0 | AQ27: =Q27*$F27 -> 0 | AR27: =U27*$F27 -> 0 | AS27: =V27*$F27 -> 0 | AT27: =T27*$F27 -> 0 | AU27: =X27*$F27 -> 0 | AV27: =Y27*$F27 -> 0 | AW27: =W27*$F27 -> 0 | AX27: =AA27*$F27 -> 0 | AY27: =AB27*$F27 -> 0 | AZ27: =Z27*$F27 -> 0 | BA27: =AD27*$F27 -> 0 | BB27: 82111-47370 | BC27: =ROUNDUP(O27/$BC$13,0) -> 0 | BD27: =ROUNDUP(R27/$BD$13,0) -> 0 | BE27: =ROUNDUP(U27/$BE$13,0) -> 0 | BF27: =ROUNDUP(X27/$BF$13,0) -> 0 | BG27: =ROUNDUP(AA27/$BG$13,0) -> 0 | BH27: =ROUNDUP(AD27/$BH$13,0) -> 0 | BI27: =BI25+1 -> 11
C28: 82111-47380 H | D28: =VLOOKUP(C28,#REF!,2,0) -> #REF! | E28: =VLOOKUP(C28,#REF!,4,0) -> #REF! | F28: 347 | G28: 6 | H28: =VLOOKUP(C28,#REF!,3,0) -> #REF! | I28: =VLOOKUP(C28,#REF!,7,0) -> #REF! | J28: =(GUM!I49-(GUM!I49*0.2)) -> 0 | K28: =(GUM!J49-(GUM!J49*0.2)) -> 0 | L28: =(GUM!K49-(GUM!K49*0.2)) -> 0 | M28: =(GUM!L49-(GUM!L49*0.2)) -> 0 | N28: =(GUM!M49-(GUM!M49*0.2)) -> 0 | O28: =(GUM!N49-(GUM!N49*0.2)) -> 0 | P28: =(GUM!O49-(GUM!O49*0.2)) -> 0 | Q28: =(GUM!P49-(GUM!P49*0.2)) -> 0 | ... AE28: =(GUM!AD49-(GUM!AD49*0.2)) -> 0 | AF28: =AF27+1 -> 15 | AG28: =J28*$F28 -> 0 | AH28: =K28*$F28 -> 0 | AI28: =L28*$F28 -> 0 | AJ28: =M28*$F28 -> 0 | AK28: =K28*$F28 -> 0 | AL28: =O28*$F28 -> 0 | AM28: =P28*$F28 -> 0 | AN28: =N28*$F28 -> 0 | AO28: =R28*$F28 -> 0 | AP28: =S28*$F28 -> 0 | AQ28: =Q28*$F28 -> 0 | AR28: =U28*$F28 -> 0 | AS28: =V28*$F28 -> 0 | AT28: =T28*$F28 -> 0 | AU28: =X28*$F28 -> 0 | AV28: =Y28*$F28 -> 0 | AW28: =W28*$F28 -> 0 | AX28: =AA28*$F28 -> 0 | AY28: =AB28*$F28 -> 0 | AZ28: =Z28*$F28 -> 0 | BA28: =AD28*$F28 -> 0 | BB28: 82111-47380 | BC28: =ROUNDUP(O28/$BC$13,0) -> 0 | BD28: =ROUNDUP(R28/$BD$13,0) -> 0 | BE28: =ROUNDUP(U28/$BE$13,0) -> 0 | BF28: =ROUNDUP(X28/$BF$13,0) -> 0 | BG28: =ROUNDUP(AA28/$BG$13,0) -> 0 | BH28: =ROUNDUP(AD28/$BH$13,0) -> 0 | BI28: =BI27+1 -> 12
B29: CANADA | C29: 82111-47390 J | D29: =VLOOKUP(C29,#REF!,2,0) -> #REF! | E29: =VLOOKUP(C29,#REF!,4,0) -> #REF! | F29: 321 | G29: 6 | H29: =VLOOKUP(C29,#REF!,3,0) -> #REF! | I29: =VLOOKUP(C29,#REF!,7,0) -> #REF! | J29: #REF! | K29: #REF! | L29: #REF! | M29: #REF! | N29: #REF! | O29: #REF! | P29: #REF! | Q29: #REF! | R29: #REF! | S29: #REF! | T29: #REF! | U29: #REF! | V29: #REF! | W29: #REF! | X29: #REF! | Y29: #REF! | Z29: #REF! | AA29: #REF! | AB29: #REF! | AC29: #REF! | AD29: #REF! | AE29: #REF! | AF29: =AF28+1 -> 16 | AG29: =J29*$F29 -> #REF! | AH29: =K29*$F29 -> #REF! | AI29: =L29*$F29 -> #REF! | AJ29: =M29*$F29 -> #REF! | AK29: =K29*$F29 -> #REF! | AL29: =O29*$F29 -> #REF! | AM29: =P29*$F29 -> #REF! | AN29: =N29*$F29 -> #REF! | AO29: =R29*$F29 -> #REF! | AP29: =S29*$F29 -> #REF! | AQ29: =Q29*$F29 -> #REF! | AR29: =U29*$F29 -> #REF! | AS29: =V29*$F29 -> #REF! | AT29: =T29*$F29 -> #REF! | AU29: =X29*$F29 -> #REF! | AV29: =Y29*$F29 -> #REF! | AW29: =W29*$F29 -> #REF! | AX29: =AA29*$F29 -> #REF! | AY29: =AB29*$F29 -> #REF! | AZ29: =Z29*$F29 -> #REF! | BA29: =AD29*$F29 -> #REF! | BB29: 82111-47390 | BC29: =ROUNDUP(O29/$BC$13,0) -> #REF! | BD29: =ROUNDUP(R29/$BD$13,0) -> #REF! | BE29: =ROUNDUP(U29/$BE$13,0) -> #REF! | BF29: =ROUNDUP(X29/$BF$13,0) -> #REF! | BG29: =ROUNDUP(AA29/$BG$13,0) -> #REF! | BH29: =ROUNDUP(AD29/$BH$13,0) -> #REF! | BI29: =BI28+1 -> 13
C30: 82111-47400 J | D30: =VLOOKUP(C30,#REF!,2,0) -> #REF! | E30: =VLOOKUP(C30,#REF!,4,0) -> #REF! | F30: 347 | G30: 6 | H30: =VLOOKUP(C30,#REF!,3,0) -> #REF! | I30: =VLOOKUP(C30,#REF!,7,0) -> #REF! | J30: #REF! | K30: #REF! | L30: #REF! | M30: #REF! | N30: #REF! | O30: #REF! | P30: #REF! | Q30: #REF! | R30: #REF! | S30: #REF! | T30: #REF! | U30: #REF! | V30: #REF! | W30: #REF! | X30: #REF! | Y30: #REF! | Z30: #REF! | AA30: #REF! | AB30: #REF! | AC30: #REF! | AD30: #REF! | AE30: #REF! | AF30: =AF29+1 -> 17 | AG30: =J30*$F30 -> #REF! | AH30: =K30*$F30 -> #REF! | AI30: =L30*$F30 -> #REF! | AJ30: =M30*$F30 -> #REF! | AK30: =K30*$F30 -> #REF! | AL30: =O30*$F30 -> #REF! | AM30: =P30*$F30 -> #REF! | AN30: =N30*$F30 -> #REF! | AO30: =R30*$F30 -> #REF! | AP30: =S30*$F30 -> #REF! | AQ30: =Q30*$F30 -> #REF! | AR30: =U30*$F30 -> #REF! | AS30: =V30*$F30 -> #REF! | AT30: =T30*$F30 -> #REF! | AU30: =X30*$F30 -> #REF! | AV30: =Y30*$F30 -> #REF! | AW30: =W30*$F30 -> #REF! | AX30: =AA30*$F30 -> #REF! | AY30: =AB30*$F30 -> #REF! | AZ30: =Z30*$F30 -> #REF! | BA30: =AD30*$F30 -> #REF! | BB30: 82111-47400 | BC30: =ROUNDUP(O30/$BC$13,0) -> #REF! | BD30: =ROUNDUP(R30/$BD$13,0) -> #REF! | BE30: =ROUNDUP(U30/$BE$13,0) -> #REF! | BF30: =ROUNDUP(X30/$BF$13,0) -> #REF! | BG30: =ROUNDUP(AA30/$BG$13,0) -> #REF! | BH30: =ROUNDUP(AD30/$BH$13,0) -> #REF! | BI30: =BI29+1 -> 14
B31: EC | C31: 82111-47410 J | D31: 0 | E31: =VLOOKUP(C31,#REF!,4,0) -> #REF! | F31: 313 | G31: 6 | H31: =VLOOKUP(C31,#REF!,3,0) -> #REF! | I31: =VLOOKUP(C31,#REF!,7,0) -> #REF! | J31: #REF! | K31: #REF! | L31: #REF! | M31: #REF! | N31: #REF! | O31: #REF! | P31: #REF! | Q31: #REF! | R31: #REF! | S31: #REF! | T31: #REF! | U31: #REF! | V31: #REF! | W31: #REF! | X31: #REF! | Y31: #REF! | Z31: #REF! | AA31: #REF! | AB31: #REF! | AC31: #REF! | AD31: #REF! | AE31: #REF! | AF31: =AF30+1 -> 18 | AG31: =J31*$F31 -> #REF! | AH31: =K31*$F31 -> #REF! | AI31: =L31*$F31 -> #REF! | AJ31: =M31*$F31 -> #REF! | AK31: =K31*$F31 -> #REF! | AL31: =O31*$F31 -> #REF! | AM31: =P31*$F31 -> #REF! | AN31: =N31*$F31 -> #REF! | AO31: =R31*$F31 -> #REF! | AP31: =S31*$F31 -> #REF! | AQ31: =Q31*$F31 -> #REF! | AR31: =U31*$F31 -> #REF! | AS31: =V31*$F31 -> #REF! | AT31: =T31*$F31 -> #REF! | AU31: =X31*$F31 -> #REF! | AV31: =Y31*$F31 -> #REF! | AW31: =W31*$F31 -> #REF! | AX31: =AA31*$F31 -> #REF! | AY31: =AB31*$F31 -> #REF! | AZ31: =Z31*$F31 -> #REF! | BA31: =AD31*$F31 -> #REF! | BB31: 82111-47410 | BC31: =ROUNDUP(O31/$BC$13,0) -> #REF! | BD31: =ROUNDUP(R31/$BD$13,0) -> #REF! | BE31: =ROUNDUP(U31/$BE$13,0) -> #REF! | BF31: =ROUNDUP(X31/$BF$13,0) -> #REF! | BG31: =ROUNDUP(AA31/$BG$13,0) -> #REF! | BH31: =ROUNDUP(AD31/$BH$13,0) -> #REF! | BI31: =BI30+1 -> 15
C32: 82111-47420 J | D32: =VLOOKUP(C32,#REF!,2,0) -> #REF! | E32: =VLOOKUP(C32,#REF!,4,0) -> #REF! | F32: 337 | G32: 6 | H32: =VLOOKUP(C32,#REF!,3,0) -> #REF! | I32: =VLOOKUP(C32,#REF!,7,0) -> #REF! | J32: #REF! | K32: #REF! | L32: #REF! | M32: #REF! | N32: #REF! | O32: #REF! | P32: #REF! | Q32: #REF! | R32: #REF! | S32: #REF! | T32: #REF! | U32: #REF! | V32: #REF! | W32: #REF! | X32: #REF! | Y32: #REF! | Z32: #REF! | AA32: #REF! | AB32: #REF! | AC32: #REF! | AD32: #REF! | AE32: #REF! | AF32: =AF31+1 -> 19 | AG32: =J32*$F32 -> #REF! | AH32: =K32*$F32 -> #REF! | AI32: =L32*$F32 -> #REF! | AJ32: =M32*$F32 -> #REF! | AK32: =K32*$F32 -> #REF! | AL32: =O32*$F32 -> #REF! | AM32: =P32*$F32 -> #REF! | AN32: =N32*$F32 -> #REF! | AO32: =R32*$F32 -> #REF! | AP32: =S32*$F32 -> #REF! | AQ32: =Q32*$F32 -> #REF! | AR32: =U32*$F32 -> #REF! | AS32: =V32*$F32 -> #REF! | AT32: =T32*$F32 -> #REF! | AU32: =X32*$F32 -> #REF! | AV32: =Y32*$F32 -> #REF! | AW32: =W32*$F32 -> #REF! | AX32: =AA32*$F32 -> #REF! | AY32: =AB32*$F32 -> #REF! | AZ32: =Z32*$F32 -> #REF! | BA32: =AD32*$F32 -> #REF! | BB32: 82111-47420 | BC32: =ROUNDUP(O32/$BC$13,0) -> #REF! | BD32: =ROUNDUP(R32/$BD$13,0) -> #REF! | BE32: =ROUNDUP(U32/$BE$13,0) -> #REF! | BF32: =ROUNDUP(X32/$BF$13,0) -> #REF! | BG32: =ROUNDUP(AA32/$BG$13,0) -> #REF! | BH32: =ROUNDUP(AD32/$BH$13,0) -> #REF! | BI32: =BI31+1 -> 16
C33: 82111-47430 J | D33: =VLOOKUP(C33,#REF!,2,0) -> #REF! | E33: =VLOOKUP(C33,#REF!,4,0) -> #REF! | F33: 313 | G33: 6 | H33: =VLOOKUP(C33,#REF!,3,0) -> #REF! | I33: =VLOOKUP(C33,#REF!,7,0) -> #REF! | J33: #REF! | K33: #REF! | L33: #REF! | M33: #REF! | N33: #REF! | O33: #REF! | P33: #REF! | Q33: #REF! | R33: #REF! | S33: #REF! | T33: #REF! | U33: #REF! | V33: #REF! | W33: #REF! | X33: #REF! | Y33: #REF! | Z33: #REF! | AA33: #REF! | AB33: #REF! | AC33: #REF! | AD33: #REF! | AE33: #REF! | AF33: =AF32+1 -> 20 | AG33: =J33*$F33 -> #REF! | AH33: =K33*$F33 -> #REF! | AI33: =L33*$F33 -> #REF! | AJ33: =M33*$F33 -> #REF! | AK33: =K33*$F33 -> #REF! | AL33: =O33*$F33 -> #REF! | AM33: =P33*$F33 -> #REF! | AN33: =N33*$F33 -> #REF! | AO33: =R33*$F33 -> #REF! | AP33: =S33*$F33 -> #REF! | AQ33: =Q33*$F33 -> #REF! | AR33: =U33*$F33 -> #REF! | AS33: =V33*$F33 -> #REF! | AT33: =T33*$F33 -> #REF! | AU33: =X33*$F33 -> #REF! | AV33: =Y33*$F33 -> #REF! | AW33: =W33*$F33 -> #REF! | AX33: =AA33*$F33 -> #REF! | AY33: =AB33*$F33 -> #REF! | AZ33: =Z33*$F33 -> #REF! | BA33: =AD33*$F33 -> #REF! | BB33: 82111-47430 | BC33: =ROUNDUP(O33/$BC$13,0) -> #REF! | BD33: =ROUNDUP(R33/$BD$13,0) -> #REF! | BE33: =ROUNDUP(U33/$BE$13,0) -> #REF! | BF33: =ROUNDUP(X33/$BF$13,0) -> #REF! | BG33: =ROUNDUP(AA33/$BG$13,0) -> #REF! | BH33: =ROUNDUP(AD33/$BH$13,0) -> #REF! | BI33: =BI32+1 -> 17
C34: 82111-47440 J | D34: =VLOOKUP(C34,#REF!,2,0) -> #REF! | E34: =VLOOKUP(C34,#REF!,4,0) -> #REF! | F34: 337 | G34: 6 | H34: =VLOOKUP(C34,#REF!,3,0) -> #REF! | I34: =VLOOKUP(C34,#REF!,7,0) -> #REF! | J34: #REF! | K34: #REF! | L34: #REF! | M34: #REF! | N34: #REF! | O34: #REF! | P34: #REF! | Q34: #REF! | R34: #REF! | S34: #REF! | T34: #REF! | U34: #REF! | V34: #REF! | W34: #REF! | X34: #REF! | Y34: #REF! | Z34: #REF! | AA34: #REF! | AB34: #REF! | AC34: #REF! | AD34: #REF! | AE34: #REF! | AF34: =AF33+1 -> 21 | AG34: =J34*$F34 -> #REF! | AH34: =K34*$F34 -> #REF! | AI34: =L34*$F34 -> #REF! | AJ34: =M34*$F34 -> #REF! | AK34: =K34*$F34 -> #REF! | AL34: =O34*$F34 -> #REF! | AM34: =P34*$F34 -> #REF! | AN34: =N34*$F34 -> #REF! | AO34: =R34*$F34 -> #REF! | AP34: =S34*$F34 -> #REF! | AQ34: =Q34*$F34 -> #REF! | AR34: =U34*$F34 -> #REF! | AS34: =V34*$F34 -> #REF! | AT34: =T34*$F34 -> #REF! | AU34: =X34*$F34 -> #REF! | AV34: =Y34*$F34 -> #REF! | AW34: =W34*$F34 -> #REF! | AX34: =AA34*$F34 -> #REF! | AY34: =AB34*$F34 -> #REF! | AZ34: =Z34*$F34 -> #REF! | BA34: =AD34*$F34 -> #REF! | BB34: 82111-47440 | BC34: =ROUNDUP(O34/$BC$13,0) -> #REF! | BD34: =ROUNDUP(R34/$BD$13,0) -> #REF! | BE34: =ROUNDUP(U34/$BE$13,0) -> #REF! | BF34: =ROUNDUP(X34/$BF$13,0) -> #REF! | BG34: =ROUNDUP(AA34/$BG$13,0) -> #REF! | BH34: =ROUNDUP(AD34/$BH$13,0) -> #REF! | BI34: =BI33+1 -> 18
B35: USA | C35: 82111-47371 | D35: =VLOOKUP(C35,#REF!,2,0) -> #REF! | E35: =VLOOKUP(C35,#REF!,4,0) -> #REF! | F35: 321 | G35: 6 | H35: =VLOOKUP(C35,#REF!,3,0) -> #REF! | I35: =VLOOKUP(C35,#REF!,7,0) -> #REF! | J35: #REF! | K35: #REF! | L35: #REF! | M35: #REF! | N35: #REF! | O35: #REF! | P35: #REF! | Q35: #REF! | R35: #REF! | S35: #REF! | T35: #REF! | U35: #REF! | V35: #REF! | W35: #REF! | X35: #REF! | Y35: #REF! | Z35: #REF! | AA35: #REF! | AB35: #REF! | AC35: #REF! | AD35: #REF! | AE35: #REF! | AF35: =AF34+1 -> 22 | AG35: =J35*$F35 -> #REF! | AH35: =K35*$F35 -> #REF! | AI35: =L35*$F35 -> #REF! | AJ35: =M35*$F35 -> #REF! | AK35: =K35*$F35 -> #REF! | AL35: =O35*$F35 -> #REF! | AM35: =P35*$F35 -> #REF! | AN35: =N35*$F35 -> #REF! | AO35: =R35*$F35 -> #REF! | AP35: =S35*$F35 -> #REF! | AQ35: =Q35*$F35 -> #REF! | AR35: =U35*$F35 -> #REF! | AS35: =V35*$F35 -> #REF! | AT35: =T35*$F35 -> #REF! | AU35: =X35*$F35 -> #REF! | AV35: =Y35*$F35 -> #REF! | AW35: =W35*$F35 -> #REF! | AX35: =AA35*$F35 -> #REF! | AY35: =AB35*$F35 -> #REF! | AZ35: =Z35*$F35 -> #REF! | BA35: =AD35*$F35 -> #REF! | BB35: 82111-47390 | BC35: =ROUNDUP(O35/$BC$13,0) -> #REF! | BD35: =ROUNDUP(R35/$BD$13,0) -> #REF! | BE35: =ROUNDUP(U35/$BE$13,0) -> #REF! | BF35: =ROUNDUP(X35/$BF$13,0) -> #REF! | BG35: =ROUNDUP(AA35/$BG$13,0) -> #REF! | BH35: =ROUNDUP(AD35/$BH$13,0) -> #REF! | BI35: =BI34+1 -> 19
C36: 82111-47372 | D36: =VLOOKUP(C36,#REF!,2,0) -> #REF! | E36: =VLOOKUP(C36,#REF!,4,0) -> #REF! | F36: 321 | G36: 6 | H36: =VLOOKUP(C36,#REF!,3,0) -> #REF! | I36: =VLOOKUP(C36,#REF!,7,0) -> #REF! | J36: #REF! | K36: #REF! | L36: #REF! | M36: #REF! | N36: #REF! | O36: #REF! | P36: #REF! | Q36: #REF! | R36: #REF! | S36: #REF! | T36: #REF! | U36: #REF! | V36: #REF! | W36: #REF! | X36: #REF! | Y36: #REF! | Z36: #REF! | AA36: #REF! | AB36: #REF! | AC36: #REF! | AD36: #REF! | AE36: #REF! | AF36: =AF35+1 -> 23 | AG36: =J36*$F36 -> #REF! | AH36: =K36*$F36 -> #REF! | AI36: =L36*$F36 -> #REF! | AJ36: =M36*$F36 -> #REF! | AK36: =K36*$F36 -> #REF! | AL36: =O36*$F36 -> #REF! | AM36: =P36*$F36 -> #REF! | AN36: =N36*$F36 -> #REF! | AO36: =R36*$F36 -> #REF! | AP36: =S36*$F36 -> #REF! | AQ36: =Q36*$F36 -> #REF! | AR36: =U36*$F36 -> #REF! | AS36: =V36*$F36 -> #REF! | AT36: =T36*$F36 -> #REF! | AU36: =X36*$F36 -> #REF! | AV36: =Y36*$F36 -> #REF! | AW36: =W36*$F36 -> #REF! | AX36: =AA36*$F36 -> #REF! | AY36: =AB36*$F36 -> #REF! | AZ36: =Z36*$F36 -> #REF! | BA36: =AD36*$F36 -> #REF! | BB36: 82111-47390 | BC36: =ROUNDUP(O36/$BC$13,0) -> #REF! | BD36: =ROUNDUP(R36/$BD$13,0) -> #REF! | BE36: =ROUNDUP(U36/$BE$13,0) -> #REF! | BF36: =ROUNDUP(X36/$BF$13,0) -> #REF! | BG36: =ROUNDUP(AA36/$BG$13,0) -> #REF! | BH36: =ROUNDUP(AD36/$BH$13,0) -> #REF! | BI36: =BI35+1 -> 20
B37: CANADA | C37: 82111-47391 | D37: =VLOOKUP(C37,#REF!,2,0) -> #REF! | E37: =VLOOKUP(C37,#REF!,4,0) -> #REF! | F37: 347 | G37: 6 | H37: =VLOOKUP(C37,#REF!,3,0) -> #REF! | I37: =VLOOKUP(C37,#REF!,7,0) -> #REF! | J37: #REF! | K37: #REF! | L37: #REF! | M37: #REF! | N37: #REF! | O37: #REF! | P37: #REF! | Q37: #REF! | R37: #REF! | S37: #REF! | T37: #REF! | U37: #REF! | V37: #REF! | W37: #REF! | X37: #REF! | Y37: #REF! | Z37: #REF! | AA37: #REF! | AB37: #REF! | AC37: #REF! | AD37: #REF! | AE37: #REF! | AF37: =AF36+1 -> 24 | AG37: =J37*$F37 -> #REF! | AH37: =K37*$F37 -> #REF! | AI37: =L37*$F37 -> #REF! | AJ37: =M37*$F37 -> #REF! | AK37: =K37*$F37 -> #REF! | AL37: =O37*$F37 -> #REF! | AM37: =P37*$F37 -> #REF! | AN37: =N37*$F37 -> #REF! | AO37: =R37*$F37 -> #REF! | AP37: =S37*$F37 -> #REF! | AQ37: =Q37*$F37 -> #REF! | AR37: =U37*$F37 -> #REF! | AS37: =V37*$F37 -> #REF! | AT37: =T37*$F37 -> #REF! | AU37: =X37*$F37 -> #REF! | AV37: =Y37*$F37 -> #REF! | AW37: =W37*$F37 -> #REF! | AX37: =AA37*$F37 -> #REF! | AY37: =AB37*$F37 -> #REF! | AZ37: =Z37*$F37 -> #REF! | BA37: =AD37*$F37 -> #REF! | BB37: 82111-47400 | BC37: =ROUNDUP(O37/$BC$13,0) -> #REF! | BD37: =ROUNDUP(R37/$BD$13,0) -> #REF! | BE37: =ROUNDUP(U37/$BE$13,0) -> #REF! | BF37: =ROUNDUP(X37/$BF$13,0) -> #REF! | BG37: =ROUNDUP(AA37/$BG$13,0) -> #REF! | BH37: =ROUNDUP(AD37/$BH$13,0) -> #REF! | BI37: =BI35+1 -> 20
C38: 82111-47392 | D38: =VLOOKUP(C38,#REF!,2,0) -> #REF! | E38: =VLOOKUP(C38,#REF!,4,0) -> #REF! | F38: 347 | G38: 6 | H38: =VLOOKUP(C38,#REF!,3,0) -> #REF! | I38: =VLOOKUP(C38,#REF!,7,0) -> #REF! | J38: #REF! | K38: #REF! | L38: #REF! | M38: #REF! | N38: #REF! | O38: #REF! | P38: #REF! | Q38: #REF! | R38: #REF! | S38: #REF! | T38: #REF! | U38: #REF! | V38: #REF! | W38: #REF! | X38: #REF! | Y38: #REF! | Z38: #REF! | AA38: #REF! | AB38: #REF! | AC38: #REF! | AD38: #REF! | AE38: #REF! | AF38: =AF37+1 -> 25 | AG38: =J38*$F38 -> #REF! | AH38: =K38*$F38 -> #REF! | AI38: =L38*$F38 -> #REF! | AJ38: =M38*$F38 -> #REF! | AK38: =K38*$F38 -> #REF! | AL38: =O38*$F38 -> #REF! | AM38: =P38*$F38 -> #REF! | AN38: =N38*$F38 -> #REF! | AO38: =R38*$F38 -> #REF! | AP38: =S38*$F38 -> #REF! | AQ38: =Q38*$F38 -> #REF! | AR38: =U38*$F38 -> #REF! | AS38: =V38*$F38 -> #REF! | AT38: =T38*$F38 -> #REF! | AU38: =X38*$F38 -> #REF! | AV38: =Y38*$F38 -> #REF! | AW38: =W38*$F38 -> #REF! | AX38: =AA38*$F38 -> #REF! | AY38: =AB38*$F38 -> #REF! | AZ38: =Z38*$F38 -> #REF! | BA38: =AD38*$F38 -> #REF! | BB38: 82111-47400 | BC38: =ROUNDUP(O38/$BC$13,0) -> #REF! | BD38: =ROUNDUP(R38/$BD$13,0) -> #REF! | BE38: =ROUNDUP(U38/$BE$13,0) -> #REF! | BF38: =ROUNDUP(X38/$BF$13,0) -> #REF! | BG38: =ROUNDUP(AA38/$BG$13,0) -> #REF! | BH38: =ROUNDUP(AD38/$BH$13,0) -> #REF! | BI38: =BI36+1 -> 21
C39: 82111-47401 | D39: =VLOOKUP(C39,#REF!,2,0) -> #REF! | E39: =VLOOKUP(C39,#REF!,4,0) -> #REF! | F39: 313 | G39: 6 | H39: =VLOOKUP(C39,#REF!,3,0) -> #REF! | I39: =VLOOKUP(C39,#REF!,7,0) -> #REF! | J39: #REF! | K39: #REF! | L39: #REF! | M39: #REF! | N39: #REF! | O39: #REF! | P39: #REF! | Q39: #REF! | R39: #REF! | S39: #REF! | T39: #REF! | U39: #REF! | V39: #REF! | W39: #REF! | X39: #REF! | Y39: #REF! | Z39: #REF! | AA39: #REF! | AB39: #REF! | AC39: #REF! | AD39: #REF! | AE39: #REF! | AF39: =AF38+1 -> 26 | AG39: =J39*$F39 -> #REF! | AH39: =K39*$F39 -> #REF! | AI39: =L39*$F39 -> #REF! | AJ39: =M39*$F39 -> #REF! | AK39: =K39*$F39 -> #REF! | AL39: =O39*$F39 -> #REF! | AM39: =P39*$F39 -> #REF! | AN39: =N39*$F39 -> #REF! | AO39: =R39*$F39 -> #REF! | AP39: =S39*$F39 -> #REF! | AQ39: =Q39*$F39 -> #REF! | AR39: =U39*$F39 -> #REF! | AS39: =V39*$F39 -> #REF! | AT39: =T39*$F39 -> #REF! | AU39: =X39*$F39 -> #REF! | AV39: =Y39*$F39 -> #REF! | AW39: =W39*$F39 -> #REF! | AX39: =AA39*$F39 -> #REF! | AY39: =AB39*$F39 -> #REF! | AZ39: =Z39*$F39 -> #REF! | BA39: =AD39*$F39 -> #REF! | BB39: 82111-47410 | BC39: =ROUNDUP(O39/$BC$13,0) -> #REF! | BD39: =ROUNDUP(R39/$BD$13,0) -> #REF! | BE39: =ROUNDUP(U39/$BE$13,0) -> #REF! | BF39: =ROUNDUP(X39/$BF$13,0) -> #REF! | BG39: =ROUNDUP(AA39/$BG$13,0) -> #REF! | BH39: =ROUNDUP(AD39/$BH$13,0) -> #REF! | BI39: =BI37+1 -> 21
C40: 82111-47402 | D40: =VLOOKUP(C40,#REF!,2,0) -> #REF! | E40: =VLOOKUP(C40,#REF!,4,0) -> #REF! | F40: 313 | G40: 6 | H40: =H39 -> #REF! | I40: =I39 -> #REF! | J40: #REF! | K40: #REF! | L40: #REF! | M40: #REF! | N40: #REF! | O40: #REF! | P40: #REF! | Q40: #REF! | R40: #REF! | S40: #REF! | T40: #REF! | U40: #REF! | V40: #REF! | W40: #REF! | X40: #REF! | Y40: #REF! | Z40: #REF! | AA40: #REF! | AB40: #REF! | AC40: #REF! | AD40: #REF! | AE40: #REF! | AF40: =AF39+1 -> 27 | AG40: =J40*$F40 -> #REF! | AH40: =K40*$F40 -> #REF! | AI40: =L40*$F40 -> #REF! | AJ40: =M40*$F40 -> #REF! | AK40: =K40*$F40 -> #REF! | AL40: =O40*$F40 -> #REF! | AM40: =P40*$F40 -> #REF! | AN40: =N40*$F40 -> #REF! | AO40: =R40*$F40 -> #REF! | AP40: =S40*$F40 -> #REF! | AQ40: =Q40*$F40 -> #REF! | AR40: =U40*$F40 -> #REF! | AS40: =V40*$F40 -> #REF! | AT40: =T40*$F40 -> #REF! | AU40: =X40*$F40 -> #REF! | AV40: =Y40*$F40 -> #REF! | AW40: =W40*$F40 -> #REF! | AX40: =AA40*$F40 -> #REF! | AY40: =AB40*$F40 -> #REF! | AZ40: =Z40*$F40 -> #REF! | BA40: =AD40*$F40 -> #REF! | BB40: 82111-47410 | BC40: =ROUNDUP(O40/$BC$13,0) -> #REF! | BD40: =ROUNDUP(R40/$BD$13,0) -> #REF! | BE40: =ROUNDUP(U40/$BE$13,0) -> #REF! | BF40: =ROUNDUP(X40/$BF$13,0) -> #REF! | BG40: =ROUNDUP(AA40/$BG$13,0) -> #REF! | BH40: =ROUNDUP(AD40/$BH$13,0) -> #REF! | BI40: =BI38+1 -> 22
B41: EC | C41: 82111-47411 | D41: =VLOOKUP(C41,#REF!,2,0) -> #REF! | E41: =VLOOKUP(C41,#REF!,4,0) -> #REF! | F41: 337 | G41: 6 | H41: =VLOOKUP(C41,#REF!,3,0) -> #REF! | I41: =VLOOKUP(C41,#REF!,7,0) -> #REF! | J41: #REF! | K41: #REF! | L41: #REF! | M41: #REF! | N41: #REF! | O41: #REF! | P41: #REF! | Q41: #REF! | R41: #REF! | S41: #REF! | T41: #REF! | U41: #REF! | V41: #REF! | W41: #REF! | X41: #REF! | Y41: #REF! | Z41: #REF! | AA41: #REF! | AB41: #REF! | AC41: #REF! | AD41: #REF! | AE41: #REF! | AF41: =AF40+1 -> 28 | AG41: =J41*$F41 -> #REF! | AH41: =K41*$F41 -> #REF! | AI41: =L41*$F41 -> #REF! | AJ41: =M41*$F41 -> #REF! | AK41: =K41*$F41 -> #REF! | AL41: =O41*$F41 -> #REF! | AM41: =P41*$F41 -> #REF! | AN41: =N41*$F41 -> #REF! | AO41: =R41*$F41 -> #REF! | AP41: =S41*$F41 -> #REF! | AQ41: =Q41*$F41 -> #REF! | AR41: =U41*$F41 -> #REF! | AS41: =V41*$F41 -> #REF! | AT41: =T41*$F41 -> #REF! | AU41: =X41*$F41 -> #REF! | AV41: =Y41*$F41 -> #REF! | AW41: =W41*$F41 -> #REF! | AX41: =AA41*$F41 -> #REF! | AY41: =AB41*$F41 -> #REF! | AZ41: =Z41*$F41 -> #REF! | BA41: =AD41*$F41 -> #REF! | BB41: 82111-47420 | BC41: =ROUNDUP(O41/$BC$13,0) -> #REF! | BD41: =ROUNDUP(R41/$BD$13,0) -> #REF! | BE41: =ROUNDUP(U41/$BE$13,0) -> #REF! | BF41: =ROUNDUP(X41/$BF$13,0) -> #REF! | BG41: =ROUNDUP(AA41/$BG$13,0) -> #REF! | BH41: =ROUNDUP(AD41/$BH$13,0) -> #REF! | BI41: =BI39+1 -> 22
...

Sheet (AS-400 Jembatan)
D3: 4 | M3: =VLOOKUP(M$5,WEEK!A2:D13,4,0) -> 5 | V3: =VLOOKUP(V$5,WEEK!A2:D13,4,0) -> 4 | AE3: =VLOOKUP(AE$5,WEEK!A2:D13,4,0) -> 4 | AN3: =VLOOKUP(AN$5,WEEK!$A$2:$D$13,4,0) -> 5 | AW3: =VLOOKUP(AW$5,WEEK!$A$2:$D$13,4,0) -> 4
A4: Printed : | B4: =NOW() -> 46195.105 | D4: T | M4: W | V4: Z | AE4: AC | AN4: AC | AW4: AC
A5: TYPE | B5: HARNESS No. | C5: LEVEL | D5: =+GUM!L11 -> MAR | M5: =+GUM!O11 -> APR | V5: =+GUM!R11 -> MAY | AE5: =+GUM!U11 -> JUN | AN5: =+GUM!X11 -> JUL | AW5: =+GUM!AA11 -> AUG
D7: 1 | E7: 2 | F7: 3 | G7: 4 | H7: 5 | I7: SR | J7: SPP | K7: BAL | L7: VALUE | M7: 1 | N7: 2 | O7: 3 | P7: 4 | Q7: 5 | R7: SR | S7: SPP | T7: BAL | U7: VALUE | V7: 1 | W7: 2 | X7: 3 | Y7: 4 | Z7: 5 | AA7: SR | AB7: SPP | AC7: BAL | AD7: VALUE | AE7: 1 | AF7: 2 | AG7: 3 | AH7: 4 | AI7: 5 | AJ7: SR | AK7: SPP | AL7: BAL | AM7: VALUE | AN7: 1 | AO7: 2 | AP7: 3 | AQ7: 4 | AR7: 5 | AS7: SR | AT7: SPP | AU7: BAL | AV7: VALUE | AW7: 1 | AX7: 2 | AY7: 3 | AZ7: 4 | BA7: 5 | BB7: SR | BC7: SPP | BD7: BAL | BE7: VALUE
A8: =GUM!A14 -> LHD HEV | B8: =+GUM!C14 -> 82115-0E470 | C8: =GUM!D14 -> H 0001 | D8: 0 | E8: 0 | F8: 0 | G8: 0 | H8: 0 | I8: =SUM(D8:H8) -> 0 | J8: 0 | K8: 0 | R8: =SUM(M8:M8) -> 0 | S8: =+VLOOKUP($B8,GUM!C14:AD46,15,0) -> 0 | T8: =ROUNDUP((S8-R8)/$M$3,0) -> 0 | AA8: =SUM(V8:V8) -> 0 | AB8: =+VLOOKUP($B8,GUM!C14:AC46,18,0) -> 0 | AC8: =ROUNDUP((AB8-AA8)/$V$3,0) -> 0 | AJ8: =SUM(AE8:AE8) -> 0 | AK8: =+VLOOKUP($B8,GUM!C14:AD46,21,0) -> 0 | AL8: =ROUNDUP((AK8-AJ8)/$AE$3,) -> #VALUE! | AS8: =SUM(AN8:AN8) -> 0 | AT8: =+VLOOKUP($B8,GUM!C14:AD46,24,0) -> 0 | AU8: =ROUNDUP((AT8-AS8)/$AE$3,) -> #VALUE! | AW8: =+AN8 | AX8: =+AO8 | AY8: =+AP8 | AZ8: =+AQ8 | BA8: =+AR8 | BB8: =SUM(AW8:AW8) -> 0 | BC8: =+VLOOKUP($B8,GUM!C14:AD46,27,0) -> 0 | BD8: =ROUNDUP((BC8-BB8)/$AE$3,) -> #VALUE!
B9: =+GUM!C15 -> 82115-0E480 G | C9: =GUM!D15 -> G 0101 | D9: =+VLOOKUP($B9,#REF!,3,0) -> #REF! | E9: =+VLOOKUP($B9,#REF!,4,0) -> #REF! | F9: =+VLOOKUP($B9,#REF!,5,0) -> #REF! | G9: =+VLOOKUP($B9,#REF!,6,0) -> #REF! | I9: =SUM(D9:H9) -> #REF! | J9: =+VLOOKUP($B9,GUM!C14:AD69,12,0) -> 0 | K9: =ROUNDUP((J9-I9)/$D$3,0) -> #REF! | R9: =SUM(M9:M9) -> 0 | S9: =+VLOOKUP($B9,GUM!C15:AD47,15,0) -> 0 | T9: =ROUNDUP((S9-R9)/$M$3,0) -> 0 | AA9: =SUM(V9:V9) -> 0 | AB9: =+VLOOKUP($B9,GUM!C15:AC47,18,0) -> 0 | AC9: =ROUNDUP((AB9-AA9)/$V$3,0) -> 0 | AJ9: =SUM(AE9:AE9) -> 0 | AK9: =+VLOOKUP($B9,GUM!C15:AD47,21,0) -> 0 | AL9: =ROUNDUP((AK9-AJ9)/$AE$3,) -> #VALUE! | AS9: =SUM(AN9:AN9) -> 0 | AT9: =+VLOOKUP($B9,GUM!C15:AD47,24,0) -> 0 | AU9: =ROUNDUP((AT9-AS9)/$AE$3,) -> #VALUE! | BB9: =SUM(AW9:AW9) -> 0 | BC9: =+VLOOKUP($B9,GUM!C15:AD47,27,0) -> 0 | BD9: =ROUNDUP((BC9-BB9)/$AE$3,) -> #VALUE!
B10: =+GUM!C16 -> 82115-0E490 H | C10: =GUM!D16 -> H 0001 | D10: =+VLOOKUP($B10,#REF!,3,0) -> #REF! | E10: =+VLOOKUP($B10,#REF!,4,0) -> #REF! | F10: =+VLOOKUP($B10,#REF!,5,0) -> #REF! | G10: =+VLOOKUP($B10,#REF!,6,0) -> #REF! | I10: =SUM(D10:H10) -> #REF! | J10: =+VLOOKUP($B10,GUM!C15:AD98,12,0) -> 0 | K10: =ROUNDUP((J10-I10)/$D$3,0) -> #REF! | M10: 0 | N10: 0 | O10: 0 | P10: 0 | R10: =SUM(M10:M10) -> 0 | S10: =+VLOOKUP($B10,GUM!C16:AD48,15,0) -> 0 | T10: =ROUNDUP((S10-R10)/$M$3,0) -> 0 | V10: 0 | W10: 0 | X10: 0 | Y10: 0 | AA10: =SUM(V10:V10) -> 0 | AB10: =+VLOOKUP($B10,GUM!C16:AC48,18,0) -> 0 | AC10: =ROUNDUP((AB10-AA10)/$V$3,0) -> 0 | AE10: 0 | AF10: 0 | AG10: 0 | AH10: 0 | AJ10: =SUM(AE10:AE10) -> 0 | AK10: =+VLOOKUP($B10,GUM!C16:AD48,21,0) -> 0 | AL10: =ROUNDUP((AK10-AJ10)/$AE$3,) -> #VALUE! | AN10: 0 | AO10: 0 | AP10: 0 | AQ10: 0 | AS10: =SUM(AN10:AN10) -> 0 | AT10: =+VLOOKUP($B10,GUM!C16:AD48,24,0) -> 0 | AU10: =ROUNDUP((AT10-AS10)/$AE$3,) -> #VALUE! | AW10: 0 | AX10: 0 | AY10: 0 | AZ10: 0 | BB10: =SUM(AW10:AW10) -> 0 | BC10: =+VLOOKUP($B10,GUM!C16:AD48,27,0) -> 0 | BD10: =ROUNDUP((BC10-BB10)/$AE$3,) -> #VALUE!
B11: =+GUM!C17 -> 82115-0EA10 H | C11: =GUM!D17 -> H 0001 | D11: =+VLOOKUP($B11,#REF!,3,0) -> #REF! | E11: =+VLOOKUP($B11,#REF!,4,0) -> #REF! | F11: =+VLOOKUP($B11,#REF!,5,0) -> #REF! | G11: =+VLOOKUP($B11,#REF!,6,0) -> #REF! | I11: =SUM(D11:H11) -> #REF! | J11: =+VLOOKUP($B11,GUM!C16:AD99,12,0) -> 0 | K11: =ROUNDUP((J11-I11)/$D$3,0) -> #REF! | M11: 0 | N11: 0 | O11: 0 | P11: 0 | R11: =SUM(M11:M11) -> 0 | S11: =+VLOOKUP($B11,GUM!C17:AD49,15,0) -> 0 | T11: =ROUNDUP((S11-R11)/$M$3,0) -> 0 | V11: 0 | W11: 0 | X11: 0 | Y11: 0 | AA11: =SUM(V11:V11) -> 0 | AB11: =+VLOOKUP($B11,GUM!C17:AC49,18,0) -> 0 | AC11: =ROUNDUP((AB11-AA11)/$V$3,0) -> 0 | AE11: 0 | AF11: 0 | AG11: 0 | AH11: 0 | AJ11: =SUM(AE11:AE11) -> 0 | AK11: =+VLOOKUP($B11,GUM!C17:AD49,21,0) -> 0 | AL11: =ROUNDUP((AK11-AJ11)/$AE$3,) -> #VALUE! | AN11: 0 | AO11: 0 | AP11: 0 | AQ11: 0 | AS11: =SUM(AN11:AN11) -> 0 | AT11: =+VLOOKUP($B11,GUM!C17:AD49,24,0) -> 0 | AU11: =ROUNDUP((AT11-AS11)/$AE$3,) -> #VALUE! | AW11: 0 | AX11: 0 | AY11: 0 | AZ11: 0 | BB11: =SUM(AW11:AW11) -> 0 | BC11: =+VLOOKUP($B11,GUM!C17:AD49,27,0) -> 0 | BD11: =ROUNDUP((BC11-BB11)/$AE$3,) -> #VALUE!
B12: =+GUM!C18 -> 82115-0E480 | C12: =GUM!D18 -> J 0101 | D12: =+VLOOKUP($B12,#REF!,3,0) -> #REF! | E12: =+VLOOKUP($B12,#REF!,4,0) -> #REF! | F12: =+VLOOKUP($B12,#REF!,5,0) -> #REF! | G12: =+VLOOKUP($B12,#REF!,6,0) -> #REF! | I12: =SUM(D12:H12) -> #REF! | J12: =+VLOOKUP($B12,GUM!C15:AD98,12,0) -> 0 | K12: =ROUNDUP((J12-I12)/$D$3,0) -> #REF! | M12: 0 | N12: 0 | O12: 0 | P12: 0 | R12: =SUM(M12:M12) -> 0 | S12: =+VLOOKUP($B12,GUM!C18:AD50,15,0) -> 0 | T12: =ROUNDUP((S12-R12)/$M$3,0) -> 0 | V12: 0 | W12: 0 | X12: 0 | Y12: 0 | AA12: =SUM(V12:V12) -> 0 | AB12: =+VLOOKUP($B12,GUM!C18:AC50,18,0) -> 0 | AC12: =ROUNDUP((AB12-AA12)/$V$3,0) -> 0 | AE12: 0 | AF12: 0 | AG12: 0 | AH12: 0 | AJ12: =SUM(AE12:AE12) -> 0 | AK12: =+VLOOKUP($B12,GUM!C18:AD50,21,0) -> 0 | AL12: =ROUNDUP((AK12-AJ12)/$AE$3,) -> #VALUE! | AN12: 0 | AO12: 0 | AP12: 0 | AQ12: 0 | AS12: =SUM(AN12:AN12) -> 0 | AT12: =+VLOOKUP($B12,GUM!C18:AD50,24,0) -> 0 | AU12: =ROUNDUP((AT12-AS12)/$AE$3,) -> #VALUE! | AW12: 0 | AX12: 0 | AY12: 0 | AZ12: 0 | BB12: =SUM(AW12:AW12) -> 0 | BC12: =+VLOOKUP($B12,GUM!C18:AD50,27,0) -> 0 | BD12: =ROUNDUP((BC12-BB12)/$AE$3,) -> #VALUE!
B13: =+GUM!C19 -> 82115-0E490 K | C13: =GUM!D19 -> K 0001 | M13: =VLOOKUP($B13,#REF!,12,0) -> #REF! | N13: =VLOOKUP($B13,#REF!,13,0) -> #REF! | O13: =VLOOKUP($B13,#REF!,14,0) -> #REF! | P13: =VLOOKUP($B13,#REF!,15,0) -> #REF! | Q13: =VLOOKUP($B13,#REF!,16,0) -> #REF! | R13: =SUM(M13:M13) -> #REF! | S13: =+VLOOKUP($B13,GUM!C19:AD51,15,0) -> #REF! | T13: =ROUNDUP((S13-R13)/$M$3,0) -> #REF! | V13: =VLOOKUP($B13,#REF!,17,0) -> #REF! | W13: =VLOOKUP($B13,#REF!,18,0) -> #REF! | X13: =VLOOKUP($B13,#REF!,19,0) -> #REF! | Y13: =VLOOKUP($B13,#REF!,20,0) -> #REF! | AA13: =SUM(V13:V13) -> #REF! | AB13: =+VLOOKUP($B13,GUM!C19:AC51,18,0) -> #REF! | AC13: =ROUNDUP((AB13-AA13)/$V$3,0) -> #REF! | AE13: =VLOOKUP($B13,#REF!,21,0) -> #REF! | AF13: =VLOOKUP($B13,#REF!,22,0) -> #REF! | AG13: =VLOOKUP($B13,#REF!,23,0) -> #REF! | AH13: =VLOOKUP($B13,#REF!,24,0) -> #REF! | AJ13: =SUM(AE13:AE13) -> #REF! | AK13: =+VLOOKUP($B13,GUM!C19:AD51,21,0) -> #REF! | AL13: =ROUNDUP((AK13-AJ13)/$AE$3,) -> #REF! | AN13: =VLOOKUP($B13,#REF!,25,0) -> #REF! | AO13: =VLOOKUP($B13,#REF!,26,0) -> #REF! | AP13: =VLOOKUP($B13,#REF!,27,0) -> #REF! | AQ13: =VLOOKUP($B13,#REF!,28,0) -> #REF! | AR13: =VLOOKUP($B13,#REF!,29,0) -> #REF! | AS13: =SUM(AN13:AN13) -> #REF! | AT13: =+VLOOKUP($B13,GUM!C19:AD51,24,0) -> #REF! | AU13: =ROUNDUP((AT13-AS13)/$AE$3,) -> #REF! | AW13: =VLOOKUP($B13,#REF!,30,0) -> #REF! | AX13: =VLOOKUP($B13,#REF!,31,0) -> #REF! | AY13: =VLOOKUP($B13,#REF!,32,0) -> #REF! | AZ13: =VLOOKUP($B13,#REF!,33,0) -> #REF! | BB13: =SUM(AW13:AW13) -> #REF! | BC13: =+VLOOKUP($B13,GUM!C19:AD51,27,0) -> #REF! | BD13: =ROUNDUP((BC13-BB13)/$AE$3,) -> #REF!
