Workbook
Name ProdLines: [1]Chart!$A$66:$A$66

Sheet NOTES
B2: JAI Meeting Notes from 01/05
B24: Release Notes from 01/05
B40: JAI Meeting Notes from 01/08
B53: Release Notes from 01/10
B64: Release Notes from 01/15
B74: Release Notes from 01/22
B90: Release Notes from 01/29
B99: Release Notes from 02/05
B109: Release Notes from 02/12
B117: Release Notes from 02/19
B124: Release Notes from 02/26
B133: Release Notes from 03/04
... B195: 5.) Ask for updated capacity check to be filled out

Sheet Final SR
A1: 1 | F1: Yazaki North America, Inc. | P1: Boxes | Q1: =Q437/4 -> 1256 | R1: =R437/4 -> 0 | S1: =S437/4 -> 800 | T1: =T437/4 -> 800 | U1: =U437/4 -> 799 | V1: =V437/4 -> 640 | W1: =W437/4 -> 606 | X1: =X437/4 -> 441 | ... BI1: =BI437/4 -> 1002
A2: 2 | F2: Supplier Shipping Release | P2: 40FT | Q2: =Q1/160 -> 7.85 | R2: =R1/160 -> 0 | S2: =S1/160 -> 5 | T2: =T1/160 -> 5 | U2: =U1/160 -> 4.99375 | V2: =V1/160 -> 4 | W2: =W1/160 -> 3.7875 | X2: =X1/160 -> 2.75625 | ... BI2: =BI1/160 -> 6.2625
A3: 3 | Q3: SHIP | R3: FAB | Z3: RAW
A4: 4 | F4: Ordering Plant | G4: 1090 | H4: Ordering Plant Name | I4: Memphis | L4: Product Group | N4: NONE | P4: 46083 | Q4: 46090 | R4: 46097 | S4: 46104 | T4: 46111 | U4: 46118 | V4: 46125 | W4: 46132 | X4: 46139 | Y4: 46146 | Z4: 46153 | AA4: 46160 | AB4: 46167 | AC4: 46174 | AD4: 46181 | AE4: 46188 | AF4: 46195 | AG4: 46202 | AH4: 46209 | AI4: 46216 | AJ4: 46223 | AK4: 46230 | AL4: 46237 | AM4: 46244 | AN4: 46251 | AO4: 46258 | AP4: 46265 | AQ4: 46272 | AR4: 46279 | AS4: 46286 | AT4: 46293 | AU4: 46300 | AV4: 46307 | AW4: 46314 | AX4: 46321 | AY4: 46328 | AZ4: 46335 | BA4: 46342 | BB4: 46349 | BC4: 46356 | BD4: 46363 | BE4: 46370 | BF4: 46377 | BG4: 46384 | BH4: 46391 | BI4: 46398
A5: 5 | F5: Vendor | G5: 6000224 | H5: Vendor Name | I5: PT JATIM AUTOCOMP INDONESIA | L5: Date Created | N5: 46086
A7: =+A6+1 -> 1 | B7: =IF(F7=$F$7,G8,B6) -> F0013546309 | C7: =IF(F7=$F$7,G9,C6) -> 82115-0EA10 J | D7: =VLOOKUP(B7,'Timing Table'!B:J,9,0) -> C/O | E7: =VLOOKUP(B7,'Timing Table'!B:H,7,0) -> 495D-HV | F7: PSA# | G7: 5501017964 | H7: Release# | I7: 93 | J7: BEAMS ID | K7: 1177750 | M7: Release Date | O7: 46086 | P7: Std. Pack | Q7: 4
A8: =+A7+1 -> 2 | B8: =IF(F8=$F$7,G9,B7) -> F0013546309 | C8: =IF(F8=$F$7,G10,C7) -> 82115-0EA10 J | D8: =VLOOKUP(B8,'Timing Table'!B:J,9,0) -> C/O | E8: =VLOOKUP(B8,'Timing Table'!B:H,7,0) -> 495D-HV | F8: YNA Part# | G8: F0013546309 | H8: YNA Part Description | I8: 82115-0EA10_J1 491D HV-2025 82115 | M8: Model Year | N8: 2025 | O8: Eng. Revision | Q8: J1
A9: =+A8+1 -> 3 | B9: =IF(F9=$F$7,G10,B8) -> F0013546309 | C9: =IF(F9=$F$7,G11,C8) -> 82115-0EA10 J | D9: =VLOOKUP(B9,'Timing Table'!B:J,9,0) -> C/O | E9: =VLOOKUP(B9,'Timing Table'!B:H,7,0) -> 495D-HV | F9: Customer Part# | G9: 82115-0EA10 J | H9: PIA Part# | Q9: SHIP | R9: FAB | Z9: RAW
A10: =+A9+1 -> 4 | B10: =IF(F10=$F$7,G11,B9) -> F0013546309 | C10: =IF(F10=$F$7,G12,C9) -> 82115-0EA10 J | D10: =VLOOKUP(B10,'Timing Table'!B:J,9,0) -> C/O | E10: =VLOOKUP(B10,'Timing Table'!B:H,7,0) -> 495D-HV | F10: High Fab | G10: 21448 | H10: B | I10: ETD Date | J10: 46041 | K10: 46048 | L10: 46055 | M10: 46062 | N10: 46069 | O10: 46076 | P10: 46083 | Q10: 46090 | R10: 46097 | S10: 46104 | T10: 46111 | U10: 46118 | V10: 46125 | W10: 46132 | X10: 46139 | Y10: 46146 | Z10: 46153 | AA10: 46160 | AB10: 46167 | AC10: 46174 | AD10: 46181 | AE10: 46188 | AF10: 46195 | AG10: 46202 | AH10: 46209 | AI10: 46216 | AJ10: 46223 | AK10: 46230 | AL10: 46237 | AM10: 46244 | AN10: 46251 | AO10: 46258 | AP10: 46265 | AQ10: 46272 | AR10: 46279 | AS10: 46286 | AT10: 46293 | AU10: 46300 | AV10: 46307 | AW10: 46314 | AX10: 46321 | AY10: 46328 | AZ10: 46335 | BA10: 46342 | BB10: 46349 | BC10: 46356 | BD10: 46363 | BE10: 46370 | BF10: 46377 | BG10: 46384 | BH10: 46391 | BI10: 46398
A11: =+A10+1 -> 5 | B11: =IF(F11=$F$7,G12,B10) -> F0013546309 | C11: =IF(F11=$F$7,G13,C10) -> 82115-0EA10 J | D11: =VLOOKUP(B11,'Timing Table'!B:J,9,0) -> C/O | E11: =VLOOKUP(B11,'Timing Table'!B:H,7,0) -> 495D-HV | F11: High Raw | G11: 22720 | I11: ETA Date | J11: 46083 | K11: 46090 | L11: 46097 | M11: 46104 | N11: 46111 | O11: 46118 | P11: 46125 | Q11: 46132 | R11: 46139 | S11: 46146 | T11: 46153 | U11: 46160 | V11: 46167 | W11: 46174 | X11: 46181 | Y11: 46188 | Z11: 46195 | AA11: 46202 | AB11: 46209 | AC11: 46216 | AD11: 46223 | AE11: 46230 | AF11: 46237 | AG11: 46244 | AH11: 46251 | AI11: 46258 | AJ11: 46265 | AK11: 46272 | AL11: 46279 | AM11: 46286 | AN11: 46293 | AO11: 46300 | AP11: 46307 | AQ11: 46314 | AR11: 46321 | AS11: 46328 | AT11: 46335 | AU11: 46342 | AV11: 46349 | AW11: 46356 | AX11: 46363 | AY11: 46370 | AZ11: 46377 | BA11: 46384 | BB11: 46391 | BC11: 46398 | BD11: 46399 | BE11: 46406 | BF11: 46413 | BG11: 46420 | BH11: 46427 | BI11: =+BH11+7 -> 46434
A12: =+A11+1 -> 6 | B12: =IF(F12=$F$7,G13,B11) -> F0013546309 | C12: =IF(F12=$F$7,G14,C11) -> 82115-0EA10 J | D12: =VLOOKUP(B12,'Timing Table'!B:J,9,0) -> C/O | E12: =VLOOKUP(B12,'Timing Table'!B:H,7,0) -> 495D-HV | F12: Car line | G12: GRAND HIGHLANDER HYBRID 200D | H12: 82115-0EA10 | I12: Net | J12: 1444 | K12: 0 | L12: 0 | M12: 0 | N12: 0 | O12: 0 | P12: 0 | Q12: 0 | R12: 0 | S12: 0 | T12: 0 | U12: 0 | V12: 0 | W12: 0 | X12: 0 | Y12: 0 | Z12: 0 | AA12: 0 | AB12: 0 | AC12: 0 | AD12: 0 | AE12: 0 | AF12: 0 | AG12: 0 | AH12: 0 | AI12: 0 | AJ12: 0 | AK12: 0 | AL12: 0 | AM12: 0 | AN12: 0 | AO12: 0 | AP12: 0 | AQ12: 0 | AR12: 0 | AS12: 0 | AT12: 0 | AU12: 0 | AV12: 0 | AW12: 0 | AX12: 0 | AY12: 0 | AZ12: 0 | BA12: 0 | BB12: 0 | BC12: 0 | BD12: 0 | BE12: 0 | BF12: 0 | BG12: 0 | BH12: 0 | BI12: 0
A13: =+A12+1 -> 7 | B13: =IF(F13=$F$7,G14,B12) -> F0013546309 | C13: =IF(F13=$F$7,G15,C12) -> 82115-0EA10 J | D13: =VLOOKUP(B13,'Timing Table'!B:J,9,0) -> C/O | E13: =VLOOKUP(B13,'Timing Table'!B:H,7,0) -> 495D-HV | F13: Family | G13: 82115 | H13: 82115-0EA10 | I13: Cum | J13: 21448 | K13: 21448 | L13: 21448 | M13: 21448 | N13: 21448 | O13: 21448 | P13: 21448 | Q13: 21448 | R13: 21448 | S13: 21448 | T13: 21448 | U13: 21448 | V13: 21448 | W13: 21448 | X13: 21448 | Y13: 21448 | Z13: 21448 | AA13: 21448 | AB13: 21448 | AC13: 21448 | AD13: 21448 | AE13: 21448 | AF13: 21448 | AG13: 21448 | AH13: 21448 | AI13: 21448 | AJ13: 21448 | AK13: 21448 | AL13: 21448 | AM13: 21448 | AN13: 21448 | AO13: 21448 | AP13: 21448 | AQ13: 21448 | AR13: 21448 | AS13: 21448 | AT13: 21448 | AU13: 21448 | AV13: 21448 | AW13: 21448 | AX13: 21448 | AY13: 21448 | AZ13: 21448 | BA13: 21448 | BB13: 21448 | BC13: 21448 | BD13: 21448 | BE13: 21448 | BF13: 21448 | BG13: 21448 | BH13: 21448 | BI13: 21448
A14: =+A13+1 -> 8 | B14: =IF(F14=$F$7,G15,B13) -> F0013546309 | C14: =IF(F14=$F$7,G16,C13) -> 82115-0EA10 J | D14: =VLOOKUP(B14,'Timing Table'!B:J,9,0) -> C/O | E14: =VLOOKUP(B14,'Timing Table'!B:H,7,0) -> 495D-HV | F14: Cum Received | G14: 20004 | H14: Last Goods Receipt Invoice | J14: JAOJ60001B
A15: =+A14+1 -> 9 | B15: =IF(F15=$F$7,G16,B14) -> F0013546309 | C15: =IF(F15=$F$7,G17,C14) -> 82115-0EA10 J | D15: =VLOOKUP(B15,'Timing Table'!B:J,9,0) -> C/O | E15: =VLOOKUP(B15,'Timing Table'!B:H,7,0) -> 495D-HV | F15: Comments
A16: =+A15+1 -> 10 | B16: =IF(F16=$F$7,G17,B15) -> F0013546309 | C16: =IF(F16=$F$7,G18,C15) -> 82115-0EA10 J | D16: =VLOOKUP(B16,'Timing Table'!B:J,9,0) -> C/O | E16: =VLOOKUP(B16,'Timing Table'!B:H,7,0) -> 495D-HV
A17: =+A16+1 -> 11 | B17: =IF(F17=$F$7,G18,B16) -> F0013546310 | C17: =IF(F17=$F$7,G19,C16) -> 82115-0EA10 K | D17: =VLOOKUP(B17,'Timing Table'!B:J,9,0) -> C/O | E17: =VLOOKUP(B17,'Timing Table'!B:H,7,0) -> 495D-HV | F17: PSA# | G17: 5501060671 | H17: Release# | I17: 18 | J17: BEAMS ID | K17: 1179886 | M17: Release Date | O17: 46086 | P17: Std. Pack | Q17: 4
A18: =+A17+1 -> 12 | B18: =IF(F18=$F$7,G19,B17) -> F0013546310 | C18: =IF(F18=$F$7,G20,C17) -> 82115-0EA10 K | D18: =VLOOKUP(B18,'Timing Table'!B:J,9,0) -> C/O | E18: =VLOOKUP(B18,'Timing Table'!B:H,7,0) -> 495D-HV | F18: YNA Part# | G18: F0013546310 | H18: YNA Part Description | I18: 82115-0EA10_K0 491D-2025 82115 | M18: Model Year | N18: 2023 | O18: Eng. Revision | Q18: K0
A19: =+A18+1 -> 13 | B19: =IF(F19=$F$7,G20,B18) -> F0013546310 | C19: =IF(F19=$F$7,G21,C18) -> 82115-0EA10 K | D19: =VLOOKUP(B19,'Timing Table'!B:J,9,0) -> C/O | E19: =VLOOKUP(B19,'Timing Table'!B:H,7,0) -> 495D-HV | F19: Customer Part# | G19: 82115-0EA10 K | H19: PIA Part# | Q19: SHIP | R19: FAB | Z19: RAW
A20: =+A19+1 -> 14 | B20: =IF(F20=$F$7,G21,B19) -> F0013546310 | C20: =IF(F20=$F$7,G22,C19) -> 82115-0EA10 K | D20: =VLOOKUP(B20,'Timing Table'!B:J,9,0) -> C/O | E20: =VLOOKUP(B20,'Timing Table'!B:H,7,0) -> 495D-HV | F20: High Fab | G20: 5536 | H20: B | I20: ETD Date | J20: 46041 | K20: 46048 | L20: 46055 | M20: 46062 | N20: 46069 | O20: 46076 | P20: 46083 | Q20: 46090 | R20: 46097 | S20: 46104 | T20: 46111 | U20: 46118 | V20: 46125 | W20: 46132 | X20: 46139 | Y20: 46146 | Z20: 46153 | AA20: 46160 | AB20: 46167 | AC20: 46174 | AD20: 46181 | AE20: 46188 | AF20: 46195 | AG20: 46202 | AH20: 46209 | AI20: 46216 | AJ20: 46223 | AK20: 46230 | AL20: 46237 | AM20: 46244 | AN20: 46251 | AO20: 46258 | AP20: 46265 | AQ20: 46272 | AR20: 46279 | AS20: 46286 | AT20: 46293 | AU20: 46300 | AV20: 46307 | AW20: 46314 | AX20: 46321 | AY20: 46328 | AZ20: 46335 | BA20: 46342 | BB20: 46349 | BC20: 46356 | BD20: 46363 | BE20: 46370 | BF20: 46377 | BG20: 46384 | BH20: 46391 | BI20: 46398
A21: =+A20+1 -> 15 | B21: =IF(F21=$F$7,G22,B20) -> F0013546310 | C21: =IF(F21=$F$7,G23,C20) -> 82115-0EA10 K | D21: =VLOOKUP(B21,'Timing Table'!B:J,9,0) -> C/O | E21: =VLOOKUP(B21,'Timing Table'!B:H,7,0) -> 495D-HV | F21: High Raw | G21: 8080 | I21: ETA Date
A22: =+A21+1 -> 16 | B22: =IF(F22=$F$7,G23,B21) -> F0013546310 | C22: =IF(F22=$F$7,G24,C21) -> 82115-0EA10 K | D22: =VLOOKUP(B22,'Timing Table'!B:J,9,0) -> C/O | E22: =VLOOKUP(B22,'Timing Table'!B:H,7,0) -> 495D-HV | F22: Car line | G22: GRAND HIGHLANDER HYBRID 200D | H22: 82115-0EA10 | I22: Net | J22: 456 | K22: 680 | L22: 320 | M22: 592 | N22: 1172 | O22: 640 | P22: 400 | Q22: 780 | R22: 0 | S22: 496 | T22: 228 | U22: 512 | V22: 284 | W22: 480 | X22: 304 | Y22: 304 | Z22: 432 | AA22: 564 | AB22: 564 | AC22: 568 | AD22: 476 | AE22: 480 | AF22: 392 | AG22: 544 | AH22: 324 | AI22: 556 | AJ22: 528 | AK22: 532 | AL22: 732 | AM22: 736 | AN22: 736 | AO22: 736 | AP22: 736 | AQ22: 736 | AR22: 736 | AS22: 736 | AT22: 736 | AU22: 736 | AV22: 736 | AW22: 736 | AX22: 736 | AY22: 736 | AZ22: 736 | BA22: 736 | BB22: 736 | BC22: 736 | BD22: 736 | BE22: 736 | BF22: 736 | BG22: 736 | BH22: 736 | BI22: 736
A23: =+A22+1 -> 17 | B23: =IF(F23=$F$7,G24,B22) -> F0013546310 | C23: =IF(F23=$F$7,G25,C22) -> 82115-0EA10 K | D23: =VLOOKUP(B23,'Timing Table'!B:J,9,0) -> C/O | E23: =VLOOKUP(B23,'Timing Table'!B:H,7,0) -> 495D-HV | F23: Family | G23: 82115 | H23: 82115-0EA10 | I23: Cum | J23: 456 | K23: 1136 | L23: 1456 | M23: 2048 | N23: 3220 | O23: 3860 | P23: 4260 | Q23: 5040 | R23: 5040 | S23: 5536 | T23: 5764 | U23: 6276 | V23: 6560 | W23: 7040 | X23: 7344 | Y23: 7648 | Z23: 8080 | AA23: 8644 | AB23: 9208 | AC23: 9776 | AD23: 10252 | AE23: 10732 | AF23: 11124 | AG23: 11668 | AH23: 11992 | AI23: 12548 | AJ23: 13076 | AK23: 13608 | AL23: 14340 | AM23: 15076 | AN23: 15812 | AO23: 16548 | AP23: 17284 | AQ23: 18020 | AR23: 18756 | AS23: 19492 | AT23: 20228 | AU23: 20964 | AV23: 21700 | AW23: 22436 | AX23: 23172 | AY23: 23908 | AZ23: 24644 | BA23: 25380 | BB23: 26116 | BC23: 26852 | BD23: 27588 | BE23: 28324 | BF23: 29060 | BG23: 29796 | BH23: 30532 | BI23: 31268
A24: =+A23+1 -> 18 | B24: =IF(F24=$F$7,G25,B23) -> F0013546310 | C24: =IF(F24=$F$7,G26,C23) -> 82115-0EA10 K | D24: =VLOOKUP(B24,'Timing Table'!B:J,9,0) -> C/O | E24: =VLOOKUP(B24,'Timing Table'!B:H,7,0) -> 495D-HV | F24: Cum Received | G24: 0 | H24: Last Goods Receipt Invoice | Q24: 0.95
A25: =+A24+1 -> 19 | B25: =IF(F25=$F$7,G26,B24) -> F0013546310 | C25: =IF(F25=$F$7,G27,C24) -> 82115-0EA10 K | D25: =VLOOKUP(B25,'Timing Table'!B:J,9,0) -> C/O | E25: =VLOOKUP(B25,'Timing Table'!B:H,7,0) -> 495D-HV | F25: Comments | Q25: SNPs: 95
A26: =+A25+1 -> 20 | B26: =IF(F26=$F$7,G27,B25) -> F0013546310 | C26: =IF(F26=$F$7,G28,C25) -> 82115-0EA10 K | D26: =VLOOKUP(B26,'Timing Table'!B:J,9,0) -> C/O | E26: =VLOOKUP(B26,'Timing Table'!B:H,7,0) -> 495D-HV
A27: =+A26+1 -> 21 | B27: =IF(F27=$F$7,G28,B26) -> F0013546510 | C27: =IF(F27=$F$7,G29,C26) -> 82115-0E480 K | D27: =VLOOKUP(B27,'Timing Table'!B:J,9,0) -> C/O | E27: =VLOOKUP(B27,'Timing Table'!B:H,7,0) -> 495D-HV | F27: PSA# | G27: 5501044286 | H27: Release# | I27: 51 | J27: BEAMS ID | K27: 1179884 | M27: Release Date | O27: 46086 | P27: Std. Pack | Q27: 4
A28: =+A27+1 -> 22 | B28: =IF(F28=$F$7,G29,B27) -> F0013546510 | C28: =IF(F28=$F$7,G30,C27) -> 82115-0E480 K | D28: =VLOOKUP(B28,'Timing Table'!B:J,9,0) -> C/O | E28: =VLOOKUP(B28,'Timing Table'!B:H,7,0) -> 495D-HV | F28: YNA Part# | G28: F0013546510 | H28: YNA Part Description | I28: 82115-0E480_K0 491D-2025 82115 | M28: Model Year | N28: 2023 | O28: Eng. Revision | Q28: K0
A29: =+A28+1 -> 23 | B29: =IF(F29=$F$7,G30,B28) -> F0013546510 | C29: =IF(F29=$F$7,G31,C28) -> 82115-0E480 K | D29: =VLOOKUP(B29,'Timing Table'!B:J,9,0) -> C/O | E29: =VLOOKUP(B29,'Timing Table'!B:H,7,0) -> 495D-HV | F29: Customer Part# | G29: 82115-0E480 K | H29: PIA Part# | Q29: SHIP | R29: FAB | Z29: RAW
A30: =+A29+1 -> 24 | B30: =IF(F30=$F$7,G31,B29) -> F0013546510 | C30: =IF(F30=$F$7,G32,C29) -> 82115-0E480 K | D30: =VLOOKUP(B30,'Timing Table'!B:J,9,0) -> C/O | E30: =VLOOKUP(B30,'Timing Table'!B:H,7,0) -> 495D-HV | F30: High Fab | G30: 7576 | I30: ETD Date | J30: 46041 | K30: 46048 | L30: 46055 | M30: 46062 | N30: 46069 | O30: 46076 | P30: 46083 | Q30: 46090 | R30: 46097 | S30: 46104 | T30: 46111 | U30: 46118 | V30: 46125 | W30: 46132 | X30: 46139 | Y30: 46146 | Z30: 46153 | AA30: 46160 | AB30: 46167 | AC30: 46174 | AD30: 46181 | AE30: 46188 | AF30: 46195 | AG30: 46202 | AH30: 46209 | AI30: 46216 | AJ30: 46223 | AK30: 46230 | AL30: 46237 | AM30: 46244 | AN30: 46251 | AO30: 46258 | AP30: 46265 | AQ30: 46272 | AR30: 46279 | AS30: 46286 | AT30: 46293 | AU30: 46300 | AV30: 46307 | AW30: 46314 | AX30: 46321 | AY30: 46328 | AZ30: 46335 | BA30: 46342 | BB30: 46349 | BC30: 46356 | BD30: 46363 | BE30: 46370 | BF30: 46377 | BG30: 46384 | BH30: 46391 | BI30: 46398
A31: =+A30+1 -> 25 | B31: =IF(F31=$F$7,G32,B30) -> F0013546510 | C31: =IF(F31=$F$7,G33,C30) -> 82115-0E480 K | D31: =VLOOKUP(B31,'Timing Table'!B:J,9,0) -> C/O | E31: =VLOOKUP(B31,'Timing Table'!B:H,7,0) -> 495D-HV | F31: High Raw | G31: 9836 | I31: ETA Date
A32: =+A31+1 -> 26 | B32: =IF(F32=$F$7,G33,B31) -> F0013546510 | C32: =IF(F32=$F$7,G34,C31) -> 82115-0E480 K | D32: =VLOOKUP(B32,'Timing Table'!B:J,9,0) -> C/O | E32: =VLOOKUP(B32,'Timing Table'!B:H,7,0) -> 495D-HV | F32: Car line | G32: GRAND HIGHLANDER HYBRID 491D | H32: 82115-0E480 | I32: Net | J32: 788 | K32: 348 | L32: 348 | M32: 348 | N32: 348 | O32: 348 | P32: 520 | Q32: 524 | R32: 0 | S32: 596 | T32: 248 | U32: 248 | V32: 248 | W32: 248 | X32: 248 | Y32: 248 | Z32: 248 | AA32: 248 | AB32: 248 | AC32: 248 | AD32: 248 | AE32: 248 | AF32: 248 | AG32: 248 | AH32: 248 | AI32: 248 | AJ32: 248 | AK32: 248 | AL32: 248 | AM32: 248 | AN32: 248 | AO32: 248 | AP32: 248 | AQ32: 248 | AR32: 248 | AS32: 248 | AT32: 248 | AU32: 248 | AV32: 248 | AW32: 248 | AX32: 248 | AY32: 248 | AZ32: 248 | BA32: 248 | BB32: 248 | BC32: 248 | BD32: 248 | BE32: 248 | BF32: 248 | BG32: 248 | BH32: 248 | BI32: 248
A33: =+A32+1 -> 27 | B33: =IF(F33=$F$7,G34,B32) -> F0013546510 | C33: =IF(F33=$F$7,G35,C32) -> 82115-0E480 K | D33: =VLOOKUP(B33,'Timing Table'!B:J,9,0) -> C/O | E33: =VLOOKUP(B33,'Timing Table'!B:H,7,0) -> 495D-HV | F33: Family | G33: 82115 | H33: 82115-0E480 | I33: Cum | J33: 4444 | K33: 4792 | L33: 5140 | M33: 5488 | N33: 5836 | O33: 6184 | P33: 6704 | Q33: 7228 | R33: 7228 | S33: 7824 | T33: 8072 | U33: 8320 | V33: 8568 | W33: 8816 | X33: 9064 | Y33: 9312 | Z33: 9560 | AA33: 9808 | AB33: 10056 | AC33: 10304 | AD33: 10552 | AE33: 10800 | AF33: 11048 | AG33: 11296 | AH33: 11544 | AI33: 11792 | AJ33: 12040 | AK33: 12288 | AL33: 12536 | AM33: 12784 | AN33: 13032 | AO33: 13280 | AP33: 13528 | AQ33: 13776 | AR33: 14024 | AS33: 14272 | AT33: 14520 | AU33: 14768 | AV33: 15016 | AW33: 15264 | AX33: 15512 | AY33: 15760 | AZ33: 16008 | BA33: 16256 | BB33: 16504 | BC33: 16752 | BD33: 17000 | BE33: 17248 | BF33: 17496 | BG33: 17744 | BH33: 17992 | BI33: 18240
A34: =+A33+1 -> 28 | B34: =IF(F34=$F$7,G35,B33) -> F0013546510 | C34: =IF(F34=$F$7,G36,C33) -> 82115-0E480 K | D34: =VLOOKUP(B34,'Timing Table'!B:J,9,0) -> C/O | E34: =VLOOKUP(B34,'Timing Table'!B:H,7,0) -> 495D-HV | F34: Cum Received | G34: 3656 | H34: Last Goods Receipt Invoice | J34: JAOJ50240B | Q34: 0.0076923077
A35: =+A34+1 -> 29 | B35: =IF(F35=$F$7,G36,B34) -> F0013546510 | C35: =IF(F35=$F$7,#REF!,C34) -> 82115-0E480 K | D35: =VLOOKUP(B35,'Timing Table'!B:J,9,0) -> C/O | E35: =VLOOKUP(B35,'Timing Table'!B:H,7,0) -> 495D-HV | F35: Comments | Q35: SNPs: 1
A36: =+A35+1 -> 30 | B36: =IF(F36=$F$7,#REF!,B35) -> F0013546510 | C36: =IF(F36=$F$7,#REF!,C35) -> 82115-0E480 K | D36: =VLOOKUP(B36,'Timing Table'!B:J,9,0) -> C/O | E36: =VLOOKUP(B36,'Timing Table'!B:H,7,0) -> 495D-HV
A37: =+A36+1 -> 31 | B37: =IF(F37=$F$7,G38,#REF!) -> F0013547309 | C37: =IF(F37=$F$7,G39,#REF!) -> 82115-0E490 J | D37: =VLOOKUP(B37,'Timing Table'!B:J,9,0) -> C/O | E37: =VLOOKUP(B37,'Timing Table'!B:H,7,0) -> 495D-HV | F37: PSA# | G37: 5501017963 | H37: Release# | I37: 91 | J37: BEAMS ID | K37: 1177749 | M37: Release Date | O37: 46086 | P37: Std. Pack | Q37: 4
A38: =+A37+1 -> 32 | B38: =IF(F38=$F$7,G39,B37) -> F0013547309 | C38: =IF(F38=$F$7,G40,C37) -> 82115-0E490 J | D38: =VLOOKUP(B38,'Timing Table'!B:J,9,0) -> C/O | E38: =VLOOKUP(B38,'Timing Table'!B:H,7,0) -> 495D-HV | F38: YNA Part# | G38: F0013547309 | H38: YNA Part Description | I38: 82115-0E490_J1 491D HV-2025 82115 | M38: Model Year | N38: 2023 | O38: Eng. Revision | Q38: J1
A39: =+A38+1 -> 33 | B39: =IF(F39=$F$7,G40,B38) -> F0013547309 | C39: =IF(F39=$F$7,G41,C38) -> 82115-0E490 J | D39: =VLOOKUP(B39,'Timing Table'!B:J,9,0) -> C/O | E39: =VLOOKUP(B39,'Timing Table'!B:H,7,0) -> 495D-HV | F39: Customer Part# | G39: 82115-0E490 J | H39: PIA Part# | Q39: SHIP | R39: FAB | Z39: RAW
A40: =+A39+1 -> 34 | B40: =IF(F40=$F$7,G41,B39) -> F0013547309 | C40: =IF(F40=$F$7,G42,C39) -> 82115-0E490 J | D40: =VLOOKUP(B40,'Timing Table'!B:J,9,0) -> C/O | E40: =VLOOKUP(B40,'Timing Table'!B:H,7,0) -> 495D-HV | F40: High Fab | G40: 4940 | H40: C | I40: ETD Date | J40: 46041 | K40: 46048 | L40: 46055 | M40: 46062 | N40: 46069 | O40: 46076 | P40: 46083 | Q40: 46090 | R40: 46097 | S40: 46104 | T40: 46111 | U40: 46118 | V40: 46125 | W40: 46132 | X40: 46139 | Y40: 46146 | Z40: 46153 | AA40: 46160 | AB40: 46167 | AC40: 46174 | AD40: 46181 | AE40: 46188 | AF40: 46195 | AG40: 46202 | AH40: 46209 | AI40: 46216 | AJ40: 46223 | AK40: 46230 | AL40: 46237 | AM40: 46244 | AN40: 46251 | AO40: 46258 | AP40: 46265 | AQ40: 46272 | AR40: 46279 | AS40: 46286 | AT40: 46293 | AU40: 46300 | AV40: 46307 | AW40: 46314 | AX40: 46321 | AY40: 46328 | AZ40: 46335 | BA40: 46342 | BB40: 46349 | BC40: 46356 | BD40: 46363 | BE40: 46370 | BF40: 46377 | BG40: 46384 | BH40: 46391 | BI40: 46398
A41: =+A40+1 -> 35 | B41: =IF(F41=$F$7,G42,B40) -> F0013547309 | C41: =IF(F41=$F$7,G43,C40) -> 82115-0E490 J | D41: =VLOOKUP(B41,'Timing Table'!B:J,9,0) -> C/O | E41: =VLOOKUP(B41,'Timing Table'!B:H,7,0) -> 495D-HV | F41: High Raw | G41: 5128 | I41: ETA Date
...

Sheet JAI TOTALs
C2: ETD Date | E2: ='Final SR'!$J$10 -> 46041 | F2: =E2+7 -> 46048 | G2: =F2+7 -> 46055 | H2: =G2+7 -> 46062 | I2: =H2+7 -> 46069 | J2: =I2+7 -> 46076 | K2: =J2+7 -> 46083 | L2: =K2+7 -> 46090 | M2: =L2+7 -> 46097 | ... BD2: =BC2+7 -> 46398
E3: ='Final SR'!$J$11 -> 46083 | F3: =E3+7 -> 46090 | G3: =F3+7 -> 46097 | H3: =G3+7 -> 46104 | I3: =H3+7 -> 46111 | J3: =I3+7 -> 46118 | K3: =J3+7 -> 46125 | L3: =K3+7 -> 46132 | M3: =L3+7 -> 46139 | ... BD3: =BC3+7 -> 46440
L4: SHIP | M4: FAB | U4: RAW
A5: Family Totals | B5: 220D-GAS | C5: Net Family Totals | E5: =SUMIFS('Final SR'!J:J,'Final SR'!$E:$E,TOTALss!#REF!,'Final SR'!$I:$I,'Final SR'!$I$12) -> 0 | F5: =SUMIFS('Final SR'!K:K,'Final SR'!$E:$E,TOTALss!#REF!,'Final SR'!$I:$I,'Final SR'!$I$12) -> 0 | G5: =SUMIFS('Final SR'!L:L,'Final SR'!$E:$E,TOTALss!#REF!,'Final SR'!$I:$I,'Final SR'!$I$12) -> 0 | H5: =SUMIFS('Final SR'!M:M,'Final SR'!$E:$E,TOTALss!#REF!,'Final SR'!$I:$I,'Final SR'!$I$12) -> 0 | I5: =SUMIFS('Final SR'!N:N,'Final SR'!$E:$E,TOTALss!#REF!,'Final SR'!$I:$I,'Final SR'!$I$12) -> 0 | J5: =SUMIFS('Final SR'!O:O,'Final SR'!$E:$E,TOTALss!#REF!,'Final SR'!$I:$I,'Final SR'!$I$12) -> 0 | K5: =SUMIFS('Final SR'!P:P,'Final SR'!$E:$E,TOTALss!#REF!,'Final SR'!$I:$I,'Final SR'!$I$12) -> 0 | L5: =SUMIFS('Final SR'!Q:Q,'Final SR'!$E:$E,TOTALss!#REF!,'Final SR'!$I:$I,'Final SR'!$I$12) -> 0 | M5: =SUMIFS('Final SR'!R:R,'Final SR'!$E:$E,TOTALss!#REF!,'Final SR'!$I:$I,'Final SR'!$I$12) -> 0 | N5: =SUMIFS('Final SR'!S:S,'Final SR'!$E:$E,TOTALss!#REF!,'Final SR'!$I:$I,'Final SR'!$I$12) -> 0 | O5: =SUMIFS('Final SR'!T:T,'Final SR'!$E:$E,TOTALss!#REF!,'Final SR'!$I:$I,'Final SR'!$I$12) -> 0 | P5: =SUMIFS('Final SR'!U:U,'Final SR'!$E:$E,TOTALss!#REF!,'Final SR'!$I:$I,'Final SR'!$I$12) -> 0 | Q5: =SUMIFS('Final SR'!V:V,'Final SR'!$E:$E,TOTALss!#REF!,'Final SR'!$I:$I,'Final SR'!$I$12) -> 0 | R5: =SUMIFS('Final SR'!W:W,'Final SR'!$E:$E,TOTALss!#REF!,'Final SR'!$I:$I,'Final SR'!$I$12) -> 0 | S5: =SUMIFS('Final SR'!X:X,'Final SR'!$E:$E,TOTALss!#REF!,'Final SR'!$I:$I,'Final SR'!$I$12) -> 0 | T5: =SUMIFS('Final SR'!Y:Y,'Final SR'!$E:$E,TOTALss!#REF!,'Final SR'!$I:$I,'Final SR'!$I$12) -> 0 | U5: =SUMIFS('Final SR'!Z:Z,'Final SR'!$E:$E,TOTALss!#REF!,'Final SR'!$I:$I,'Final SR'!$I$12) -> 0 | V5: =SUMIFS('Final SR'!AA:AA,'Final SR'!$E:$E,TOTALss!#REF!,'Final SR'!$I:$I,'Final SR'!$I$12) -> 0 | W5: =SUMIFS('Final SR'!AB:AB,'Final SR'!$E:$E,TOTALss!#REF!,'Final SR'!$I:$I,'Final SR'!$I$12) -> 0 | X5: =SUMIFS('Final SR'!AC:AC,'Final SR'!$E:$E,TOTALss!#REF!,'Final SR'!$I:$I,'Final SR'!$I$12) -> 0 | Y5: =SUMIFS('Final SR'!AD:AD,'Final SR'!$E:$E,TOTALss!#REF!,'Final SR'!$I:$I,'Final SR'!$I$12) -> 0 | Z5: =SUMIFS('Final SR'!AE:AE,'Final SR'!$E:$E,TOTALss!#REF!,'Final SR'!$I:$I,'Final SR'!$I$12) -> 0 | AA5: =SUMIFS('Final SR'!AF:AF,'Final SR'!$E:$E,TOTALss!#REF!,'Final SR'!$I:$I,'Final SR'!$I$12) -> 0 | AB5: =SUMIFS('Final SR'!AG:AG,'Final SR'!$E:$E,TOTALss!#REF!,'Final SR'!$I:$I,'Final SR'!$I$12) -> 0 | AC5: =SUMIFS('Final SR'!AH:AH,'Final SR'!$E:$E,TOTALss!#REF!,'Final SR'!$I:$I,'Final SR'!$I$12) -> 0 | AD5: =SUMIFS('Final SR'!AI:AI,'Final SR'!$E:$E,TOTALss!#REF!,'Final SR'!$I:$I,'Final SR'!$I$12) -> 0 | AE5: =SUMIFS('Final SR'!AJ:AJ,'Final SR'!$E:$E,TOTALss!#REF!,'Final SR'!$I:$I,'Final SR'!$I$12) -> 0 | AF5: =SUMIFS('Final SR'!AK:AK,'Final SR'!$E:$E,TOTALss!#REF!,'Final SR'!$I:$I,'Final SR'!$I$12) -> 0 | AG5: =SUMIFS('Final SR'!AL:AL,'Final SR'!$E:$E,TOTALss!#REF!,'Final SR'!$I:$I,'Final SR'!$I$12) -> 0 | AH5: =SUMIFS('Final SR'!AM:AM,'Final SR'!$E:$E,TOTALss!#REF!,'Final SR'!$I:$I,'Final SR'!$I$12) -> 0 | AI5: =SUMIFS('Final SR'!AN:AN,'Final SR'!$E:$E,TOTALss!#REF!,'Final SR'!$I:$I,'Final SR'!$I$12) -> 0 | AJ5: =SUMIFS('Final SR'!AO:AO,'Final SR'!$E:$E,TOTALss!#REF!,'Final SR'!$I:$I,'Final SR'!$I$12) -> 0 | AK5: =SUMIFS('Final SR'!AP:AP,'Final SR'!$E:$E,TOTALss!#REF!,'Final SR'!$I:$I,'Final SR'!$I$12) -> 0 | AL5: =SUMIFS('Final SR'!AQ:AQ,'Final SR'!$E:$E,TOTALss!#REF!,'Final SR'!$I:$I,'Final SR'!$I$12) -> 0 | AM5: =SUMIFS('Final SR'!AR:AR,'Final SR'!$E:$E,TOTALss!#REF!,'Final SR'!$I:$I,'Final SR'!$I$12) -> 0 | AN5: =SUMIFS('Final SR'!AS:AS,'Final SR'!$E:$E,TOTALss!#REF!,'Final SR'!$I:$I,'Final SR'!$I$12) -> 0 | AO5: =SUMIFS('Final SR'!AT:AT,'Final SR'!$E:$E,TOTALss!#REF!,'Final SR'!$I:$I,'Final SR'!$I$12) -> 0 | AP5: =SUMIFS('Final SR'!AU:AU,'Final SR'!$E:$E,TOTALss!#REF!,'Final SR'!$I:$I,'Final SR'!$I$12) -> 0 | AQ5: =SUMIFS('Final SR'!AV:AV,'Final SR'!$E:$E,TOTALss!#REF!,'Final SR'!$I:$I,'Final SR'!$I$12) -> 0 | AR5: =SUMIFS('Final SR'!AW:AW,'Final SR'!$E:$E,TOTALss!#REF!,'Final SR'!$I:$I,'Final SR'!$I$12) -> 0 | AS5: =SUMIFS('Final SR'!AX:AX,'Final SR'!$E:$E,TOTALss!#REF!,'Final SR'!$I:$I,'Final SR'!$I$12) -> 0 | AT5: =SUMIFS('Final SR'!AY:AY,'Final SR'!$E:$E,TOTALss!#REF!,'Final SR'!$I:$I,'Final SR'!$I$12) -> 0 | AU5: =SUMIFS('Final SR'!AZ:AZ,'Final SR'!$E:$E,TOTALss!#REF!,'Final SR'!$I:$I,'Final SR'!$I$12) -> 0 | AV5: =SUMIFS('Final SR'!BA:BA,'Final SR'!$E:$E,TOTALss!#REF!,'Final SR'!$I:$I,'Final SR'!$I$12) -> 0 | AW5: =SUMIFS('Final SR'!BB:BB,'Final SR'!$E:$E,TOTALss!#REF!,'Final SR'!$I:$I,'Final SR'!$I$12) -> 0 | AX5: =SUMIFS('Final SR'!BC:BC,'Final SR'!$E:$E,TOTALss!#REF!,'Final SR'!$I:$I,'Final SR'!$I$12) -> 0 | AY5: =SUMIFS('Final SR'!BD:BD,'Final SR'!$E:$E,TOTALss!#REF!,'Final SR'!$I:$I,'Final SR'!$I$12) -> 0 | AZ5: =SUMIFS('Final SR'!BE:BE,'Final SR'!$E:$E,TOTALss!#REF!,'Final SR'!$I:$I,'Final SR'!$I$12) -> 0 | BA5: =SUMIFS('Final SR'!BF:BF,'Final SR'!$E:$E,TOTALss!#REF!,'Final SR'!$I:$I,'Final SR'!$I$12) -> 0 | BB5: =SUMIFS('Final SR'!BG:BG,'Final SR'!$E:$E,TOTALss!#REF!,'Final SR'!$I:$I,'Final SR'!$I$12) -> 0 | BC5: =SUMIFS('Final SR'!BH:BH,'Final SR'!$E:$E,TOTALss!#REF!,'Final SR'!$I:$I,'Final SR'!$I$12) -> 0 | BD5: =SUMIFS('Final SR'!BI:BI,'Final SR'!$E:$E,TOTALss!#REF!,'Final SR'!$I:$I,'Final SR'!$I$12) -> 0
C6: Cum Family Totals | E6: =SUMIFS('Final SR'!J:J,'Final SR'!$E:$E,TOTALss!#REF!,'Final SR'!$I:$I,'Final SR'!$I$13) -> 0 | F6: =+F5+E6 -> 0 | G6: =+G5+F6 -> 0 | H6: =+H5+G6 -> 0 | I6: =+I5+H6 -> 0 | J6: =+J5+I6 -> 0 | K6: =+K5+J6 -> 0 | L6: =+L5+K6 -> 0 | M6: =+M5+L6 -> 0 | ... BD6: =+BD5+BC6 -> 0
L7: SHIP | M7: FAB | U7: RAW
K8: SHIP | L8: FAB
G9: =B5 -> 220D-GAS | H9: THIS WEEK | I9: NET | J9: =K5 -> 0 | K9: =L5 -> 0 | L9: =M5 -> 0 | M9: =K9=K11 -> TRUE | N9: =K10-K12 -> -36
I10: CUM | J10: =K6 -> 0 | K10: =L6 -> 0 | L10: =M6 -> 0 | M10: =K10=K12 -> FALSE
H11: LAST SR | I11: NET | K11: 0
I12: CUM | K12: 36
L14: SHIP | M14: FAB | U14: RAW
A15: Family Totals | B15: 220D-HV | C15: Net Family Totals | E15: =SUMIFS('Final SR'!J:J,'Final SR'!$E:$E,TOTALss!#REF!,'Final SR'!$I:$I,'Final SR'!$I$12) -> 0 | F15: =SUMIFS('Final SR'!K:K,'Final SR'!$E:$E,TOTALss!#REF!,'Final SR'!$I:$I,'Final SR'!$I$12) -> 0 | G15: =SUMIFS('Final SR'!L:L,'Final SR'!$E:$E,TOTALss!#REF!,'Final SR'!$I:$I,'Final SR'!$I$12) -> 0 | H15: =SUMIFS('Final SR'!M:M,'Final SR'!$E:$E,TOTALss!#REF!,'Final SR'!$I:$I,'Final SR'!$I$12) -> 0 | I15: =SUMIFS('Final SR'!N:N,'Final SR'!$E:$E,TOTALss!#REF!,'Final SR'!$I:$I,'Final SR'!$I$12) -> 0 | J15: =SUMIFS('Final SR'!O:O,'Final SR'!$E:$E,TOTALss!#REF!,'Final SR'!$I:$I,'Final SR'!$I$12) -> 0 | K15: =SUMIFS('Final SR'!P:P,'Final SR'!$E:$E,TOTALss!#REF!,'Final SR'!$I:$I,'Final SR'!$I$12) -> 0 | L15: =SUMIFS('Final SR'!Q:Q,'Final SR'!$E:$E,TOTALss!#REF!,'Final SR'!$I:$I,'Final SR'!$I$12) -> 0 | M15: =SUMIFS('Final SR'!R:R,'Final SR'!$E:$E,TOTALss!#REF!,'Final SR'!$I:$I,'Final SR'!$I$12) -> 0 | N15: =SUMIFS('Final SR'!S:S,'Final SR'!$E:$E,TOTALss!#REF!,'Final SR'!$I:$I,'Final SR'!$I$12) -> 0 | O15: =SUMIFS('Final SR'!T:T,'Final SR'!$E:$E,TOTALss!#REF!,'Final SR'!$I:$I,'Final SR'!$I$12) -> 0 | P15: =SUMIFS('Final SR'!U:U,'Final SR'!$E:$E,TOTALss!#REF!,'Final SR'!$I:$I,'Final SR'!$I$12) -> 0 | Q15: =SUMIFS('Final SR'!V:V,'Final SR'!$E:$E,TOTALss!#REF!,'Final SR'!$I:$I,'Final SR'!$I$12) -> 0 | R15: =SUMIFS('Final SR'!W:W,'Final SR'!$E:$E,TOTALss!#REF!,'Final SR'!$I:$I,'Final SR'!$I$12) -> 0 | S15: =SUMIFS('Final SR'!X:X,'Final SR'!$E:$E,TOTALss!#REF!,'Final SR'!$I:$I,'Final SR'!$I$12) -> 0 | T15: =SUMIFS('Final SR'!Y:Y,'Final SR'!$E:$E,TOTALss!#REF!,'Final SR'!$I:$I,'Final SR'!$I$12) -> 0 | U15: =SUMIFS('Final SR'!Z:Z,'Final SR'!$E:$E,TOTALss!#REF!,'Final SR'!$I:$I,'Final SR'!$I$12) -> 0 | V15: =SUMIFS('Final SR'!AA:AA,'Final SR'!$E:$E,TOTALss!#REF!,'Final SR'!$I:$I,'Final SR'!$I$12) -> 0 | W15: =SUMIFS('Final SR'!AB:AB,'Final SR'!$E:$E,TOTALss!#REF!,'Final SR'!$I:$I,'Final SR'!$I$12) -> 0 | X15: =SUMIFS('Final SR'!AC:AC,'Final SR'!$E:$E,TOTALss!#REF!,'Final SR'!$I:$I,'Final SR'!$I$12) -> 0 | Y15: =SUMIFS('Final SR'!AD:AD,'Final SR'!$E:$E,TOTALss!#REF!,'Final SR'!$I:$I,'Final SR'!$I$12) -> 0 | Z15: =SUMIFS('Final SR'!AE:AE,'Final SR'!$E:$E,TOTALss!#REF!,'Final SR'!$I:$I,'Final SR'!$I$12) -> 0 | AA15: =SUMIFS('Final SR'!AF:AF,'Final SR'!$E:$E,TOTALss!#REF!,'Final SR'!$I:$I,'Final SR'!$I$12) -> 0 | AB15: =SUMIFS('Final SR'!AG:AG,'Final SR'!$E:$E,TOTALss!#REF!,'Final SR'!$I:$I,'Final SR'!$I$12) -> 0 | AC15: =SUMIFS('Final SR'!AH:AH,'Final SR'!$E:$E,TOTALss!#REF!,'Final SR'!$I:$I,'Final SR'!$I$12) -> 0 | AD15: =SUMIFS('Final SR'!AI:AI,'Final SR'!$E:$E,TOTALss!#REF!,'Final SR'!$I:$I,'Final SR'!$I$12) -> 0 | AE15: =SUMIFS('Final SR'!AJ:AJ,'Final SR'!$E:$E,TOTALss!#REF!,'Final SR'!$I:$I,'Final SR'!$I$12) -> 0 | AF15: =SUMIFS('Final SR'!AK:AK,'Final SR'!$E:$E,TOTALss!#REF!,'Final SR'!$I:$I,'Final SR'!$I$12) -> 0 | AG15: =SUMIFS('Final SR'!AL:AL,'Final SR'!$E:$E,TOTALss!#REF!,'Final SR'!$I:$I,'Final SR'!$I$12) -> 0 | AH15: =SUMIFS('Final SR'!AM:AM,'Final SR'!$E:$E,TOTALss!#REF!,'Final SR'!$I:$I,'Final SR'!$I$12) -> 0 | AI15: =SUMIFS('Final SR'!AN:AN,'Final SR'!$E:$E,TOTALss!#REF!,'Final SR'!$I:$I,'Final SR'!$I$12) -> 0 | AJ15: =SUMIFS('Final SR'!AO:AO,'Final SR'!$E:$E,TOTALss!#REF!,'Final SR'!$I:$I,'Final SR'!$I$12) -> 0 | AK15: =SUMIFS('Final SR'!AP:AP,'Final SR'!$E:$E,TOTALss!#REF!,'Final SR'!$I:$I,'Final SR'!$I$12) -> 0 | AL15: =SUMIFS('Final SR'!AQ:AQ,'Final SR'!$E:$E,TOTALss!#REF!,'Final SR'!$I:$I,'Final SR'!$I$12) -> 0 | AM15: =SUMIFS('Final SR'!AR:AR,'Final SR'!$E:$E,TOTALss!#REF!,'Final SR'!$I:$I,'Final SR'!$I$12) -> 0 | AN15: =SUMIFS('Final SR'!AS:AS,'Final SR'!$E:$E,TOTALss!#REF!,'Final SR'!$I:$I,'Final SR'!$I$12) -> 0 | AO15: =SUMIFS('Final SR'!AT:AT,'Final SR'!$E:$E,TOTALss!#REF!,'Final SR'!$I:$I,'Final SR'!$I$12) -> 0 | AP15: =SUMIFS('Final SR'!AU:AU,'Final SR'!$E:$E,TOTALss!#REF!,'Final SR'!$I:$I,'Final SR'!$I$12) -> 0 | AQ15: =SUMIFS('Final SR'!AV:AV,'Final SR'!$E:$E,TOTALss!#REF!,'Final SR'!$I:$I,'Final SR'!$I$12) -> 0 | AR15: =SUMIFS('Final SR'!AW:AW,'Final SR'!$E:$E,TOTALss!#REF!,'Final SR'!$I:$I,'Final SR'!$I$12) -> 0 | AS15: =SUMIFS('Final SR'!AX:AX,'Final SR'!$E:$E,TOTALss!#REF!,'Final SR'!$I:$I,'Final SR'!$I$12) -> 0 | AT15: =SUMIFS('Final SR'!AY:AY,'Final SR'!$E:$E,TOTALss!#REF!,'Final SR'!$I:$I,'Final SR'!$I$12) -> 0 | AU15: =SUMIFS('Final SR'!AZ:AZ,'Final SR'!$E:$E,TOTALss!#REF!,'Final SR'!$I:$I,'Final SR'!$I$12) -> 0 | AV15: =SUMIFS('Final SR'!BA:BA,'Final SR'!$E:$E,TOTALss!#REF!,'Final SR'!$I:$I,'Final SR'!$I$12) -> 0 | AW15: =SUMIFS('Final SR'!BB:BB,'Final SR'!$E:$E,TOTALss!#REF!,'Final SR'!$I:$I,'Final SR'!$I$12) -> 0 | AX15: =SUMIFS('Final SR'!BC:BC,'Final SR'!$E:$E,TOTALss!#REF!,'Final SR'!$I:$I,'Final SR'!$I$12) -> 0 | AY15: =SUMIFS('Final SR'!BD:BD,'Final SR'!$E:$E,TOTALss!#REF!,'Final SR'!$I:$I,'Final SR'!$I$12) -> 0 | AZ15: =SUMIFS('Final SR'!BE:BE,'Final SR'!$E:$E,TOTALss!#REF!,'Final SR'!$I:$I,'Final SR'!$I$12) -> 0 | BA15: =SUMIFS('Final SR'!BF:BF,'Final SR'!$E:$E,TOTALss!#REF!,'Final SR'!$I:$I,'Final SR'!$I$12) -> 0 | BB15: =SUMIFS('Final SR'!BG:BG,'Final SR'!$E:$E,TOTALss!#REF!,'Final SR'!$I:$I,'Final SR'!$I$12) -> 0 | BC15: =SUMIFS('Final SR'!BH:BH,'Final SR'!$E:$E,TOTALss!#REF!,'Final SR'!$I:$I,'Final SR'!$I$12) -> 0 | BD15: =SUMIFS('Final SR'!BI:BI,'Final SR'!$E:$E,TOTALss!#REF!,'Final SR'!$I:$I,'Final SR'!$I$12) -> 0
C16: Cum Family Totals | E16: =SUMIFS('Final SR'!J:J,'Final SR'!$E:$E,TOTALss!#REF!,'Final SR'!$I:$I,'Final SR'!$I$13) -> 0 | F16: =SUMIFS('Final SR'!K:K,'Final SR'!$E:$E,TOTALss!#REF!,'Final SR'!$I:$I,'Final SR'!$I$13) -> 0 | G16: =SUMIFS('Final SR'!L:L,'Final SR'!$E:$E,TOTALss!#REF!,'Final SR'!$I:$I,'Final SR'!$I$13) -> 0 | H16: =SUMIFS('Final SR'!M:M,'Final SR'!$E:$E,TOTALss!#REF!,'Final SR'!$I:$I,'Final SR'!$I$13) -> 0 | I16: =SUMIFS('Final SR'!N:N,'Final SR'!$E:$E,TOTALss!#REF!,'Final SR'!$I:$I,'Final SR'!$I$13) -> 0 | J16: =SUMIFS('Final SR'!O:O,'Final SR'!$E:$E,TOTALss!#REF!,'Final SR'!$I:$I,'Final SR'!$I$13) -> 0 | K16: =SUMIFS('Final SR'!P:P,'Final SR'!$E:$E,TOTALss!#REF!,'Final SR'!$I:$I,'Final SR'!$I$13) -> 0 | L16: =SUMIFS('Final SR'!Q:Q,'Final SR'!$E:$E,TOTALss!#REF!,'Final SR'!$I:$I,'Final SR'!$I$13) -> 0 | M16: =SUMIFS('Final SR'!R:R,'Final SR'!$E:$E,TOTALss!#REF!,'Final SR'!$I:$I,'Final SR'!$I$13) -> 0 | N16: =SUMIFS('Final SR'!S:S,'Final SR'!$E:$E,TOTALss!#REF!,'Final SR'!$I:$I,'Final SR'!$I$13) -> 0 | O16: =SUMIFS('Final SR'!T:T,'Final SR'!$E:$E,TOTALss!#REF!,'Final SR'!$I:$I,'Final SR'!$I$13) -> 0 | P16: =SUMIFS('Final SR'!U:U,'Final SR'!$E:$E,TOTALss!#REF!,'Final SR'!$I:$I,'Final SR'!$I$13) -> 0 | Q16: =SUMIFS('Final SR'!V:V,'Final SR'!$E:$E,TOTALss!#REF!,'Final SR'!$I:$I,'Final SR'!$I$13) -> 0 | R16: =SUMIFS('Final SR'!W:W,'Final SR'!$E:$E,TOTALss!#REF!,'Final SR'!$I:$I,'Final SR'!$I$13) -> 0 | S16: =SUMIFS('Final SR'!X:X,'Final SR'!$E:$E,TOTALss!#REF!,'Final SR'!$I:$I,'Final SR'!$I$13) -> 0 | T16: =SUMIFS('Final SR'!Y:Y,'Final SR'!$E:$E,TOTALss!#REF!,'Final SR'!$I:$I,'Final SR'!$I$13) -> 0 | U16: =SUMIFS('Final SR'!Z:Z,'Final SR'!$E:$E,TOTALss!#REF!,'Final SR'!$I:$I,'Final SR'!$I$13) -> 0 | V16: =SUMIFS('Final SR'!AA:AA,'Final SR'!$E:$E,TOTALss!#REF!,'Final SR'!$I:$I,'Final SR'!$I$13) -> 0 | W16: =SUMIFS('Final SR'!AB:AB,'Final SR'!$E:$E,TOTALss!#REF!,'Final SR'!$I:$I,'Final SR'!$I$13) -> 0 | X16: =SUMIFS('Final SR'!AC:AC,'Final SR'!$E:$E,TOTALss!#REF!,'Final SR'!$I:$I,'Final SR'!$I$13) -> 0 | Y16: =SUMIFS('Final SR'!AD:AD,'Final SR'!$E:$E,TOTALss!#REF!,'Final SR'!$I:$I,'Final SR'!$I$13) -> 0 | Z16: =SUMIFS('Final SR'!AE:AE,'Final SR'!$E:$E,TOTALss!#REF!,'Final SR'!$I:$I,'Final SR'!$I$13) -> 0 | AA16: =SUMIFS('Final SR'!AF:AF,'Final SR'!$E:$E,TOTALss!#REF!,'Final SR'!$I:$I,'Final SR'!$I$13) -> 0 | AB16: =SUMIFS('Final SR'!AG:AG,'Final SR'!$E:$E,TOTALss!#REF!,'Final SR'!$I:$I,'Final SR'!$I$13) -> 0 | AC16: =SUMIFS('Final SR'!AH:AH,'Final SR'!$E:$E,TOTALss!#REF!,'Final SR'!$I:$I,'Final SR'!$I$13) -> 0 | AD16: =SUMIFS('Final SR'!AI:AI,'Final SR'!$E:$E,TOTALss!#REF!,'Final SR'!$I:$I,'Final SR'!$I$13) -> 0 | AE16: =SUMIFS('Final SR'!AJ:AJ,'Final SR'!$E:$E,TOTALss!#REF!,'Final SR'!$I:$I,'Final SR'!$I$13) -> 0 | AF16: =SUMIFS('Final SR'!AK:AK,'Final SR'!$E:$E,TOTALss!#REF!,'Final SR'!$I:$I,'Final SR'!$I$13) -> 0 | AG16: =SUMIFS('Final SR'!AL:AL,'Final SR'!$E:$E,TOTALss!#REF!,'Final SR'!$I:$I,'Final SR'!$I$13) -> 0 | AH16: =SUMIFS('Final SR'!AM:AM,'Final SR'!$E:$E,TOTALss!#REF!,'Final SR'!$I:$I,'Final SR'!$I$13) -> 0 | AI16: =SUMIFS('Final SR'!AN:AN,'Final SR'!$E:$E,TOTALss!#REF!,'Final SR'!$I:$I,'Final SR'!$I$13) -> 0 | AJ16: =SUMIFS('Final SR'!AO:AO,'Final SR'!$E:$E,TOTALss!#REF!,'Final SR'!$I:$I,'Final SR'!$I$13) -> 0 | AK16: =SUMIFS('Final SR'!AP:AP,'Final SR'!$E:$E,TOTALss!#REF!,'Final SR'!$I:$I,'Final SR'!$I$13) -> 0 | AL16: =SUMIFS('Final SR'!AQ:AQ,'Final SR'!$E:$E,TOTALss!#REF!,'Final SR'!$I:$I,'Final SR'!$I$13) -> 0 | AM16: =SUMIFS('Final SR'!AR:AR,'Final SR'!$E:$E,TOTALss!#REF!,'Final SR'!$I:$I,'Final SR'!$I$13) -> 0 | AN16: =SUMIFS('Final SR'!AS:AS,'Final SR'!$E:$E,TOTALss!#REF!,'Final SR'!$I:$I,'Final SR'!$I$13) -> 0 | AO16: =SUMIFS('Final SR'!AT:AT,'Final SR'!$E:$E,TOTALss!#REF!,'Final SR'!$I:$I,'Final SR'!$I$13) -> 0 | AP16: =SUMIFS('Final SR'!AU:AU,'Final SR'!$E:$E,TOTALss!#REF!,'Final SR'!$I:$I,'Final SR'!$I$13) -> 0 | AQ16: =SUMIFS('Final SR'!AV:AV,'Final SR'!$E:$E,TOTALss!#REF!,'Final SR'!$I:$I,'Final SR'!$I$13) -> 0 | AR16: =SUMIFS('Final SR'!AW:AW,'Final SR'!$E:$E,TOTALss!#REF!,'Final SR'!$I:$I,'Final SR'!$I$13) -> 0 | AS16: =SUMIFS('Final SR'!AX:AX,'Final SR'!$E:$E,TOTALss!#REF!,'Final SR'!$I:$I,'Final SR'!$I$13) -> 0 | AT16: =SUMIFS('Final SR'!AY:AY,'Final SR'!$E:$E,TOTALss!#REF!,'Final SR'!$I:$I,'Final SR'!$I$13) -> 0 | AU16: =SUMIFS('Final SR'!AZ:AZ,'Final SR'!$E:$E,TOTALss!#REF!,'Final SR'!$I:$I,'Final SR'!$I$13) -> 0 | AV16: =SUMIFS('Final SR'!BA:BA,'Final SR'!$E:$E,TOTALss!#REF!,'Final SR'!$I:$I,'Final SR'!$I$13) -> 0 | AW16: =SUMIFS('Final SR'!BB:BB,'Final SR'!$E:$E,TOTALss!#REF!,'Final SR'!$I:$I,'Final SR'!$I$13) -> 0 | AX16: =SUMIFS('Final SR'!BC:BC,'Final SR'!$E:$E,TOTALss!#REF!,'Final SR'!$I:$I,'Final SR'!$I$13) -> 0 | AY16: =SUMIFS('Final SR'!BD:BD,'Final SR'!$E:$E,TOTALss!#REF!,'Final SR'!$I:$I,'Final SR'!$I$13) -> 0 | AZ16: =SUMIFS('Final SR'!BE:BE,'Final SR'!$E:$E,TOTALss!#REF!,'Final SR'!$I:$I,'Final SR'!$I$13) -> 0 | BA16: =SUMIFS('Final SR'!BF:BF,'Final SR'!$E:$E,TOTALss!#REF!,'Final SR'!$I:$I,'Final SR'!$I$13) -> 0 | BB16: =SUMIFS('Final SR'!BG:BG,'Final SR'!$E:$E,TOTALss!#REF!,'Final SR'!$I:$I,'Final SR'!$I$13) -> 0 | BC16: =SUMIFS('Final SR'!BH:BH,'Final SR'!$E:$E,TOTALss!#REF!,'Final SR'!$I:$I,'Final SR'!$I$13) -> 0 | BD16: =SUMIFS('Final SR'!BI:BI,'Final SR'!$E:$E,TOTALss!#REF!,'Final SR'!$I:$I,'Final SR'!$I$13) -> 0
L17: SHIP | M17: FAB | U17: RAW
K18: SHIP | L18: FAB
G19: =B15 -> 220D-HV | H19: THIS WEEK | I19: NET | J19: =K15 -> 0 | K19: =L15 -> 0 | L19: =M15 -> 0 | M19: =K19=K21 -> TRUE | N19: =K20-K22 -> 0
I20: CUM | J20: =K16 -> 0 | K20: =L16 -> 0 | L20: =M16 -> 0 | M20: =K20=K22 -> TRUE
H21: LAST SR | I21: NET | K21: 0
I22: CUM | K22: 0
L24: SHIP | M24: FAB | U24: RAW
A25: Family Totals | B25: GAS | C25: Net Family Totals | E25: =SUMIFS('Final SR'!J:J,'Final SR'!$E:$E,TOTALss!$B6,'Final SR'!$I:$I,'Final SR'!$I$12) -> 6652 | F25: =SUMIFS('Final SR'!K:K,'Final SR'!$E:$E,TOTALss!$B6,'Final SR'!$I:$I,'Final SR'!$I$12) -> 2784 | G25: =SUMIFS('Final SR'!L:L,'Final SR'!$E:$E,TOTALss!$B6,'Final SR'!$I:$I,'Final SR'!$I$12) -> 2276 | H25: =SUMIFS('Final SR'!M:M,'Final SR'!$E:$E,TOTALss!$B6,'Final SR'!$I:$I,'Final SR'!$I$12) -> 2648 | I25: =SUMIFS('Final SR'!N:N,'Final SR'!$E:$E,TOTALss!$B6,'Final SR'!$I:$I,'Final SR'!$I$12) -> 2928 | J25: =SUMIFS('Final SR'!O:O,'Final SR'!$E:$E,TOTALss!$B6,'Final SR'!$I:$I,'Final SR'!$I$12) -> 2688 | K25: =SUMIFS('Final SR'!P:P,'Final SR'!$E:$E,TOTALss!$B6,'Final SR'!$I:$I,'Final SR'!$I$12) -> 3716 | L25: =SUMIFS('Final SR'!Q:Q,'Final SR'!$E:$E,TOTALss!$B6,'Final SR'!$I:$I,'Final SR'!$I$12) -> 3720 | M25: =SUMIFS('Final SR'!R:R,'Final SR'!$E:$E,TOTALss!$B6,'Final SR'!$I:$I,'Final SR'!$I$12) -> 0 | N25: =SUMIFS('Final SR'!S:S,'Final SR'!$E:$E,TOTALss!$B6,'Final SR'!$I:$I,'Final SR'!$I$12) -> 2056 | O25: =SUMIFS('Final SR'!T:T,'Final SR'!$E:$E,TOTALss!$B6,'Final SR'!$I:$I,'Final SR'!$I$12) -> 2640 | P25: =SUMIFS('Final SR'!U:U,'Final SR'!$E:$E,TOTALss!$B6,'Final SR'!$I:$I,'Final SR'!$I$12) -> 2348 | Q25: =SUMIFS('Final SR'!V:V,'Final SR'!$E:$E,TOTALss!$B6,'Final SR'!$I:$I,'Final SR'!$I$12) -> 1944 | R25: =SUMIFS('Final SR'!W:W,'Final SR'!$E:$E,TOTALss!$B6,'Final SR'!$I:$I,'Final SR'!$I$12) -> 1620 | S25: =SUMIFS('Final SR'!X:X,'Final SR'!$E:$E,TOTALss!$B6,'Final SR'!$I:$I,'Final SR'!$I$12) -> 1152 | T25: =SUMIFS('Final SR'!Y:Y,'Final SR'!$E:$E,TOTALss!$B6,'Final SR'!$I:$I,'Final SR'!$I$12) -> 1192 | U25: =SUMIFS('Final SR'!Z:Z,'Final SR'!$E:$E,TOTALss!$B6,'Final SR'!$I:$I,'Final SR'!$I$12) -> 1740 | V25: =SUMIFS('Final SR'!AA:AA,'Final SR'!$E:$E,TOTALss!$B6,'Final SR'!$I:$I,'Final SR'!$I$12) -> 2184 | W25: =SUMIFS('Final SR'!AB:AB,'Final SR'!$E:$E,TOTALss!$B6,'Final SR'!$I:$I,'Final SR'!$I$12) -> 2176 | X25: =SUMIFS('Final SR'!AC:AC,'Final SR'!$E:$E,TOTALss!$B6,'Final SR'!$I:$I,'Final SR'!$I$12) -> 2180 | Y25: =SUMIFS('Final SR'!AD:AD,'Final SR'!$E:$E,TOTALss!$B6,'Final SR'!$I:$I,'Final SR'!$I$12) -> 1656 | Z25: =SUMIFS('Final SR'!AE:AE,'Final SR'!$E:$E,TOTALss!$B6,'Final SR'!$I:$I,'Final SR'!$I$12) -> 1704 | AA25: =SUMIFS('Final SR'!AF:AF,'Final SR'!$E:$E,TOTALss!$B6,'Final SR'!$I:$I,'Final SR'!$I$12) -> 1804 | AB25: =SUMIFS('Final SR'!AG:AG,'Final SR'!$E:$E,TOTALss!$B6,'Final SR'!$I:$I,'Final SR'!$I$12) -> 2096 | AC25: =SUMIFS('Final SR'!AH:AH,'Final SR'!$E:$E,TOTALss!$B6,'Final SR'!$I:$I,'Final SR'!$I$12) -> 1508 | AD25: =SUMIFS('Final SR'!AI:AI,'Final SR'!$E:$E,TOTALss!$B6,'Final SR'!$I:$I,'Final SR'!$I$12) -> 1908 | AE25: =SUMIFS('Final SR'!AJ:AJ,'Final SR'!$E:$E,TOTALss!$B6,'Final SR'!$I:$I,'Final SR'!$I$12) -> 2364 | AF25: =SUMIFS('Final SR'!AK:AK,'Final SR'!$E:$E,TOTALss!$B6,'Final SR'!$I:$I,'Final SR'!$I$12) -> 2360 | AG25: =SUMIFS('Final SR'!AL:AL,'Final SR'!$E:$E,TOTALss!$B6,'Final SR'!$I:$I,'Final SR'!$I$12) -> 3076 | AH25: =SUMIFS('Final SR'!AM:AM,'Final SR'!$E:$E,TOTALss!$B6,'Final SR'!$I:$I,'Final SR'!$I$12) -> 3012 | AI25: =SUMIFS('Final SR'!AN:AN,'Final SR'!$E:$E,TOTALss!$B6,'Final SR'!$I:$I,'Final SR'!$I$12) -> 2904 | AJ25: =SUMIFS('Final SR'!AO:AO,'Final SR'!$E:$E,TOTALss!$B6,'Final SR'!$I:$I,'Final SR'!$I$12) -> 2904 | AK25: =SUMIFS('Final SR'!AP:AP,'Final SR'!$E:$E,TOTALss!$B6,'Final SR'!$I:$I,'Final SR'!$I$12) -> 2904 | AL25: =SUMIFS('Final SR'!AQ:AQ,'Final SR'!$E:$E,TOTALss!$B6,'Final SR'!$I:$I,'Final SR'!$I$12) -> 2904 | AM25: =SUMIFS('Final SR'!AR:AR,'Final SR'!$E:$E,TOTALss!$B6,'Final SR'!$I:$I,'Final SR'!$I$12) -> 2904 | AN25: =SUMIFS('Final SR'!AS:AS,'Final SR'!$E:$E,TOTALss!$B6,'Final SR'!$I:$I,'Final SR'!$I$12) -> 2904 | AO25: =SUMIFS('Final SR'!AT:AT,'Final SR'!$E:$E,TOTALss!$B6,'Final SR'!$I:$I,'Final SR'!$I$12) -> 2904 | AP25: =SUMIFS('Final SR'!AU:AU,'Final SR'!$E:$E,TOTALss!$B6,'Final SR'!$I:$I,'Final SR'!$I$12) -> 2904 | AQ25: =SUMIFS('Final SR'!AV:AV,'Final SR'!$E:$E,TOTALss!$B6,'Final SR'!$I:$I,'Final SR'!$I$12) -> 2904 | AR25: =SUMIFS('Final SR'!AW:AW,'Final SR'!$E:$E,TOTALss!$B6,'Final SR'!$I:$I,'Final SR'!$I$12) -> 2904 | AS25: =SUMIFS('Final SR'!AX:AX,'Final SR'!$E:$E,TOTALss!$B6,'Final SR'!$I:$I,'Final SR'!$I$12) -> 2904 | AT25: =SUMIFS('Final SR'!AY:AY,'Final SR'!$E:$E,TOTALss!$B6,'Final SR'!$I:$I,'Final SR'!$I$12) -> 2904 | AU25: =SUMIFS('Final SR'!AZ:AZ,'Final SR'!$E:$E,TOTALss!$B6,'Final SR'!$I:$I,'Final SR'!$I$12) -> 2904 | AV25: =SUMIFS('Final SR'!BA:BA,'Final SR'!$E:$E,TOTALss!$B6,'Final SR'!$I:$I,'Final SR'!$I$12) -> 2904 | AW25: =SUMIFS('Final SR'!BB:BB,'Final SR'!$E:$E,TOTALss!$B6,'Final SR'!$I:$I,'Final SR'!$I$12) -> 2904 | AX25: =SUMIFS('Final SR'!BC:BC,'Final SR'!$E:$E,TOTALss!$B6,'Final SR'!$I:$I,'Final SR'!$I$12) -> 2904 | AY25: =SUMIFS('Final SR'!BD:BD,'Final SR'!$E:$E,TOTALss!$B6,'Final SR'!$I:$I,'Final SR'!$I$12) -> 2904 | AZ25: =SUMIFS('Final SR'!BE:BE,'Final SR'!$E:$E,TOTALss!$B6,'Final SR'!$I:$I,'Final SR'!$I$12) -> 2904 | BA25: =SUMIFS('Final SR'!BF:BF,'Final SR'!$E:$E,TOTALss!$B6,'Final SR'!$I:$I,'Final SR'!$I$12) -> 2904 | BB25: =SUMIFS('Final SR'!BG:BG,'Final SR'!$E:$E,TOTALss!$B6,'Final SR'!$I:$I,'Final SR'!$I$12) -> 2904 | BC25: =SUMIFS('Final SR'!BH:BH,'Final SR'!$E:$E,TOTALss!$B6,'Final SR'!$I:$I,'Final SR'!$I$12) -> 2904 | BD25: =SUMIFS('Final SR'!BI:BI,'Final SR'!$E:$E,TOTALss!$B6,'Final SR'!$I:$I,'Final SR'!$I$12) -> 2904
C26: Cum Family Totals | E26: =SUMIFS('Final SR'!J:J,'Final SR'!$E:$E,TOTALss!$B6,'Final SR'!$I:$I,'Final SR'!$I$13) -> 102932 | F26: =SUMIFS('Final SR'!K:K,'Final SR'!$E:$E,TOTALss!$B6,'Final SR'!$I:$I,'Final SR'!$I$13) -> 105716 | G26: =SUMIFS('Final SR'!L:L,'Final SR'!$E:$E,TOTALss!$B6,'Final SR'!$I:$I,'Final SR'!$I$13) -> 107992 | H26: =SUMIFS('Final SR'!M:M,'Final SR'!$E:$E,TOTALss!$B6,'Final SR'!$I:$I,'Final SR'!$I$13) -> 110640 | I26: =SUMIFS('Final SR'!N:N,'Final SR'!$E:$E,TOTALss!$B6,'Final SR'!$I:$I,'Final SR'!$I$13) -> 113568 | J26: =SUMIFS('Final SR'!O:O,'Final SR'!$E:$E,TOTALss!$B6,'Final SR'!$I:$I,'Final SR'!$I$13) -> 116256 | K26: =SUMIFS('Final SR'!P:P,'Final SR'!$E:$E,TOTALss!$B6,'Final SR'!$I:$I,'Final SR'!$I$13) -> 119972 | L26: =SUMIFS('Final SR'!Q:Q,'Final SR'!$E:$E,TOTALss!$B6,'Final SR'!$I:$I,'Final SR'!$I$13) -> 123692 | M26: =SUMIFS('Final SR'!R:R,'Final SR'!$E:$E,TOTALss!$B6,'Final SR'!$I:$I,'Final SR'!$I$13) -> 123692 | N26: =SUMIFS('Final SR'!S:S,'Final SR'!$E:$E,TOTALss!$B6,'Final SR'!$I:$I,'Final SR'!$I$13) -> 125748 | O26: =SUMIFS('Final SR'!T:T,'Final SR'!$E:$E,TOTALss!$B6,'Final SR'!$I:$I,'Final SR'!$I$13) -> 128388 | P26: =SUMIFS('Final SR'!U:U,'Final SR'!$E:$E,TOTALss!$B6,'Final SR'!$I:$I,'Final SR'!$I$13) -> 130736 | Q26: =SUMIFS('Final SR'!V:V,'Final SR'!$E:$E,TOTALss!$B6,'Final SR'!$I:$I,'Final SR'!$I$13) -> 132680 | R26: =SUMIFS('Final SR'!W:W,'Final SR'!$E:$E,TOTALss!$B6,'Final SR'!$I:$I,'Final SR'!$I$13) -> 134300 | S26: =SUMIFS('Final SR'!X:X,'Final SR'!$E:$E,TOTALss!$B6,'Final SR'!$I:$I,'Final SR'!$I$13) -> 135452 | T26: =SUMIFS('Final SR'!Y:Y,'Final SR'!$E:$E,TOTALss!$B6,'Final SR'!$I:$I,'Final SR'!$I$13) -> 136644 | U26: =SUMIFS('Final SR'!Z:Z,'Final SR'!$E:$E,TOTALss!$B6,'Final SR'!$I:$I,'Final SR'!$I$13) -> 138384 | V26: =SUMIFS('Final SR'!AA:AA,'Final SR'!$E:$E,TOTALss!$B6,'Final SR'!$I:$I,'Final SR'!$I$13) -> 140568 | W26: =SUMIFS('Final SR'!AB:AB,'Final SR'!$E:$E,TOTALss!$B6,'Final SR'!$I:$I,'Final SR'!$I$13) -> 142744 | X26: =SUMIFS('Final SR'!AC:AC,'Final SR'!$E:$E,TOTALss!$B6,'Final SR'!$I:$I,'Final SR'!$I$13) -> 144924 | Y26: =SUMIFS('Final SR'!AD:AD,'Final SR'!$E:$E,TOTALss!$B6,'Final SR'!$I:$I,'Final SR'!$I$13) -> 146580 | Z26: =SUMIFS('Final SR'!AE:AE,'Final SR'!$E:$E,TOTALss!$B6,'Final SR'!$I:$I,'Final SR'!$I$13) -> 148284 | AA26: =SUMIFS('Final SR'!AF:AF,'Final SR'!$E:$E,TOTALss!$B6,'Final SR'!$I:$I,'Final SR'!$I$13) -> 150088 | AB26: =SUMIFS('Final SR'!AG:AG,'Final SR'!$E:$E,TOTALss!$B6,'Final SR'!$I:$I,'Final SR'!$I$13) -> 152184 | AC26: =SUMIFS('Final SR'!AH:AH,'Final SR'!$E:$E,TOTALss!$B6,'Final SR'!$I:$I,'Final SR'!$I$13) -> 153692 | AD26: =SUMIFS('Final SR'!AI:AI,'Final SR'!$E:$E,TOTALss!$B6,'Final SR'!$I:$I,'Final SR'!$I$13) -> 155600 | AE26: =SUMIFS('Final SR'!AJ:AJ,'Final SR'!$E:$E,TOTALss!$B6,'Final SR'!$I:$I,'Final SR'!$I$13) -> 157964 | AF26: =SUMIFS('Final SR'!AK:AK,'Final SR'!$E:$E,TOTALss!$B6,'Final SR'!$I:$I,'Final SR'!$I$13) -> 160324 | AG26: =SUMIFS('Final SR'!AL:AL,'Final SR'!$E:$E,TOTALss!$B6,'Final SR'!$I:$I,'Final SR'!$I$13) -> 163400 | AH26: =SUMIFS('Final SR'!AM:AM,'Final SR'!$E:$E,TOTALss!$B6,'Final SR'!$I:$I,'Final SR'!$I$13) -> 166412 | AI26: =SUMIFS('Final SR'!AN:AN,'Final SR'!$E:$E,TOTALss!$B6,'Final SR'!$I:$I,'Final SR'!$I$13) -> 169316 | AJ26: =SUMIFS('Final SR'!AO:AO,'Final SR'!$E:$E,TOTALss!$B6,'Final SR'!$I:$I,'Final SR'!$I$13) -> 172220 | AK26: =SUMIFS('Final SR'!AP:AP,'Final SR'!$E:$E,TOTALss!$B6,'Final SR'!$I:$I,'Final SR'!$I$13) -> 175124 | AL26: =SUMIFS('Final SR'!AQ:AQ,'Final SR'!$E:$E,TOTALss!$B6,'Final SR'!$I:$I,'Final SR'!$I$13) -> 178028 | AM26: =SUMIFS('Final SR'!AR:AR,'Final SR'!$E:$E,TOTALss!$B6,'Final SR'!$I:$I,'Final SR'!$I$13) -> 180932 | AN26: =SUMIFS('Final SR'!AS:AS,'Final SR'!$E:$E,TOTALss!$B6,'Final SR'!$I:$I,'Final SR'!$I$13) -> 183836 | AO26: =SUMIFS('Final SR'!AT:AT,'Final SR'!$E:$E,TOTALss!$B6,'Final SR'!$I:$I,'Final SR'!$I$13) -> 186740 | AP26: =SUMIFS('Final SR'!AU:AU,'Final SR'!$E:$E,TOTALss!$B6,'Final SR'!$I:$I,'Final SR'!$I$13) -> 189644 | AQ26: =SUMIFS('Final SR'!AV:AV,'Final SR'!$E:$E,TOTALss!$B6,'Final SR'!$I:$I,'Final SR'!$I$13) -> 192548 | AR26: =SUMIFS('Final SR'!AW:AW,'Final SR'!$E:$E,TOTALss!$B6,'Final SR'!$I:$I,'Final SR'!$I$13) -> 195452 | AS26: =SUMIFS('Final SR'!AX:AX,'Final SR'!$E:$E,TOTALss!$B6,'Final SR'!$I:$I,'Final SR'!$I$13) -> 198356 | AT26: =SUMIFS('Final SR'!AY:AY,'Final SR'!$E:$E,TOTALss!$B6,'Final SR'!$I:$I,'Final SR'!$I$13) -> 201260 | AU26: =SUMIFS('Final SR'!AZ:AZ,'Final SR'!$E:$E,TOTALss!$B6,'Final SR'!$I:$I,'Final SR'!$I$13) -> 204164 | AV26: =SUMIFS('Final SR'!BA:BA,'Final SR'!$E:$E,TOTALss!$B6,'Final SR'!$I:$I,'Final SR'!$I$13) -> 207068 | AW26: =SUMIFS('Final SR'!BB:BB,'Final SR'!$E:$E,TOTALss!$B6,'Final SR'!$I:$I,'Final SR'!$I$13) -> 209972 | AX26: =SUMIFS('Final SR'!BC:BC,'Final SR'!$E:$E,TOTALss!$B6,'Final SR'!$I:$I,'Final SR'!$I$13) -> 212876 | AY26: =SUMIFS('Final SR'!BD:BD,'Final SR'!$E:$E,TOTALss!$B6,'Final SR'!$I:$I,'Final SR'!$I$13) -> 215780 | AZ26: =SUMIFS('Final SR'!BE:BE,'Final SR'!$E:$E,TOTALss!$B6,'Final SR'!$I:$I,'Final SR'!$I$13) -> 218684 | BA26: =SUMIFS('Final SR'!BF:BF,'Final SR'!$E:$E,TOTALss!$B6,'Final SR'!$I:$I,'Final SR'!$I$13) -> 221588 | BB26: =SUMIFS('Final SR'!BG:BG,'Final SR'!$E:$E,TOTALss!$B6,'Final SR'!$I:$I,'Final SR'!$I$13) -> 224492 | BC26: =SUMIFS('Final SR'!BH:BH,'Final SR'!$E:$E,TOTALss!$B6,'Final SR'!$I:$I,'Final SR'!$I$13) -> 227396 | BD26: =SUMIFS('Final SR'!BI:BI,'Final SR'!$E:$E,TOTALss!$B6,'Final SR'!$I:$I,'Final SR'!$I$13) -> 230300
L27: SHIP | M27: FAB | U27: RAW
K28: SHIP | L28: FAB
G29: =B25 -> GAS | H29: THIS WEEK | I29: NET | J29: =K25 -> 3716 | K29: =L25 -> 3720 | L29: =M25 -> 0 | M29: =K29=K31 -> TRUE | N29: =K30-K32 -> -176
I30: CUM | J30: =K26 -> 119972 | K30: =L26 -> 123692 | L30: =M26 -> 123692 | M30: =K30=K32 -> FALSE
H31: LAST SR | I31: NET | K31: 3720
I32: CUM | K32: 123868
L36: SHIP | M36: FAB | U36: RAW
A37: Family Totals | B37: 491D-HV | C37: Net Family Totals | E37: =SUMIFS('Final SR'!J:J,'Final SR'!$E:$E,TOTALss!$B65,'Final SR'!$I:$I,'Final SR'!$I$12) -> 3196 | F37: =SUMIFS('Final SR'!K:K,'Final SR'!$E:$E,TOTALss!$B65,'Final SR'!$I:$I,'Final SR'!$I$12) -> 1112 | G37: =SUMIFS('Final SR'!L:L,'Final SR'!$E:$E,TOTALss!$B65,'Final SR'!$I:$I,'Final SR'!$I$12) -> 836 | H37: =SUMIFS('Final SR'!M:M,'Final SR'!$E:$E,TOTALss!$B65,'Final SR'!$I:$I,'Final SR'!$I$12) -> 1168 | I37: =SUMIFS('Final SR'!N:N,'Final SR'!$E:$E,TOTALss!$B65,'Final SR'!$I:$I,'Final SR'!$I$12) -> 1520 | J37: =SUMIFS('Final SR'!O:O,'Final SR'!$E:$E,TOTALss!$B65,'Final SR'!$I:$I,'Final SR'!$I$12) -> 1044 | K37: =SUMIFS('Final SR'!P:P,'Final SR'!$E:$E,TOTALss!$B65,'Final SR'!$I:$I,'Final SR'!$I$12) -> 1224 | L37: =SUMIFS('Final SR'!Q:Q,'Final SR'!$E:$E,TOTALss!$B65,'Final SR'!$I:$I,'Final SR'!$I$12) -> 1304 | M37: =SUMIFS('Final SR'!R:R,'Final SR'!$E:$E,TOTALss!$B65,'Final SR'!$I:$I,'Final SR'!$I$12) -> 0 | N37: =SUMIFS('Final SR'!S:S,'Final SR'!$E:$E,TOTALss!$B65,'Final SR'!$I:$I,'Final SR'!$I$12) -> 1144 | O37: =SUMIFS('Final SR'!T:T,'Final SR'!$E:$E,TOTALss!$B65,'Final SR'!$I:$I,'Final SR'!$I$12) -> 560 | P37: =SUMIFS('Final SR'!U:U,'Final SR'!$E:$E,TOTALss!$B65,'Final SR'!$I:$I,'Final SR'!$I$12) -> 848 | Q37: =SUMIFS('Final SR'!V:V,'Final SR'!$E:$E,TOTALss!$B65,'Final SR'!$I:$I,'Final SR'!$I$12) -> 616 | R37: =SUMIFS('Final SR'!W:W,'Final SR'!$E:$E,TOTALss!$B65,'Final SR'!$I:$I,'Final SR'!$I$12) -> 804 | S37: =SUMIFS('Final SR'!X:X,'Final SR'!$E:$E,TOTALss!$B65,'Final SR'!$I:$I,'Final SR'!$I$12) -> 612 | T37: =SUMIFS('Final SR'!Y:Y,'Final SR'!$E:$E,TOTALss!$B65,'Final SR'!$I:$I,'Final SR'!$I$12) -> 612 | U37: =SUMIFS('Final SR'!Z:Z,'Final SR'!$E:$E,TOTALss!$B65,'Final SR'!$I:$I,'Final SR'!$I$12) -> 760 | V37: =SUMIFS('Final SR'!AA:AA,'Final SR'!$E:$E,TOTALss!$B65,'Final SR'!$I:$I,'Final SR'!$I$12) -> 916 | W37: =SUMIFS('Final SR'!AB:AB,'Final SR'!$E:$E,TOTALss!$B65,'Final SR'!$I:$I,'Final SR'!$I$12) -> 912 | X37: =SUMIFS('Final SR'!AC:AC,'Final SR'!$E:$E,TOTALss!$B65,'Final SR'!$I:$I,'Final SR'!$I$12) -> 920 | Y37: =SUMIFS('Final SR'!AD:AD,'Final SR'!$E:$E,TOTALss!$B65,'Final SR'!$I:$I,'Final SR'!$I$12) -> 808 | Z37: =SUMIFS('Final SR'!AE:AE,'Final SR'!$E:$E,TOTALss!$B65,'Final SR'!$I:$I,'Final SR'!$I$12) -> 840 | AA37: =SUMIFS('Final SR'!AF:AF,'Final SR'!$E:$E,TOTALss!$B65,'Final SR'!$I:$I,'Final SR'!$I$12) -> 708 | AB37: =SUMIFS('Final SR'!AG:AG,'Final SR'!$E:$E,TOTALss!$B65,'Final SR'!$I:$I,'Final SR'!$I$12) -> 892 | AC37: =SUMIFS('Final SR'!AH:AH,'Final SR'!$E:$E,TOTALss!$B65,'Final SR'!$I:$I,'Final SR'!$I$12) -> 612 | AD37: =SUMIFS('Final SR'!AI:AI,'Final SR'!$E:$E,TOTALss!$B65,'Final SR'!$I:$I,'Final SR'!$I$12) -> 908 | AE37: =SUMIFS('Final SR'!AJ:AJ,'Final SR'!$E:$E,TOTALss!$B65,'Final SR'!$I:$I,'Final SR'!$I$12) -> 872 | AF37: =SUMIFS('Final SR'!AK:AK,'Final SR'!$E:$E,TOTALss!$B65,'Final SR'!$I:$I,'Final SR'!$I$12) -> 876 | AG37: =SUMIFS('Final SR'!AL:AL,'Final SR'!$E:$E,TOTALss!$B65,'Final SR'!$I:$I,'Final SR'!$I$12) -> 1136 | AH37: =SUMIFS('Final SR'!AM:AM,'Final SR'!$E:$E,TOTALss!$B65,'Final SR'!$I:$I,'Final SR'!$I$12) -> 1096 | AI37: =SUMIFS('Final SR'!AN:AN,'Final SR'!$E:$E,TOTALss!$B65,'Final SR'!$I:$I,'Final SR'!$I$12) -> 1104 | AJ37: =SUMIFS('Final SR'!AO:AO,'Final SR'!$E:$E,TOTALss!$B65,'Final SR'!$I:$I,'Final SR'!$I$12) -> 1104 | AK37: =SUMIFS('Final SR'!AP:AP,'Final SR'!$E:$E,TOTALss!$B65,'Final SR'!$I:$I,'Final SR'!$I$12) -> 1104 | AL37: =SUMIFS('Final SR'!AQ:AQ,'Final SR'!$E:$E,TOTALss!$B65,'Final SR'!$I:$I,'Final SR'!$I$12) -> 1104 | AM37: =SUMIFS('Final SR'!AR:AR,'Final SR'!$E:$E,TOTALss!$B65,'Final SR'!$I:$I,'Final SR'!$I$12) -> 1104 | AN37: =SUMIFS('Final SR'!AS:AS,'Final SR'!$E:$E,TOTALss!$B65,'Final SR'!$I:$I,'Final SR'!$I$12) -> 1104 | AO37: =SUMIFS('Final SR'!AT:AT,'Final SR'!$E:$E,TOTALss!$B65,'Final SR'!$I:$I,'Final SR'!$I$12) -> 1104 | AP37: =SUMIFS('Final SR'!AU:AU,'Final SR'!$E:$E,TOTALss!$B65,'Final SR'!$I:$I,'Final SR'!$I$12) -> 1104 | AQ37: =SUMIFS('Final SR'!AV:AV,'Final SR'!$E:$E,TOTALss!$B65,'Final SR'!$I:$I,'Final SR'!$I$12) -> 1104 | AR37: =SUMIFS('Final SR'!AW:AW,'Final SR'!$E:$E,TOTALss!$B65,'Final SR'!$I:$I,'Final SR'!$I$12) -> 1104 | AS37: =SUMIFS('Final SR'!AX:AX,'Final SR'!$E:$E,TOTALss!$B65,'Final SR'!$I:$I,'Final SR'!$I$12) -> 1104 | AT37: =SUMIFS('Final SR'!AY:AY,'Final SR'!$E:$E,TOTALss!$B65,'Final SR'!$I:$I,'Final SR'!$I$12) -> 1104 | AU37: =SUMIFS('Final SR'!AZ:AZ,'Final SR'!$E:$E,TOTALss!$B65,'Final SR'!$I:$I,'Final SR'!$I$12) -> 1104 | AV37: =SUMIFS('Final SR'!BA:BA,'Final SR'!$E:$E,TOTALss!$B65,'Final SR'!$I:$I,'Final SR'!$I$12) -> 1104 | AW37: =SUMIFS('Final SR'!BB:BB,'Final SR'!$E:$E,TOTALss!$B65,'Final SR'!$I:$I,'Final SR'!$I$12) -> 1104 | AX37: =SUMIFS('Final SR'!BC:BC,'Final SR'!$E:$E,TOTALss!$B65,'Final SR'!$I:$I,'Final SR'!$I$12) -> 1104 | AY37: =SUMIFS('Final SR'!BD:BD,'Final SR'!$E:$E,TOTALss!$B65,'Final SR'!$I:$I,'Final SR'!$I$12) -> 1104 | AZ37: =SUMIFS('Final SR'!BE:BE,'Final SR'!$E:$E,TOTALss!$B65,'Final SR'!$I:$I,'Final SR'!$I$12) -> 1104 | BA37: =SUMIFS('Final SR'!BF:BF,'Final SR'!$E:$E,TOTALss!$B65,'Final SR'!$I:$I,'Final SR'!$I$12) -> 1104 | BB37: =SUMIFS('Final SR'!BG:BG,'Final SR'!$E:$E,TOTALss!$B65,'Final SR'!$I:$I,'Final SR'!$I$12) -> 1104 | BC37: =SUMIFS('Final SR'!BH:BH,'Final SR'!$E:$E,TOTALss!$B65,'Final SR'!$I:$I,'Final SR'!$I$12) -> 1104 | BD37: =SUMIFS('Final SR'!BI:BI,'Final SR'!$E:$E,TOTALss!$B65,'Final SR'!$I:$I,'Final SR'!$I$12) -> 1104
C38: Cum Family Totals | E38: =SUMIFS('Final SR'!J:J,'Final SR'!$E:$E,TOTALss!$B65,'Final SR'!$I:$I,'Final SR'!$I$13) -> 31424 | F38: =SUMIFS('Final SR'!K:K,'Final SR'!$E:$E,TOTALss!$B65,'Final SR'!$I:$I,'Final SR'!$I$13) -> 32536 | G38: =SUMIFS('Final SR'!L:L,'Final SR'!$E:$E,TOTALss!$B65,'Final SR'!$I:$I,'Final SR'!$I$13) -> 33372 | H38: =SUMIFS('Final SR'!M:M,'Final SR'!$E:$E,TOTALss!$B65,'Final SR'!$I:$I,'Final SR'!$I$13) -> 34540 | I38: =SUMIFS('Final SR'!N:N,'Final SR'!$E:$E,TOTALss!$B65,'Final SR'!$I:$I,'Final SR'!$I$13) -> 36060 | J38: =SUMIFS('Final SR'!O:O,'Final SR'!$E:$E,TOTALss!$B65,'Final SR'!$I:$I,'Final SR'!$I$13) -> 37104 | K38: =SUMIFS('Final SR'!P:P,'Final SR'!$E:$E,TOTALss!$B65,'Final SR'!$I:$I,'Final SR'!$I$13) -> 38328 | L38: =SUMIFS('Final SR'!Q:Q,'Final SR'!$E:$E,TOTALss!$B65,'Final SR'!$I:$I,'Final SR'!$I$13) -> 39632 | M38: =SUMIFS('Final SR'!R:R,'Final SR'!$E:$E,TOTALss!$B65,'Final SR'!$I:$I,'Final SR'!$I$13) -> 39632 | N38: =SUMIFS('Final SR'!S:S,'Final SR'!$E:$E,TOTALss!$B65,'Final SR'!$I:$I,'Final SR'!$I$13) -> 40776 | O38: =SUMIFS('Final SR'!T:T,'Final SR'!$E:$E,TOTALss!$B65,'Final SR'!$I:$I,'Final SR'!$I$13) -> 41336 | P38: =SUMIFS('Final SR'!U:U,'Final SR'!$E:$E,TOTALss!$B65,'Final SR'!$I:$I,'Final SR'!$I$13) -> 42184 | Q38: =SUMIFS('Final SR'!V:V,'Final SR'!$E:$E,TOTALss!$B65,'Final SR'!$I:$I,'Final SR'!$I$13) -> 42800 | R38: =SUMIFS('Final SR'!W:W,'Final SR'!$E:$E,TOTALss!$B65,'Final SR'!$I:$I,'Final SR'!$I$13) -> 43604 | S38: =SUMIFS('Final SR'!X:X,'Final SR'!$E:$E,TOTALss!$B65,'Final SR'!$I:$I,'Final SR'!$I$13) -> 44216 | T38: =SUMIFS('Final SR'!Y:Y,'Final SR'!$E:$E,TOTALss!$B65,'Final SR'!$I:$I,'Final SR'!$I$13) -> 44828 | U38: =SUMIFS('Final SR'!Z:Z,'Final SR'!$E:$E,TOTALss!$B65,'Final SR'!$I:$I,'Final SR'!$I$13) -> 45588 | V38: =SUMIFS('Final SR'!AA:AA,'Final SR'!$E:$E,TOTALss!$B65,'Final SR'!$I:$I,'Final SR'!$I$13) -> 46504 | W38: =SUMIFS('Final SR'!AB:AB,'Final SR'!$E:$E,TOTALss!$B65,'Final SR'!$I:$I,'Final SR'!$I$13) -> 47416 | X38: =SUMIFS('Final SR'!AC:AC,'Final SR'!$E:$E,TOTALss!$B65,'Final SR'!$I:$I,'Final SR'!$I$13) -> 48336 | Y38: =SUMIFS('Final SR'!AD:AD,'Final SR'!$E:$E,TOTALss!$B65,'Final SR'!$I:$I,'Final SR'!$I$13) -> 49144 | Z38: =SUMIFS('Final SR'!AE:AE,'Final SR'!$E:$E,TOTALss!$B65,'Final SR'!$I:$I,'Final SR'!$I$13) -> 49984 | AA38: =SUMIFS('Final SR'!AF:AF,'Final SR'!$E:$E,TOTALss!$B65,'Final SR'!$I:$I,'Final SR'!$I$13) -> 50692 | AB38: =SUMIFS('Final SR'!AG:AG,'Final SR'!$E:$E,TOTALss!$B65,'Final SR'!$I:$I,'Final SR'!$I$13) -> 51584 | AC38: =SUMIFS('Final SR'!AH:AH,'Final SR'!$E:$E,TOTALss!$B65,'Final SR'!$I:$I,'Final SR'!$I$13) -> 52196 | AD38: =SUMIFS('Final SR'!AI:AI,'Final SR'!$E:$E,TOTALss!$B65,'Final SR'!$I:$I,'Final SR'!$I$13) -> 53104 | AE38: =SUMIFS('Final SR'!AJ:AJ,'Final SR'!$E:$E,TOTALss!$B65,'Final SR'!$I:$I,'Final SR'!$I$13) -> 53976 | AF38: =SUMIFS('Final SR'!AK:AK,'Final SR'!$E:$E,TOTALss!$B65,'Final SR'!$I:$I,'Final SR'!$I$13) -> 54852 | AG38: =SUMIFS('Final SR'!AL:AL,'Final SR'!$E:$E,TOTALss!$B65,'Final SR'!$I:$I,'Final SR'!$I$13) -> 55988 | AH38: =SUMIFS('Final SR'!AM:AM,'Final SR'!$E:$E,TOTALss!$B65,'Final SR'!$I:$I,'Final SR'!$I$13) -> 57084 | AI38: =SUMIFS('Final SR'!AN:AN,'Final SR'!$E:$E,TOTALss!$B65,'Final SR'!$I:$I,'Final SR'!$I$13) -> 58188 | AJ38: =SUMIFS('Final SR'!AO:AO,'Final SR'!$E:$E,TOTALss!$B65,'Final SR'!$I:$I,'Final SR'!$I$13) -> 59292 | AK38: =SUMIFS('Final SR'!AP:AP,'Final SR'!$E:$E,TOTALss!$B65,'Final SR'!$I:$I,'Final SR'!$I$13) -> 60396 | AL38: =SUMIFS('Final SR'!AQ:AQ,'Final SR'!$E:$E,TOTALss!$B65,'Final SR'!$I:$I,'Final SR'!$I$13) -> 61500 | AM38: =SUMIFS('Final SR'!AR:AR,'Final SR'!$E:$E,TOTALss!$B65,'Final SR'!$I:$I,'Final SR'!$I$13) -> 62604 | AN38: =SUMIFS('Final SR'!AS:AS,'Final SR'!$E:$E,TOTALss!$B65,'Final SR'!$I:$I,'Final SR'!$I$13) -> 63708 | AO38: =SUMIFS('Final SR'!AT:AT,'Final SR'!$E:$E,TOTALss!$B65,'Final SR'!$I:$I,'Final SR'!$I$13) -> 64812 | AP38: =SUMIFS('Final SR'!AU:AU,'Final SR'!$E:$E,TOTALss!$B65,'Final SR'!$I:$I,'Final SR'!$I$13) -> 65916 | AQ38: =SUMIFS('Final SR'!AV:AV,'Final SR'!$E:$E,TOTALss!$B65,'Final SR'!$I:$I,'Final SR'!$I$13) -> 67020 | AR38: =SUMIFS('Final SR'!AW:AW,'Final SR'!$E:$E,TOTALss!$B65,'Final SR'!$I:$I,'Final SR'!$I$13) -> 68124 | AS38: =SUMIFS('Final SR'!AX:AX,'Final SR'!$E:$E,TOTALss!$B65,'Final SR'!$I:$I,'Final SR'!$I$13) -> 69228 | AT38: =SUMIFS('Final SR'!AY:AY,'Final SR'!$E:$E,TOTALss!$B65,'Final SR'!$I:$I,'Final SR'!$I$13) -> 70332 | AU38: =SUMIFS('Final SR'!AZ:AZ,'Final SR'!$E:$E,TOTALss!$B65,'Final SR'!$I:$I,'Final SR'!$I$13) -> 71436 | AV38: =SUMIFS('Final SR'!BA:BA,'Final SR'!$E:$E,TOTALss!$B65,'Final SR'!$I:$I,'Final SR'!$I$13) -> 72540 | AW38: =SUMIFS('Final SR'!BB:BB,'Final SR'!$E:$E,TOTALss!$B65,'Final SR'!$I:$I,'Final SR'!$I$13) -> 73644 | AX38: =SUMIFS('Final SR'!BC:BC,'Final SR'!$E:$E,TOTALss!$B65,'Final SR'!$I:$I,'Final SR'!$I$13) -> 74748 | AY38: =SUMIFS('Final SR'!BD:BD,'Final SR'!$E:$E,TOTALss!$B65,'Final SR'!$I:$I,'Final SR'!$I$13) -> 75852 | AZ38: =SUMIFS('Final SR'!BE:BE,'Final SR'!$E:$E,TOTALss!$B65,'Final SR'!$I:$I,'Final SR'!$I$13) -> 76956 | BA38: =SUMIFS('Final SR'!BF:BF,'Final SR'!$E:$E,TOTALss!$B65,'Final SR'!$I:$I,'Final SR'!$I$13) -> 78060 | BB38: =SUMIFS('Final SR'!BG:BG,'Final SR'!$E:$E,TOTALss!$B65,'Final SR'!$I:$I,'Final SR'!$I$13) -> 79164 | BC38: =SUMIFS('Final SR'!BH:BH,'Final SR'!$E:$E,TOTALss!$B65,'Final SR'!$I:$I,'Final SR'!$I$13) -> 80268 | BD38: =SUMIFS('Final SR'!BI:BI,'Final SR'!$E:$E,TOTALss!$B65,'Final SR'!$I:$I,'Final SR'!$I$13) -> 81372
L39: SHIP | M39: FAB | U39: RAW
K40: SHIP | L40: FAB
G41: =B37 -> 491D-HV | H41: THIS WEEK | I41: NET | J41: =K37 -> 1224 | K41: =L37 -> 1304 | L41: =M37 -> 0 | M41: =K41=K43 -> TRUE | N41: =K42-K44 -> 0
I42: CUM | J42: =K38 -> 38328 | K42: =L38 -> 39632 | L42: =M38 -> 39632 | M42: =K42=K44 -> TRUE
H43: LAST SR | I43: NET | K43: 1304
I44: CUM | K44: 39632

Sheet TOTALss
B1: TOTAL NO OF PALLETS
B2: NO OF CONTAINERS
